Workbook

Sheet МП_Total
B2: Рекламная система | C2: Рекламный формат, размер, вид размещения | D2: Таргетинги | F2: Январь | G2: Февраль | H2: Март | I2: Апрель | J2: Май | K2: Июнь | L2: Июль | M2: Август | N2: Сентябрь | O2: Октябрь | P2: Ноябрь | Q2: Декабрь | S2: Период | T2: Модель закупки | U2: Стоимость единицы закупки (без НДС) | V2: Кол-во единиц закупки | X2: Стоимость (без НДС) | Y2: СК, % | Z2: Стоимость с учетом СК (без НДС) | AA2: АК, % | AB2: Итоговая стоимость (без НДС) | AC2: Итоговая стоимость (с НДС) | AD2: Доля рекламного бюджета, % | AF2: Показы | AG2: Частота (весь срок) | AH2: Охват | AI2: CPM (с НДС) | AJ2: CPT (с НДС) | AK2: Доступная емкость аудитории | AL2: SOV, % | AN2: CTR, % | AO2: Клики | AP2: CPC (с НДС) | AR2: CR, % | AS2: Конверсии | AT2: CPA (с НДС) | AV2: CR(I), % | AW2: Установки | AX2: CPI | AZ2: ДРР, % | BA2: Средний чек | BB2: Доход | BD2: RTR, % | BE2: Дочитывания | BF2: CPR (с НДС) | BG2: % открытий статьи | BH2: Открытия статьи | BJ2: ER, % | BK2: Вовлечения | BL2: CPE (с НДС)
B3: Рекламная система | C3: Рекламный формат, размер, вид размещения | D3: См. *Название вкладки* | T3: CPI | U3: =IFERROR(X3/V3,"-") -> - | V3: =IFERROR(МП_Periods!I3+МП_Periods!I11+МП_Periods!I19+МП_Periods!I27+МП_Periods!I35+МП_Periods!I43+МП_Periods!I51+МП_Periods!I59+МП_Periods!I67+МП_Periods!I75+МП_Periods!I83+МП_Periods!I91,"-") -> 0 | X3: =IFERROR(МП_Periods!K3+МП_Periods!K11+МП_Periods!K19+МП_Periods!K27+МП_Periods!K35+МП_Periods!K43+МП_Periods!K51+МП_Periods!K59+МП_Periods!K67+МП_Periods!K75+МП_Periods!K83+МП_Periods!K91,"-") -> 0 | Y3: =IFERROR(1-(Z3/X3),"-") -> - | Z3: =IFERROR(МП_Periods!M3+МП_Periods!M11+МП_Periods!M19+МП_Periods!M27+МП_Periods!M35+МП_Periods!M43+МП_Periods!M51+МП_Periods!M59+МП_Periods!M67+МП_Periods!M75+МП_Periods!M83+МП_Periods!M91,"-") -> 0 | AA3: =IFERROR((AB3/Z3)-1,"-") -> - | AB3: =IFERROR(МП_Periods!O3+МП_Periods!O11+МП_Periods!O19+МП_Periods!O27+МП_Periods!O35+МП_Periods!O43+МП_Periods!O51+МП_Periods!O59+МП_Periods!O67+МП_Periods!O75+МП_Periods!O83+МП_Periods!O91,"-") -> 0 | AC3: =IFERROR(МП_Periods!P3+МП_Periods!P11+МП_Periods!P19+МП_Periods!P27+МП_Periods!P35+МП_Periods!P43+МП_Periods!P51+МП_Periods!P59+МП_Periods!P67+МП_Periods!P75+МП_Periods!P83+МП_Periods!P91,"-") -> 0 | AD3: =IFERROR(AC3/$AC$8,"-") -> - | AF3: =IFERROR(МП_Periods!S3+МП_Periods!S11+МП_Periods!S19+МП_Periods!S27+МП_Periods!S35+МП_Periods!S43+МП_Periods!S51+МП_Periods!S59+МП_Periods!S67+МП_Periods!S75+МП_Periods!S83+МП_Periods!S91,"-") -> 0 | AG3: =IFERROR(AF3/AH3,"-") -> - | AH3: =IFERROR(МП_Periods!#REF!+МП_Periods!#REF!+МП_Periods!#REF!+МП_Periods!#REF!+МП_Periods!#REF!+МП_Periods!#REF!+МП_Periods!#REF!+МП_Periods!#REF!+МП_Periods!#REF!+МП_Periods!#REF!+МП_Periods!#REF!+МП_Periods!#REF!,"-") -> - | AI3: =IFERROR(AC3/AF3*1000,"-") -> - | AJ3: =IFERROR(AC3/AH3*1000,"-") -> - | AK3: =IFERROR(MAX(МП_Periods!#REF!,МП_Periods!#REF!,МП_Periods!#REF!,МП_Periods!#REF!,МП_Periods!#REF!,МП_Periods!#REF!,МП_Periods!#REF!,МП_Periods!#REF!,МП_Periods!#REF!,МП_Periods!#REF!,МП_Periods!#REF!,МП_Periods!#REF!),"-") -> - | AL3: =IFERROR(#REF!/AK3,"-") -> - | AN3: =IFERROR(AO3/AF3,"-") -> - | AO3: =IFERROR(МП_Periods!W3+МП_Periods!W11+МП_Periods!W19+МП_Periods!W27+МП_Periods!W35+МП_Periods!W43+МП_Periods!W51+МП_Periods!W59+МП_Periods!W67+МП_Periods!W75+МП_Periods!W83+МП_Periods!W91,"-") -> 0 | AP3: =IFERROR(AC3/AO3,"-") -> - | AR3: =IFERROR(AS3/AO3,"-") -> - | AS3: =IFERROR(МП_Periods!AA3+МП_Periods!AA11+МП_Periods!AA19+МП_Periods!AA27+МП_Periods!AA35+МП_Periods!AA43+МП_Periods!AA51+МП_Periods!AA59+МП_Periods!AA67+МП_Periods!AA75+МП_Periods!AA83+МП_Periods!AA91,"-") -> 0 | AT3: =IFERROR(AC3/AS3,"-") -> - | AV3: =IFERROR(AW3/AO3,"-") -> - | AW3: =IFERROR(МП_Periods!AE3+МП_Periods!AE11+МП_Periods!AE19+МП_Periods!AE27+МП_Periods!AE35+МП_Periods!AE43+МП_Periods!AE51+МП_Periods!AE59+МП_Periods!AE67+МП_Periods!AE75+МП_Periods!AE83+МП_Periods!AE91,"-") -> 0 | AX3: =IFERROR(AC3/AW3,"-") -> - | AZ3: =IFERROR(AC3/BB3,"-") -> - | BA3: =IFERROR(AVERAGE(МП_Periods!AI3,МП_Periods!AI11,МП_Periods!AI19,МП_Periods!AI27,МП_Periods!AI35,МП_Periods!AI43,МП_Periods!AI51,МП_Periods!AI59,МП_Periods!AI67,МП_Periods!AI75,МП_Periods!AI83,МП_Periods!AI91),"-") -> - | BB3: - | BD3: =IFERROR(BE3/AF3,"-") -> - | BE3: =IFERROR(#REF!+#REF!+#REF!+#REF!+#REF!+#REF!+#REF!+#REF!+#REF!+#REF!+#REF!+#REF!,"-") -> - | BF3: =IFERROR(AC3/BE3,"-") -> - | BG3: =IFERROR(BH3/AF3,"-") -> - | BH3: =IFERROR(#REF!+#REF!+#REF!+#REF!+#REF!+#REF!+#REF!+#REF!+#REF!+#REF!+#REF!+#REF!,"-") -> - | BJ3: =IFERROR(BK3/AF3,"-") -> - | BK3: =IFERROR(#REF!+#REF!+#REF!+#REF!+#REF!+#REF!+#REF!+#REF!+#REF!+#REF!+#REF!+#REF!,"-") -> - | BL3: =IFERROR(AC3/BK3,"-") -> -
B4: Рекламная система | C4: Рекламный формат, размер, вид размещения | D4: См. *Название вкладки* | T4: Дочитывания | U4: =IFERROR(X4/V4,"-") -> - | V4: =IFERROR(МП_Periods!I4+МП_Periods!I12+МП_Periods!I20+МП_Periods!I28+МП_Periods!I36+МП_Periods!I44+МП_Periods!I52+МП_Periods!I60+МП_Periods!I68+МП_Periods!I76+МП_Periods!I84+МП_Periods!I92,"-") -> 0 | X4: =IFERROR(МП_Periods!K4+МП_Periods!K12+МП_Periods!K20+МП_Periods!K28+МП_Periods!K36+МП_Periods!K44+МП_Periods!K52+МП_Periods!K60+МП_Periods!K68+МП_Periods!K76+МП_Periods!K84+МП_Periods!K92,"-") -> 0 | Y4: =IFERROR(1-(Z4/X4),"-") -> - | Z4: =IFERROR(МП_Periods!M4+МП_Periods!M12+МП_Periods!M20+МП_Periods!M28+МП_Periods!M36+МП_Periods!M44+МП_Periods!M52+МП_Periods!M60+МП_Periods!M68+МП_Periods!M76+МП_Periods!M84+МП_Periods!M92,"-") -> 0 | AA4: =IFERROR((AB4/Z4)-1,"-") -> - | AB4: =IFERROR(МП_Periods!O4+МП_Periods!O12+МП_Periods!O20+МП_Periods!O28+МП_Periods!O36+МП_Periods!O44+МП_Periods!O52+МП_Periods!O60+МП_Periods!O68+МП_Periods!O76+МП_Periods!O84+МП_Periods!O92,"-") -> 0 | AC4: =IFERROR(МП_Periods!P4+МП_Periods!P12+МП_Periods!P20+МП_Periods!P28+МП_Periods!P36+МП_Periods!P44+МП_Periods!P52+МП_Periods!P60+МП_Periods!P68+МП_Periods!P76+МП_Periods!P84+МП_Periods!P92,"-") -> 0 | AD4: =IFERROR(AC4/$AC$8,"-") -> - | AF4: =IFERROR(МП_Periods!S4+МП_Periods!S12+МП_Periods!S20+МП_Periods!S28+МП_Periods!S36+МП_Periods!S44+МП_Periods!S52+МП_Periods!S60+МП_Periods!S68+МП_Periods!S76+МП_Periods!S84+МП_Periods!S92,"-") -> 0 | AG4: =IFERROR(AF4/AH4,"-") -> - | AH4: =IFERROR(МП_Periods!#REF!+МП_Periods!#REF!+МП_Periods!#REF!+МП_Periods!#REF!+МП_Periods!#REF!+МП_Periods!#REF!+МП_Periods!#REF!+МП_Periods!#REF!+МП_Periods!#REF!+МП_Periods!#REF!+МП_Periods!#REF!+МП_Periods!#REF!,"-") -> - | AI4: =IFERROR(AC4/AF4*1000,"-") -> - | AJ4: =IFERROR(AC4/AH4*1000,"-") -> - | AK4: =IFERROR(MAX(МП_Periods!#REF!,МП_Periods!#REF!,МП_Periods!#REF!,МП_Periods!#REF!,МП_Periods!#REF!,МП_Periods!#REF!,МП_Periods!#REF!,МП_Periods!#REF!,МП_Periods!#REF!,МП_Periods!#REF!,МП_Periods!#REF!,МП_Periods!#REF!),"-") -> - | AL4: =IFERROR(#REF!/AK4,"-") -> - | AN4: =IFERROR(AO4/AF4,"-") -> - | AO4: =IFERROR(МП_Periods!W4+МП_Periods!W12+МП_Periods!W20+МП_Periods!W28+МП_Periods!W36+МП_Periods!W44+МП_Periods!W52+МП_Periods!W60+МП_Periods!W68+МП_Periods!W76+МП_Periods!W84+МП_Periods!W92,"-") -> 0 | AP4: =IFERROR(AC4/AO4,"-") -> - | AR4: =IFERROR(AS4/AO4,"-") -> - | AS4: =IFERROR(МП_Periods!AA4+МП_Periods!AA12+МП_Periods!AA20+МП_Periods!AA28+МП_Periods!AA36+МП_Periods!AA44+МП_Periods!AA52+МП_Periods!AA60+МП_Periods!AA68+МП_Periods!AA76+МП_Periods!AA84+МП_Periods!AA92,"-") -> 0 | AT4: =IFERROR(AC4/AS4,"-") -> - | AV4: =IFERROR(AW4/AO4,"-") -> - | AW4: =IFERROR(МП_Periods!AE4+МП_Periods!AE12+МП_Periods!AE20+МП_Periods!AE28+МП_Periods!AE36+МП_Periods!AE44+МП_Periods!AE52+МП_Periods!AE60+МП_Periods!AE68+МП_Periods!AE76+МП_Periods!AE84+МП_Periods!AE92,"-") -> 0 | AX4: =IFERROR(AC4/AW4,"-") -> - | AZ4: =IFERROR(AC4/BB4,"-") -> - | BA4: =IFERROR(AVERAGE(МП_Periods!AI4,МП_Periods!AI12,МП_Periods!AI20,МП_Periods!AI28,МП_Periods!AI36,МП_Periods!AI44,МП_Periods!AI52,МП_Periods!AI60,МП_Periods!AI68,МП_Periods!AI76,МП_Periods!AI84,МП_Periods!AI92),"-") -> - | BB4: - | BD4: =IFERROR(BE4/AF4,"-") -> - | BE4: =IFERROR(#REF!+#REF!+#REF!+#REF!+#REF!+#REF!+#REF!+#REF!+#REF!+#REF!+#REF!+#REF!,"-") -> - | BF4: =IFERROR(AC4/BE4,"-") -> - | BG4: =IFERROR(BH4/AF4,"-") -> - | BH4: =IFERROR(#REF!+#REF!+#REF!+#REF!+#REF!+#REF!+#REF!+#REF!+#REF!+#REF!+#REF!+#REF!,"-") -> - | BJ4: =IFERROR(BK4/AF4,"-") -> - | BK4: =IFERROR(#REF!+#REF!+#REF!+#REF!+#REF!+#REF!+#REF!+#REF!+#REF!+#REF!+#REF!+#REF!,"-") -> - | BL4: =IFERROR(AC4/BK4,"-") -> -
B5: Рекламная система | C5: Рекламный формат, размер, вид размещения | D5: См. *Название вкладки* | T5: CPM | U5: =IFERROR(X5/V5,"-") -> - | V5: =IFERROR(МП_Periods!I5+МП_Periods!I13+МП_Periods!I21+МП_Periods!I29+МП_Periods!I37+МП_Periods!I45+МП_Periods!I53+МП_Periods!I61+МП_Periods!I69+МП_Periods!I77+МП_Periods!I85+МП_Periods!I93,"-") -> 0 | X5: =IFERROR(МП_Periods!K5+МП_Periods!K13+МП_Periods!K21+МП_Periods!K29+МП_Periods!K37+МП_Periods!K45+МП_Periods!K53+МП_Periods!K61+МП_Periods!K69+МП_Periods!K77+МП_Periods!K85+МП_Periods!K93,"-") -> 0 | Y5: =IFERROR(1-(Z5/X5),"-") -> - | Z5: =IFERROR(МП_Periods!M5+МП_Periods!M13+МП_Periods!M21+МП_Periods!M29+МП_Periods!M37+МП_Periods!M45+МП_Periods!M53+МП_Periods!M61+МП_Periods!M69+МП_Periods!M77+МП_Periods!M85+МП_Periods!M93,"-") -> 0 | AA5: =IFERROR((AB5/Z5)-1,"-") -> - | AB5: =IFERROR(МП_Periods!O5+МП_Periods!O13+МП_Periods!O21+МП_Periods!O29+МП_Periods!O37+МП_Periods!O45+МП_Periods!O53+МП_Periods!O61+МП_Periods!O69+МП_Periods!O77+МП_Periods!O85+МП_Periods!O93,"-") -> 0 | AC5: =IFERROR(МП_Periods!P5+МП_Periods!P13+МП_Periods!P21+МП_Periods!P29+МП_Periods!P37+МП_Periods!P45+МП_Periods!P53+МП_Periods!P61+МП_Periods!P69+МП_Periods!P77+МП_Periods!P85+МП_Periods!P93,"-") -> 0 | AD5: =IFERROR(AC5/$AC$8,"-") -> - | AF5: =IFERROR(МП_Periods!S5+МП_Periods!S13+МП_Periods!S21+МП_Periods!S29+МП_Periods!S37+МП_Periods!S45+МП_Periods!S53+МП_Periods!S61+МП_Periods!S69+МП_Periods!S77+МП_Periods!S85+МП_Periods!S93,"-") -> 0 | AG5: =IFERROR(AF5/AH5,"-") -> - | AH5: =IFERROR(МП_Periods!#REF!+МП_Periods!#REF!+МП_Periods!#REF!+МП_Periods!#REF!+МП_Periods!#REF!+МП_Periods!#REF!+МП_Periods!#REF!+МП_Periods!#REF!+МП_Periods!#REF!+МП_Periods!#REF!+МП_Periods!#REF!+МП_Periods!#REF!,"-") -> - | AI5: =IFERROR(AC5/AF5*1000,"-") -> - | AJ5: =IFERROR(AC5/AH5*1000,"-") -> - | AK5: =IFERROR(MAX(МП_Periods!#REF!,МП_Periods!#REF!,МП_Periods!#REF!,МП_Periods!#REF!,МП_Periods!#REF!,МП_Periods!#REF!,МП_Periods!#REF!,МП_Periods!#REF!,МП_Periods!#REF!,МП_Periods!#REF!,МП_Periods!#REF!,МП_Periods!#REF!),"-") -> - | AL5: =IFERROR(#REF!/AK5,"-") -> - | AN5: =IFERROR(AO5/AF5,"-") -> - | AO5: =IFERROR(МП_Periods!W5+МП_Periods!W13+МП_Periods!W21+МП_Periods!W29+МП_Periods!W37+МП_Periods!W45+МП_Periods!W53+МП_Periods!W61+МП_Periods!W69+МП_Periods!W77+МП_Periods!W85+МП_Periods!W93,"-") -> 0 | AP5: =IFERROR(AC5/AO5,"-") -> - | AR5: =IFERROR(AS5/AO5,"-") -> - | AS5: =IFERROR(МП_Periods!AA5+МП_Periods!AA13+МП_Periods!AA21+МП_Periods!AA29+МП_Periods!AA37+МП_Periods!AA45+МП_Periods!AA53+МП_Periods!AA61+МП_Periods!AA69+МП_Periods!AA77+МП_Periods!AA85+МП_Periods!AA93,"-") -> 0 | AT5: =IFERROR(AC5/AS5,"-") -> - | AV5: =IFERROR(AW5/AO5,"-") -> - | AW5: =IFERROR(МП_Periods!AE5+МП_Periods!AE13+МП_Periods!AE21+МП_Periods!AE29+МП_Periods!AE37+МП_Periods!AE45+МП_Periods!AE53+МП_Periods!AE61+МП_Periods!AE69+МП_Periods!AE77+МП_Periods!AE85+МП_Periods!AE93,"-") -> 0 | AX5: =IFERROR(AC5/AW5,"-") -> - | AZ5: =IFERROR(AC5/BB5,"-") -> - | BA5: =IFERROR(AVERAGE(МП_Periods!AI5,МП_Periods!AI13,МП_Periods!AI21,МП_Periods!AI29,МП_Periods!AI37,МП_Periods!AI45,МП_Periods!AI53,МП_Periods!AI61,МП_Periods!AI69,МП_Periods!AI77,МП_Periods!AI85,МП_Periods!AI93),"-") -> - | BB5: - | BD5: =IFERROR(BE5/AF5,"-") -> - | BE5: =IFERROR(#REF!+#REF!+#REF!+#REF!+#REF!+#REF!+#REF!+#REF!+#REF!+#REF!+#REF!+#REF!,"-") -> - | BF5: =IFERROR(AC5/BE5,"-") -> - | BG5: =IFERROR(BH5/AF5,"-") -> - | BH5: =IFERROR(#REF!+#REF!+#REF!+#REF!+#REF!+#REF!+#REF!+#REF!+#REF!+#REF!+#REF!+#REF!,"-") -> - | BJ5: =IFERROR(BK5/AF5,"-") -> - | BK5: =IFERROR(#REF!+#REF!+#REF!+#REF!+#REF!+#REF!+#REF!+#REF!+#REF!+#REF!+#REF!+#REF!,"-") -> - | BL5: =IFERROR(AC5/BK5,"-") -> -
B6: Рекламная система | C6: Рекламный формат, размер, вид размещения | D6: См. *Название вкладки* | T6: CPM | U6: =IFERROR(X6/V6,"-") -> - | V6: =IFERROR(МП_Periods!I6+МП_Periods!I14+МП_Periods!I22+МП_Periods!I30+МП_Periods!I38+МП_Periods!I46+МП_Periods!I54+МП_Periods!I62+МП_Periods!I70+МП_Periods!I78+МП_Periods!I86+МП_Periods!I94,"-") -> 0 | X6: =IFERROR(МП_Periods!K6+МП_Periods!K14+МП_Periods!K22+МП_Periods!K30+МП_Periods!K38+МП_Periods!K46+МП_Periods!K54+МП_Periods!K62+МП_Periods!K70+МП_Periods!K78+МП_Periods!K86+МП_Periods!K94,"-") -> 0 | Y6: =IFERROR(1-(Z6/X6),"-") -> - | Z6: =IFERROR(МП_Periods!M6+МП_Periods!M14+МП_Periods!M22+МП_Periods!M30+МП_Periods!M38+МП_Periods!M46+МП_Periods!M54+МП_Periods!M62+МП_Periods!M70+МП_Periods!M78+МП_Periods!M86+МП_Periods!M94,"-") -> 0 | AA6: =IFERROR((AB6/Z6)-1,"-") -> - | AB6: =IFERROR(МП_Periods!O6+МП_Periods!O14+МП_Periods!O22+МП_Periods!O30+МП_Periods!O38+МП_Periods!O46+МП_Periods!O54+МП_Periods!O62+МП_Periods!O70+МП_Periods!O78+МП_Periods!O86+МП_Periods!O94,"-") -> 0 | AC6: =IFERROR(МП_Periods!P6+МП_Periods!P14+МП_Periods!P22+МП_Periods!P30+МП_Periods!P38+МП_Periods!P46+МП_Periods!P54+МП_Periods!P62+МП_Periods!P70+МП_Periods!P78+МП_Periods!P86+МП_Periods!P94,"-") -> 0 | AD6: =IFERROR(AC6/$AC$8,"-") -> - | AF6: =IFERROR(МП_Periods!S6+МП_Periods!S14+МП_Periods!S22+МП_Periods!S30+МП_Periods!S38+МП_Periods!S46+МП_Periods!S54+МП_Periods!S62+МП_Periods!S70+МП_Periods!S78+МП_Periods!S86+МП_Periods!S94,"-") -> 0 | AG6: =IFERROR(AF6/AH6,"-") -> - | AH6: =IFERROR(МП_Periods!#REF!+МП_Periods!#REF!+МП_Periods!#REF!+МП_Periods!#REF!+МП_Periods!#REF!+МП_Periods!#REF!+МП_Periods!#REF!+МП_Periods!#REF!+МП_Periods!#REF!+МП_Periods!#REF!+МП_Periods!#REF!+МП_Periods!#REF!,"-") -> - | AI6: =IFERROR(AC6/AF6*1000,"-") -> - | AJ6: =IFERROR(AC6/AH6*1000,"-") -> - | AK6: =IFERROR(MAX(МП_Periods!#REF!,МП_Periods!#REF!,МП_Periods!#REF!,МП_Periods!#REF!,МП_Periods!#REF!,МП_Periods!#REF!,МП_Periods!#REF!,МП_Periods!#REF!,МП_Periods!#REF!,МП_Periods!#REF!,МП_Periods!#REF!,МП_Periods!#REF!),"-") -> - | AL6: =IFERROR(#REF!/AK6,"-") -> - | AN6: =IFERROR(AO6/AF6,"-") -> - | AO6: =IFERROR(МП_Periods!W6+МП_Periods!W14+МП_Periods!W22+МП_Periods!W30+МП_Periods!W38+МП_Periods!W46+МП_Periods!W54+МП_Periods!W62+МП_Periods!W70+МП_Periods!W78+МП_Periods!W86+МП_Periods!W94,"-") -> 0 | AP6: =IFERROR(AC6/AO6,"-") -> - | AR6: =IFERROR(AS6/AO6,"-") -> - | AS6: =IFERROR(МП_Periods!AA6+МП_Periods!AA14+МП_Periods!AA22+МП_Periods!AA30+МП_Periods!AA38+МП_Periods!AA46+МП_Periods!AA54+МП_Periods!AA62+МП_Periods!AA70+МП_Periods!AA78+МП_Periods!AA86+МП_Periods!AA94,"-") -> 0 | AT6: =IFERROR(AC6/AS6,"-") -> - | AV6: =IFERROR(AW6/AO6,"-") -> - | AW6: =IFERROR(МП_Periods!AE6+МП_Periods!AE14+МП_Periods!AE22+МП_Periods!AE30+МП_Periods!AE38+МП_Periods!AE46+МП_Periods!AE54+МП_Periods!AE62+МП_Periods!AE70+МП_Periods!AE78+МП_Periods!AE86+МП_Periods!AE94,"-") -> 0 | AX6: =IFERROR(AC6/AW6,"-") -> - | AZ6: =IFERROR(AC6/BB6,"-") -> - | BA6: =IFERROR(AVERAGE(МП_Periods!AI6,МП_Periods!AI14,МП_Periods!AI22,МП_Periods!AI30,МП_Periods!AI38,МП_Periods!AI46,МП_Periods!AI54,МП_Periods!AI62,МП_Periods!AI70,МП_Periods!AI78,МП_Periods!AI86,МП_Periods!AI94),"-") -> - | BB6: - | BD6: =IFERROR(BE6/AF6,"-") -> - | BE6: =IFERROR(#REF!+#REF!+#REF!+#REF!+#REF!+#REF!+#REF!+#REF!+#REF!+#REF!+#REF!+#REF!,"-") -> - | BF6: =IFERROR(AC6/BE6,"-") -> - | BG6: =IFERROR(BH6/AF6,"-") -> - | BH6: =IFERROR(#REF!+#REF!+#REF!+#REF!+#REF!+#REF!+#REF!+#REF!+#REF!+#REF!+#REF!+#REF!,"-") -> - | BJ6: =IFERROR(BK6/AF6,"-") -> - | BK6: =IFERROR(#REF!+#REF!+#REF!+#REF!+#REF!+#REF!+#REF!+#REF!+#REF!+#REF!+#REF!+#REF!,"-") -> - | BL6: =IFERROR(AC6/BK6,"-") -> -
B7: Рекламная система | C7: Рекламный формат, размер, вид размещения | D7: См. *Название вкладки* | T7: CPM | U7: =IFERROR(X7/V7,"-") -> - | V7: =IFERROR(МП_Periods!I7+МП_Periods!I15+МП_Periods!I23+МП_Periods!I31+МП_Periods!I39+МП_Periods!I47+МП_Periods!I55+МП_Periods!I63+МП_Periods!I71+МП_Periods!I79+МП_Periods!I87+МП_Periods!I95,"-") -> 0 | X7: =IFERROR(МП_Periods!K7+МП_Periods!K15+МП_Periods!K23+МП_Periods!K31+МП_Periods!K39+МП_Periods!K47+МП_Periods!K55+МП_Periods!K63+МП_Periods!K71+МП_Periods!K79+МП_Periods!K87+МП_Periods!K95,"-") -> 0 | Y7: =IFERROR(1-(Z7/X7),"-") -> - | Z7: =IFERROR(МП_Periods!M7+МП_Periods!M15+МП_Periods!M23+МП_Periods!M31+МП_Periods!M39+МП_Periods!M47+МП_Periods!M55+МП_Periods!M63+МП_Periods!M71+МП_Periods!M79+МП_Periods!M87+МП_Periods!M95,"-") -> 0 | AA7: =IFERROR((AB7/Z7)-1,"-") -> - | AB7: =IFERROR(МП_Periods!O7+МП_Periods!O15+МП_Periods!O23+МП_Periods!O31+МП_Periods!O39+МП_Periods!O47+МП_Periods!O55+МП_Periods!O63+МП_Periods!O71+МП_Periods!O79+МП_Periods!O87+МП_Periods!O95,"-") -> 0 | AC7: =IFERROR(МП_Periods!P7+МП_Periods!P15+МП_Periods!P23+МП_Periods!P31+МП_Periods!P39+МП_Periods!P47+МП_Periods!P55+МП_Periods!P63+МП_Periods!P71+МП_Periods!P79+МП_Periods!P87+МП_Periods!P95,"-") -> 0 | AD7: =IFERROR(AC7/$AC$8,"-") -> - | AF7: =IFERROR(МП_Periods!S7+МП_Periods!S15+МП_Periods!S23+МП_Periods!S31+МП_Periods!S39+МП_Periods!S47+МП_Periods!S55+МП_Periods!S63+МП_Periods!S71+МП_Periods!S79+МП_Periods!S87+МП_Periods!S95,"-") -> 0 | AG7: =IFERROR(AF7/AH7,"-") -> - | AH7: =IFERROR(МП_Periods!#REF!+МП_Periods!#REF!+МП_Periods!#REF!+МП_Periods!#REF!+МП_Periods!#REF!+МП_Periods!#REF!+МП_Periods!#REF!+МП_Periods!#REF!+МП_Periods!#REF!+МП_Periods!#REF!+МП_Periods!#REF!+МП_Periods!#REF!,"-") -> - | AI7: =IFERROR(AC7/AF7*1000,"-") -> - | AJ7: =IFERROR(AC7/AH7*1000,"-") -> - | AK7: =IFERROR(MAX(МП_Periods!#REF!,МП_Periods!#REF!,МП_Periods!#REF!,МП_Periods!#REF!,МП_Periods!#REF!,МП_Periods!#REF!,МП_Periods!#REF!,МП_Periods!#REF!,МП_Periods!#REF!,МП_Periods!#REF!,МП_Periods!#REF!,МП_Periods!#REF!),"-") -> - | AL7: =IFERROR(#REF!/AK7,"-") -> - | AN7: =IFERROR(AO7/AF7,"-") -> - | AO7: =IFERROR(МП_Periods!W7+МП_Periods!W15+МП_Periods!W23+МП_Periods!W31+МП_Periods!W39+МП_Periods!W47+МП_Periods!W55+МП_Periods!W63+МП_Periods!W71+МП_Periods!W79+МП_Periods!W87+МП_Periods!W95,"-") -> 0 | AP7: =IFERROR(AC7/AO7,"-") -> - | AR7: =IFERROR(AS7/AO7,"-") -> - | AS7: =IFERROR(МП_Periods!AA7+МП_Periods!AA15+МП_Periods!AA23+МП_Periods!AA31+МП_Periods!AA39+МП_Periods!AA47+МП_Periods!AA55+МП_Periods!AA63+МП_Periods!AA71+МП_Periods!AA79+МП_Periods!AA87+МП_Periods!AA95,"-") -> 0 | AT7: =IFERROR(AC7/AS7,"-") -> - | AV7: =IFERROR(AW7/AO7,"-") -> - | AW7: =IFERROR(МП_Periods!AE7+МП_Periods!AE15+МП_Periods!AE23+МП_Periods!AE31+МП_Periods!AE39+МП_Periods!AE47+МП_Periods!AE55+МП_Periods!AE63+МП_Periods!AE71+МП_Periods!AE79+МП_Periods!AE87+МП_Periods!AE95,"-") -> 0 | AX7: =IFERROR(AC7/AW7,"-") -> - | AZ7: =IFERROR(AC7/BB7,"-") -> - | BA7: =IFERROR(AVERAGE(МП_Periods!AI7,МП_Periods!AI15,МП_Periods!AI23,МП_Periods!AI31,МП_Periods!AI39,МП_Periods!AI47,МП_Periods!AI55,МП_Periods!AI63,МП_Periods!AI71,МП_Periods!AI79,МП_Periods!AI87,МП_Periods!AI95),"-") -> - | BB7: - | BD7: =IFERROR(BE7/AF7,"-") -> - | BE7: =IFERROR(#REF!+#REF!+#REF!+#REF!+#REF!+#REF!+#REF!+#REF!+#REF!+#REF!+#REF!+#REF!,"-") -> - | BF7: =IFERROR(AC7/BE7,"-") -> - | BG7: =IFERROR(BH7/AF7,"-") -> - | BH7: =IFERROR(#REF!+#REF!+#REF!+#REF!+#REF!+#REF!+#REF!+#REF!+#REF!+#REF!+#REF!+#REF!,"-") -> - | BJ7: =IFERROR(BK7/AF7,"-") -> - | BK7: =IFERROR(#REF!+#REF!+#REF!+#REF!+#REF!+#REF!+#REF!+#REF!+#REF!+#REF!+#REF!+#REF!,"-") -> - | BL7: =IFERROR(AC7/BK7,"-") -> -
B8: Итого | C8: - | D8: - | F8: - | G8: - | H8: - | I8: - | J8: - | K8: - | L8: - | M8: - | N8: - | O8: - | P8: - | Q8: - | S8: - | T8: - | U8: - | V8: - | X8: 528 | Y8: - | Z8: 528 | AA8: - | AB8: =IFERROR(SUM(AB3:AB7),"-") -> 0 | AC8: =IFERROR(AB8*1.2,"-") -> 0 | AD8: 1 | AF8: =IFERROR(SUM(AF3:AF7),"-") -> 0 | AG8: - | AH8: - | AI8: =IFERROR(AC8/AF8*1000,"-") -> - | AJ8: =IFERROR(AC8/AH8*1000,"-") -> - | AK8: - | AL8: - | AN8: =IFERROR(AO8/AF8,"-") -> - | AO8: =IFERROR(SUM(AO3:AO7),"-") -> 0 | AP8: =IFERROR(AC8/AO8,"-") -> - | AR8: =IFERROR(AS8/AO8,"-") -> - | AS8: 0 | AT8: =IFERROR(AC8/AS8,"-") -> - | AV8: =IFERROR(AW8/AO8,"-") -> - | AW8: 0 | AX8: =IFERROR(Y8/AW8,"-") -> - | AZ8: =IFERROR(AC8/BB8,"-") -> - | BA8: =IFERROR(BB8/#REF!,"-") -> - | BB8: =IFERROR(SUM(BB3:BB7),"-") -> 0 | BD8: =IFERROR(BE8/AF8,"-") -> - | BE8: =IFERROR(SUM(BE3:BE7),"-") -> 0 | BF8: =IFERROR(AC8/BE8,"-") -> - | BG8: =IFERROR(BH8/AF8,"-") -> - | BH8: =IFERROR(SUM(BH3:BH7),"-") -> 0 | BJ8: =IFERROR(BK8/AF8,"-") -> - | BK8: =IFERROR(SUM(BK3:BK7),"-") -> 0 | BL8: =IFERROR(AC8/BK8,"-") -> -
B10: Медиабюджет до НДС | C10: =IFERROR(Z8,"-") -> 528
B11: Агентская комиссия до НДС | C11: =IFERROR((AB8-Z8),"-") -> -528
B12: Медиабюджет с АК до НДС | C12: =IFERROR(SUM(C10:C11),"-") -> 0
B13: НДС | C13: =IFERROR((AC8-AB8),"-") -> 0
B14: Медиабюджет с АК и НДС | C14: =IFERROR(SUM(C12:C13),"-") -> 0
B15: Разработка креативов | C15: 0
B16: Настройка аналитики | C16: 0
B17: Итого с АК и НДС | C17: =IFERROR(SUM(C14:C16),"-") -> 0

Sheet МП_Periods
AC1: \
B2: Рекламная система | C2: Рекламный формат, размер, вид размещения | D2: Таргетинги | F2: Период | G2: Модель закупки | H2: Стоимость единицы закупки (без НДС) | I2: Кол-во единиц закупки | K2: Стоимость (без НДС) | L2: СК, % | M2: Стоимость с учетом СК (без НДС) | N2: АК, % | O2: Итоговая стоимость (без НДС) | P2: Итоговая стоимость (с НДС) | Q2: Доля рекламного бюджета, % | S2: Показы | T2: SOV, % | V2: CTR, % | W2: Клики | X2: CPC (с НДС) | Z2: CR, % | AA2: Конверсии | AB2: CPA (с НДС) | AD2: CR(I), % | AE2: Установки | AF2: CPI (с НДС) | AH2: ДРР, % | AI2: Средний чек | AJ2: Доход
B3: Рекламная система | C3: Рекламный формат, размер, вид размещения | D3: См. *Название вкладки* | F3: 01.01.2023 - 31.01.2023 | G3: CPC | I3: =INT(S3*V3) -> 0 | K3: =IFERROR((H3*I3),"-") -> 0 | M3: =IFERROR(K3*(1-L3),"-") -> 0 | O3: =IFERROR(M3*(1+N3),"-") -> 0 | P3: =IFERROR(O3*1.2,"-") -> 0 | Q3: =IFERROR(P3/$P$8,"-") -> - | T3: =IFERROR(#REF!/#REF!,"-") -> - | V3: 0.0066 | W3: =IFERROR(ROUNDDOWN(S3*V3,0),"-") -> 0 | X3: =IFERROR(P3/W3,"-") -> - | Z3: 0.002 | AA3: =IF(G3="CPI",AE3*Z3,IFERROR(ROUNDDOWN(W3*Z3,0),"-")) -> 0 | AB3: =IFERROR(P3/AA3,"-") -> - | AE3: =IF(G3="CPI",I3,0) -> 0 | AF3: =IFERROR(P3/AE3,"-") -> - | AH3: =IFERROR(P3/AJ3,"-") -> - | AJ3: 0
B4: Рекламная система | C4: Рекламный формат, размер, вид размещения | D4: См. *Название вкладки* | F4: 01.01.2023 - 31.01.2023 | G4: CPC | I4: =INT(S4*V4) -> 0 | K4: =IFERROR((H4*I4),"-") -> 0 | M4: =IFERROR(K4*(1-L4),"-") -> 0 | O4: =IFERROR(M4*(1+N4),"-") -> 0 | P4: =IFERROR(O4*1.2,"-") -> 0 | Q4: =IFERROR(P4/$P$8,"-") -> - | T4: =IFERROR(#REF!/#REF!,"-") -> - | V4: 0.01 | W4: =IFERROR(ROUNDDOWN(S4*V4,0),"-") -> 0 | X4: =IFERROR(P4/W4,"-") -> - | Z4: 0.002 | AA4: =IF(G4="CPI",AE4*Z4,IFERROR(ROUNDDOWN(W4*Z4,0),"-")) -> 0 | AB4: =IFERROR(P4/AA4,"-") -> - | AE4: =IF(G4="CPI",I4,0) -> 0 | AF4: =IFERROR(P4/AE4,"-") -> - | AH4: =IFERROR(P4/AJ4,"-") -> - | AJ4: 0
B5: Рекламная система | C5: Рекламный формат, размер, вид размещения | D5: См. *Название вкладки* | F5: 01.01.2023 - 31.01.2023 | G5: CPC | I5: =INT(S5*V5) -> 0 | K5: =IFERROR((H5*I5),"-") -> 0 | M5: =IFERROR(K5*(1-L5),"-") -> 0 | O5: =IFERROR(M5*(1+N5),"-") -> 0 | P5: =IFERROR(O5*1.2,"-") -> 0 | Q5: =IFERROR(P5/$P$8,"-") -> - | T5: =IFERROR(#REF!/#REF!,"-") -> - | V5: 0.011 | W5: =IFERROR(ROUNDDOWN(S5*V5,0),"-") -> 0 | X5: =IFERROR(P5/W5,"-") -> - | Z5: 0.012 | AA5: =IF(G5="CPI",AE5*Z5,IFERROR(ROUNDDOWN(W5*Z5,0),"-")) -> 0 | AB5: =IFERROR(P5/AA5,"-") -> - | AE5: =IF(G5="CPI",I5,0) -> 0 | AF5: =IFERROR(P5/AE5,"-") -> - | AH5: =IFERROR(P5/AJ5,"-") -> - | AJ5: 0
B6: Рекламная система | C6: Рекламный формат, размер, вид размещения | D6: См. *Название вкладки* | F6: 01.01.2023 - 31.01.2023 | G6: CPC | I6: =INT(S6*V6) -> 0 | K6: =IFERROR((H6*I6),"-") -> 0 | M6: =IFERROR(K6*(1-L6),"-") -> 0 | O6: =IFERROR(M6*(1+N6),"-") -> 0 | P6: =IFERROR(O6*1.2,"-") -> 0 | Q6: =IFERROR(P6/$P$8,"-") -> - | T6: =IFERROR(#REF!/#REF!,"-") -> - | V6: 0.013 | W6: =IFERROR(ROUNDDOWN(S6*V6,0),"-") -> 0 | X6: =IFERROR(P6/W6,"-") -> - | Z6: 0.01 | AA6: =IF(G6="CPI",AE6*Z6,IFERROR(ROUNDDOWN(W6*Z6,0),"-")) -> 0 | AB6: =IFERROR(P6/AA6,"-") -> - | AE6: =IF(G6="CPI",I6,0) -> 0 | AF6: =IFERROR(P6/AE6,"-") -> - | AH6: =IFERROR(P6/AJ6,"-") -> - | AJ6: 0
B7: Рекламная система | C7: Рекламный формат, размер, вид размещения | D7: См. *Название вкладки* | F7: 01.01.2023 - 31.01.2023 | G7: CPC | I7: =INT(S7*V7) -> 0 | K7: =IFERROR((H7*I7),"-") -> 0 | M7: =IFERROR(K7*(1-L7),"-") -> 0 | O7: =IFERROR(M7*(1+N7),"-") -> 0 | P7: =IFERROR(O7*1.2,"-") -> 0 | Q7: =IFERROR(P7/$P$8,"-") -> - | T7: =IFERROR(#REF!/#REF!,"-") -> - | V7: 0.013 | W7: =IFERROR(ROUNDDOWN(S7*V7,0),"-") -> 0 | X7: =IFERROR(P7/W7,"-") -> - | Z7: 0.01 | AA7: =IF(G7="CPI",AE7*Z7,IFERROR(ROUNDDOWN(W7*Z7,0),"-")) -> 0 | AB7: =IFERROR(P7/AA7,"-") -> - | AE7: =IF(G7="CPI",I7,0) -> 0 | AF7: =IFERROR(P7/AE7,"-") -> - | AH7: =IFERROR(P7/AJ7,"-") -> - | AJ7: -
B8: Итого | C8: - | D8: - | F8: - | G8: - | H8: - | I8: - | K8: 0 | L8: - | M8: 0 | N8: - | O8: =IFERROR(SUM(O3:O7),"-") -> 0 | P8: =IFERROR(O8*1.2,"-") -> 0 | Q8: 0 | S8: =IFERROR(SUM(S3:S7),"-") -> 0 | T8: - | V8: =IFERROR(W8/S8,"-") -> - | W8: =IFERROR(SUM(W3:W7),"-") -> 0 | X8: =IFERROR(P8/W8,"-") -> - | Z8: =IFERROR(AA8/W8,"-") -> - | AA8: 0 | AB8: =IFERROR(P8/AA8,"-") -> - | AD8: =IFERROR(AE8/W8,"-") -> - | AE8: 0 | AF8: =IFERROR(L8/AE8,"-") -> - | AH8: =IFERROR(P8/AJ8,"-") -> - | AI8: =IFERROR(AJ8/#REF!,"-") -> - | AJ8: =IFERROR(SUM(AJ3:AJ7),"-") -> 0
B10: Рекламная система | C10: Рекламный формат, размер, вид размещения | D10: Таргетинги | F10: Период | G10: Единица измерения стоимости | H10: Цена за единицу (без НДС) | I10: Кол-во единиц | K10: Стоимость (без НДС) | L10: СК, % | M10: Стоимость с учетом СК (без НДС) | N10: АК, % | O10: Итоговая стоимость (без НДС) | P10: Итоговая стоимость (с НДС) | Q10: Доля рекламного бюджета, % | S10: Показы | T10: SOV, % | V10: CTR, % | W10: Клики | X10: CPC (с НДС) | Z10: CR, % | AA10: Конверсии | AB10: CPA (с НДС) | AD10: CR(I), % | AE10: Установки | AF10: CPI | AH10: ДРР, % | AI10: Средний чек | AJ10: Доход
B11: Рекламная система | C11: Рекламный формат, размер, вид размещения | D11: См. *Название вкладки* | F11: 01.02.2023 - 28.02.2023 | G11: CPC | I11: =INT(S11*V11) -> 0 | K11: =IFERROR((H11*I11),"-") -> 0 | M11: =IFERROR(K11*(1-L11),"-") -> 0 | O11: =IFERROR(M11*(1+N11),"-") -> 0 | P11: =IFERROR(O11*1.2,"-") -> 0 | Q11: =IFERROR(P11/$P$8,"-") -> - | T11: =IFERROR(#REF!/#REF!,"-") -> - | W11: =IFERROR(ROUNDDOWN(S11*V11,0),"-") -> 0 | X11: =IFERROR(P11/W11,"-") -> - | AA11: =IF(G11="CPI",AE11*Z11,IFERROR(ROUNDDOWN(W11*Z11,0),"-")) -> 0 | AB11: =IFERROR(P11/AA11,"-") -> - | AE11: =IF(G11="CPI",I11,0) -> 0 | AF11: =IFERROR(P11/AE11,"-") -> - | AH11: =IFERROR(P11/AJ11,"-") -> - | AJ11: 0
B12: Рекламная система | C12: Рекламный формат, размер, вид размещения | D12: См. *Название вкладки* | F12: 01.02.2023 - 28.02.2023 | G12: CPC | I12: =INT(S12*V12) -> 0 | K12: =IFERROR((H12*I12),"-") -> 0 | M12: =IFERROR(K12*(1-L12),"-") -> 0 | O12: =IFERROR(M12*(1+N12),"-") -> 0 | P12: =IFERROR(O12*1.2,"-") -> 0 | Q12: =IFERROR(P12/$P$8,"-") -> - | T12: =IFERROR(#REF!/#REF!,"-") -> - | V12: 0.01 | W12: =IFERROR(ROUNDDOWN(S12*V12,0),"-") -> 0 | X12: =IFERROR(P12/W12,"-") -> - | Z12: 0.02 | AA12: =IF(G12="CPI",AE12*Z12,IFERROR(ROUNDDOWN(W12*Z12,0),"-")) -> 0 | AB12: =IFERROR(P12/AA12,"-") -> - | AE12: =IF(G12="CPI",I12,0) -> 0 | AF12: =IFERROR(P12/AE12,"-") -> - | AH12: =IFERROR(P12/AJ12,"-") -> - | AJ12: 0
B13: Рекламная система | C13: Рекламный формат, размер, вид размещения | D13: См. *Название вкладки* | F13: 01.02.2023 - 28.02.2023 | G13: CPC | I13: =INT(S13*V13) -> 0 | K13: =IFERROR((H13*I13),"-") -> 0 | M13: =IFERROR(K13*(1-L13),"-") -> 0 | O13: =IFERROR(M13*(1+N13),"-") -> 0 | P13: =IFERROR(O13*1.2,"-") -> 0 | Q13: =IFERROR(P13/$P$8,"-") -> - | T13: =IFERROR(#REF!/#REF!,"-") -> - | W13: =IFERROR(ROUNDDOWN(S13*V13,0),"-") -> 0 | X13: =IFERROR(P13/W13,"-") -> - | AA13: =IF(G13="CPI",AE13*Z13,IFERROR(ROUNDDOWN(W13*Z13,0),"-")) -> 0 | AB13: =IFERROR(P13/AA13,"-") -> - | AE13: =IF(G13="CPI",I13,0) -> 0 | AF13: =IFERROR(P13/AE13,"-") -> - | AH13: =IFERROR(P13/AJ13,"-") -> - | AJ13: 0
B14: Рекламная система | C14: Рекламный формат, размер, вид размещения | D14: См. *Название вкладки* | F14: 01.02.2023 - 28.02.2023 | G14: CPC | I14: =INT(S14*V14) -> 0 | K14: =IFERROR((H14*I14),"-") -> 0 | M14: =IFERROR(K14*(1-L14),"-") -> 0 | O14: =IFERROR(M14*(1+N14),"-") -> 0 | P14: =IFERROR(O14*1.2,"-") -> 0 | Q14: =IFERROR(P14/$P$8,"-") -> - | T14: =IFERROR(#REF!/#REF!,"-") -> - | W14: =IFERROR(ROUNDDOWN(S14*V14,0),"-") -> 0 | X14: =IFERROR(P14/W14,"-") -> - | AA14: =IF(G14="CPI",AE14*Z14,IFERROR(ROUNDDOWN(W14*Z14,0),"-")) -> 0 | AB14: =IFERROR(P14/AA14,"-") -> - | AE14: =IF(G14="CPI",I14,0) -> 0 | AF14: =IFERROR(P14/AE14,"-") -> - | AH14: =IFERROR(P14/AJ14,"-") -> - | AJ14: 0
B15: Рекламная система | C15: Рекламный формат, размер, вид размещения | D15: См. *Название вкладки* | F15: 01.02.2023 - 28.02.2023 | G15: CPC | I15: =INT(S15*V15) -> 0 | K15: =IFERROR((H15*I15),"-") -> 0 | M15: =IFERROR(K15*(1-L15),"-") -> 0 | O15: =IFERROR(M15*(1+N15),"-") -> 0 | P15: =IFERROR(O15*1.2,"-") -> 0 | Q15: =IFERROR(P15/$P$8,"-") -> - | T15: =IFERROR(#REF!/#REF!,"-") -> - | W15: =IFERROR(ROUNDDOWN(S15*V15,0),"-") -> 0 | X15: =IFERROR(P15/W15,"-") -> - | AA15: =IF(G15="CPI",AE15*Z15,IFERROR(ROUNDDOWN(W15*Z15,0),"-")) -> 0 | AB15: =IFERROR(P15/AA15,"-") -> - | AE15: =IF(G15="CPI",I15,0) -> 0 | AF15: =IFERROR(P15/AE15,"-") -> - | AH15: =IFERROR(P15/AJ15,"-") -> - | AJ15: 0
B16: Итого | C16: - | D16: - | F16: - | G16: - | H16: - | I16: - | K16: 300 | L16: - | M16: 300 | N16: - | O16: =IFERROR(SUM(O11:O15),"-") -> 0 | P16: =IFERROR(O16*1.2,"-") -> 0 | Q16: 0 | S16: =IFERROR(SUM(S11:S15),"-") -> 0 | T16: - | V16: =IFERROR(W16/S16,"-") -> - | W16: =IFERROR(SUM(W11:W15),"-") -> 0 | X16: =IFERROR(P16/W16,"-") -> - | Z16: =IFERROR(AA16/W16,"-") -> - | AA16: 0 | AB16: =IFERROR(P16/AA16,"-") -> - | AD16: =IFERROR(AE16/W16,"-") -> - | AE16: 0 | AF16: =IFERROR(L16/AE16,"-") -> - | AH16: =IFERROR(P16/AJ16,"-") -> - | AI16: =IFERROR(AJ16/#REF!,"-") -> - | AJ16: =IFERROR(SUM(AJ11:AJ15),"-") -> 0
B18: Рекламная система | C18: Рекламный формат, размер, вид размещения | D18: Таргетинги | F18: Период | G18: Единица измерения стоимости | H18: Цена за единицу (без НДС) | I18: Кол-во единиц | K18: Стоимость (без НДС) | L18: СК, % | M18: Стоимость с учетом СК (без НДС) | N18: АК, % | O18: Итоговая стоимость (без НДС) | P18: Итоговая стоимость (с НДС) | Q18: Доля рекламного бюджета, % | S18: Показы | T18: SOV, % | V18: CTR, % | W18: Клики | X18: CPC (с НДС) | Z18: CR, % | AA18: Конверсии | AB18: CPA (с НДС) | AD18: CR(I), % | AE18: Установки | AF18: CPI | AH18: ДРР, % | AI18: Средний чек | AJ18: Доход
B19: Рекламная система | C19: Рекламный формат, размер, вид размещения | D19: См. *Название вкладки* | F19: 01.03.2023 - 31.03.2023 | G19: CPA | I19: =INT(S19*V19) -> 0 | K19: =IFERROR((H19*I19),"-") -> 0 | M19: =IFERROR(K19*(1-L19),"-") -> 0 | O19: =IFERROR(M19*(1+N19),"-") -> 0 | P19: =IFERROR(O19*1.2,"-") -> 0 | Q19: =IFERROR(P19/$P$8,"-") -> - | T19: =IFERROR(#REF!/#REF!,"-") -> - | W19: =IFERROR(ROUNDDOWN(S19*V19,0),"-") -> 0 | X19: =IFERROR(P19/W19,"-") -> - | AA19: =IF(G19="CPI",AE19*Z19,IFERROR(ROUNDDOWN(W19*Z19,0),"-")) -> 0 | AB19: =IFERROR(P19/AA19,"-") -> - | AE19: =IF(G19="CPI",I19,0) -> 0 | AF19: =IFERROR(P19/AE19,"-") -> - | AH19: =IFERROR(P19/AJ19,"-") -> - | AJ19: 0
B20: Рекламная система | C20: Рекламный формат, размер, вид размещения | D20: См. *Название вкладки* | F20: 01.03.2023 - 31.03.2023 | G20: CPM | I20: =INT(S20*V20) -> 0 | K20: =IFERROR((H20*I20),"-") -> 0 | M20: =IFERROR(K20*(1-L20),"-") -> 0 | O20: =IFERROR(M20*(1+N20),"-") -> 0 | P20: =IFERROR(O20*1.2,"-") -> 0 | Q20: =IFERROR(P20/$P$8,"-") -> - | T20: =IFERROR(#REF!/#REF!,"-") -> - | W20: =IFERROR(ROUNDDOWN(S20*V20,0),"-") -> 0 | X20: =IFERROR(P20/W20,"-") -> - | AA20: =IF(G20="CPI",AE20*Z20,IFERROR(ROUNDDOWN(W20*Z20,0),"-")) -> 0 | AB20: =IFERROR(P20/AA20,"-") -> - | AE20: =IF(G20="CPI",I20,0) -> 0 | AF20: =IFERROR(P20/AE20,"-") -> - | AH20: =IFERROR(P20/AJ20,"-") -> - | AJ20: 0
B21: Рекламная система | C21: Рекламный формат, размер, вид размещения | D21: См. *Название вкладки* | F21: 01.03.2023 - 31.03.2023 | G21: CPM | I21: =INT(S21*V21) -> 0 | K21: =IFERROR((H21*I21),"-") -> 0 | M21: =IFERROR(K21*(1-L21),"-") -> 0 | O21: =IFERROR(M21*(1+N21),"-") -> 0 | P21: =IFERROR(O21*1.2,"-") -> 0 | Q21: =IFERROR(P21/$P$8,"-") -> - | T21: =IFERROR(#REF!/#REF!,"-") -> - | W21: =IFERROR(ROUNDDOWN(S21*V21,0),"-") -> 0 | X21: =IFERROR(P21/W21,"-") -> - | AA21: =IF(G21="CPI",AE21*Z21,IFERROR(ROUNDDOWN(W21*Z21,0),"-")) -> 0 | AB21: =IFERROR(P21/AA21,"-") -> - | AE21: =IF(G21="CPI",I21,0) -> 0 | AF21: =IFERROR(P21/AE21,"-") -> - | AH21: =IFERROR(P21/AJ21,"-") -> - | AJ21: 0
B22: Рекламная система | C22: Рекламный формат, размер, вид размещения | D22: См. *Название вкладки* | F22: 01.03.2023 - 31.03.2023 | G22: CPM | I22: =INT(S22*V22) -> 0 | K22: =IFERROR((H22*I22),"-") -> 0 | M22: =IFERROR(K22*(1-L22),"-") -> 0 | O22: =IFERROR(M22*(1+N22),"-") -> 0 | P22: =IFERROR(O22*1.2,"-") -> 0 | Q22: =IFERROR(P22/$P$8,"-") -> - | T22: =IFERROR(#REF!/#REF!,"-") -> - | W22: =IFERROR(ROUNDDOWN(S22*V22,0),"-") -> 0 | X22: =IFERROR(P22/W22,"-") -> - | AA22: =IF(G22="CPI",AE22*Z22,IFERROR(ROUNDDOWN(W22*Z22,0),"-")) -> 0 | AB22: =IFERROR(P22/AA22,"-") -> - | AE22: =IF(G22="CPI",I22,0) -> 0 | AF22: =IFERROR(P22/AE22,"-") -> - | AH22: =IFERROR(P22/AJ22,"-") -> - | AJ22: 0
B23: Рекламная система | C23: Рекламный формат, размер, вид размещения | D23: См. *Название вкладки* | F23: 01.03.2023 - 31.03.2023 | G23: CPM | I23: =INT(S23*V23) -> 0 | K23: =IFERROR((H23*I23),"-") -> 0 | M23: =IFERROR(K23*(1-L23),"-") -> 0 | O23: =IFERROR(M23*(1+N23),"-") -> 0 | P23: =IFERROR(O23*1.2,"-") -> 0 | Q23: =IFERROR(P23/$P$8,"-") -> - | T23: =IFERROR(#REF!/#REF!,"-") -> - | W23: =IFERROR(ROUNDDOWN(S23*V23,0),"-") -> 0 | X23: =IFERROR(P23/W23,"-") -> - | AA23: =IF(G23="CPI",AE23*Z23,IFERROR(ROUNDDOWN(W23*Z23,0),"-")) -> 0 | AB23: =IFERROR(P23/AA23,"-") -> - | AE23: =IF(G23="CPI",I23,0) -> 0 | AF23: =IFERROR(P23/AE23,"-") -> - | AH23: =IFERROR(P23/AJ23,"-") -> - | AJ23: 0
B24: Итого | C24: - | D24: - | F24: - | G24: - | H24: - | I24: - | K24: 0 | L24: - | M24: 0 | N24: - | O24: =IFERROR(SUM(O19:O23),"-") -> 0 | P24: =IFERROR(O24*1.2,"-") -> 0 | Q24: 0 | S24: =IFERROR(SUM(S19:S23),"-") -> 0 | T24: - | V24: =IFERROR(W24/S24,"-") -> - | W24: =IFERROR(SUM(W19:W23),"-") -> 0 | X24: =IFERROR(P24/W24,"-") -> - | Z24: =IFERROR(AA24/W24,"-") -> - | AA24: 0 | AB24: =IFERROR(P24/AA24,"-") -> - | AD24: =IFERROR(AE24/W24,"-") -> - | AE24: 0 | AF24: =IFERROR(L24/AE24,"-") -> - | AH24: =IFERROR(P24/AJ24,"-") -> - | AI24: =IFERROR(AJ24/#REF!,"-") -> - | AJ24: =IFERROR(SUM(AJ19:AJ23),"-") -> 0
B26: Рекламная система | C26: Рекламный формат, размер, вид размещения | D26: Таргетинги | F26: Период | G26: Единица измерения стоимости | H26: Цена за единицу (без НДС) | I26: Кол-во единиц | K26: Стоимость (без НДС) | L26: СК, % | M26: Стоимость с учетом СК (без НДС) | N26: АК, % | O26: Итоговая стоимость (без НДС) | P26: Итоговая стоимость (с НДС) | Q26: Доля рекламного бюджета, % | S26: Показы | T26: SOV, % | V26: CTR, % | W26: Клики | X26: CPC (с НДС) | Z26: CR, % | AA26: Конверсии | AB26: CPA (с НДС) | AD26: CR(I), % | AE26: Установки | AF26: CPI | AH26: ДРР, % | AI26: Средний чек | AJ26: Доход
B27: Рекламная система | C27: Рекламный формат, размер, вид размещения | D27: См. *Название вкладки* | F27: 01.04.2023 - 30.04.2023 | G27: CPM | I27: =INT(S27*V27) -> 0 | K27: =IFERROR((H27*I27),"-") -> 0 | M27: =IFERROR(K27*(1-L27),"-") -> 0 | O27: =IFERROR(M27*(1+N27),"-") -> 0 | P27: =IFERROR(O27*1.2,"-") -> 0 | Q27: =IFERROR(P27/$P$8,"-") -> - | T27: =IFERROR(#REF!/#REF!,"-") -> - | W27: =IFERROR(ROUNDDOWN(S27*V27,0),"-") -> 0 | X27: =IFERROR(P27/W27,"-") -> - | AA27: =IF(G27="CPI",AE27*Z27,IFERROR(ROUNDDOWN(W27*Z27,0),"-")) -> 0 | AB27: =IFERROR(P27/AA27,"-") -> - | AE27: =IF(G27="CPI",I27,0) -> 0 | AF27: =IFERROR(P27/AE27,"-") -> - | AH27: =IFERROR(P27/AJ27,"-") -> - | AJ27: 0
B28: Рекламная система | C28: Рекламный формат, размер, вид размещения | D28: См. *Название вкладки* | F28: 01.04.2023 - 30.04.2023 | G28: CPM | I28: =INT(S28*V28) -> 0 | K28: =IFERROR((H28*I28),"-") -> 0 | M28: =IFERROR(K28*(1-L28),"-") -> 0 | O28: =IFERROR(M28*(1+N28),"-") -> 0 | P28: =IFERROR(O28*1.2,"-") -> 0 | Q28: =IFERROR(P28/$P$8,"-") -> - | T28: =IFERROR(#REF!/#REF!,"-") -> - | W28: =IFERROR(ROUNDDOWN(S28*V28,0),"-") -> 0 | X28: =IFERROR(P28/W28,"-") -> - | AA28: =IF(G28="CPI",AE28*Z28,IFERROR(ROUNDDOWN(W28*Z28,0),"-")) -> 0 | AB28: =IFERROR(P28/AA28,"-") -> - | AE28: =IF(G28="CPI",I28,0) -> 0 | AF28: =IFERROR(P28/AE28,"-") -> - | AH28: =IFERROR(P28/AJ28,"-") -> - | AJ28: 0
B29: Рекламная система | C29: Рекламный формат, размер, вид размещения | D29: См. *Название вкладки* | F29: 01.04.2023 - 30.04.2023 | G29: CPM | I29: =INT(S29*V29) -> 0 | K29: =IFERROR((H29*I29),"-") -> 0 | M29: =IFERROR(K29*(1-L29),"-") -> 0 | O29: =IFERROR(M29*(1+N29),"-") -> 0 | P29: =IFERROR(O29*1.2,"-") -> 0 | Q29: =IFERROR(P29/$P$8,"-") -> - | T29: =IFERROR(#REF!/#REF!,"-") -> - | W29: =IFERROR(ROUNDDOWN(S29*V29,0),"-") -> 0 | X29: =IFERROR(P29/W29,"-") -> - | AA29: =IF(G29="CPI",AE29*Z29,IFERROR(ROUNDDOWN(W29*Z29,0),"-")) -> 0 | AB29: =IFERROR(P29/AA29,"-") -> - | AE29: =IF(G29="CPI",I29,0) -> 0 | AF29: =IFERROR(P29/AE29,"-") -> - | AH29: =IFERROR(P29/AJ29,"-") -> - | AJ29: 0
B30: Рекламная система | C30: Рекламный формат, размер, вид размещения | D30: См. *Название вкладки* | F30: 01.04.2023 - 30.04.2023 | G30: CPM | I30: =INT(S30*V30) -> 0 | K30: =IFERROR((H30*I30),"-") -> 0 | M30: =IFERROR(K30*(1-L30),"-") -> 0 | O30: =IFERROR(M30*(1+N30),"-") -> 0 | P30: =IFERROR(O30*1.2,"-") -> 0 | Q30: =IFERROR(P30/$P$8,"-") -> - | T30: =IFERROR(#REF!/#REF!,"-") -> - | W30: =IFERROR(ROUNDDOWN(S30*V30,0),"-") -> 0 | X30: =IFERROR(P30/W30,"-") -> - | AA30: =IF(G30="CPI",AE30*Z30,IFERROR(ROUNDDOWN(W30*Z30,0),"-")) -> 0 | AB30: =IFERROR(P30/AA30,"-") -> - | AE30: =IF(G30="CPI",I30,0) -> 0 | AF30: =IFERROR(P30/AE30,"-") -> - | AH30: =IFERROR(P30/AJ30,"-") -> - | AJ30: 0
B31: Рекламная система | C31: Рекламный формат, размер, вид размещения | D31: См. *Название вкладки* | F31: 01.04.2023 - 30.04.2023 | G31: CPM | I31: =INT(S31*V31) -> 0 | K31: =IFERROR((H31*I31),"-") -> 0 | M31: =IFERROR(K31*(1-L31),"-") -> 0 | O31: =IFERROR(M31*(1+N31),"-") -> 0 | P31: =IFERROR(O31*1.2,"-") -> 0 | Q31: =IFERROR(P31/$P$8,"-") -> - | T31: =IFERROR(#REF!/#REF!,"-") -> - | W31: =IFERROR(ROUNDDOWN(S31*V31,0),"-") -> 0 | X31: =IFERROR(P31/W31,"-") -> - | AA31: =IF(G31="CPI",AE31*Z31,IFERROR(ROUNDDOWN(W31*Z31,0),"-")) -> 0 | AB31: =IFERROR(P31/AA31,"-") -> - | AE31: =IF(G31="CPI",I31,0) -> 0 | AF31: =IFERROR(P31/AE31,"-") -> - | AH31: =IFERROR(P31/AJ31,"-") -> - | AJ31: 0
B32: Итого | C32: - | D32: - | F32: - | G32: - | H32: - | I32: - | K32: 0 | L32: - | M32: 0 | N32: - | O32: =IFERROR(SUM(O27:O31),"-") -> 0 | P32: =IFERROR(O32*1.2,"-") -> 0 | Q32: 0 | S32: =IFERROR(SUM(S27:S31),"-") -> 0 | T32: - | V32: =IFERROR(W32/S32,"-") -> - | W32: =IFERROR(SUM(W27:W31),"-") -> 0 | X32: =IFERROR(P32/W32,"-") -> - | Z32: =IFERROR(AA32/W32,"-") -> - | AA32: 0 | AB32: =IFERROR(P32/AA32,"-") -> - | AD32: =IFERROR(AE32/W32,"-") -> - | AE32: 0 | AF32: =IFERROR(L32/AE32,"-") -> - | AH32: =IFERROR(P32/AJ32,"-") -> - | AI32: =IFERROR(AJ32/#REF!,"-") -> - | AJ32: =IFERROR(SUM(AJ27:AJ31),"-") -> 0
B34: Рекламная система | C34: Рекламный формат, размер, вид размещения | D34: Таргетинги | F34: Период | G34: Единица измерения стоимости | H34: Цена за единицу (без НДС) | I34: Кол-во единиц | K34: Стоимость (без НДС) | L34: СК, % | M34: Стоимость с учетом СК (без НДС) | N34: АК, % | O34: Итоговая стоимость (без НДС) | P34: Итоговая стоимость (с НДС) | Q34: Доля рекламного бюджета, % | S34: Показы | T34: SOV, % | V34: CTR, % | W34: Клики | X34: CPC (с НДС) | Z34: CR, % | AA34: Конверсии | AB34: CPA (с НДС) | AD34: CR(I), % | AE34: Установки | AF34: CPI | AH34: ДРР, % | AI34: Средний чек | AJ34: Доход
B35: Рекламная система | C35: Рекламный формат, размер, вид размещения | D35: См. *Название вкладки* | F35: 01.05.2023 - 31.05.2023 | G35: CPM | I35: =INT(S35*V35) -> 0 | K35: =IFERROR((H35*I35),"-") -> 0 | M35: =IFERROR(K35*(1-L35),"-") -> 0 | O35: =IFERROR(M35*(1+N35),"-") -> 0 | P35: =IFERROR(O35*1.2,"-") -> 0 | Q35: =IFERROR(P35/$P$8,"-") -> - | T35: =IFERROR(#REF!/#REF!,"-") -> - | W35: =IFERROR(ROUNDDOWN(S35*V35,0),"-") -> 0 | X35: =IFERROR(P35/W35,"-") -> - | AA35: =IF(G35="CPI",AE35*Z35,IFERROR(ROUNDDOWN(W35*Z35,0),"-")) -> 0 | AB35: =IFERROR(P35/AA35,"-") -> - | AE35: =IF(G35="CPI",I35,0) -> 0 | AF35: =IFERROR(P35/AE35,"-") -> - | AH35: =IFERROR(P35/AJ35,"-") -> - | AJ35: 0
B36: Рекламная система | C36: Рекламный формат, размер, вид размещения | D36: См. *Название вкладки* | F36: 01.05.2023 - 31.05.2023 | G36: CPM | I36: =INT(S36*V36) -> 0 | K36: =IFERROR((H36*I36),"-") -> 0 | M36: =IFERROR(K36*(1-L36),"-") -> 0 | O36: =IFERROR(M36*(1+N36),"-") -> 0 | P36: =IFERROR(O36*1.2,"-") -> 0 | Q36: =IFERROR(P36/$P$8,"-") -> - | T36: =IFERROR(#REF!/#REF!,"-") -> - | W36: =IFERROR(ROUNDDOWN(S36*V36,0),"-") -> 0 | X36: =IFERROR(P36/W36,"-") -> - | AA36: =IF(G36="CPI",AE36*Z36,IFERROR(ROUNDDOWN(W36*Z36,0),"-")) -> 0 | AB36: =IFERROR(P36/AA36,"-") -> - | AE36: =IF(G36="CPI",I36,0) -> 0 | AF36: =IFERROR(P36/AE36,"-") -> - | AH36: =IFERROR(P36/AJ36,"-") -> - | AJ36: 0
B37: Рекламная система | C37: Рекламный формат, размер, вид размещения | D37: См. *Название вкладки* | F37: 01.05.2023 - 31.05.2023 | G37: CPM | I37: =INT(S37*V37) -> 0 | K37: =IFERROR((H37*I37),"-") -> 0 | M37: =IFERROR(K37*(1-L37),"-") -> 0 | O37: =IFERROR(M37*(1+N37),"-") -> 0 | P37: =IFERROR(O37*1.2,"-") -> 0 | Q37: =IFERROR(P37/$P$8,"-") -> - | T37: =IFERROR(#REF!/#REF!,"-") -> - | W37: =IFERROR(ROUNDDOWN(S37*V37,0),"-") -> 0 | X37: =IFERROR(P37/W37,"-") -> - | AA37: =IF(G37="CPI",AE37*Z37,IFERROR(ROUNDDOWN(W37*Z37,0),"-")) -> 0 | AB37: =IFERROR(P37/AA37,"-") -> - | AE37: =IF(G37="CPI",I37,0) -> 0 | AF37: =IFERROR(P37/AE37,"-") -> - | AH37: =IFERROR(P37/AJ37,"-") -> - | AJ37: 0
B38: Рекламная система | C38: Рекламный формат, размер, вид размещения | D38: См. *Название вкладки* | F38: 01.05.2023 - 31.05.2023 | G38: CPM | I38: =INT(S38*V38) -> 0 | K38: =IFERROR((H38*I38),"-") -> 0 | M38: =IFERROR(K38*(1-L38),"-") -> 0 | O38: =IFERROR(M38*(1+N38),"-") -> 0 | P38: =IFERROR(O38*1.2,"-") -> 0 | Q38: =IFERROR(P38/$P$8,"-") -> - | T38: =IFERROR(#REF!/#REF!,"-") -> - | W38: =IFERROR(ROUNDDOWN(S38*V38,0),"-") -> 0 | X38: =IFERROR(P38/W38,"-") -> - | AA38: =IF(G38="CPI",AE38*Z38,IFERROR(ROUNDDOWN(W38*Z38,0),"-")) -> 0 | AB38: =IFERROR(P38/AA38,"-") -> - | AE38: =IF(G38="CPI",I38,0) -> 0 | AF38: =IFERROR(P38/AE38,"-") -> - | AH38: =IFERROR(P38/AJ38,"-") -> - | AJ38: 0
B39: Рекламная система | C39: Рекламный формат, размер, вид размещения | D39: См. *Название вкладки* | F39: 01.05.2023 - 31.05.2023 | G39: CPM | I39: =INT(S39*V39) -> 0 | K39: =IFERROR((H39*I39),"-") -> 0 | M39: =IFERROR(K39*(1-L39),"-") -> 0 | O39: =IFERROR(M39*(1+N39),"-") -> 0 | P39: =IFERROR(O39*1.2,"-") -> 0 | Q39: =IFERROR(P39/$P$8,"-") -> - | T39: =IFERROR(#REF!/#REF!,"-") -> - | W39: =IFERROR(ROUNDDOWN(S39*V39,0),"-") -> 0 | X39: =IFERROR(P39/W39,"-") -> - | AA39: =IF(G39="CPI",AE39*Z39,IFERROR(ROUNDDOWN(W39*Z39,0),"-")) -> 0 | AB39: =IFERROR(P39/AA39,"-") -> - | AE39: =IF(G39="CPI",I39,0) -> 0 | AF39: =IFERROR(P39/AE39,"-") -> - | AH39: =IFERROR(P39/AJ39,"-") -> - | AJ39: 0
B40: Итого | C40: - | D40: - | F40: - | G40: - | H40: - | I40: - | K40: 0 | L40: - | M40: 0 | N40: - | O40: =IFERROR(SUM(O35:O39),"-") -> 0 | P40: =IFERROR(O40*1.2,"-") -> 0 | Q40: 0 | S40: =IFERROR(SUM(S35:S39),"-") -> 0 | T40: - | V40: =IFERROR(W40/S40,"-") -> - | W40: =IFERROR(SUM(W35:W39),"-") -> 0 | X40: =IFERROR(P40/W40,"-") -> - | Z40: =IFERROR(AA40/W40,"-") -> - | AA40: 0 | AB40: =IFERROR(P40/AA40,"-") -> - | AD40: =IFERROR(AE40/W40,"-") -> - | AE40: 0 | AF40: =IFERROR(L40/AE40,"-") -> - | AH40: =IFERROR(P40/AJ40,"-") -> - | AI40: =IFERROR(AJ40/#REF!,"-") -> - | AJ40: =IFERROR(SUM(AJ35:AJ39),"-") -> 0
B42: Рекламная система | C42: Рекламный формат, размер, вид размещения | D42: Таргетинги | F42: Период | G42: Единица измерения стоимости | H42: Цена за единицу (без НДС) | I42: Кол-во единиц | K42: Стоимость (без НДС) | L42: СК, % | M42: Стоимость с учетом СК (без НДС) | N42: АК, % | O42: Итоговая стоимость (без НДС) | P42: Итоговая стоимость (с НДС) | Q42: Доля рекламного бюджета, % | S42: Показы | T42: SOV, % | V42: CTR, % | W42: Клики | X42: CPC (с НДС) | Z42: CR, % | AA42: Конверсии | AB42: CPA (с НДС) | AD42: CR(I), % | AE42: Установки | AF42: CPI | AH42: ДРР, % | AI42: Средний чек | AJ42: Доход
B43: Рекламная система | C43: Рекламный формат, размер, вид размещения | D43: См. *Название вкладки* | F43: 01.06.2023 - 30.06.2023 | G43: CPM | I43: =INT(S43*V43) -> 0 | K43: =IFERROR((H43*I43),"-") -> 0 | M43: =IFERROR(K43*(1-L43),"-") -> 0 | O43: =IFERROR(M43*(1+N43),"-") -> 0 | P43: =IFERROR(O43*1.2,"-") -> 0 | Q43: =IFERROR(P43/$P$8,"-") -> - | T43: =IFERROR(#REF!/#REF!,"-") -> - | W43: =IFERROR(ROUNDDOWN(S43*V43,0),"-") -> 0 | X43: =IFERROR(P43/W43,"-") -> - | AA43: =IF(G43="CPI",AE43*Z43,IFERROR(ROUNDDOWN(W43*Z43,0),"-")) -> 0 | AB43: =IFERROR(P43/AA43,"-") -> - | AE43: =IF(G43="CPI",I43,0) -> 0 | AF43: =IFERROR(P43/AE43,"-") -> - | AH43: =IFERROR(P43/AJ43,"-") -> - | AJ43: 0
B44: Рекламная система | C44: Рекламный формат, размер, вид размещения | D44: См. *Название вкладки* | F44: 01.06.2023 - 30.06.2023 | G44: CPM | I44: =INT(S44*V44) -> 0 | K44: =IFERROR((H44*I44),"-") -> 0 | M44: =IFERROR(K44*(1-L44),"-") -> 0 | O44: =IFERROR(M44*(1+N44),"-") -> 0 | P44: =IFERROR(O44*1.2,"-") -> 0 | Q44: =IFERROR(P44/$P$8,"-") -> - | T44: =IFERROR(#REF!/#REF!,"-") -> - | W44: =IFERROR(ROUNDDOWN(S44*V44,0),"-") -> 0 | X44: =IFERROR(P44/W44,"-") -> - | AA44: =IF(G44="CPI",AE44*Z44,IFERROR(ROUNDDOWN(W44*Z44,0),"-")) -> 0 | AB44: =IFERROR(P44/AA44,"-") -> - | AE44: =IF(G44="CPI",I44,0) -> 0 | AF44: =IFERROR(P44/AE44,"-") -> - | AH44: =IFERROR(P44/AJ44,"-") -> - | AJ44: 0
B45: Рекламная система | C45: Рекламный формат, размер, вид размещения | D45: См. *Название вкладки* | F45: 01.06.2023 - 30.06.2023 | G45: CPM | I45: =INT(S45*V45) -> 0 | K45: =IFERROR((H45*I45),"-") -> 0 | M45: =IFERROR(K45*(1-L45),"-") -> 0 | O45: =IFERROR(M45*(1+N45),"-") -> 0 | P45: =IFERROR(O45*1.2,"-") -> 0 | Q45: =IFERROR(P45/$P$8,"-") -> - | T45: =IFERROR(#REF!/#REF!,"-") -> - | W45: =IFERROR(ROUNDDOWN(S45*V45,0),"-") -> 0 | X45: =IFERROR(P45/W45,"-") -> - | AA45: =IF(G45="CPI",AE45*Z45,IFERROR(ROUNDDOWN(W45*Z45,0),"-")) -> 0 | AB45: =IFERROR(P45/AA45,"-") -> - | AE45: =IF(G45="CPI",I45,0) -> 0 | AF45: =IFERROR(P45/AE45,"-") -> - | AH45: =IFERROR(P45/AJ45,"-") -> - | AJ45: 0
...
