Workbook

Sheet Total
A1: Месяц+Год | B1: Тип клиента | C1: Площадка | D1: Формат | E1: Гео | F1: Модель закупки | G1: Единица закупки | H1: Кол-во единиц закупки | I1: Стоимость единицы закупки, руб. с НДС | J1: АК% | K1: АК, руб. (абс.) | L1: НДС, руб. (абс.) | M1: Тотал бюджет, руб. без НДС и АК | N1: Тотал бюджет, руб. без НДС и с учетом АК | O1: Тотал бюджет руб. с учетом НДС и АК | P1: Кол-во показов | Q1: CTR, % | R1: Кол-во кликов | S1: СРС, руб. с НДС | T1: Кол-во оформленных заказов | U1: Стоимость оформл. заказа, руб. с НДС | V1: CR (конверсия из клика в заказ), % | W1: Оформленный доход, руб. с НДС | X1: ДРР от оформл. дохода, % | Y1: ROAS офомл. (Доход/Бюджет) | Z1: Средний чек по оформл. доходу, с НДС | AA1: Кол-во отгруженных заказов | AB1: Стоимость отгр. заказа, руб. с НДС | AC1: CR 2 (конверсия из оформленного в отгруженный заказ), % | AD1: Выручка (отгруженный доход), руб. с НДС | AE1: ДРР от выручки, % | AF1: ROAS отгр. (Выручка/Бюджет) | AG1: Средний чек по выручке, с НДС | AH1: Кол-во клиентов | AI1: Частота заказа | AJ1: Кол-во абсолютно новых клиентов (ранее не заказывали) | AK1: Кол-во вернувшихся клиентов (не заказывали более 12 мес) | AL1: Кол-во новых клиентов (абсолютно новые + вернувшиеся) | AM1: Доля новых клиентов, % | AN1: САС, руб. | AO1: СРА: кол-во активных веб мастеров | AP1: СРА: % аппрува | AR1: СR из клика в клиента, %
A2: 2026-2027 | B2: В2В | H2: =IFERROR(Periods!H2+Periods!H118+Periods!H234+Periods!H350+Periods!H466+Periods!H582+Periods!H698+Periods!H814+Periods!H930+Periods!H1046+Periods!H1162+Periods!H1278, "-") -> 0 | I2: =(M2*1.22)/R2 -> #DIV/0! | J2: =IFERROR(N2/M2-1,"-") -> - | K2: =I2*J2*H2 -> #DIV/0! | L2: =IFERROR(Periods!L2+Periods!L118+Periods!L234+Periods!L350+Periods!L466+Periods!L582+Periods!L698+Periods!L814+Periods!L930+Periods!L1046+Periods!L1162+Periods!L1278, "-") -> 0 | M2: =IFERROR(Periods!M2+Periods!M118+Periods!M234+Periods!M350+Periods!M466+Periods!M582+Periods!M698+Periods!M814+Periods!M930+Periods!M1046+Periods!M1162+Periods!M1278, "-") -> 0 | N2: =IFERROR(Periods!N2+Periods!N118+Periods!N234+Periods!N350+Periods!N466+Periods!N582+Periods!N698+Periods!N814+Periods!N930+Periods!N1046+Periods!N1162+Periods!N1278, "-") -> 0 | O2: =IFERROR(Periods!O2+Periods!O118+Periods!O234+Periods!O350+Periods!O466+Periods!O582+Periods!O698+Periods!O814+Periods!O930+Periods!O1046+Periods!O1162+Periods!O1278, "-") -> 0 | P2: =IFERROR(Periods!P2+Periods!P118+Periods!P234+Periods!P350+Periods!P466+Periods!P582+Periods!P698+Periods!P814+Periods!P930+Periods!P1046+Periods!P1162+Periods!P1278, "-") -> 0 | Q2: =IFERROR(R2/P2, "-") -> - | R2: =IFERROR(Periods!R2+Periods!R118+Periods!R234+Periods!R350+Periods!R466+Periods!R582+Periods!R698+Periods!R814+Periods!R930+Periods!R1046+Periods!R1162+Periods!R1278, "-") -> 0 | S2: =(ROUNDDOWN(O2/R2,0)) -> #DIV/0! | T2: =IFERROR(Periods!T2+Periods!T118+Periods!T234+Periods!T350+Periods!T466+Periods!T582+Periods!T698+Periods!T814+Periods!T930+Periods!T1046+Periods!T1162+Periods!T1278, "-") -> 0 | U2: =IFERROR(O2/T2, "-") -> - | V2: =IFERROR(R2/T2, "-") -> - | W2: =IFERROR(Periods!W2+Periods!W118+Periods!W234+Periods!W350+Periods!W466+Periods!W582+Periods!W698+Periods!W814+Periods!W930+Periods!W1046+Periods!W1162+Periods!W1278, "-") -> 0 | X2: =O2/W2 -> #DIV/0! | Y2: =W2/O2 -> #DIV/0! | Z2: =W2/T2 -> #DIV/0! | AA2: =IFERROR(Periods!AA2+Periods!AA118+Periods!AA234+Periods!AA350+Periods!AA466+Periods!AA582+Periods!AA698+Periods!AA814+Periods!AA930+Periods!AA1046+Periods!AA1162+Periods!AA1278, "-") -> 0 | AB2: =O2/AA2 -> #DIV/0! | AC2: =IFERROR(AA2/T2, "-") -> - | AD2: =IFERROR(Periods!AD2+Periods!AD118+Periods!AD234+Periods!AD350+Periods!AD466+Periods!AD582+Periods!AD698+Periods!AD814+Periods!AD930+Periods!AD1046+Periods!AD1162+Periods!AD1278, "-") -> 0 | AE2: =O2/AD2 -> #DIV/0! | AF2: =AD2/O2 -> #DIV/0! | AG2: =AD2/AA2 -> #DIV/0! | AH2: =IFERROR(Periods!AH2+Periods!AH118+Periods!AH234+Periods!AH350+Periods!AH466+Periods!AH582+Periods!AH698+Periods!AH814+Periods!AH930+Periods!AH1046+Periods!AH1162+Periods!AH1278, "-") -> 0 | AI2: =IFERROR(AVERAGE(Periods!AI2,Periods!AI118,Periods!AI234,Periods!AI350,Periods!AI466,Periods!AI582,Periods!AI698,Periods!AI814,Periods!AI930,Periods!AI1046,Periods!AI1162,Periods!AI1278), "-") -> - | AJ2: =IFERROR(Periods!AJ2+Periods!AJ118+Periods!AJ234+Periods!AJ350+Periods!AJ466+Periods!AJ582+Periods!AJ698+Periods!AJ814+Periods!AJ930+Periods!AJ1046+Periods!AJ1162+Periods!AJ1278, "-") -> 0 | AK2: =IFERROR(Periods!AK2+Periods!AK118+Periods!AK234+Periods!AK350+Periods!AK466+Periods!AK582+Periods!AK698+Periods!AK814+Periods!AK930+Periods!AK1046+Periods!AK1162+Periods!AK1278, "-") -> 0 | AL2: =AJ2+AK2 -> 0 | AM2: =AL2/AH2 -> #DIV/0! | AN2: =O2/AL2 -> #DIV/0! | AO2: =IFERROR(Periods!AO2+Periods!AO118+Periods!AO234+Periods!AO350+Periods!AO466+Periods!AO582+Periods!AO698+Periods!AO814+Periods!AO930+Periods!AO1046+Periods!AO1162+Periods!AO1278, "-") -> 0 | AP2: =IFERROR(AVERAGE(Periods!AP2,Periods!AP118,Periods!AP234,Periods!AP350,Periods!AP466,Periods!AP582,Periods!AP698,Periods!AP814,Periods!AP930,Periods!AP1046,Periods!AP1162,Periods!AP1278), "-") -> - | AR2: =IFERROR(AH2/R2, "-") -> -
A3: 2026-2027 | B3: В2В | H3: =IFERROR(Periods!H3+Periods!H119+Periods!H235+Periods!H351+Periods!H467+Periods!H583+Periods!H699+Periods!H815+Periods!H931+Periods!H1047+Periods!H1163+Periods!H1279, "-") -> 0 | I3: =(M3*1.22)/R3 -> #DIV/0! | J3: =IFERROR(N3/M3-1,"-") -> - | K3: =I3*J3*H3 -> #DIV/0! | L3: =IFERROR(Periods!L3+Periods!L119+Periods!L235+Periods!L351+Periods!L467+Periods!L583+Periods!L699+Periods!L815+Periods!L931+Periods!L1047+Periods!L1163+Periods!L1279, "-") -> 0 | M3: =IFERROR(Periods!M3+Periods!M119+Periods!M235+Periods!M351+Periods!M467+Periods!M583+Periods!M699+Periods!M815+Periods!M931+Periods!M1047+Periods!M1163+Periods!M1279, "-") -> 0 | N3: =IFERROR(Periods!N3+Periods!N119+Periods!N235+Periods!N351+Periods!N467+Periods!N583+Periods!N699+Periods!N815+Periods!N931+Periods!N1047+Periods!N1163+Periods!N1279, "-") -> 0 | O3: =IFERROR(Periods!O3+Periods!O119+Periods!O235+Periods!O351+Periods!O467+Periods!O583+Periods!O699+Periods!O815+Periods!O931+Periods!O1047+Periods!O1163+Periods!O1279, "-") -> 0 | P3: =IFERROR(Periods!P3+Periods!P119+Periods!P235+Periods!P351+Periods!P467+Periods!P583+Periods!P699+Periods!P815+Periods!P931+Periods!P1047+Periods!P1163+Periods!P1279, "-") -> 0 | Q3: =IFERROR(R3/P3, "-") -> - | R3: =IFERROR(Periods!R3+Periods!R119+Periods!R235+Periods!R351+Periods!R467+Periods!R583+Periods!R699+Periods!R815+Periods!R931+Periods!R1047+Periods!R1163+Periods!R1279, "-") -> 0 | S3: =(ROUNDDOWN(O3/R3,0)) -> #DIV/0! | T3: =IFERROR(Periods!T3+Periods!T119+Periods!T235+Periods!T351+Periods!T467+Periods!T583+Periods!T699+Periods!T815+Periods!T931+Periods!T1047+Periods!T1163+Periods!T1279, "-") -> 0 | U3: =IFERROR(O3/T3, "-") -> - | V3: =IFERROR(R3/T3, "-") -> - | W3: =IFERROR(Periods!W3+Periods!W119+Periods!W235+Periods!W351+Periods!W467+Periods!W583+Periods!W699+Periods!W815+Periods!W931+Periods!W1047+Periods!W1163+Periods!W1279, "-") -> 0 | X3: =O3/W3 -> #DIV/0! | Y3: =W3/O3 -> #DIV/0! | Z3: =W3/T3 -> #DIV/0! | AA3: =IFERROR(Periods!AA3+Periods!AA119+Periods!AA235+Periods!AA351+Periods!AA467+Periods!AA583+Periods!AA699+Periods!AA815+Periods!AA931+Periods!AA1047+Periods!AA1163+Periods!AA1279, "-") -> 0 | AB3: =O3/AA3 -> #DIV/0! | AC3: =IFERROR(AA3/T3, "-") -> - | AD3: =IFERROR(Periods!AD3+Periods!AD119+Periods!AD235+Periods!AD351+Periods!AD467+Periods!AD583+Periods!AD699+Periods!AD815+Periods!AD931+Periods!AD1047+Periods!AD1163+Periods!AD1279, "-") -> 0 | AE3: =O3/AD3 -> #DIV/0! | AF3: =AD3/O3 -> #DIV/0! | AG3: =AD3/AA3 -> #DIV/0! | AH3: =IFERROR(Periods!AH3+Periods!AH119+Periods!AH235+Periods!AH351+Periods!AH467+Periods!AH583+Periods!AH699+Periods!AH815+Periods!AH931+Periods!AH1047+Periods!AH1163+Periods!AH1279, "-") -> 0 | AI3: =IFERROR(AVERAGE(Periods!AI3,Periods!AI119,Periods!AI235,Periods!AI351,Periods!AI467,Periods!AI583,Periods!AI699,Periods!AI815,Periods!AI931,Periods!AI1047,Periods!AI1163,Periods!AI1279), "-") -> - | AJ3: =IFERROR(Periods!AJ3+Periods!AJ119+Periods!AJ235+Periods!AJ351+Periods!AJ467+Periods!AJ583+Periods!AJ699+Periods!AJ815+Periods!AJ931+Periods!AJ1047+Periods!AJ1163+Periods!AJ1279, "-") -> 0 | AK3: =IFERROR(Periods!AK3+Periods!AK119+Periods!AK235+Periods!AK351+Periods!AK467+Periods!AK583+Periods!AK699+Periods!AK815+Periods!AK931+Periods!AK1047+Periods!AK1163+Periods!AK1279, "-") -> 0 | AL3: =AJ3+AK3 -> 0 | AM3: =AL3/AH3 -> #DIV/0! | AN3: =O3/AL3 -> #DIV/0! | AO3: =IFERROR(Periods!AO3+Periods!AO119+Periods!AO235+Periods!AO351+Periods!AO467+Periods!AO583+Periods!AO699+Periods!AO815+Periods!AO931+Periods!AO1047+Periods!AO1163+Periods!AO1279, "-") -> 0 | AP3: =IFERROR(AVERAGE(Periods!AP3,Periods!AP119,Periods!AP235,Periods!AP351,Periods!AP467,Periods!AP583,Periods!AP699,Periods!AP815,Periods!AP931,Periods!AP1047,Periods!AP1163,Periods!AP1279), "-") -> - | AR3: =IFERROR(AH3/R3, "-") -> -
A4: 2026-2027 | B4: В2В | H4: =IFERROR(Periods!H4+Periods!H120+Periods!H236+Periods!H352+Periods!H468+Periods!H584+Periods!H700+Periods!H816+Periods!H932+Periods!H1048+Periods!H1164+Periods!H1280, "-") -> 0 | I4: =(M4*1.22)/R4 -> #DIV/0! | J4: =IFERROR(N4/M4-1,"-") -> - | K4: =I4*J4*H4 -> #DIV/0! | L4: =IFERROR(Periods!L4+Periods!L120+Periods!L236+Periods!L352+Periods!L468+Periods!L584+Periods!L700+Periods!L816+Periods!L932+Periods!L1048+Periods!L1164+Periods!L1280, "-") -> 0 | M4: =IFERROR(Periods!M4+Periods!M120+Periods!M236+Periods!M352+Periods!M468+Periods!M584+Periods!M700+Periods!M816+Periods!M932+Periods!M1048+Periods!M1164+Periods!M1280, "-") -> 0 | N4: =IFERROR(Periods!N4+Periods!N120+Periods!N236+Periods!N352+Periods!N468+Periods!N584+Periods!N700+Periods!N816+Periods!N932+Periods!N1048+Periods!N1164+Periods!N1280, "-") -> 0 | O4: =IFERROR(Periods!O4+Periods!O120+Periods!O236+Periods!O352+Periods!O468+Periods!O584+Periods!O700+Periods!O816+Periods!O932+Periods!O1048+Periods!O1164+Periods!O1280, "-") -> 0 | P4: =IFERROR(Periods!P4+Periods!P120+Periods!P236+Periods!P352+Periods!P468+Periods!P584+Periods!P700+Periods!P816+Periods!P932+Periods!P1048+Periods!P1164+Periods!P1280, "-") -> 0 | Q4: =IFERROR(R4/P4, "-") -> - | R4: =IFERROR(Periods!R4+Periods!R120+Periods!R236+Periods!R352+Periods!R468+Periods!R584+Periods!R700+Periods!R816+Periods!R932+Periods!R1048+Periods!R1164+Periods!R1280, "-") -> 0 | S4: =(ROUNDDOWN(O4/R4,0)) -> #DIV/0! | T4: =IFERROR(Periods!T4+Periods!T120+Periods!T236+Periods!T352+Periods!T468+Periods!T584+Periods!T700+Periods!T816+Periods!T932+Periods!T1048+Periods!T1164+Periods!T1280, "-") -> 0 | U4: =IFERROR(O4/T4, "-") -> - | V4: =IFERROR(R4/T4, "-") -> - | W4: =IFERROR(Periods!W4+Periods!W120+Periods!W236+Periods!W352+Periods!W468+Periods!W584+Periods!W700+Periods!W816+Periods!W932+Periods!W1048+Periods!W1164+Periods!W1280, "-") -> 0 | X4: =O4/W4 -> #DIV/0! | Y4: =W4/O4 -> #DIV/0! | Z4: =W4/T4 -> #DIV/0! | AA4: =IFERROR(Periods!AA4+Periods!AA120+Periods!AA236+Periods!AA352+Periods!AA468+Periods!AA584+Periods!AA700+Periods!AA816+Periods!AA932+Periods!AA1048+Periods!AA1164+Periods!AA1280, "-") -> 0 | AB4: =O4/AA4 -> #DIV/0! | AC4: =IFERROR(AA4/T4, "-") -> - | AD4: =IFERROR(Periods!AD4+Periods!AD120+Periods!AD236+Periods!AD352+Periods!AD468+Periods!AD584+Periods!AD700+Periods!AD816+Periods!AD932+Periods!AD1048+Periods!AD1164+Periods!AD1280, "-") -> 0 | AE4: =O4/AD4 -> #DIV/0! | AF4: =AD4/O4 -> #DIV/0! | AG4: =AD4/AA4 -> #DIV/0! | AH4: =IFERROR(Periods!AH4+Periods!AH120+Periods!AH236+Periods!AH352+Periods!AH468+Periods!AH584+Periods!AH700+Periods!AH816+Periods!AH932+Periods!AH1048+Periods!AH1164+Periods!AH1280, "-") -> 0 | AI4: =IFERROR(AVERAGE(Periods!AI4,Periods!AI120,Periods!AI236,Periods!AI352,Periods!AI468,Periods!AI584,Periods!AI700,Periods!AI816,Periods!AI932,Periods!AI1048,Periods!AI1164,Periods!AI1280), "-") -> - | AJ4: =IFERROR(Periods!AJ4+Periods!AJ120+Periods!AJ236+Periods!AJ352+Periods!AJ468+Periods!AJ584+Periods!AJ700+Periods!AJ816+Periods!AJ932+Periods!AJ1048+Periods!AJ1164+Periods!AJ1280, "-") -> 0 | AK4: =IFERROR(Periods!AK4+Periods!AK120+Periods!AK236+Periods!AK352+Periods!AK468+Periods!AK584+Periods!AK700+Periods!AK816+Periods!AK932+Periods!AK1048+Periods!AK1164+Periods!AK1280, "-") -> 0 | AL4: =AJ4+AK4 -> 0 | AM4: =AL4/AH4 -> #DIV/0! | AN4: =O4/AL4 -> #DIV/0! | AO4: =IFERROR(Periods!AO4+Periods!AO120+Periods!AO236+Periods!AO352+Periods!AO468+Periods!AO584+Periods!AO700+Periods!AO816+Periods!AO932+Periods!AO1048+Periods!AO1164+Periods!AO1280, "-") -> 0 | AP4: =IFERROR(AVERAGE(Periods!AP4,Periods!AP120,Periods!AP236,Periods!AP352,Periods!AP468,Periods!AP584,Periods!AP700,Periods!AP816,Periods!AP932,Periods!AP1048,Periods!AP1164,Periods!AP1280), "-") -> - | AR4: =IFERROR(AH4/R4, "-") -> -
A5: 2026-2027 | B5: В2В | H5: =IFERROR(Periods!H5+Periods!H121+Periods!H237+Periods!H353+Periods!H469+Periods!H585+Periods!H701+Periods!H817+Periods!H933+Periods!H1049+Periods!H1165+Periods!H1281, "-") -> 0 | I5: =(M5*1.22)/R5 -> #DIV/0! | J5: =IFERROR(N5/M5-1,"-") -> - | K5: =I5*J5*H5 -> #DIV/0! | L5: =IFERROR(Periods!L5+Periods!L121+Periods!L237+Periods!L353+Periods!L469+Periods!L585+Periods!L701+Periods!L817+Periods!L933+Periods!L1049+Periods!L1165+Periods!L1281, "-") -> 0 | M5: =IFERROR(Periods!M5+Periods!M121+Periods!M237+Periods!M353+Periods!M469+Periods!M585+Periods!M701+Periods!M817+Periods!M933+Periods!M1049+Periods!M1165+Periods!M1281, "-") -> 0 | N5: =IFERROR(Periods!N5+Periods!N121+Periods!N237+Periods!N353+Periods!N469+Periods!N585+Periods!N701+Periods!N817+Periods!N933+Periods!N1049+Periods!N1165+Periods!N1281, "-") -> 0 | O5: =IFERROR(Periods!O5+Periods!O121+Periods!O237+Periods!O353+Periods!O469+Periods!O585+Periods!O701+Periods!O817+Periods!O933+Periods!O1049+Periods!O1165+Periods!O1281, "-") -> 0 | P5: =IFERROR(Periods!P5+Periods!P121+Periods!P237+Periods!P353+Periods!P469+Periods!P585+Periods!P701+Periods!P817+Periods!P933+Periods!P1049+Periods!P1165+Periods!P1281, "-") -> 0 | Q5: =IFERROR(R5/P5, "-") -> - | R5: =IFERROR(Periods!R5+Periods!R121+Periods!R237+Periods!R353+Periods!R469+Periods!R585+Periods!R701+Periods!R817+Periods!R933+Periods!R1049+Periods!R1165+Periods!R1281, "-") -> 0 | S5: =(ROUNDDOWN(O5/R5,0)) -> #DIV/0! | T5: =IFERROR(Periods!T5+Periods!T121+Periods!T237+Periods!T353+Periods!T469+Periods!T585+Periods!T701+Periods!T817+Periods!T933+Periods!T1049+Periods!T1165+Periods!T1281, "-") -> 0 | U5: =IFERROR(O5/T5, "-") -> - | V5: =IFERROR(R5/T5, "-") -> - | W5: =IFERROR(Periods!W5+Periods!W121+Periods!W237+Periods!W353+Periods!W469+Periods!W585+Periods!W701+Periods!W817+Periods!W933+Periods!W1049+Periods!W1165+Periods!W1281, "-") -> 0 | X5: =O5/W5 -> #DIV/0! | Y5: =W5/O5 -> #DIV/0! | Z5: =W5/T5 -> #DIV/0! | AA5: =IFERROR(Periods!AA5+Periods!AA121+Periods!AA237+Periods!AA353+Periods!AA469+Periods!AA585+Periods!AA701+Periods!AA817+Periods!AA933+Periods!AA1049+Periods!AA1165+Periods!AA1281, "-") -> 0 | AB5: =O5/AA5 -> #DIV/0! | AC5: =IFERROR(AA5/T5, "-") -> - | AD5: =IFERROR(Periods!AD5+Periods!AD121+Periods!AD237+Periods!AD353+Periods!AD469+Periods!AD585+Periods!AD701+Periods!AD817+Periods!AD933+Periods!AD1049+Periods!AD1165+Periods!AD1281, "-") -> 0 | AE5: =O5/AD5 -> #DIV/0! | AF5: =AD5/O5 -> #DIV/0! | AG5: =AD5/AA5 -> #DIV/0! | AH5: =IFERROR(Periods!AH5+Periods!AH121+Periods!AH237+Periods!AH353+Periods!AH469+Periods!AH585+Periods!AH701+Periods!AH817+Periods!AH933+Periods!AH1049+Periods!AH1165+Periods!AH1281, "-") -> 0 | AI5: =IFERROR(AVERAGE(Periods!AI5,Periods!AI121,Periods!AI237,Periods!AI353,Periods!AI469,Periods!AI585,Periods!AI701,Periods!AI817,Periods!AI933,Periods!AI1049,Periods!AI1165,Periods!AI1281), "-") -> - | AJ5: =IFERROR(Periods!AJ5+Periods!AJ121+Periods!AJ237+Periods!AJ353+Periods!AJ469+Periods!AJ585+Periods!AJ701+Periods!AJ817+Periods!AJ933+Periods!AJ1049+Periods!AJ1165+Periods!AJ1281, "-") -> 0 | AK5: =IFERROR(Periods!AK5+Periods!AK121+Periods!AK237+Periods!AK353+Periods!AK469+Periods!AK585+Periods!AK701+Periods!AK817+Periods!AK933+Periods!AK1049+Periods!AK1165+Periods!AK1281, "-") -> 0 | AL5: =AJ5+AK5 -> 0 | AM5: =AL5/AH5 -> #DIV/0! | AN5: =O5/AL5 -> #DIV/0! | AO5: =IFERROR(Periods!AO5+Periods!AO121+Periods!AO237+Periods!AO353+Periods!AO469+Periods!AO585+Periods!AO701+Periods!AO817+Periods!AO933+Periods!AO1049+Periods!AO1165+Periods!AO1281, "-") -> 0 | AP5: =IFERROR(AVERAGE(Periods!AP5,Periods!AP121,Periods!AP237,Periods!AP353,Periods!AP469,Periods!AP585,Periods!AP701,Periods!AP817,Periods!AP933,Periods!AP1049,Periods!AP1165,Periods!AP1281), "-") -> - | AR5: =IFERROR(AH5/R5, "-") -> -
A6: 2026-2027 | B6: В2В | H6: =IFERROR(Periods!H6+Periods!H122+Periods!H238+Periods!H354+Periods!H470+Periods!H586+Periods!H702+Periods!H818+Periods!H934+Periods!H1050+Periods!H1166+Periods!H1282, "-") -> 0 | I6: =(M6*1.22)/R6 -> #DIV/0! | J6: =IFERROR(N6/M6-1,"-") -> - | K6: =I6*J6*H6 -> #DIV/0! | L6: =IFERROR(Periods!L6+Periods!L122+Periods!L238+Periods!L354+Periods!L470+Periods!L586+Periods!L702+Periods!L818+Periods!L934+Periods!L1050+Periods!L1166+Periods!L1282, "-") -> 0 | M6: =IFERROR(Periods!M6+Periods!M122+Periods!M238+Periods!M354+Periods!M470+Periods!M586+Periods!M702+Periods!M818+Periods!M934+Periods!M1050+Periods!M1166+Periods!M1282, "-") -> 0 | N6: =IFERROR(Periods!N6+Periods!N122+Periods!N238+Periods!N354+Periods!N470+Periods!N586+Periods!N702+Periods!N818+Periods!N934+Periods!N1050+Periods!N1166+Periods!N1282, "-") -> 0 | O6: =IFERROR(Periods!O6+Periods!O122+Periods!O238+Periods!O354+Periods!O470+Periods!O586+Periods!O702+Periods!O818+Periods!O934+Periods!O1050+Periods!O1166+Periods!O1282, "-") -> 0 | P6: =IFERROR(Periods!P6+Periods!P122+Periods!P238+Periods!P354+Periods!P470+Periods!P586+Periods!P702+Periods!P818+Periods!P934+Periods!P1050+Periods!P1166+Periods!P1282, "-") -> 0 | Q6: =IFERROR(R6/P6, "-") -> - | R6: =IFERROR(Periods!R6+Periods!R122+Periods!R238+Periods!R354+Periods!R470+Periods!R586+Periods!R702+Periods!R818+Periods!R934+Periods!R1050+Periods!R1166+Periods!R1282, "-") -> 0 | S6: =(ROUNDDOWN(O6/R6,0)) -> #DIV/0! | T6: =IFERROR(Periods!T6+Periods!T122+Periods!T238+Periods!T354+Periods!T470+Periods!T586+Periods!T702+Periods!T818+Periods!T934+Periods!T1050+Periods!T1166+Periods!T1282, "-") -> 0 | U6: =IFERROR(O6/T6, "-") -> - | V6: =IFERROR(R6/T6, "-") -> - | W6: =IFERROR(Periods!W6+Periods!W122+Periods!W238+Periods!W354+Periods!W470+Periods!W586+Periods!W702+Periods!W818+Periods!W934+Periods!W1050+Periods!W1166+Periods!W1282, "-") -> 0 | X6: =O6/W6 -> #DIV/0! | Y6: =W6/O6 -> #DIV/0! | Z6: =W6/T6 -> #DIV/0! | AA6: =IFERROR(Periods!AA6+Periods!AA122+Periods!AA238+Periods!AA354+Periods!AA470+Periods!AA586+Periods!AA702+Periods!AA818+Periods!AA934+Periods!AA1050+Periods!AA1166+Periods!AA1282, "-") -> 0 | AB6: =O6/AA6 -> #DIV/0! | AC6: =IFERROR(AA6/T6, "-") -> - | AD6: =IFERROR(Periods!AD6+Periods!AD122+Periods!AD238+Periods!AD354+Periods!AD470+Periods!AD586+Periods!AD702+Periods!AD818+Periods!AD934+Periods!AD1050+Periods!AD1166+Periods!AD1282, "-") -> 0 | AE6: =O6/AD6 -> #DIV/0! | AF6: =AD6/O6 -> #DIV/0! | AG6: =AD6/AA6 -> #DIV/0! | AH6: =IFERROR(Periods!AH6+Periods!AH122+Periods!AH238+Periods!AH354+Periods!AH470+Periods!AH586+Periods!AH702+Periods!AH818+Periods!AH934+Periods!AH1050+Periods!AH1166+Periods!AH1282, "-") -> 0 | AI6: =IFERROR(AVERAGE(Periods!AI6,Periods!AI122,Periods!AI238,Periods!AI354,Periods!AI470,Periods!AI586,Periods!AI702,Periods!AI818,Periods!AI934,Periods!AI1050,Periods!AI1166,Periods!AI1282), "-") -> - | AJ6: =IFERROR(Periods!AJ6+Periods!AJ122+Periods!AJ238+Periods!AJ354+Periods!AJ470+Periods!AJ586+Periods!AJ702+Periods!AJ818+Periods!AJ934+Periods!AJ1050+Periods!AJ1166+Periods!AJ1282, "-") -> 0 | AK6: =IFERROR(Periods!AK6+Periods!AK122+Periods!AK238+Periods!AK354+Periods!AK470+Periods!AK586+Periods!AK702+Periods!AK818+Periods!AK934+Periods!AK1050+Periods!AK1166+Periods!AK1282, "-") -> 0 | AL6: =AJ6+AK6 -> 0 | AM6: =AL6/AH6 -> #DIV/0! | AN6: =O6/AL6 -> #DIV/0! | AO6: =IFERROR(Periods!AO6+Periods!AO122+Periods!AO238+Periods!AO354+Periods!AO470+Periods!AO586+Periods!AO702+Periods!AO818+Periods!AO934+Periods!AO1050+Periods!AO1166+Periods!AO1282, "-") -> 0 | AP6: =IFERROR(AVERAGE(Periods!AP6,Periods!AP122,Periods!AP238,Periods!AP354,Periods!AP470,Periods!AP586,Periods!AP702,Periods!AP818,Periods!AP934,Periods!AP1050,Periods!AP1166,Periods!AP1282), "-") -> - | AR6: =IFERROR(AH6/R6, "-") -> -
A7: 2026-2027 | B7: В2В | H7: =IFERROR(Periods!H7+Periods!H123+Periods!H239+Periods!H355+Periods!H471+Periods!H587+Periods!H703+Periods!H819+Periods!H935+Periods!H1051+Periods!H1167+Periods!H1283, "-") -> 0 | I7: =(M7*1.22)/R7 -> #DIV/0! | J7: =IFERROR(N7/M7-1,"-") -> - | K7: =I7*J7*H7 -> #DIV/0! | L7: =IFERROR(Periods!L7+Periods!L123+Periods!L239+Periods!L355+Periods!L471+Periods!L587+Periods!L703+Periods!L819+Periods!L935+Periods!L1051+Periods!L1167+Periods!L1283, "-") -> 0 | M7: =IFERROR(Periods!M7+Periods!M123+Periods!M239+Periods!M355+Periods!M471+Periods!M587+Periods!M703+Periods!M819+Periods!M935+Periods!M1051+Periods!M1167+Periods!M1283, "-") -> 0 | N7: =IFERROR(Periods!N7+Periods!N123+Periods!N239+Periods!N355+Periods!N471+Periods!N587+Periods!N703+Periods!N819+Periods!N935+Periods!N1051+Periods!N1167+Periods!N1283, "-") -> 0 | O7: =IFERROR(Periods!O7+Periods!O123+Periods!O239+Periods!O355+Periods!O471+Periods!O587+Periods!O703+Periods!O819+Periods!O935+Periods!O1051+Periods!O1167+Periods!O1283, "-") -> 0 | P7: =IFERROR(Periods!P7+Periods!P123+Periods!P239+Periods!P355+Periods!P471+Periods!P587+Periods!P703+Periods!P819+Periods!P935+Periods!P1051+Periods!P1167+Periods!P1283, "-") -> 0 | Q7: =IFERROR(R7/P7, "-") -> - | R7: =IFERROR(Periods!R7+Periods!R123+Periods!R239+Periods!R355+Periods!R471+Periods!R587+Periods!R703+Periods!R819+Periods!R935+Periods!R1051+Periods!R1167+Periods!R1283, "-") -> 0 | S7: =(ROUNDDOWN(O7/R7,0)) -> #DIV/0! | T7: =IFERROR(Periods!T7+Periods!T123+Periods!T239+Periods!T355+Periods!T471+Periods!T587+Periods!T703+Periods!T819+Periods!T935+Periods!T1051+Periods!T1167+Periods!T1283, "-") -> 0 | U7: =IFERROR(O7/T7, "-") -> - | V7: =IFERROR(R7/T7, "-") -> - | W7: =IFERROR(Periods!W7+Periods!W123+Periods!W239+Periods!W355+Periods!W471+Periods!W587+Periods!W703+Periods!W819+Periods!W935+Periods!W1051+Periods!W1167+Periods!W1283, "-") -> 0 | X7: =O7/W7 -> #DIV/0! | Y7: =W7/O7 -> #DIV/0! | Z7: =W7/T7 -> #DIV/0! | AA7: =IFERROR(Periods!AA7+Periods!AA123+Periods!AA239+Periods!AA355+Periods!AA471+Periods!AA587+Periods!AA703+Periods!AA819+Periods!AA935+Periods!AA1051+Periods!AA1167+Periods!AA1283, "-") -> 0 | AB7: =O7/AA7 -> #DIV/0! | AC7: =IFERROR(AA7/T7, "-") -> - | AD7: =IFERROR(Periods!AD7+Periods!AD123+Periods!AD239+Periods!AD355+Periods!AD471+Periods!AD587+Periods!AD703+Periods!AD819+Periods!AD935+Periods!AD1051+Periods!AD1167+Periods!AD1283, "-") -> 0 | AE7: =O7/AD7 -> #DIV/0! | AF7: =AD7/O7 -> #DIV/0! | AG7: =AD7/AA7 -> #DIV/0! | AH7: =IFERROR(Periods!AH7+Periods!AH123+Periods!AH239+Periods!AH355+Periods!AH471+Periods!AH587+Periods!AH703+Periods!AH819+Periods!AH935+Periods!AH1051+Periods!AH1167+Periods!AH1283, "-") -> 0 | AI7: =IFERROR(AVERAGE(Periods!AI7,Periods!AI123,Periods!AI239,Periods!AI355,Periods!AI471,Periods!AI587,Periods!AI703,Periods!AI819,Periods!AI935,Periods!AI1051,Periods!AI1167,Periods!AI1283), "-") -> - | AJ7: =IFERROR(Periods!AJ7+Periods!AJ123+Periods!AJ239+Periods!AJ355+Periods!AJ471+Periods!AJ587+Periods!AJ703+Periods!AJ819+Periods!AJ935+Periods!AJ1051+Periods!AJ1167+Periods!AJ1283, "-") -> 0 | AK7: =IFERROR(Periods!AK7+Periods!AK123+Periods!AK239+Periods!AK355+Periods!AK471+Periods!AK587+Periods!AK703+Periods!AK819+Periods!AK935+Periods!AK1051+Periods!AK1167+Periods!AK1283, "-") -> 0 | AL7: =AJ7+AK7 -> 0 | AM7: =AL7/AH7 -> #DIV/0! | AN7: =O7/AL7 -> #DIV/0! | AO7: =IFERROR(Periods!AO7+Periods!AO123+Periods!AO239+Periods!AO355+Periods!AO471+Periods!AO587+Periods!AO703+Periods!AO819+Periods!AO935+Periods!AO1051+Periods!AO1167+Periods!AO1283, "-") -> 0 | AP7: =IFERROR(AVERAGE(Periods!AP7,Periods!AP123,Periods!AP239,Periods!AP355,Periods!AP471,Periods!AP587,Periods!AP703,Periods!AP819,Periods!AP935,Periods!AP1051,Periods!AP1167,Periods!AP1283), "-") -> - | AR7: =IFERROR(AH7/R7, "-") -> -
A8: 2026-2027 | B8: В2В | H8: =IFERROR(Periods!H8+Periods!H124+Periods!H240+Periods!H356+Periods!H472+Periods!H588+Periods!H704+Periods!H820+Periods!H936+Periods!H1052+Periods!H1168+Periods!H1284, "-") -> 0 | I8: =(M8*1.22)/R8 -> #DIV/0! | J8: =IFERROR(N8/M8-1,"-") -> - | K8: =I8*J8*H8 -> #DIV/0! | L8: =IFERROR(Periods!L8+Periods!L124+Periods!L240+Periods!L356+Periods!L472+Periods!L588+Periods!L704+Periods!L820+Periods!L936+Periods!L1052+Periods!L1168+Periods!L1284, "-") -> 0 | M8: =IFERROR(Periods!M8+Periods!M124+Periods!M240+Periods!M356+Periods!M472+Periods!M588+Periods!M704+Periods!M820+Periods!M936+Periods!M1052+Periods!M1168+Periods!M1284, "-") -> 0 | N8: =IFERROR(Periods!N8+Periods!N124+Periods!N240+Periods!N356+Periods!N472+Periods!N588+Periods!N704+Periods!N820+Periods!N936+Periods!N1052+Periods!N1168+Periods!N1284, "-") -> 0 | O8: =IFERROR(Periods!O8+Periods!O124+Periods!O240+Periods!O356+Periods!O472+Periods!O588+Periods!O704+Periods!O820+Periods!O936+Periods!O1052+Periods!O1168+Periods!O1284, "-") -> 0 | P8: =IFERROR(Periods!P8+Periods!P124+Periods!P240+Periods!P356+Periods!P472+Periods!P588+Periods!P704+Periods!P820+Periods!P936+Periods!P1052+Periods!P1168+Periods!P1284, "-") -> 0 | Q8: =IFERROR(R8/P8, "-") -> - | R8: =IFERROR(Periods!R8+Periods!R124+Periods!R240+Periods!R356+Periods!R472+Periods!R588+Periods!R704+Periods!R820+Periods!R936+Periods!R1052+Periods!R1168+Periods!R1284, "-") -> 0 | S8: =(ROUNDDOWN(O8/R8,0)) -> #DIV/0! | T8: =IFERROR(Periods!T8+Periods!T124+Periods!T240+Periods!T356+Periods!T472+Periods!T588+Periods!T704+Periods!T820+Periods!T936+Periods!T1052+Periods!T1168+Periods!T1284, "-") -> 0 | U8: =IFERROR(O8/T8, "-") -> - | V8: =IFERROR(R8/T8, "-") -> - | W8: =IFERROR(Periods!W8+Periods!W124+Periods!W240+Periods!W356+Periods!W472+Periods!W588+Periods!W704+Periods!W820+Periods!W936+Periods!W1052+Periods!W1168+Periods!W1284, "-") -> 0 | X8: =O8/W8 -> #DIV/0! | Y8: =W8/O8 -> #DIV/0! | Z8: =W8/T8 -> #DIV/0! | AA8: =IFERROR(Periods!AA8+Periods!AA124+Periods!AA240+Periods!AA356+Periods!AA472+Periods!AA588+Periods!AA704+Periods!AA820+Periods!AA936+Periods!AA1052+Periods!AA1168+Periods!AA1284, "-") -> 0 | AB8: =O8/AA8 -> #DIV/0! | AC8: =IFERROR(AA8/T8, "-") -> - | AD8: =IFERROR(Periods!AD8+Periods!AD124+Periods!AD240+Periods!AD356+Periods!AD472+Periods!AD588+Periods!AD704+Periods!AD820+Periods!AD936+Periods!AD1052+Periods!AD1168+Periods!AD1284, "-") -> 0 | AE8: =O8/AD8 -> #DIV/0! | AF8: =AD8/O8 -> #DIV/0! | AG8: =AD8/AA8 -> #DIV/0! | AH8: =IFERROR(Periods!AH8+Periods!AH124+Periods!AH240+Periods!AH356+Periods!AH472+Periods!AH588+Periods!AH704+Periods!AH820+Periods!AH936+Periods!AH1052+Periods!AH1168+Periods!AH1284, "-") -> 0 | AI8: =IFERROR(AVERAGE(Periods!AI8,Periods!AI124,Periods!AI240,Periods!AI356,Periods!AI472,Periods!AI588,Periods!AI704,Periods!AI820,Periods!AI936,Periods!AI1052,Periods!AI1168,Periods!AI1284), "-") -> - | AJ8: =IFERROR(Periods!AJ8+Periods!AJ124+Periods!AJ240+Periods!AJ356+Periods!AJ472+Periods!AJ588+Periods!AJ704+Periods!AJ820+Periods!AJ936+Periods!AJ1052+Periods!AJ1168+Periods!AJ1284, "-") -> 0 | AK8: =IFERROR(Periods!AK8+Periods!AK124+Periods!AK240+Periods!AK356+Periods!AK472+Periods!AK588+Periods!AK704+Periods!AK820+Periods!AK936+Periods!AK1052+Periods!AK1168+Periods!AK1284, "-") -> 0 | AL8: =AJ8+AK8 -> 0 | AM8: =AL8/AH8 -> #DIV/0! | AN8: =O8/AL8 -> #DIV/0! | AO8: =IFERROR(Periods!AO8+Periods!AO124+Periods!AO240+Periods!AO356+Periods!AO472+Periods!AO588+Periods!AO704+Periods!AO820+Periods!AO936+Periods!AO1052+Periods!AO1168+Periods!AO1284, "-") -> 0 | AP8: =IFERROR(AVERAGE(Periods!AP8,Periods!AP124,Periods!AP240,Periods!AP356,Periods!AP472,Periods!AP588,Periods!AP704,Periods!AP820,Periods!AP936,Periods!AP1052,Periods!AP1168,Periods!AP1284), "-") -> - | AR8: =IFERROR(AH8/R8, "-") -> -
A9: 2026-2027 | B9: В2В | H9: =IFERROR(Periods!H9+Periods!H125+Periods!H241+Periods!H357+Periods!H473+Periods!H589+Periods!H705+Periods!H821+Periods!H937+Periods!H1053+Periods!H1169+Periods!H1285, "-") -> 0 | I9: =(M9*1.22)/R9 -> #DIV/0! | J9: =IFERROR(N9/M9-1,"-") -> - | K9: =I9*J9*H9 -> #DIV/0! | L9: =IFERROR(Periods!L9+Periods!L125+Periods!L241+Periods!L357+Periods!L473+Periods!L589+Periods!L705+Periods!L821+Periods!L937+Periods!L1053+Periods!L1169+Periods!L1285, "-") -> 0 | M9: =IFERROR(Periods!M9+Periods!M125+Periods!M241+Periods!M357+Periods!M473+Periods!M589+Periods!M705+Periods!M821+Periods!M937+Periods!M1053+Periods!M1169+Periods!M1285, "-") -> 0 | N9: =IFERROR(Periods!N9+Periods!N125+Periods!N241+Periods!N357+Periods!N473+Periods!N589+Periods!N705+Periods!N821+Periods!N937+Periods!N1053+Periods!N1169+Periods!N1285, "-") -> 0 | O9: =IFERROR(Periods!O9+Periods!O125+Periods!O241+Periods!O357+Periods!O473+Periods!O589+Periods!O705+Periods!O821+Periods!O937+Periods!O1053+Periods!O1169+Periods!O1285, "-") -> 0 | P9: =IFERROR(Periods!P9+Periods!P125+Periods!P241+Periods!P357+Periods!P473+Periods!P589+Periods!P705+Periods!P821+Periods!P937+Periods!P1053+Periods!P1169+Periods!P1285, "-") -> 0 | Q9: =IFERROR(R9/P9, "-") -> - | R9: =IFERROR(Periods!R9+Periods!R125+Periods!R241+Periods!R357+Periods!R473+Periods!R589+Periods!R705+Periods!R821+Periods!R937+Periods!R1053+Periods!R1169+Periods!R1285, "-") -> 0 | S9: =(ROUNDDOWN(O9/R9,0)) -> #DIV/0! | T9: =IFERROR(Periods!T9+Periods!T125+Periods!T241+Periods!T357+Periods!T473+Periods!T589+Periods!T705+Periods!T821+Periods!T937+Periods!T1053+Periods!T1169+Periods!T1285, "-") -> 0 | U9: =IFERROR(O9/T9, "-") -> - | V9: =IFERROR(R9/T9, "-") -> - | W9: =IFERROR(Periods!W9+Periods!W125+Periods!W241+Periods!W357+Periods!W473+Periods!W589+Periods!W705+Periods!W821+Periods!W937+Periods!W1053+Periods!W1169+Periods!W1285, "-") -> 0 | X9: =O9/W9 -> #DIV/0! | Y9: =W9/O9 -> #DIV/0! | Z9: =W9/T9 -> #DIV/0! | AA9: =IFERROR(Periods!AA9+Periods!AA125+Periods!AA241+Periods!AA357+Periods!AA473+Periods!AA589+Periods!AA705+Periods!AA821+Periods!AA937+Periods!AA1053+Periods!AA1169+Periods!AA1285, "-") -> 0 | AB9: =O9/AA9 -> #DIV/0! | AC9: =IFERROR(AA9/T9, "-") -> - | AD9: =IFERROR(Periods!AD9+Periods!AD125+Periods!AD241+Periods!AD357+Periods!AD473+Periods!AD589+Periods!AD705+Periods!AD821+Periods!AD937+Periods!AD1053+Periods!AD1169+Periods!AD1285, "-") -> 0 | AE9: =O9/AD9 -> #DIV/0! | AF9: =AD9/O9 -> #DIV/0! | AG9: =AD9/AA9 -> #DIV/0! | AH9: =IFERROR(Periods!AH9+Periods!AH125+Periods!AH241+Periods!AH357+Periods!AH473+Periods!AH589+Periods!AH705+Periods!AH821+Periods!AH937+Periods!AH1053+Periods!AH1169+Periods!AH1285, "-") -> 0 | AI9: =IFERROR(AVERAGE(Periods!AI9,Periods!AI125,Periods!AI241,Periods!AI357,Periods!AI473,Periods!AI589,Periods!AI705,Periods!AI821,Periods!AI937,Periods!AI1053,Periods!AI1169,Periods!AI1285), "-") -> - | AJ9: =IFERROR(Periods!AJ9+Periods!AJ125+Periods!AJ241+Periods!AJ357+Periods!AJ473+Periods!AJ589+Periods!AJ705+Periods!AJ821+Periods!AJ937+Periods!AJ1053+Periods!AJ1169+Periods!AJ1285, "-") -> 0 | AK9: =IFERROR(Periods!AK9+Periods!AK125+Periods!AK241+Periods!AK357+Periods!AK473+Periods!AK589+Periods!AK705+Periods!AK821+Periods!AK937+Periods!AK1053+Periods!AK1169+Periods!AK1285, "-") -> 0 | AL9: =AJ9+AK9 -> 0 | AM9: =AL9/AH9 -> #DIV/0! | AN9: =O9/AL9 -> #DIV/0! | AO9: =IFERROR(Periods!AO9+Periods!AO125+Periods!AO241+Periods!AO357+Periods!AO473+Periods!AO589+Periods!AO705+Periods!AO821+Periods!AO937+Periods!AO1053+Periods!AO1169+Periods!AO1285, "-") -> 0 | AP9: =IFERROR(AVERAGE(Periods!AP9,Periods!AP125,Periods!AP241,Periods!AP357,Periods!AP473,Periods!AP589,Periods!AP705,Periods!AP821,Periods!AP937,Periods!AP1053,Periods!AP1169,Periods!AP1285), "-") -> - | AR9: =IFERROR(AH9/R9, "-") -> -
A10: 2026-2027 | B10: В2В | H10: =IFERROR(Periods!H10+Periods!H126+Periods!H242+Periods!H358+Periods!H474+Periods!H590+Periods!H706+Periods!H822+Periods!H938+Periods!H1054+Periods!H1170+Periods!H1286, "-") -> 0 | I10: =(M10*1.22)/R10 -> #DIV/0! | J10: =IFERROR(N10/M10-1,"-") -> - | K10: =I10*J10*H10 -> #DIV/0! | L10: =IFERROR(Periods!L10+Periods!L126+Periods!L242+Periods!L358+Periods!L474+Periods!L590+Periods!L706+Periods!L822+Periods!L938+Periods!L1054+Periods!L1170+Periods!L1286, "-") -> 0 | M10: =IFERROR(Periods!M10+Periods!M126+Periods!M242+Periods!M358+Periods!M474+Periods!M590+Periods!M706+Periods!M822+Periods!M938+Periods!M1054+Periods!M1170+Periods!M1286, "-") -> 0 | N10: =IFERROR(Periods!N10+Periods!N126+Periods!N242+Periods!N358+Periods!N474+Periods!N590+Periods!N706+Periods!N822+Periods!N938+Periods!N1054+Periods!N1170+Periods!N1286, "-") -> 0 | O10: =IFERROR(Periods!O10+Periods!O126+Periods!O242+Periods!O358+Periods!O474+Periods!O590+Periods!O706+Periods!O822+Periods!O938+Periods!O1054+Periods!O1170+Periods!O1286, "-") -> 0 | P10: =IFERROR(Periods!P10+Periods!P126+Periods!P242+Periods!P358+Periods!P474+Periods!P590+Periods!P706+Periods!P822+Periods!P938+Periods!P1054+Periods!P1170+Periods!P1286, "-") -> 0 | Q10: =IFERROR(R10/P10, "-") -> - | R10: =IFERROR(Periods!R10+Periods!R126+Periods!R242+Periods!R358+Periods!R474+Periods!R590+Periods!R706+Periods!R822+Periods!R938+Periods!R1054+Periods!R1170+Periods!R1286, "-") -> 0 | S10: =(ROUNDDOWN(O10/R10,0)) -> #DIV/0! | T10: =IFERROR(Periods!T10+Periods!T126+Periods!T242+Periods!T358+Periods!T474+Periods!T590+Periods!T706+Periods!T822+Periods!T938+Periods!T1054+Periods!T1170+Periods!T1286, "-") -> 0 | U10: =IFERROR(O10/T10, "-") -> - | V10: =IFERROR(R10/T10, "-") -> - | W10: =IFERROR(Periods!W10+Periods!W126+Periods!W242+Periods!W358+Periods!W474+Periods!W590+Periods!W706+Periods!W822+Periods!W938+Periods!W1054+Periods!W1170+Periods!W1286, "-") -> 0 | X10: =O10/W10 -> #DIV/0! | Y10: =W10/O10 -> #DIV/0! | Z10: =W10/T10 -> #DIV/0! | AA10: =IFERROR(Periods!AA10+Periods!AA126+Periods!AA242+Periods!AA358+Periods!AA474+Periods!AA590+Periods!AA706+Periods!AA822+Periods!AA938+Periods!AA1054+Periods!AA1170+Periods!AA1286, "-") -> 0 | AB10: =O10/AA10 -> #DIV/0! | AC10: =IFERROR(AA10/T10, "-") -> - | AD10: =IFERROR(Periods!AD10+Periods!AD126+Periods!AD242+Periods!AD358+Periods!AD474+Periods!AD590+Periods!AD706+Periods!AD822+Periods!AD938+Periods!AD1054+Periods!AD1170+Periods!AD1286, "-") -> 0 | AE10: =O10/AD10 -> #DIV/0! | AF10: =AD10/O10 -> #DIV/0! | AG10: =AD10/AA10 -> #DIV/0! | AH10: =IFERROR(Periods!AH10+Periods!AH126+Periods!AH242+Periods!AH358+Periods!AH474+Periods!AH590+Periods!AH706+Periods!AH822+Periods!AH938+Periods!AH1054+Periods!AH1170+Periods!AH1286, "-") -> 0 | AI10: =IFERROR(AVERAGE(Periods!AI10,Periods!AI126,Periods!AI242,Periods!AI358,Periods!AI474,Periods!AI590,Periods!AI706,Periods!AI822,Periods!AI938,Periods!AI1054,Periods!AI1170,Periods!AI1286), "-") -> - | AJ10: =IFERROR(Periods!AJ10+Periods!AJ126+Periods!AJ242+Periods!AJ358+Periods!AJ474+Periods!AJ590+Periods!AJ706+Periods!AJ822+Periods!AJ938+Periods!AJ1054+Periods!AJ1170+Periods!AJ1286, "-") -> 0 | AK10: =IFERROR(Periods!AK10+Periods!AK126+Periods!AK242+Periods!AK358+Periods!AK474+Periods!AK590+Periods!AK706+Periods!AK822+Periods!AK938+Periods!AK1054+Periods!AK1170+Periods!AK1286, "-") -> 0 | AL10: =AJ10+AK10 -> 0 | AM10: =AL10/AH10 -> #DIV/0! | AN10: =O10/AL10 -> #DIV/0! | AO10: =IFERROR(Periods!AO10+Periods!AO126+Periods!AO242+Periods!AO358+Periods!AO474+Periods!AO590+Periods!AO706+Periods!AO822+Periods!AO938+Periods!AO1054+Periods!AO1170+Periods!AO1286, "-") -> 0 | AP10: =IFERROR(AVERAGE(Periods!AP10,Periods!AP126,Periods!AP242,Periods!AP358,Periods!AP474,Periods!AP590,Periods!AP706,Periods!AP822,Periods!AP938,Periods!AP1054,Periods!AP1170,Periods!AP1286), "-") -> - | AR10: =IFERROR(AH10/R10, "-") -> -
A11: 2026-2027 | B11: В2В | H11: =IFERROR(Periods!H11+Periods!H127+Periods!H243+Periods!H359+Periods!H475+Periods!H591+Periods!H707+Periods!H823+Periods!H939+Periods!H1055+Periods!H1171+Periods!H1287, "-") -> 0 | I11: =(M11*1.22)/R11 -> #DIV/0! | J11: =IFERROR(N11/M11-1,"-") -> - | K11: =I11*J11*H11 -> #DIV/0! | L11: =IFERROR(Periods!L11+Periods!L127+Periods!L243+Periods!L359+Periods!L475+Periods!L591+Periods!L707+Periods!L823+Periods!L939+Periods!L1055+Periods!L1171+Periods!L1287, "-") -> 0 | M11: =IFERROR(Periods!M11+Periods!M127+Periods!M243+Periods!M359+Periods!M475+Periods!M591+Periods!M707+Periods!M823+Periods!M939+Periods!M1055+Periods!M1171+Periods!M1287, "-") -> 0 | N11: =IFERROR(Periods!N11+Periods!N127+Periods!N243+Periods!N359+Periods!N475+Periods!N591+Periods!N707+Periods!N823+Periods!N939+Periods!N1055+Periods!N1171+Periods!N1287, "-") -> 0 | O11: =IFERROR(Periods!O11+Periods!O127+Periods!O243+Periods!O359+Periods!O475+Periods!O591+Periods!O707+Periods!O823+Periods!O939+Periods!O1055+Periods!O1171+Periods!O1287, "-") -> 0 | P11: =IFERROR(Periods!P11+Periods!P127+Periods!P243+Periods!P359+Periods!P475+Periods!P591+Periods!P707+Periods!P823+Periods!P939+Periods!P1055+Periods!P1171+Periods!P1287, "-") -> 0 | Q11: =IFERROR(R11/P11, "-") -> - | R11: =IFERROR(Periods!R11+Periods!R127+Periods!R243+Periods!R359+Periods!R475+Periods!R591+Periods!R707+Periods!R823+Periods!R939+Periods!R1055+Periods!R1171+Periods!R1287, "-") -> 0 | S11: =(ROUNDDOWN(O11/R11,0)) -> #DIV/0! | T11: =IFERROR(Periods!T11+Periods!T127+Periods!T243+Periods!T359+Periods!T475+Periods!T591+Periods!T707+Periods!T823+Periods!T939+Periods!T1055+Periods!T1171+Periods!T1287, "-") -> 0 | U11: =IFERROR(O11/T11, "-") -> - | V11: =IFERROR(R11/T11, "-") -> - | W11: =IFERROR(Periods!W11+Periods!W127+Periods!W243+Periods!W359+Periods!W475+Periods!W591+Periods!W707+Periods!W823+Periods!W939+Periods!W1055+Periods!W1171+Periods!W1287, "-") -> 0 | X11: =O11/W11 -> #DIV/0! | Y11: =W11/O11 -> #DIV/0! | Z11: =W11/T11 -> #DIV/0! | AA11: =IFERROR(Periods!AA11+Periods!AA127+Periods!AA243+Periods!AA359+Periods!AA475+Periods!AA591+Periods!AA707+Periods!AA823+Periods!AA939+Periods!AA1055+Periods!AA1171+Periods!AA1287, "-") -> 0 | AB11: =O11/AA11 -> #DIV/0! | AC11: =IFERROR(AA11/T11, "-") -> - | AD11: =IFERROR(Periods!AD11+Periods!AD127+Periods!AD243+Periods!AD359+Periods!AD475+Periods!AD591+Periods!AD707+Periods!AD823+Periods!AD939+Periods!AD1055+Periods!AD1171+Periods!AD1287, "-") -> 0 | AE11: =O11/AD11 -> #DIV/0! | AF11: =AD11/O11 -> #DIV/0! | AG11: =AD11/AA11 -> #DIV/0! | AH11: =IFERROR(Periods!AH11+Periods!AH127+Periods!AH243+Periods!AH359+Periods!AH475+Periods!AH591+Periods!AH707+Periods!AH823+Periods!AH939+Periods!AH1055+Periods!AH1171+Periods!AH1287, "-") -> 0 | AI11: =IFERROR(AVERAGE(Periods!AI11,Periods!AI127,Periods!AI243,Periods!AI359,Periods!AI475,Periods!AI591,Periods!AI707,Periods!AI823,Periods!AI939,Periods!AI1055,Periods!AI1171,Periods!AI1287), "-") -> - | AJ11: =IFERROR(Periods!AJ11+Periods!AJ127+Periods!AJ243+Periods!AJ359+Periods!AJ475+Periods!AJ591+Periods!AJ707+Periods!AJ823+Periods!AJ939+Periods!AJ1055+Periods!AJ1171+Periods!AJ1287, "-") -> 0 | AK11: =IFERROR(Periods!AK11+Periods!AK127+Periods!AK243+Periods!AK359+Periods!AK475+Periods!AK591+Periods!AK707+Periods!AK823+Periods!AK939+Periods!AK1055+Periods!AK1171+Periods!AK1287, "-") -> 0 | AL11: =AJ11+AK11 -> 0 | AM11: =AL11/AH11 -> #DIV/0! | AN11: =O11/AL11 -> #DIV/0! | AO11: =IFERROR(Periods!AO11+Periods!AO127+Periods!AO243+Periods!AO359+Periods!AO475+Periods!AO591+Periods!AO707+Periods!AO823+Periods!AO939+Periods!AO1055+Periods!AO1171+Periods!AO1287, "-") -> 0 | AP11: =IFERROR(AVERAGE(Periods!AP11,Periods!AP127,Periods!AP243,Periods!AP359,Periods!AP475,Periods!AP591,Periods!AP707,Periods!AP823,Periods!AP939,Periods!AP1055,Periods!AP1171,Periods!AP1287), "-") -> - | AR11: =IFERROR(AH11/R11, "-") -> -
A12: 2026-2027 | B12: В2В | H12: =IFERROR(Periods!H12+Periods!H128+Periods!H244+Periods!H360+Periods!H476+Periods!H592+Periods!H708+Periods!H824+Periods!H940+Periods!H1056+Periods!H1172+Periods!H1288, "-") -> 0 | I12: =(M12*1.22)/R12 -> #DIV/0! | J12: =IFERROR(N12/M12-1,"-") -> - | K12: =I12*J12*H12 -> #DIV/0! | L12: =IFERROR(Periods!L12+Periods!L128+Periods!L244+Periods!L360+Periods!L476+Periods!L592+Periods!L708+Periods!L824+Periods!L940+Periods!L1056+Periods!L1172+Periods!L1288, "-") -> 0 | M12: =IFERROR(Periods!M12+Periods!M128+Periods!M244+Periods!M360+Periods!M476+Periods!M592+Periods!M708+Periods!M824+Periods!M940+Periods!M1056+Periods!M1172+Periods!M1288, "-") -> 0 | N12: =IFERROR(Periods!N12+Periods!N128+Periods!N244+Periods!N360+Periods!N476+Periods!N592+Periods!N708+Periods!N824+Periods!N940+Periods!N1056+Periods!N1172+Periods!N1288, "-") -> 0 | O12: =IFERROR(Periods!O12+Periods!O128+Periods!O244+Periods!O360+Periods!O476+Periods!O592+Periods!O708+Periods!O824+Periods!O940+Periods!O1056+Periods!O1172+Periods!O1288, "-") -> 0 | P12: =IFERROR(Periods!P12+Periods!P128+Periods!P244+Periods!P360+Periods!P476+Periods!P592+Periods!P708+Periods!P824+Periods!P940+Periods!P1056+Periods!P1172+Periods!P1288, "-") -> 0 | Q12: =IFERROR(R12/P12, "-") -> - | R12: =IFERROR(Periods!R12+Periods!R128+Periods!R244+Periods!R360+Periods!R476+Periods!R592+Periods!R708+Periods!R824+Periods!R940+Periods!R1056+Periods!R1172+Periods!R1288, "-") -> 0 | S12: =(ROUNDDOWN(O12/R12,0)) -> #DIV/0! | T12: =IFERROR(Periods!T12+Periods!T128+Periods!T244+Periods!T360+Periods!T476+Periods!T592+Periods!T708+Periods!T824+Periods!T940+Periods!T1056+Periods!T1172+Periods!T1288, "-") -> 0 | U12: =IFERROR(O12/T12, "-") -> - | V12: =IFERROR(R12/T12, "-") -> - | W12: =IFERROR(Periods!W12+Periods!W128+Periods!W244+Periods!W360+Periods!W476+Periods!W592+Periods!W708+Periods!W824+Periods!W940+Periods!W1056+Periods!W1172+Periods!W1288, "-") -> 0 | X12: =O12/W12 -> #DIV/0! | Y12: =W12/O12 -> #DIV/0! | Z12: =W12/T12 -> #DIV/0! | AA12: =IFERROR(Periods!AA12+Periods!AA128+Periods!AA244+Periods!AA360+Periods!AA476+Periods!AA592+Periods!AA708+Periods!AA824+Periods!AA940+Periods!AA1056+Periods!AA1172+Periods!AA1288, "-") -> 0 | AB12: =O12/AA12 -> #DIV/0! | AC12: =IFERROR(AA12/T12, "-") -> - | AD12: =IFERROR(Periods!AD12+Periods!AD128+Periods!AD244+Periods!AD360+Periods!AD476+Periods!AD592+Periods!AD708+Periods!AD824+Periods!AD940+Periods!AD1056+Periods!AD1172+Periods!AD1288, "-") -> 0 | AE12: =O12/AD12 -> #DIV/0! | AF12: =AD12/O12 -> #DIV/0! | AG12: =AD12/AA12 -> #DIV/0! | AH12: =IFERROR(Periods!AH12+Periods!AH128+Periods!AH244+Periods!AH360+Periods!AH476+Periods!AH592+Periods!AH708+Periods!AH824+Periods!AH940+Periods!AH1056+Periods!AH1172+Periods!AH1288, "-") -> 0 | AI12: =IFERROR(AVERAGE(Periods!AI12,Periods!AI128,Periods!AI244,Periods!AI360,Periods!AI476,Periods!AI592,Periods!AI708,Periods!AI824,Periods!AI940,Periods!AI1056,Periods!AI1172,Periods!AI1288), "-") -> - | AJ12: =IFERROR(Periods!AJ12+Periods!AJ128+Periods!AJ244+Periods!AJ360+Periods!AJ476+Periods!AJ592+Periods!AJ708+Periods!AJ824+Periods!AJ940+Periods!AJ1056+Periods!AJ1172+Periods!AJ1288, "-") -> 0 | AK12: =IFERROR(Periods!AK12+Periods!AK128+Periods!AK244+Periods!AK360+Periods!AK476+Periods!AK592+Periods!AK708+Periods!AK824+Periods!AK940+Periods!AK1056+Periods!AK1172+Periods!AK1288, "-") -> 0 | AL12: =AJ12+AK12 -> 0 | AM12: =AL12/AH12 -> #DIV/0! | AN12: =O12/AL12 -> #DIV/0! | AO12: =IFERROR(Periods!AO12+Periods!AO128+Periods!AO244+Periods!AO360+Periods!AO476+Periods!AO592+Periods!AO708+Periods!AO824+Periods!AO940+Periods!AO1056+Periods!AO1172+Periods!AO1288, "-") -> 0 | AP12: =IFERROR(AVERAGE(Periods!AP12,Periods!AP128,Periods!AP244,Periods!AP360,Periods!AP476,Periods!AP592,Periods!AP708,Periods!AP824,Periods!AP940,Periods!AP1056,Periods!AP1172,Periods!AP1288), "-") -> - | AR12: =IFERROR(AH12/R12, "-") -> -
A13: 2026-2027 | B13: В2В | H13: =IFERROR(Periods!H13+Periods!H129+Periods!H245+Periods!H361+Periods!H477+Periods!H593+Periods!H709+Periods!H825+Periods!H941+Periods!H1057+Periods!H1173+Periods!H1289, "-") -> 0 | I13: =(M13*1.22)/R13 -> #DIV/0! | J13: =IFERROR(N13/M13-1,"-") -> - | K13: =I13*J13*H13 -> #DIV/0! | L13: =IFERROR(Periods!L13+Periods!L129+Periods!L245+Periods!L361+Periods!L477+Periods!L593+Periods!L709+Periods!L825+Periods!L941+Periods!L1057+Periods!L1173+Periods!L1289, "-") -> 0 | M13: =IFERROR(Periods!M13+Periods!M129+Periods!M245+Periods!M361+Periods!M477+Periods!M593+Periods!M709+Periods!M825+Periods!M941+Periods!M1057+Periods!M1173+Periods!M1289, "-") -> 0 | N13: =IFERROR(Periods!N13+Periods!N129+Periods!N245+Periods!N361+Periods!N477+Periods!N593+Periods!N709+Periods!N825+Periods!N941+Periods!N1057+Periods!N1173+Periods!N1289, "-") -> 0 | O13: =IFERROR(Periods!O13+Periods!O129+Periods!O245+Periods!O361+Periods!O477+Periods!O593+Periods!O709+Periods!O825+Periods!O941+Periods!O1057+Periods!O1173+Periods!O1289, "-") -> 0 | P13: =IFERROR(Periods!P13+Periods!P129+Periods!P245+Periods!P361+Periods!P477+Periods!P593+Periods!P709+Periods!P825+Periods!P941+Periods!P1057+Periods!P1173+Periods!P1289, "-") -> 0 | Q13: =IFERROR(R13/P13, "-") -> - | R13: =IFERROR(Periods!R13+Periods!R129+Periods!R245+Periods!R361+Periods!R477+Periods!R593+Periods!R709+Periods!R825+Periods!R941+Periods!R1057+Periods!R1173+Periods!R1289, "-") -> 0 | S13: =(ROUNDDOWN(O13/R13,0)) -> #DIV/0! | T13: =IFERROR(Periods!T13+Periods!T129+Periods!T245+Periods!T361+Periods!T477+Periods!T593+Periods!T709+Periods!T825+Periods!T941+Periods!T1057+Periods!T1173+Periods!T1289, "-") -> 0 | U13: =IFERROR(O13/T13, "-") -> - | V13: =IFERROR(R13/T13, "-") -> - | W13: =IFERROR(Periods!W13+Periods!W129+Periods!W245+Periods!W361+Periods!W477+Periods!W593+Periods!W709+Periods!W825+Periods!W941+Periods!W1057+Periods!W1173+Periods!W1289, "-") -> 0 | X13: =O13/W13 -> #DIV/0! | Y13: =W13/O13 -> #DIV/0! | Z13: =W13/T13 -> #DIV/0! | AA13: =IFERROR(Periods!AA13+Periods!AA129+Periods!AA245+Periods!AA361+Periods!AA477+Periods!AA593+Periods!AA709+Periods!AA825+Periods!AA941+Periods!AA1057+Periods!AA1173+Periods!AA1289, "-") -> 0 | AB13: =O13/AA13 -> #DIV/0! | AC13: =IFERROR(AA13/T13, "-") -> - | AD13: =IFERROR(Periods!AD13+Periods!AD129+Periods!AD245+Periods!AD361+Periods!AD477+Periods!AD593+Periods!AD709+Periods!AD825+Periods!AD941+Periods!AD1057+Periods!AD1173+Periods!AD1289, "-") -> 0 | AE13: =O13/AD13 -> #DIV/0! | AF13: =AD13/O13 -> #DIV/0! | AG13: =AD13/AA13 -> #DIV/0! | AH13: =IFERROR(Periods!AH13+Periods!AH129+Periods!AH245+Periods!AH361+Periods!AH477+Periods!AH593+Periods!AH709+Periods!AH825+Periods!AH941+Periods!AH1057+Periods!AH1173+Periods!AH1289, "-") -> 0 | AI13: =IFERROR(AVERAGE(Periods!AI13,Periods!AI129,Periods!AI245,Periods!AI361,Periods!AI477,Periods!AI593,Periods!AI709,Periods!AI825,Periods!AI941,Periods!AI1057,Periods!AI1173,Periods!AI1289), "-") -> - | AJ13: =IFERROR(Periods!AJ13+Periods!AJ129+Periods!AJ245+Periods!AJ361+Periods!AJ477+Periods!AJ593+Periods!AJ709+Periods!AJ825+Periods!AJ941+Periods!AJ1057+Periods!AJ1173+Periods!AJ1289, "-") -> 0 | AK13: =IFERROR(Periods!AK13+Periods!AK129+Periods!AK245+Periods!AK361+Periods!AK477+Periods!AK593+Periods!AK709+Periods!AK825+Periods!AK941+Periods!AK1057+Periods!AK1173+Periods!AK1289, "-") -> 0 | AL13: =AJ13+AK13 -> 0 | AM13: =AL13/AH13 -> #DIV/0! | AN13: =O13/AL13 -> #DIV/0! | AO13: =IFERROR(Periods!AO13+Periods!AO129+Periods!AO245+Periods!AO361+Periods!AO477+Periods!AO593+Periods!AO709+Periods!AO825+Periods!AO941+Periods!AO1057+Periods!AO1173+Periods!AO1289, "-") -> 0 | AP13: =IFERROR(AVERAGE(Periods!AP13,Periods!AP129,Periods!AP245,Periods!AP361,Periods!AP477,Periods!AP593,Periods!AP709,Periods!AP825,Periods!AP941,Periods!AP1057,Periods!AP1173,Periods!AP1289), "-") -> - | AR13: =IFERROR(AH13/R13, "-") -> -
... A56: 2026-2027 | B56: В2В | H56: =IFERROR(Periods!H56+Periods!H172+Periods!H288+Periods!H404+Periods!H520+Periods!H636+Periods!H752+Periods!H868+Periods!H984+Periods!H1100+Periods!H1216+Periods!H1332, "-") -> 0 | I56: =(M56*1.22)/R56 -> #DIV/0! | J56: =IFERROR(N56/M56-1,"-") -> - | K56: =I56*J56*H56 -> #DIV/0! | L56: =IFERROR(Periods!L56+Periods!L172+Periods!L288+Periods!L404+Periods!L520+Periods!L636+Periods!L752+Periods!L868+Periods!L984+Periods!L1100+Periods!L1216+Periods!L1332, "-") -> 0 | M56: =IFERROR(Periods!M56+Periods!M172+Periods!M288+Periods!M404+Periods!M520+Periods!M636+Periods!M752+Periods!M868+Periods!M984+Periods!M1100+Periods!M1216+Periods!M1332, "-") -> 0 | N56: =IFERROR(Periods!N56+Periods!N172+Periods!N288+Periods!N404+Periods!N520+Periods!N636+Periods!N752+Periods!N868+Periods!N984+Periods!N1100+Periods!N1216+Periods!N1332, "-") -> 0 | O56: =IFERROR(Periods!O56+Periods!O172+Periods!O288+Periods!O404+Periods!O520+Periods!O636+Periods!O752+Periods!O868+Periods!O984+Periods!O1100+Periods!O1216+Periods!O1332, "-") -> 0 | P56: =IFERROR(Periods!P56+Periods!P172+Periods!P288+Periods!P404+Periods!P520+Periods!P636+Periods!P752+Periods!P868+Periods!P984+Periods!P1100+Periods!P1216+Periods!P1332, "-") -> 0 | Q56: =IFERROR(R56/P56, "-") -> - | R56: =IFERROR(Periods!R56+Periods!R172+Periods!R288+Periods!R404+Periods!R520+Periods!R636+Periods!R752+Periods!R868+Periods!R984+Periods!R1100+Periods!R1216+Periods!R1332, "-") -> 0 | S56: =(ROUNDDOWN(O56/R56,0)) -> #DIV/0! | T56: =IFERROR(Periods!T56+Periods!T172+Periods!T288+Periods!T404+Periods!T520+Periods!T636+Periods!T752+Periods!T868+Periods!T984+Periods!T1100+Periods!T1216+Periods!T1332, "-") -> 0 | U56: =IFERROR(O56/T56, "-") -> - | V56: =IFERROR(R56/T56, "-") -> - | W56: =IFERROR(Periods!W56+Periods!W172+Periods!W288+Periods!W404+Periods!W520+Periods!W636+Periods!W752+Periods!W868+Periods!W984+Periods!W1100+Periods!W1216+Periods!W1332, "-") -> 0 | X56: =O56/W56 -> #DIV/0! | Y56: =W56/O56 -> #DIV/0! | Z56: =W56/T56 -> #DIV/0! | AA56: =IFERROR(Periods!AA56+Periods!AA172+Periods!AA288+Periods!AA404+Periods!AA520+Periods!AA636+Periods!AA752+Periods!AA868+Periods!AA984+Periods!AA1100+Periods!AA1216+Periods!AA1332, "-") -> 0 | AB56: =O56/AA56 -> #DIV/0! | AC56: =IFERROR(AA56/T56, "-") -> - | AD56: =IFERROR(Periods!AD56+Periods!AD172+Periods!AD288+Periods!AD404+Periods!AD520+Periods!AD636+Periods!AD752+Periods!AD868+Periods!AD984+Periods!AD1100+Periods!AD1216+Periods!AD1332, "-") -> 0 | AE56: =O56/AD56 -> #DIV/0! | AF56: =AD56/O56 -> #DIV/0! | AG56: =AD56/AA56 -> #DIV/0! | AH56: =IFERROR(Periods!AH56+Periods!AH172+Periods!AH288+Periods!AH404+Periods!AH520+Periods!AH636+Periods!AH752+Periods!AH868+Periods!AH984+Periods!AH1100+Periods!AH1216+Periods!AH1332, "-") -> 0 | AI56: =IFERROR(AVERAGE(Periods!AI56,Periods!AI172,Periods!AI288,Periods!AI404,Periods!AI520,Periods!AI636,Periods!AI752,Periods!AI868,Periods!AI984,Periods!AI1100,Periods!AI1216,Periods!AI1332), "-") -> - | AJ56: =IFERROR(Periods!AJ56+Periods!AJ172+Periods!AJ288+Periods!AJ404+Periods!AJ520+Periods!AJ636+Periods!AJ752+Periods!AJ868+Periods!AJ984+Periods!AJ1100+Periods!AJ1216+Periods!AJ1332, "-") -> 0 | AK56: =IFERROR(Periods!AK56+Periods!AK172+Periods!AK288+Periods!AK404+Periods!AK520+Periods!AK636+Periods!AK752+Periods!AK868+Periods!AK984+Periods!AK1100+Periods!AK1216+Periods!AK1332, "-") -> 0 | AL56: =AJ56+AK56 -> 0 | AM56: =AL56/AH56 -> #DIV/0! | AN56: =O56/AL56 -> #DIV/0! | AO56: =IFERROR(Periods!AO56+Periods!AO172+Periods!AO288+Periods!AO404+Periods!AO520+Periods!AO636+Periods!AO752+Periods!AO868+Periods!AO984+Periods!AO1100+Periods!AO1216+Periods!AO1332, "-") -> 0 | AP56: =IFERROR(AVERAGE(Periods!AP56,Periods!AP172,Periods!AP288,Periods!AP404,Periods!AP520,Periods!AP636,Periods!AP752,Periods!AP868,Periods!AP984,Periods!AP1100,Periods!AP1216,Periods!AP1332), "-") -> - | AR56: =IFERROR(AH56/R56, "-") -> -
A57: ИТОГО | B57: B2B | H57: =IFERROR(SUM(H2:H56),"-") -> 0 | I57: =IFERROR(SUM(I2:I56),"-") -> - | J57: =IFERROR(N57/M57-1,"-") -> - | K57: =IFERROR(N57-M57,"-") -> 0 | L57: =IFERROR(SUM(L2:L56),"-") -> 0 | M57: =IFERROR(SUM(M2:M56),"-") -> 0 | N57: =IFERROR(SUM(N2:N56),"-") -> 0 | O57: =IFERROR(SUM(O2:O56),"-") -> 0 | P57: =IFERROR(SUM(P2:P56),"-") -> 0 | Q57: =IFERROR(R57/P57, "-") -> - | R57: =IFERROR(SUM(R2:R56),"-") -> 0 | S57: =IFERROR(O57/R57, "-") -> - | T57: =IFERROR(SUM(T2:T56),"-") -> 0 | U57: =IFERROR(O57/T57, "-") -> - | V57: =IFERROR(R57/T57, "-") -> - | W57: =IFERROR(SUM(W2:W56),"-") -> 0 | X57: =IFERROR(O57/W57, "-") -> - | Y57: =IFERROR(W57/O57, "-") -> - | Z57: =IFERROR(W57/T57, "-") -> - | AA57: =IFERROR(SUM(AA2:AA56),"-") -> 0 | AB57: =IFERROR(O57/AA57, "-") -> - | AC57: =IFERROR(AA57/T57, "-") -> - | AD57: =IFERROR(SUM(AD2:AD56),"-") -> 0 | AE57: =IFERROR(O57/AD57, "-") -> - | AF57: =IFERROR(AD57/O57, "-") -> - | AG57: =IFERROR(AD57/AA57, "-") -> - | AH57: =IFERROR(SUM(AH2:AH56),"-") -> 0 | AI57: =IFERROR(ROUND(AVERAGE(AI2:AI56),0),"-") -> - | AJ57: =IFERROR(SUM(AJ2:AJ56),"-") -> 0 | AK57: =IFERROR(SUM(AK2:AK56),"-") -> 0 | AL57: =IFERROR(AK57+AJ57,"-") -> 0 | AM57: =IFERROR(AL57/AH57, "-") -> - | AN57: =IFERROR(O57/AL57, "-") -> - | AO57: =IFERROR(SUM(AO2:AO56),"-") -> 0 | AP57: =IFERROR(AVERAGE(AP2:AP56),"-") -> - | AR57: =IFERROR(AH57/R57, "-") -> -
A58: 2026-2027 | B58: B2C | H58: =IFERROR(Periods!H58+Periods!H174+Periods!H290+Periods!H406+Periods!H522+Periods!H638+Periods!H754+Periods!H870+Periods!H986+Periods!H1102+Periods!H1218+Periods!H1334, "-") -> 0 | I58: =(M58*1.22)/R58 -> #DIV/0! | J58: =IFERROR(N58/M58-1,"-") -> - | K58: =I58*J58*H58 -> #DIV/0! | L58: =IFERROR(Periods!L58+Periods!L174+Periods!L290+Periods!L406+Periods!L522+Periods!L638+Periods!L754+Periods!L870+Periods!L986+Periods!L1102+Periods!L1218+Periods!L1334, "-") -> 0 | M58: =IFERROR(Periods!M58+Periods!M174+Periods!M290+Periods!M406+Periods!M522+Periods!M638+Periods!M754+Periods!M870+Periods!M986+Periods!M1102+Periods!M1218+Periods!M1334, "-") -> 0 | N58: =IFERROR(Periods!N58+Periods!N174+Periods!N290+Periods!N406+Periods!N522+Periods!N638+Periods!N754+Periods!N870+Periods!N986+Periods!N1102+Periods!N1218+Periods!N1334, "-") -> 0 | O58: =IFERROR(Periods!O58+Periods!O174+Periods!O290+Periods!O406+Periods!O522+Periods!O638+Periods!O754+Periods!O870+Periods!O986+Periods!O1102+Periods!O1218+Periods!O1334, "-") -> 0 | P58: =IFERROR(Periods!P58+Periods!P174+Periods!P290+Periods!P406+Periods!P522+Periods!P638+Periods!P754+Periods!P870+Periods!P986+Periods!P1102+Periods!P1218+Periods!P1334, "-") -> 0 | Q58: =IFERROR(R58/P58, "-") -> - | R58: =IFERROR(Periods!R58+Periods!R174+Periods!R290+Periods!R406+Periods!R522+Periods!R638+Periods!R754+Periods!R870+Periods!R986+Periods!R1102+Periods!R1218+Periods!R1334, "-") -> 0 | S58: =(ROUNDDOWN(O58/R58,0)) -> #DIV/0! | T58: =IFERROR(Periods!T58+Periods!T174+Periods!T290+Periods!T406+Periods!T522+Periods!T638+Periods!T754+Periods!T870+Periods!T986+Periods!T1102+Periods!T1218+Periods!T1334, "-") -> 0 | U58: =IFERROR(O58/T58, "-") -> - | V58: =IFERROR(R58/T58, "-") -> - | W58: =IFERROR(Periods!W58+Periods!W174+Periods!W290+Periods!W406+Periods!W522+Periods!W638+Periods!W754+Periods!W870+Periods!W986+Periods!W1102+Periods!W1218+Periods!W1334, "-") -> 0 | X58: =O58/W58 -> #DIV/0! | Y58: =W58/O58 -> #DIV/0! | Z58: =W58/T58 -> #DIV/0! | AA58: =IFERROR(Periods!AA58+Periods!AA174+Periods!AA290+Periods!AA406+Periods!AA522+Periods!AA638+Periods!AA754+Periods!AA870+Periods!AA986+Periods!AA1102+Periods!AA1218+Periods!AA1334, "-") -> 0 | AB58: =O58/AA58 -> #DIV/0! | AC58: =IFERROR(AA58/T58, "-") -> - | AD58: =IFERROR(Periods!AD58+Periods!AD174+Periods!AD290+Periods!AD406+Periods!AD522+Periods!AD638+Periods!AD754+Periods!AD870+Periods!AD986+Periods!AD1102+Periods!AD1218+Periods!AD1334, "-") -> 0 | AE58: =O58/AD58 -> #DIV/0! | AF58: =AD58/O58 -> #DIV/0! | AG58: =AD58/AA58 -> #DIV/0! | AH58: =IFERROR(Periods!AH58+Periods!AH174+Periods!AH290+Periods!AH406+Periods!AH522+Periods!AH638+Periods!AH754+Periods!AH870+Periods!AH986+Periods!AH1102+Periods!AH1218+Periods!AH1334, "-") -> 0 | AI58: =IFERROR(AVERAGE(Periods!AI58,Periods!AI174,Periods!AI290,Periods!AI406,Periods!AI522,Periods!AI638,Periods!AI754,Periods!AI870,Periods!AI986,Periods!AI1102,Periods!AI1218,Periods!AI1334), "-") -> - | AJ58: =IFERROR(Periods!AJ58+Periods!AJ174+Periods!AJ290+Periods!AJ406+Periods!AJ522+Periods!AJ638+Periods!AJ754+Periods!AJ870+Periods!AJ986+Periods!AJ1102+Periods!AJ1218+Periods!AJ1334, "-") -> 0 | AK58: =IFERROR(Periods!AK58+Periods!AK174+Periods!AK290+Periods!AK406+Periods!AK522+Periods!AK638+Periods!AK754+Periods!AK870+Periods!AK986+Periods!AK1102+Periods!AK1218+Periods!AK1334, "-") -> 0 | AL58: =AJ58+AK58 -> 0 | AM58: =AL58/AH58 -> #DIV/0! | AN58: =O58/AL58 -> #DIV/0! | AO58: =IFERROR(Periods!AO58+Periods!AO174+Periods!AO290+Periods!AO406+Periods!AO522+Periods!AO638+Periods!AO754+Periods!AO870+Periods!AO986+Periods!AO1102+Periods!AO1218+Periods!AO1334, "-") -> 0 | AP58: =IFERROR(AVERAGE(Periods!AP58,Periods!AP174,Periods!AP290,Periods!AP406,Periods!AP522,Periods!AP638,Periods!AP754,Periods!AP870,Periods!AP986,Periods!AP1102,Periods!AP1218,Periods!AP1334), "-") -> - | AR58: =IFERROR(AH58/R58, "-") -> -
