Workbook

Sheet МП_Total
B2: Рекламная система | C2: Рекламный формат, размер, вид размещения | D2: Таргетинги | F2: Январь | G2: Февраль | H2: Март | I2: Апрель | J2: Май | K2: Июнь | L2: Июль | M2: Август | N2: Сентябрь | O2: Октябрь | P2: Ноябрь | Q2: Декабрь | S2: Период | T2: Модель закупки | U2: Стоимость единицы закупки (без НДС) | V2: Кол-во единиц закупки | X2: ГЕО | Y2: Стоимость (без НДС) | Z2: СК, % | AA2: Стоимость с учетом СК (без НДС) | AB2: АК, % | AC2: Итоговая стоимость (без НДС) | AD2: Итоговая стоимость (с НДС) | AE2: Доля рекламного бюджета, % | AG2: Показы | AH2: Частота (весь срок) | AI2: Охват | AJ2: CPM (с НДС) | AK2: CPT (с НДС) | AL2: Доступная емкость аудитории | AM2: SOV, % | AO2: CTR, % | AP2: Клики | AQ2: CPC (с НДС) | AS2: CR, % | AT2: ЦО | AU2: CPQL (с НДС)
T3: CPC | U3: =IFERROR(Y3/V3,"-") -> - | V3: =IFERROR(МП_Periods!I3+МП_Periods!I16+МП_Periods!I29+МП_Periods!I42+МП_Periods!I55+МП_Periods!I68+МП_Periods!I81+МП_Periods!I94+МП_Periods!I107+МП_Periods!I120+МП_Periods!I133+МП_Periods!I146,"-") -> 0 | Y3: =SUM(МП_Periods!N3,МП_Periods!N16,МП_Periods!N29,МП_Periods!N42,МП_Periods!N55,МП_Periods!N68,МП_Periods!N81,МП_Periods!N94,МП_Periods!N107,МП_Periods!N120,МП_Periods!N133,МП_Periods!N146) -> 0 | Z3: =IFERROR(1-(AA3/Y3),"-") -> - | AA3: =SUM(МП_Periods!P3,МП_Periods!P16,МП_Periods!P29,МП_Periods!P42,МП_Periods!P55,МП_Periods!P68,МП_Periods!P81,МП_Periods!P94,МП_Periods!P107,МП_Periods!P120,МП_Periods!P133,МП_Periods!P146) -> 0 | AB3: =IFERROR((AC3/AA3)-1,"-") -> - | AC3: =SUM(МП_Periods!R3,МП_Periods!R16,МП_Periods!R29,МП_Periods!R42,МП_Periods!R55,МП_Periods!R68,МП_Periods!R81,МП_Periods!R94,МП_Periods!R107,МП_Periods!R120,МП_Periods!R133,МП_Periods!R146) -> 0 | AD3: =SUM(МП_Periods!S3,МП_Periods!S16,МП_Periods!S29,МП_Periods!S42,МП_Periods!S55,МП_Periods!S68,МП_Periods!S81,МП_Periods!S94,МП_Periods!S107,МП_Periods!S120,МП_Periods!S133,МП_Periods!S146) -> 0 | AE3: =IFERROR(AD3/$AD$13,"-") -> - | AG3: =SUM(МП_Periods!V3,МП_Periods!V16,МП_Periods!V29,МП_Periods!V42,МП_Periods!V55,МП_Periods!V68,МП_Periods!V81,МП_Periods!V94,МП_Periods!V107,МП_Periods!V120,МП_Periods!V133,МП_Periods!V146) -> 0 | AH3: =IFERROR(AG3/AI3,"-") -> - | AI3: =IFERROR(МП_Periods!X3+МП_Periods!X16+МП_Periods!X29+МП_Periods!X42+МП_Periods!X55+МП_Periods!X68+МП_Periods!X81+МП_Periods!X94+МП_Periods!X107+МП_Periods!X120+МП_Periods!X133+МП_Periods!X146,"-") -> - | AJ3: =IFERROR(AD3/AG3*1000,"-") -> - | AK3: =IFERROR(AD3/AI3*1000,"-") -> - | AL3: =SUM(МП_Periods!AA3,МП_Periods!AA16,МП_Periods!AA29,МП_Periods!AA42,МП_Periods!AA55,МП_Periods!AA68,МП_Periods!AA81,МП_Periods!AA94,МП_Periods!AA107,МП_Periods!AA120,МП_Periods!AA133,МП_Periods!AA146) -> 0 | AM3: =IFERROR(#REF!/AL3,"-") -> - | AO3: =IFERROR(AP3/AG3,"-") -> - | AP3: =SUM(МП_Periods!AE3,МП_Periods!AE16,МП_Periods!AE29,МП_Periods!AE42,МП_Periods!AE55,МП_Periods!AE68,МП_Periods!AE81,МП_Periods!AE94,МП_Periods!AE107,МП_Periods!AE120,МП_Periods!AE133,МП_Periods!AE146) -> 0 | AQ3: =IFERROR(AD3/AP3,"-") -> - | AS3: =IFERROR(AT3/AP3,"-") -> - | AT3: =SUM(МП_Periods!AI3,МП_Periods!AI16,МП_Periods!AI29,МП_Periods!AI42,МП_Periods!AI55,МП_Periods!AI68,МП_Periods!AI81,МП_Periods!AI94,МП_Periods!AI107,МП_Periods!AI120,МП_Periods!AI133,МП_Periods!AI146) -> 0 | AU3: =IFERROR(AD3/AT3,"-") -> -
T4: CPC | U4: =IFERROR(Y4/V4,"-") -> - | V4: =IFERROR(МП_Periods!I4+МП_Periods!I17+МП_Periods!I30+МП_Periods!I48+МП_Periods!I56+МП_Periods!I69+МП_Periods!I82+МП_Periods!I95+МП_Periods!I108+МП_Periods!I121+МП_Periods!I134+МП_Periods!I147,"-") -> 0 | Y4: =SUM(МП_Periods!N4,МП_Periods!N17,МП_Periods!N30,МП_Periods!N43,МП_Periods!N56,МП_Periods!N69,МП_Periods!N82,МП_Periods!N95,МП_Periods!N108,МП_Periods!N121,МП_Periods!N134,МП_Periods!N147) -> 0 | Z4: =IFERROR(1-(AA4/Y4),"-") -> - | AA4: =SUM(МП_Periods!P4,МП_Periods!P17,МП_Periods!P30,МП_Periods!P43,МП_Periods!P56,МП_Periods!P69,МП_Periods!P82,МП_Periods!P95,МП_Periods!P108,МП_Periods!P121,МП_Periods!P134,МП_Periods!P147) -> 0 | AB4: =IFERROR((AC4/AA4)-1,"-") -> - | AC4: =SUM(МП_Periods!R4,МП_Periods!R17,МП_Periods!R30,МП_Periods!R43,МП_Periods!R56,МП_Periods!R69,МП_Periods!R82,МП_Periods!R95,МП_Periods!R108,МП_Periods!R121,МП_Periods!R134,МП_Periods!R147) -> 0 | AD4: =SUM(МП_Periods!S4,МП_Periods!S17,МП_Periods!S30,МП_Periods!S43,МП_Periods!S56,МП_Periods!S69,МП_Periods!S82,МП_Periods!S95,МП_Periods!S108,МП_Periods!S121,МП_Periods!S134,МП_Periods!S147) -> 0 | AE4: =IFERROR(AD4/$AD$13,"-") -> - | AG4: =SUM(МП_Periods!V4,МП_Periods!V17,МП_Periods!V30,МП_Periods!V43,МП_Periods!V56,МП_Periods!V69,МП_Periods!V82,МП_Periods!V95,МП_Periods!V108,МП_Periods!V121,МП_Periods!V134,МП_Periods!V147) -> 0 | AH4: =IFERROR(AG4/AI4,"-") -> - | AI4: =IFERROR(МП_Periods!X4+МП_Periods!X17+МП_Periods!X30+МП_Periods!X48+МП_Periods!X56+МП_Periods!X69+МП_Periods!X82+МП_Periods!X95+МП_Periods!X108+МП_Periods!X121+МП_Periods!X134+МП_Periods!X147,"-") -> - | AJ4: =IFERROR(AD4/AG4*1000,"-") -> - | AK4: =IFERROR(AD4/AI4*1000,"-") -> - | AL4: =IFERROR(MAX(МП_Periods!AA4,МП_Periods!AA17,МП_Periods!AA30,МП_Periods!AA48,МП_Periods!AA56,МП_Periods!AA69,МП_Periods!AA82,МП_Periods!AA95,МП_Periods!AA108,МП_Periods!AA121,МП_Periods!AA134,МП_Periods!AA147),"-") -> 0 | AM4: =IFERROR(#REF!/AL4,"-") -> - | AO4: =IFERROR(AP4/AG4,"-") -> - | AP4: =SUM(МП_Periods!AE4,МП_Periods!AE17,МП_Periods!AE30,МП_Periods!AE43,МП_Periods!AE56,МП_Periods!AE69,МП_Periods!AE82,МП_Periods!AE95,МП_Periods!AE108,МП_Periods!AE121,МП_Periods!AE134,МП_Periods!AE147) -> 0 | AQ4: =IFERROR(AD4/AP4,"-") -> - | AS4: =IFERROR(AT4/AP4,"-") -> - | AT4: =SUM(МП_Periods!AI4,МП_Periods!AI17,МП_Periods!AI30,МП_Periods!AI43,МП_Periods!AI56,МП_Periods!AI69,МП_Periods!AI82,МП_Periods!AI95,МП_Periods!AI108,МП_Periods!AI121,МП_Periods!AI134,МП_Periods!AI147) -> 0 | AU4: =IFERROR(AD4/AT4,"-") -> -
T5: CPC | U5: =IFERROR(Y5/V5,"-") -> - | V5: =IFERROR(МП_Periods!I5+МП_Periods!I18+МП_Periods!I31+МП_Periods!I44+МП_Periods!I57+МП_Periods!I70+МП_Periods!I83+МП_Periods!I96+МП_Periods!I109+МП_Periods!I122+МП_Periods!I135+МП_Periods!I148,"-") -> 0 | Y5: =SUM(МП_Periods!N5,МП_Periods!N18,МП_Periods!N31,МП_Periods!N44,МП_Periods!N57,МП_Periods!N70,МП_Periods!N83,МП_Periods!N96,МП_Periods!N109,МП_Periods!N122,МП_Periods!N135,МП_Periods!N148) -> 0 | Z5: =IFERROR(1-(AA5/Y5),"-") -> - | AA5: =SUM(МП_Periods!P5,МП_Periods!P18,МП_Periods!P31,МП_Periods!P44,МП_Periods!P57,МП_Periods!P70,МП_Periods!P83,МП_Periods!P96,МП_Periods!P109,МП_Periods!P122,МП_Periods!P135,МП_Periods!P148) -> 0 | AB5: =IFERROR((AC5/AA5)-1,"-") -> - | AC5: =SUM(МП_Periods!R5,МП_Periods!R18,МП_Periods!R31,МП_Periods!R44,МП_Periods!R57,МП_Periods!R70,МП_Periods!R83,МП_Periods!R96,МП_Periods!R109,МП_Periods!R122,МП_Periods!R135,МП_Periods!R148) -> 0 | AD5: =SUM(МП_Periods!S5,МП_Periods!S18,МП_Periods!S31,МП_Periods!S44,МП_Periods!S57,МП_Periods!S70,МП_Periods!S83,МП_Periods!S96,МП_Periods!S109,МП_Periods!S122,МП_Periods!S135,МП_Periods!S148) -> 0 | AE5: =IFERROR(AD5/$AD$13,"-") -> - | AG5: =SUM(МП_Periods!V5,МП_Periods!V18,МП_Periods!V31,МП_Periods!V44,МП_Periods!V57,МП_Periods!V70,МП_Periods!V83,МП_Periods!V96,МП_Periods!V109,МП_Periods!V122,МП_Periods!V135,МП_Periods!V148) -> 0 | AH5: =IFERROR(AG5/AI5,"-") -> - | AI5: =IFERROR(МП_Periods!X5+МП_Periods!X18+МП_Periods!X31+МП_Periods!X44+МП_Periods!X57+МП_Periods!X70+МП_Periods!X83+МП_Periods!X96+МП_Periods!X109+МП_Periods!X122+МП_Periods!X135+МП_Periods!X148,"-") -> - | AJ5: =IFERROR(AD5/AG5*1000,"-") -> - | AK5: =IFERROR(AD5/AI5*1000,"-") -> - | AL5: =IFERROR(MAX(МП_Periods!AA5,МП_Periods!AA18,МП_Periods!AA31,МП_Periods!AA44,МП_Periods!AA57,МП_Periods!AA70,МП_Periods!AA83,МП_Periods!AA96,МП_Periods!AA109,МП_Periods!AA122,МП_Periods!AA135,МП_Periods!AA148),"-") -> 0 | AM5: =IFERROR(#REF!/AL5,"-") -> - | AO5: =IFERROR(AP5/AG5,"-") -> - | AP5: =SUM(МП_Periods!AE5,МП_Periods!AE18,МП_Periods!AE31,МП_Periods!AE44,МП_Periods!AE57,МП_Periods!AE70,МП_Periods!AE83,МП_Periods!AE96,МП_Periods!AE109,МП_Periods!AE122,МП_Periods!AE135,МП_Periods!AE148) -> 0 | AQ5: =IFERROR(AD5/AP5,"-") -> - | AS5: =IFERROR(AT5/AP5,"-") -> - | AT5: =SUM(МП_Periods!AI5,МП_Periods!AI18,МП_Periods!AI31,МП_Periods!AI44,МП_Periods!AI57,МП_Periods!AI70,МП_Periods!AI83,МП_Periods!AI96,МП_Periods!AI109,МП_Periods!AI122,МП_Periods!AI135,МП_Periods!AI148) -> 0 | AU5: =IFERROR(AD5/AT5,"-") -> -
T6: CPC | U6: =IFERROR(Y6/V6,"-") -> - | V6: =IFERROR(МП_Periods!I6+МП_Periods!I19+МП_Periods!I32+МП_Periods!I45+МП_Periods!I58+МП_Periods!I71+МП_Periods!I84+МП_Periods!I97+МП_Periods!I110+МП_Periods!I123+МП_Periods!I136+МП_Periods!I149,"-") -> 0 | Y6: =SUM(МП_Periods!N6,МП_Periods!N19,МП_Periods!N32,МП_Periods!N45,МП_Periods!N58,МП_Periods!N71,МП_Periods!N84,МП_Periods!N97,МП_Periods!N110,МП_Periods!N123,МП_Periods!N136,МП_Periods!N149) -> 0 | Z6: =IFERROR(1-(AA6/Y6),"-") -> - | AA6: =SUM(МП_Periods!P6,МП_Periods!P19,МП_Periods!P32,МП_Periods!P45,МП_Periods!P58,МП_Periods!P71,МП_Periods!P84,МП_Periods!P97,МП_Periods!P110,МП_Periods!P123,МП_Periods!P136,МП_Periods!P149) -> 0 | AB6: =IFERROR((AC6/AA6)-1,"-") -> - | AC6: =SUM(МП_Periods!R6,МП_Periods!R19,МП_Periods!R32,МП_Periods!R45,МП_Periods!R58,МП_Periods!R71,МП_Periods!R84,МП_Periods!R97,МП_Periods!R110,МП_Periods!R123,МП_Periods!R136,МП_Periods!R149) -> 0 | AD6: =SUM(МП_Periods!S6,МП_Periods!S19,МП_Periods!S32,МП_Periods!S45,МП_Periods!S58,МП_Periods!S71,МП_Periods!S84,МП_Periods!S97,МП_Periods!S110,МП_Periods!S123,МП_Periods!S136,МП_Periods!S149) -> 0 | AE6: =IFERROR(AD6/$AD$13,"-") -> - | AG6: =SUM(МП_Periods!V6,МП_Periods!V19,МП_Periods!V32,МП_Periods!V45,МП_Periods!V58,МП_Periods!V71,МП_Periods!V84,МП_Periods!V97,МП_Periods!V110,МП_Periods!V123,МП_Periods!V136,МП_Periods!V149) -> 0 | AH6: =IFERROR(AG6/AI6,"-") -> - | AI6: =IFERROR(МП_Periods!X6+МП_Periods!X19+МП_Periods!X32+МП_Periods!X45+МП_Periods!X58+МП_Periods!X71+МП_Periods!X84+МП_Periods!X97+МП_Periods!X110+МП_Periods!X123+МП_Periods!X136+МП_Periods!X149,"-") -> - | AJ6: =IFERROR(AD6/AG6*1000,"-") -> - | AK6: =IFERROR(AD6/AI6*1000,"-") -> - | AL6: =IFERROR(MAX(МП_Periods!AA6,МП_Periods!AA19,МП_Periods!AA32,МП_Periods!AA45,МП_Periods!AA58,МП_Periods!AA71,МП_Periods!AA84,МП_Periods!AA97,МП_Periods!AA110,МП_Periods!AA123,МП_Periods!AA136,МП_Periods!AA149),"-") -> 0 | AM6: =IFERROR(#REF!/AL6,"-") -> - | AO6: =IFERROR(AP6/AG6,"-") -> - | AP6: =SUM(МП_Periods!AE6,МП_Periods!AE19,МП_Periods!AE32,МП_Periods!AE45,МП_Periods!AE58,МП_Periods!AE71,МП_Periods!AE84,МП_Periods!AE97,МП_Periods!AE110,МП_Periods!AE123,МП_Periods!AE136,МП_Periods!AE149) -> 0 | AQ6: =IFERROR(AD6/AP6,"-") -> - | AS6: =IFERROR(AT6/AP6,"-") -> - | AT6: =SUM(МП_Periods!AI6,МП_Periods!AI19,МП_Periods!AI32,МП_Periods!AI45,МП_Periods!AI58,МП_Periods!AI71,МП_Periods!AI84,МП_Periods!AI97,МП_Periods!AI110,МП_Periods!AI123,МП_Periods!AI136,МП_Periods!AI149) -> 0 | AU6: =IFERROR(AD6/AT6,"-") -> -
T7: CPC | U7: =IFERROR(Y7/V7,"-") -> - | V7: =IFERROR(МП_Periods!I7+МП_Periods!I20+МП_Periods!I33+МП_Periods!I46+МП_Periods!I59+МП_Periods!I72+МП_Periods!I85+МП_Periods!I98+МП_Periods!I111+МП_Periods!I124+МП_Periods!I137+МП_Periods!I150,"-") -> 0 | Y7: =SUM(МП_Periods!N7,МП_Periods!N20,МП_Periods!N33,МП_Periods!N46,МП_Periods!N59,МП_Periods!N72,МП_Periods!N85,МП_Periods!N98,МП_Periods!N111,МП_Periods!N124,МП_Periods!N137,МП_Periods!N150) -> 0 | Z7: =IFERROR(1-(AA7/Y7),"-") -> - | AA7: =SUM(МП_Periods!P7,МП_Periods!P20,МП_Periods!P33,МП_Periods!P46,МП_Periods!P59,МП_Periods!P72,МП_Periods!P85,МП_Periods!P98,МП_Periods!P111,МП_Periods!P124,МП_Periods!P137,МП_Periods!P150) -> 0 | AB7: =IFERROR((AC7/AA7)-1,"-") -> - | AC7: =SUM(МП_Periods!R7,МП_Periods!R20,МП_Periods!R33,МП_Periods!R46,МП_Periods!R59,МП_Periods!R72,МП_Periods!R85,МП_Periods!R98,МП_Periods!R111,МП_Periods!R124,МП_Periods!R137,МП_Periods!R150) -> 0 | AD7: =SUM(МП_Periods!S7,МП_Periods!S20,МП_Periods!S33,МП_Periods!S46,МП_Periods!S59,МП_Periods!S72,МП_Periods!S85,МП_Periods!S98,МП_Periods!S111,МП_Periods!S124,МП_Periods!S137,МП_Periods!S150) -> 0 | AE7: =IFERROR(AD7/$AD$13,"-") -> - | AG7: =SUM(МП_Periods!V7,МП_Periods!V20,МП_Periods!V33,МП_Periods!V46,МП_Periods!V59,МП_Periods!V72,МП_Periods!V85,МП_Periods!V98,МП_Periods!V111,МП_Periods!V124,МП_Periods!V137,МП_Periods!V150) -> 0 | AH7: =IFERROR(AG7/AI7,"-") -> - | AI7: =IFERROR(МП_Periods!X7+МП_Periods!X20+МП_Periods!X33+МП_Periods!X46+МП_Periods!X59+МП_Periods!X72+МП_Periods!X85+МП_Periods!X98+МП_Periods!X111+МП_Periods!X124+МП_Periods!X137+МП_Periods!X150,"-") -> - | AJ7: =IFERROR(AD7/AG7*1000,"-") -> - | AK7: =IFERROR(AD7/AI7*1000,"-") -> - | AL7: =IFERROR(MAX(МП_Periods!AA7,МП_Periods!AA20,МП_Periods!AA33,МП_Periods!AA46,МП_Periods!AA59,МП_Periods!AA72,МП_Periods!AA85,МП_Periods!AA98,МП_Periods!AA111,МП_Periods!AA124,МП_Periods!AA137,МП_Periods!AA150),"-") -> 0 | AM7: =IFERROR(#REF!/AL7,"-") -> - | AO7: =IFERROR(AP7/AG7,"-") -> - | AP7: =SUM(МП_Periods!AE7,МП_Periods!AE20,МП_Periods!AE33,МП_Periods!AE46,МП_Periods!AE59,МП_Periods!AE72,МП_Periods!AE85,МП_Periods!AE98,МП_Periods!AE111,МП_Periods!AE124,МП_Periods!AE137,МП_Periods!AE150) -> 0 | AQ7: =IFERROR(AD7/AP7,"-") -> - | AS7: =IFERROR(AT7/AP7,"-") -> - | AT7: =SUM(МП_Periods!AI7,МП_Periods!AI20,МП_Periods!AI33,МП_Periods!AI46,МП_Periods!AI59,МП_Periods!AI72,МП_Periods!AI85,МП_Periods!AI98,МП_Periods!AI111,МП_Periods!AI124,МП_Periods!AI137,МП_Periods!AI150) -> 0 | AU7: =IFERROR(AD7/AT7,"-") -> -
T8: CPC | U8: =IFERROR(Y8/V8,"-") -> - | V8: =IFERROR(МП_Periods!I8+МП_Periods!I21+МП_Periods!I34+МП_Periods!I47+МП_Periods!I60+МП_Periods!I73+МП_Periods!I86+МП_Periods!I99+МП_Periods!I112+МП_Periods!I125+МП_Periods!I138+МП_Periods!I151,"-") -> 0 | Y8: =SUM(МП_Periods!N8,МП_Periods!N21,МП_Periods!N34,МП_Periods!N47,МП_Periods!N60,МП_Periods!N73,МП_Periods!N86,МП_Periods!N99,МП_Periods!N112,МП_Periods!N125,МП_Periods!N138,МП_Periods!N151) -> 0 | Z8: =IFERROR(1-(AA8/Y8),"-") -> - | AA8: =SUM(МП_Periods!P8,МП_Periods!P21,МП_Periods!P34,МП_Periods!P47,МП_Periods!P60,МП_Periods!P73,МП_Periods!P86,МП_Periods!P99,МП_Periods!P112,МП_Periods!P125,МП_Periods!P138,МП_Periods!P151) -> 0 | AB8: =IFERROR((AC8/AA8)-1,"-") -> - | AC8: =SUM(МП_Periods!R8,МП_Periods!R21,МП_Periods!R34,МП_Periods!R47,МП_Periods!R60,МП_Periods!R73,МП_Periods!R86,МП_Periods!R99,МП_Periods!R112,МП_Periods!R125,МП_Periods!R138,МП_Periods!R151) -> 0 | AD8: =SUM(МП_Periods!S8,МП_Periods!S21,МП_Periods!S34,МП_Periods!S47,МП_Periods!S60,МП_Periods!S73,МП_Periods!S86,МП_Periods!S99,МП_Periods!S112,МП_Periods!S125,МП_Periods!S138,МП_Periods!S151) -> 0 | AE8: =IFERROR(AD8/$AD$13,"-") -> - | AG8: =SUM(МП_Periods!V8,МП_Periods!V21,МП_Periods!V34,МП_Periods!V47,МП_Periods!V60,МП_Periods!V73,МП_Periods!V86,МП_Periods!V99,МП_Periods!V112,МП_Periods!V125,МП_Periods!V138,МП_Periods!V151) -> 0 | AH8: =IFERROR(AG8/AI8,"-") -> - | AI8: =IFERROR(МП_Periods!X8+МП_Periods!X21+МП_Periods!X34+МП_Periods!X47+МП_Periods!X60+МП_Periods!X73+МП_Periods!X86+МП_Periods!X99+МП_Periods!X112+МП_Periods!X125+МП_Periods!X138+МП_Periods!X151,"-") -> - | AJ8: =IFERROR(AD8/AG8*1000,"-") -> - | AK8: =IFERROR(AD8/AI8*1000,"-") -> - | AL8: =IFERROR(MAX(МП_Periods!AA8,МП_Periods!AA21,МП_Periods!AA34,МП_Periods!AA47,МП_Periods!AA60,МП_Periods!AA73,МП_Periods!AA86,МП_Periods!AA99,МП_Periods!AA112,МП_Periods!AA125,МП_Periods!AA138,МП_Periods!AA151),"-") -> 0 | AM8: =IFERROR(#REF!/AL8,"-") -> - | AO8: =IFERROR(AP8/AG8,"-") -> - | AP8: =SUM(МП_Periods!AE8,МП_Periods!AE21,МП_Periods!AE34,МП_Periods!AE47,МП_Periods!AE60,МП_Periods!AE73,МП_Periods!AE86,МП_Periods!AE99,МП_Periods!AE112,МП_Periods!AE125,МП_Periods!AE138,МП_Periods!AE151) -> 0 | AQ8: =IFERROR(AD8/AP8,"-") -> - | AS8: =IFERROR(AT8/AP8,"-") -> - | AT8: =SUM(МП_Periods!AI8,МП_Periods!AI21,МП_Periods!AI34,МП_Periods!AI47,МП_Periods!AI60,МП_Periods!AI73,МП_Periods!AI86,МП_Periods!AI99,МП_Periods!AI112,МП_Periods!AI125,МП_Periods!AI138,МП_Periods!AI151) -> 0 | AU8: =IFERROR(AD8/AT8,"-") -> -
T9: CPC | U9: =IFERROR(Y9/V9,"-") -> - | V9: =IFERROR(МП_Periods!I9+МП_Periods!I22+МП_Periods!I35+МП_Periods!I48+МП_Periods!I61+МП_Periods!I74+МП_Periods!I87+МП_Periods!I100+МП_Periods!I113+МП_Periods!I126+МП_Periods!I139+МП_Periods!I152,"-") -> 0 | Y9: =SUM(МП_Periods!N9,МП_Periods!N22,МП_Periods!N35,МП_Periods!N48,МП_Periods!N61,МП_Periods!N74,МП_Periods!N87,МП_Periods!N100,МП_Periods!N113,МП_Periods!N126,МП_Periods!N139,МП_Periods!N152) -> 0 | Z9: =IFERROR(1-(AA9/Y9),"-") -> - | AA9: =SUM(МП_Periods!P9,МП_Periods!P22,МП_Periods!P35,МП_Periods!P48,МП_Periods!P61,МП_Periods!P74,МП_Periods!P87,МП_Periods!P100,МП_Periods!P113,МП_Periods!P126,МП_Periods!P139,МП_Periods!P152) -> 0 | AB9: =IFERROR((AC9/AA9)-1,"-") -> - | AC9: =SUM(МП_Periods!R9,МП_Periods!R22,МП_Periods!R35,МП_Periods!R48,МП_Periods!R61,МП_Periods!R74,МП_Periods!R87,МП_Periods!R100,МП_Periods!R113,МП_Periods!R126,МП_Periods!R139,МП_Periods!R152) -> 0 | AD9: =SUM(МП_Periods!S9,МП_Periods!S22,МП_Periods!S35,МП_Periods!S48,МП_Periods!S61,МП_Periods!S74,МП_Periods!S87,МП_Periods!S100,МП_Periods!S113,МП_Periods!S126,МП_Periods!S139,МП_Periods!S152) -> 0 | AE9: =IFERROR(AD9/$AD$13,"-") -> - | AG9: =SUM(МП_Periods!V9,МП_Periods!V22,МП_Periods!V35,МП_Periods!V48,МП_Periods!V61,МП_Periods!V74,МП_Periods!V87,МП_Periods!V100,МП_Periods!V113,МП_Periods!V126,МП_Periods!V139,МП_Periods!V152) -> 0 | AH9: =IFERROR(AG9/AI9,"-") -> - | AI9: =IFERROR(МП_Periods!X9+МП_Periods!X22+МП_Periods!X35+МП_Periods!X48+МП_Periods!X61+МП_Periods!X74+МП_Periods!X87+МП_Periods!X100+МП_Periods!X113+МП_Periods!X126+МП_Periods!X139+МП_Periods!X152,"-") -> - | AJ9: =IFERROR(AD9/AG9*1000,"-") -> - | AK9: =IFERROR(AD9/AI9*1000,"-") -> - | AL9: =IFERROR(MAX(МП_Periods!AA9,МП_Periods!AA22,МП_Periods!AA35,МП_Periods!AA48,МП_Periods!AA61,МП_Periods!AA74,МП_Periods!AA87,МП_Periods!AA100,МП_Periods!AA113,МП_Periods!AA126,МП_Periods!AA139,МП_Periods!AA152),"-") -> 0 | AM9: =IFERROR(#REF!/AL9,"-") -> - | AO9: =IFERROR(AP9/AG9,"-") -> - | AP9: =SUM(МП_Periods!AE9,МП_Periods!AE22,МП_Periods!AE35,МП_Periods!AE48,МП_Periods!AE61,МП_Periods!AE74,МП_Periods!AE87,МП_Periods!AE100,МП_Periods!AE113,МП_Periods!AE126,МП_Periods!AE139,МП_Periods!AE152) -> 0 | AQ9: =IFERROR(AD9/AP9,"-") -> - | AS9: =IFERROR(AT9/AP9,"-") -> - | AT9: =SUM(МП_Periods!AI9,МП_Periods!AI22,МП_Periods!AI35,МП_Periods!AI48,МП_Periods!AI61,МП_Periods!AI74,МП_Periods!AI87,МП_Periods!AI100,МП_Periods!AI113,МП_Periods!AI126,МП_Periods!AI139,МП_Periods!AI152) -> 0 | AU9: =IFERROR(AD9/AT9,"-") -> -
T10: CPC | U10: =IFERROR(Y10/V10,"-") -> - | V10: =IFERROR(МП_Periods!I10+МП_Periods!I23+МП_Periods!I36+МП_Periods!I49+МП_Periods!I62+МП_Periods!I75+МП_Periods!I88+МП_Periods!I101+МП_Periods!I114+МП_Periods!I127+МП_Periods!I140+МП_Periods!I153,"-") -> 0 | Y10: =SUM(МП_Periods!N10,МП_Periods!N23,МП_Periods!N36,МП_Periods!N49,МП_Periods!N62,МП_Periods!N75,МП_Periods!N88,МП_Periods!N101,МП_Periods!N114,МП_Periods!N127,МП_Periods!N140,МП_Periods!N153) -> 0 | Z10: =IFERROR(1-(AA10/Y10),"-") -> - | AA10: =SUM(МП_Periods!P10,МП_Periods!P23,МП_Periods!P36,МП_Periods!P49,МП_Periods!P62,МП_Periods!P75,МП_Periods!P88,МП_Periods!P101,МП_Periods!P114,МП_Periods!P127,МП_Periods!P140,МП_Periods!P153) -> 0 | AB10: =IFERROR((AC10/AA10)-1,"-") -> - | AC10: =SUM(МП_Periods!R10,МП_Periods!R23,МП_Periods!R36,МП_Periods!R49,МП_Periods!R62,МП_Periods!R75,МП_Periods!R88,МП_Periods!R101,МП_Periods!R114,МП_Periods!R127,МП_Periods!R140,МП_Periods!R153) -> 0 | AD10: =SUM(МП_Periods!S10,МП_Periods!S23,МП_Periods!S36,МП_Periods!S49,МП_Periods!S62,МП_Periods!S75,МП_Periods!S88,МП_Periods!S101,МП_Periods!S114,МП_Periods!S127,МП_Periods!S140,МП_Periods!S153) -> 0 | AE10: =IFERROR(AD10/$AD$13,"-") -> - | AG10: =SUM(МП_Periods!V10,МП_Periods!V23,МП_Periods!V36,МП_Periods!V49,МП_Periods!V62,МП_Periods!V75,МП_Periods!V88,МП_Periods!V101,МП_Periods!V114,МП_Periods!V127,МП_Periods!V140,МП_Periods!V153) -> 0 | AH10: =IFERROR(AG10/AI10,"-") -> - | AI10: =IFERROR(МП_Periods!X10+МП_Periods!X23+МП_Periods!X36+МП_Periods!X49+МП_Periods!X62+МП_Periods!X75+МП_Periods!X88+МП_Periods!X101+МП_Periods!X114+МП_Periods!X127+МП_Periods!X140+МП_Periods!X153,"-") -> - | AJ10: =IFERROR(AD10/AG10*1000,"-") -> - | AK10: =IFERROR(AD10/AI10*1000,"-") -> - | AL10: =IFERROR(MAX(МП_Periods!AA10,МП_Periods!AA23,МП_Periods!AA36,МП_Periods!AA49,МП_Periods!AA62,МП_Periods!AA75,МП_Periods!AA88,МП_Periods!AA101,МП_Periods!AA114,МП_Periods!AA127,МП_Periods!AA140,МП_Periods!AA153),"-") -> 0 | AM10: =IFERROR(#REF!/AL10,"-") -> - | AO10: =IFERROR(AP10/AG10,"-") -> - | AP10: =SUM(МП_Periods!AE10,МП_Periods!AE23,МП_Periods!AE36,МП_Periods!AE49,МП_Periods!AE62,МП_Periods!AE75,МП_Periods!AE88,МП_Periods!AE101,МП_Periods!AE114,МП_Periods!AE127,МП_Periods!AE140,МП_Periods!AE153) -> 0 | AQ10: =IFERROR(AD10/AP10,"-") -> - | AS10: =IFERROR(AT10/AP10,"-") -> - | AT10: =SUM(МП_Periods!AI10,МП_Periods!AI23,МП_Periods!AI36,МП_Periods!AI49,МП_Periods!AI62,МП_Periods!AI75,МП_Periods!AI88,МП_Periods!AI101,МП_Periods!AI114,МП_Periods!AI127,МП_Periods!AI140,МП_Periods!AI153) -> 0 | AU10: =IFERROR(AD10/AT10,"-") -> -
T11: CPC | U11: =IFERROR(Y11/V11,"-") -> - | V11: =IFERROR(МП_Periods!I11+МП_Periods!I24+МП_Periods!I37+МП_Periods!I50+МП_Periods!I63+МП_Periods!I76+МП_Periods!I89+МП_Periods!I102+МП_Periods!I115+МП_Periods!I128+МП_Periods!I141+МП_Periods!I154,"-") -> 0 | Y11: =SUM(МП_Periods!N11,МП_Periods!N24,МП_Periods!N37,МП_Periods!N50,МП_Periods!N63,МП_Periods!N76,МП_Periods!N89,МП_Periods!N102,МП_Periods!N115,МП_Periods!N128,МП_Periods!N141,МП_Periods!N154) -> 0 | Z11: =IFERROR(1-(AA11/Y11),"-") -> - | AA11: =SUM(МП_Periods!P11,МП_Periods!P24,МП_Periods!P37,МП_Periods!P50,МП_Periods!P63,МП_Periods!P76,МП_Periods!P89,МП_Periods!P102,МП_Periods!P115,МП_Periods!P128,МП_Periods!P141,МП_Periods!P154) -> 0 | AB11: =IFERROR((AC11/AA11)-1,"-") -> - | AC11: =SUM(МП_Periods!R11,МП_Periods!R24,МП_Periods!R37,МП_Periods!R50,МП_Periods!R63,МП_Periods!R76,МП_Periods!R89,МП_Periods!R102,МП_Periods!R115,МП_Periods!R128,МП_Periods!R141,МП_Periods!R154) -> 0 | AD11: =SUM(МП_Periods!S11,МП_Periods!S24,МП_Periods!S37,МП_Periods!S50,МП_Periods!S63,МП_Periods!S76,МП_Periods!S89,МП_Periods!S102,МП_Periods!S115,МП_Periods!S128,МП_Periods!S141,МП_Periods!S154) -> 0 | AE11: =IFERROR(AD11/$AD$13,"-") -> - | AG11: =SUM(МП_Periods!V11,МП_Periods!V24,МП_Periods!V37,МП_Periods!V50,МП_Periods!V63,МП_Periods!V76,МП_Periods!V89,МП_Periods!V102,МП_Periods!V115,МП_Periods!V128,МП_Periods!V141,МП_Periods!V154) -> 0 | AH11: =IFERROR(AG11/AI11,"-") -> - | AI11: =IFERROR(МП_Periods!X11+МП_Periods!X24+МП_Periods!X37+МП_Periods!X50+МП_Periods!X63+МП_Periods!X76+МП_Periods!X89+МП_Periods!X102+МП_Periods!X115+МП_Periods!X128+МП_Periods!X141+МП_Periods!X154,"-") -> - | AJ11: =IFERROR(AD11/AG11*1000,"-") -> - | AK11: =IFERROR(AD11/AI11*1000,"-") -> - | AL11: =IFERROR(MAX(МП_Periods!AA11,МП_Periods!AA24,МП_Periods!AA37,МП_Periods!AA50,МП_Periods!AA63,МП_Periods!AA76,МП_Periods!AA89,МП_Periods!AA102,МП_Periods!AA115,МП_Periods!AA128,МП_Periods!AA141,МП_Periods!AA154),"-") -> 0 | AM11: =IFERROR(#REF!/AL11,"-") -> - | AO11: =IFERROR(AP11/AG11,"-") -> - | AP11: =SUM(МП_Periods!AE11,МП_Periods!AE24,МП_Periods!AE37,МП_Periods!AE50,МП_Periods!AE63,МП_Periods!AE76,МП_Periods!AE89,МП_Periods!AE102,МП_Periods!AE115,МП_Periods!AE128,МП_Periods!AE141,МП_Periods!AE154) -> 0 | AQ11: =IFERROR(AD11/AP11,"-") -> - | AS11: =IFERROR(AT11/AP11,"-") -> - | AT11: =SUM(МП_Periods!AI11,МП_Periods!AI24,МП_Periods!AI37,МП_Periods!AI50,МП_Periods!AI63,МП_Periods!AI76,МП_Periods!AI89,МП_Periods!AI102,МП_Periods!AI115,МП_Periods!AI128,МП_Periods!AI141,МП_Periods!AI154) -> 0 | AU11: =IFERROR(AD11/AT11,"-") -> -
T12: CPC | U12: =IFERROR(Y12/V12,"-") -> - | V12: =IFERROR(МП_Periods!I12+МП_Periods!I25+МП_Periods!I38+МП_Periods!I51+МП_Periods!I64+МП_Periods!I77+МП_Periods!I90+МП_Periods!I103+МП_Periods!I116+МП_Periods!I129+МП_Periods!I142+МП_Periods!I155,"-") -> 0 | Y12: =SUM(МП_Periods!N12,МП_Periods!N25,МП_Periods!N38,МП_Periods!N51,МП_Periods!N64,МП_Periods!N77,МП_Periods!N90,МП_Periods!N103,МП_Periods!N116,МП_Periods!N129,МП_Periods!N142,МП_Periods!N155) -> 0 | Z12: =IFERROR(1-(AA12/Y12),"-") -> - | AA12: =SUM(МП_Periods!P12,МП_Periods!P25,МП_Periods!P38,МП_Periods!P51,МП_Periods!P64,МП_Periods!P77,МП_Periods!P90,МП_Periods!P103,МП_Periods!P116,МП_Periods!P129,МП_Periods!P142,МП_Periods!P155) -> 0 | AB12: =IFERROR((AC12/AA12)-1,"-") -> - | AC12: =SUM(МП_Periods!R12,МП_Periods!R25,МП_Periods!R38,МП_Periods!R51,МП_Periods!R64,МП_Periods!R77,МП_Periods!R90,МП_Periods!R103,МП_Periods!R116,МП_Periods!R129,МП_Periods!R142,МП_Periods!R155) -> 0 | AD12: =SUM(МП_Periods!S12,МП_Periods!S25,МП_Periods!S38,МП_Periods!S51,МП_Periods!S64,МП_Periods!S77,МП_Periods!S90,МП_Periods!S103,МП_Periods!S116,МП_Periods!S129,МП_Periods!S142,МП_Periods!S155) -> 0 | AE12: =IFERROR(AD12/$AD$13,"-") -> - | AG12: =SUM(МП_Periods!V12,МП_Periods!V25,МП_Periods!V38,МП_Periods!V51,МП_Periods!V64,МП_Periods!V77,МП_Periods!V90,МП_Periods!V103,МП_Periods!V116,МП_Periods!V129,МП_Periods!V142,МП_Periods!V155) -> 0 | AH12: =IFERROR(AG12/AI12,"-") -> - | AI12: =IFERROR(МП_Periods!X12+МП_Periods!X25+МП_Periods!X38+МП_Periods!X51+МП_Periods!X64+МП_Periods!X77+МП_Periods!X90+МП_Periods!X103+МП_Periods!X116+МП_Periods!X129+МП_Periods!X142+МП_Periods!X155,"-") -> - | AJ12: =IFERROR(AD12/AG12*1000,"-") -> - | AK12: =IFERROR(AD12/AI12*1000,"-") -> - | AL12: =IFERROR(MAX(МП_Periods!AA12,МП_Periods!AA25,МП_Periods!AA38,МП_Periods!AA51,МП_Periods!AA64,МП_Periods!AA77,МП_Periods!AA90,МП_Periods!AA103,МП_Periods!AA116,МП_Periods!AA129,МП_Periods!AA142,МП_Periods!AA155),"-") -> 0 | AM12: =IFERROR(#REF!/AL12,"-") -> - | AO12: =IFERROR(AP12/AG12,"-") -> - | AP12: =SUM(МП_Periods!AE12,МП_Periods!AE25,МП_Periods!AE38,МП_Periods!AE51,МП_Periods!AE64,МП_Periods!AE77,МП_Periods!AE90,МП_Periods!AE103,МП_Periods!AE116,МП_Periods!AE129,МП_Periods!AE142,МП_Periods!AE155) -> 0 | AQ12: =IFERROR(AD12/AP12,"-") -> - | AS12: =IFERROR(AT12/AP12,"-") -> - | AT12: =SUM(МП_Periods!AI12,МП_Periods!AI25,МП_Periods!AI38,МП_Periods!AI51,МП_Periods!AI64,МП_Periods!AI77,МП_Periods!AI90,МП_Periods!AI103,МП_Periods!AI116,МП_Periods!AI129,МП_Periods!AI142,МП_Periods!AI155) -> 0 | AU12: =IFERROR(AD12/AT12,"-") -> -
B13: Итого | C13: - | D13: - | F13: - | G13: - | H13: - | I13: - | J13: - | K13: - | L13: - | M13: - | N13: - | O13: - | P13: - | Q13: - | S13: - | T13: - | U13: =IFERROR(Y13/V13,"-") -> - | V13: =SUM(V3:V12) -> 0 | Y13: =IFERROR(SUM(Y3:Y12),"-") -> 0 | Z13: - | AA13: =IFERROR(SUM(AA3:AA12),"-") -> 0 | AB13: - | AC13: =IFERROR(SUM(AC3:AC12),"-") -> 0 | AD13: =IFERROR(SUM(AD3:AD12),"-") -> 0 | AE13: 1 | AG13: =IFERROR(SUM(AG3:AG12),"-") -> 0 | AH13: - | AI13: - | AJ13: =IFERROR(AD13/AG13*1000,"-") -> - | AK13: =IFERROR(AD13/AI13*1000,"-") -> - | AL13: - | AM13: - | AO13: =IFERROR(AP13/AG13,"-") -> - | AP13: =IFERROR(SUM(AP3:AP12),"-") -> 0 | AQ13: =IFERROR(AD13/AP13,"-") -> - | AS13: =IFERROR(AT13/AP13,"-") -> - | AT13: =IFERROR(SUM(AT3:AT12),"-") -> 0 | AU13: =IFERROR(AD13/AT13,"-") -> -
B15: Медиабюджет до НДС | C15: =IFERROR(AA13,"-") -> 0
B16: Агентская комиссия до НДС | C16: =IFERROR((AC13-AA13),"-") -> 0
B17: Медиабюджет с АК до НДС | C17: =IFERROR(SUM(C15:C16),"-") -> 0
B18: НДС | C18: =IFERROR((AD13-AC13),"-") -> 0
B19: Медиабюджет с АК и НДС | C19: =IFERROR(SUM(C17:C18),"-") -> 0
B20: Разработка креативов | C20: 0
B21: Настройка аналитики | C21: 0
B22: Итого с АК и НДС | C22: =IFERROR(SUM(C19:C21),"-") -> 0

Sheet МП_Periods
B2: Рекламная система | C2: Рекламный формат, размер, вид размещения | D2: Таргетинги | F2: Период | G2: Модель закупки | H2: Стоимость единицы закупки (без НДС) | I2: Кол-во единиц закупки | K2: ГЕО | L2: Сезонный коэф. | M2: Другое | N2: Стоимость (без НДС) | O2: СК, % | P2: Стоимость с учетом СК (без НДС) | Q2: АК, % | R2: Итоговая стоимость (без НДС) | S2: Итоговая стоимость (с НДС) | T2: Доля рекламного бюджета, % | V2: Показы | W2: Частота (весь срок) | X2: Охват | Y2: CPM (с НДС) | Z2: CPT (с НДС) | AA2: Доступная емкость аудитории | AB2: SOV, % | AD2: CTR, % | AE2: Клики | AF2: CPC (с НДС) | AH2: CR, % | AI2: ЦО | AJ2: CPQL (с НДС)
F3: 01.01.2026 - 31.01.2026 | G3: CPC | I3: =IFERROR(V3*AD3,"-") -> 0 | N3: =IFERROR((H3*I3),"-") -> 0 | P3: =IFERROR(N3*(1-O3),"-") -> 0 | R3: =IFERROR(P3*(1+Q3),"-") -> 0 | S3: =IFERROR(R3*1.22,"-") -> 0 | T3: =IFERROR(S3/$S$13,"-") -> - | X3: - | Y3: =IFERROR(S3/V3*1000,"-") -> - | Z3: =IFERROR(S3/X3*1000,"-") -> - | AB3: =IFERROR(X3/AA3,"-") -> - | AE3: =IFERROR(ROUNDDOWN(V3*AD3,0),"-") -> 0 | AF3: =IFERROR(S3/AE3,"-") -> - | AI3: =IF(G3="CPI",#REF!*AH3,IFERROR(ROUNDDOWN(AE3*AH3,0),"-")) -> 0 | AJ3: =IFERROR(S3/AI3,"-") -> -
F4: 01.01.2026 - 31.01.2026 | G4: CPC | I4: =IFERROR(V4*AD4,"-") -> 0 | N4: =IFERROR((H4*I4),"-") -> 0 | P4: =IFERROR(N4*(1-O4),"-") -> 0 | R4: =IFERROR(P4*(1+Q4),"-") -> 0 | S4: =IFERROR(R4*1.22,"-") -> 0 | T4: =IFERROR(S4/$S$13,"-") -> - | X4: - | Y4: =IFERROR(S4/V4*1000,"-") -> - | Z4: =IFERROR(S4/X4*1000,"-") -> - | AB4: =IFERROR(X4/AA4,"-") -> - | AE4: =IFERROR(ROUNDDOWN(V4*AD4,0),"-") -> 0 | AF4: =IFERROR(S4/AE4,"-") -> - | AI4: =IF(G4="CPI",#REF!*AH4,IFERROR(ROUNDDOWN(AE4*AH4,0),"-")) -> 0 | AJ4: =IFERROR(S4/AI4,"-") -> -
F5: 01.01.2026 - 31.01.2026 | G5: CPC | I5: =IFERROR(V5*AD5,"-") -> 0 | N5: =IFERROR((H5*I5),"-") -> 0 | P5: =IFERROR(N5*(1-O5),"-") -> 0 | R5: =IFERROR(P5*(1+Q5),"-") -> 0 | S5: =IFERROR(R5*1.22,"-") -> 0 | T5: =IFERROR(S5/$S$13,"-") -> - | X5: - | Y5: =IFERROR(S5/V5*1000,"-") -> - | Z5: =IFERROR(S5/X5*1000,"-") -> - | AB5: =IFERROR(X5/AA5,"-") -> - | AE5: =IFERROR(ROUNDDOWN(V5*AD5,0),"-") -> 0 | AF5: =IFERROR(S5/AE5,"-") -> - | AI5: =IF(G5="CPI",#REF!*AH5,IFERROR(ROUNDDOWN(AE5*AH5,0),"-")) -> 0 | AJ5: =IFERROR(S5/AI5,"-") -> -
F6: 01.01.2026 - 31.01.2026 | G6: CPC | I6: =IFERROR(V6*AD6,"-") -> 0 | N6: =IFERROR((H6*I6),"-") -> 0 | P6: =IFERROR(N6*(1-O6),"-") -> 0 | R6: =IFERROR(P6*(1+Q6),"-") -> 0 | S6: =IFERROR(R6*1.22,"-") -> 0 | T6: =IFERROR(S6/$S$13,"-") -> - | X6: - | Y6: =IFERROR(S6/V6*1000,"-") -> - | Z6: =IFERROR(S6/X6*1000,"-") -> - | AB6: =IFERROR(X6/AA6,"-") -> - | AE6: =IFERROR(ROUNDDOWN(V6*AD6,0),"-") -> 0 | AF6: =IFERROR(S6/AE6,"-") -> - | AI6: =IF(G6="CPI",#REF!*AH6,IFERROR(ROUNDDOWN(AE6*AH6,0),"-")) -> 0 | AJ6: =IFERROR(S6/AI6,"-") -> -
F7: 01.01.2026 - 31.01.2026 | G7: CPC | I7: =IFERROR(V7*AD7,"-") -> 0 | N7: =IFERROR((H7*I7),"-") -> 0 | P7: =IFERROR(N7*(1-O7),"-") -> 0 | R7: =IFERROR(P7*(1+Q7),"-") -> 0 | S7: =IFERROR(R7*1.22,"-") -> 0 | T7: =IFERROR(S7/$S$13,"-") -> - | X7: - | Y7: =IFERROR(S7/V7*1000,"-") -> - | Z7: =IFERROR(S7/X7*1000,"-") -> - | AB7: =IFERROR(X7/AA7,"-") -> - | AE7: =IFERROR(ROUNDDOWN(V7*AD7,0),"-") -> 0 | AF7: =IFERROR(S7/AE7,"-") -> - | AI7: =IF(G7="CPI",#REF!*AH7,IFERROR(ROUNDDOWN(AE7*AH7,0),"-")) -> 0 | AJ7: =IFERROR(S7/AI7,"-") -> -
F8: 01.01.2026 - 31.01.2026 | G8: CPC | I8: =IFERROR(V8*AD8,"-") -> 0 | N8: =IFERROR((H8*I8),"-") -> 0 | P8: =IFERROR(N8*(1-O8),"-") -> 0 | R8: =IFERROR(P8*(1+Q8),"-") -> 0 | S8: =IFERROR(R8*1.22,"-") -> 0 | T8: =IFERROR(S8/$S$13,"-") -> - | X8: - | Y8: =IFERROR(S8/V8*1000,"-") -> - | Z8: =IFERROR(S8/X8*1000,"-") -> - | AB8: =IFERROR(X8/AA8,"-") -> - | AE8: =IFERROR(ROUNDDOWN(V8*AD8,0),"-") -> 0 | AF8: =IFERROR(S8/AE8,"-") -> - | AI8: =IF(G8="CPI",#REF!*AH8,IFERROR(ROUNDDOWN(AE8*AH8,0),"-")) -> 0 | AJ8: =IFERROR(S8/AI8,"-") -> -
F9: 01.01.2026 - 31.01.2026 | G9: CPC | I9: =IFERROR(V9*AD9,"-") -> 0 | N9: =IFERROR((H9*I9),"-") -> 0 | P9: =IFERROR(N9*(1-O9),"-") -> 0 | R9: =IFERROR(P9*(1+Q9),"-") -> 0 | S9: =IFERROR(R9*1.22,"-") -> 0 | T9: =IFERROR(S9/$S$13,"-") -> - | X9: - | Y9: =IFERROR(S9/V9*1000,"-") -> - | Z9: =IFERROR(S9/X9*1000,"-") -> - | AB9: =IFERROR(X9/AA9,"-") -> - | AE9: =IFERROR(ROUNDDOWN(V9*AD9,0),"-") -> 0 | AF9: =IFERROR(S9/AE9,"-") -> - | AI9: =IF(G9="CPI",#REF!*AH9,IFERROR(ROUNDDOWN(AE9*AH9,0),"-")) -> 0 | AJ9: =IFERROR(S9/AI9,"-") -> -
F10: 01.01.2026 - 31.01.2026 | G10: CPC | I10: =IFERROR(V10*AD10,"-") -> 0 | N10: =IFERROR((H10*I10),"-") -> 0 | P10: =IFERROR(N10*(1-O10),"-") -> 0 | R10: =IFERROR(P10*(1+Q10),"-") -> 0 | S10: =IFERROR(R10*1.22,"-") -> 0 | T10: =IFERROR(S10/$S$13,"-") -> - | X10: - | Y10: =IFERROR(S10/V10*1000,"-") -> - | Z10: =IFERROR(S10/X10*1000,"-") -> - | AB10: =IFERROR(X10/AA10,"-") -> - | AE10: =IFERROR(ROUNDDOWN(V10*AD10,0),"-") -> 0 | AF10: =IFERROR(S10/AE10,"-") -> - | AI10: =IF(G10="CPI",#REF!*AH10,IFERROR(ROUNDDOWN(AE10*AH10,0),"-")) -> 0 | AJ10: =IFERROR(S10/AI10,"-") -> -
F11: 01.01.2026 - 31.01.2026 | G11: CPC | I11: =IFERROR(V11*AD11,"-") -> 0 | N11: =IFERROR((H11*I11),"-") -> 0 | P11: =IFERROR(N11*(1-O11),"-") -> 0 | R11: =IFERROR(P11*(1+Q11),"-") -> 0 | S11: =IFERROR(R11*1.22,"-") -> 0 | T11: =IFERROR(S11/$S$13,"-") -> - | X11: - | Y11: =IFERROR(S11/V11*1000,"-") -> - | Z11: =IFERROR(S11/X11*1000,"-") -> - | AB11: =IFERROR(X11/AA11,"-") -> - | AE11: =IFERROR(ROUNDDOWN(V11*AD11,0),"-") -> 0 | AF11: =IFERROR(S11/AE11,"-") -> - | AI11: =IF(G11="CPI",#REF!*AH11,IFERROR(ROUNDDOWN(AE11*AH11,0),"-")) -> 0 | AJ11: =IFERROR(S11/AI11,"-") -> -
F12: 01.01.2026 - 31.01.2026 | G12: CPC | I12: =IFERROR(V12*AD12,"-") -> 0 | N12: =IFERROR((H12*I12),"-") -> 0 | P12: =IFERROR(N12*(1-O12),"-") -> 0 | R12: =IFERROR(P12*(1+Q12),"-") -> 0 | S12: =IFERROR(R12*1.22,"-") -> 0 | T12: =IFERROR(S12/$S$13,"-") -> - | X12: - | Y12: =IFERROR(S12/V12*1000,"-") -> - | Z12: =IFERROR(S12/X12*1000,"-") -> - | AB12: =IFERROR(X12/AA12,"-") -> - | AE12: =IFERROR(ROUNDDOWN(V12*AD12,0),"-") -> 0 | AF12: =IFERROR(S12/AE12,"-") -> - | AI12: =IF(G12="CPI",#REF!*AH12,IFERROR(ROUNDDOWN(AE12*AH12,0),"-")) -> 0 | AJ12: =IFERROR(S12/AI12,"-") -> -
B13: Итого | C13: - | D13: - | F13: - | G13: - | H13: =IFERROR(N13/I13,"-") -> - | I13: =IFERROR(SUM(I3:I12),"-") -> 0 | N13: =IFERROR(SUM(N3:N12),"-") -> 0 | O13: - | P13: =IFERROR(SUM(P3:P12),"-") -> 0 | Q13: - | R13: =IFERROR(SUM(R3:R12),"-") -> 0 | S13: =IFERROR(R13*1.22,"-") -> 0 | T13: 0 | V13: =IFERROR(SUM(V3:V12),"-") -> 0 | W13: - | X13: - | Y13: =IFERROR(S13/V13*1000,"-") -> - | Z13: =IFERROR(S13/X13*1000,"-") -> - | AA13: - | AB13: - | AD13: =IFERROR(AE13/V13,"-") -> - | AE13: =IFERROR(SUM(AE3:AE12),"-") -> 0 | AF13: =IFERROR(S13/AE13,"-") -> - | AH13: =IFERROR(AI13/AE13,"-") -> - | AI13: =IFERROR(SUM(AI3:AI12),"-") -> 0 | AJ13: =IFERROR(S13/AI13,"-") -> -
B15: Рекламная система | C15: Рекламный формат, размер, вид размещения | D15: Таргетинги | F15: Период | G15: Единица измерения стоимости | H15: Цена за единицу (без НДС) | I15: Кол-во единиц | K15: ГЕО | L15: Сезонный коэф. | M15: Другое | N15: Стоимость (без НДС) | O15: СК, % | P15: Стоимость с учетом СК (без НДС) | Q15: АК, % | R15: Итоговая стоимость (без НДС) | S15: Итоговая стоимость (с НДС) | T15: Доля рекламного бюджета, % | V15: Показы | W15: Частота (весь срок) | X15: Охват | Y15: CPM (с НДС) | Z15: CPT (с НДС) | AA15: Доступная емкость аудитории | AB15: SOV, % | AD15: CTR, % | AE15: Клики | AF15: CPC (с НДС) | AH15: CR, % | AI15: Конверсии | AJ15: CPA (с НДС)
F16: 01.02.2026 - 28.02.2026 | G16: CPC | I16: =IFERROR(V16*AD16,"-") -> 0 | N16: =IFERROR((H16*I16),"-") -> 0 | P16: =IFERROR(N16*(1-O16),"-") -> 0 | R16: =IFERROR(P16*(1+Q16),"-") -> 0 | S16: =IFERROR(R16*1.22,"-") -> 0 | T16: =IFERROR(S16/$S$13,"-") -> - | X16: - | Y16: =IFERROR(S16/V16*1000,"-") -> - | Z16: =IFERROR(S16/X16*1000,"-") -> - | AB16: =IFERROR(X16/AA16,"-") -> - | AE16: =IFERROR(ROUNDDOWN(V16*AD16,0),"-") -> 0 | AF16: =IFERROR(S16/AE16,"-") -> - | AI16: =IF(G16="CPI",#REF!*AH16,IFERROR(ROUNDDOWN(AE16*AH16,0),"-")) -> 0 | AJ16: =IFERROR(S16/AI16,"-") -> -
F17: 01.02.2026 - 28.02.2026 | G17: CPC | I17: =IFERROR(V17*AD17,"-") -> 0 | N17: =IFERROR((H17*I17),"-") -> 0 | P17: =IFERROR(N17*(1-O17),"-") -> 0 | R17: =IFERROR(P17*(1+Q17),"-") -> 0 | S17: =IFERROR(R17*1.22,"-") -> 0 | T17: =IFERROR(S17/$S$13,"-") -> - | X17: 0 | Y17: =IFERROR(S17/V17*1000,"-") -> - | Z17: =IFERROR(S17/X17*1000,"-") -> - | AB17: =IFERROR(X17/AA17,"-") -> - | AE17: =IFERROR(ROUNDDOWN(V17*AD17,0),"-") -> 0 | AF17: =IFERROR(S17/AE17,"-") -> - | AI17: =IF(G17="CPI",#REF!*AH17,IFERROR(ROUNDDOWN(AE17*AH17,0),"-")) -> 0 | AJ17: =IFERROR(S17/AI17,"-") -> -
F18: 01.02.2026 - 28.02.2026 | G18: CPC | I18: =IFERROR(V18*AD18,"-") -> 0 | N18: =IFERROR((H18*I18),"-") -> 0 | P18: =IFERROR(N18*(1-O18),"-") -> 0 | R18: =IFERROR(P18*(1+Q18),"-") -> 0 | S18: =IFERROR(R18*1.22,"-") -> 0 | T18: =IFERROR(S18/$S$13,"-") -> - | X18: 0 | Y18: =IFERROR(S18/V18*1000,"-") -> - | Z18: =IFERROR(S18/X18*1000,"-") -> - | AB18: =IFERROR(X18/AA18,"-") -> - | AE18: =IFERROR(ROUNDDOWN(V18*AD18,0),"-") -> 0 | AF18: =IFERROR(S18/AE18,"-") -> - | AI18: =IF(G18="CPI",#REF!*AH18,IFERROR(ROUNDDOWN(AE18*AH18,0),"-")) -> 0 | AJ18: =IFERROR(S18/AI18,"-") -> -
F19: 01.02.2026 - 28.02.2026 | G19: CPC | I19: =IFERROR(V19*AD19,"-") -> 0 | N19: =IFERROR((H19*I19),"-") -> 0 | P19: =IFERROR(N19*(1-O19),"-") -> 0 | R19: =IFERROR(P19*(1+Q19),"-") -> 0 | S19: =IFERROR(R19*1.22,"-") -> 0 | T19: =IFERROR(S19/$S$13,"-") -> - | X19: 0 | Y19: =IFERROR(S19/V19*1000,"-") -> - | Z19: =IFERROR(S19/X19*1000,"-") -> - | AB19: =IFERROR(X19/AA19,"-") -> - | AE19: =IFERROR(ROUNDDOWN(V19*AD19,0),"-") -> 0 | AF19: =IFERROR(S19/AE19,"-") -> - | AI19: =IF(G19="CPI",#REF!*AH19,IFERROR(ROUNDDOWN(AE19*AH19,0),"-")) -> 0 | AJ19: =IFERROR(S19/AI19,"-") -> -
F20: 01.02.2026 - 28.02.2026 | G20: CPC | I20: =IFERROR(V20*AD20,"-") -> 0 | N20: =IFERROR((H20*I20),"-") -> 0 | P20: =IFERROR(N20*(1-O20),"-") -> 0 | R20: =IFERROR(P20*(1+Q20),"-") -> 0 | S20: =IFERROR(R20*1.22,"-") -> 0 | T20: =IFERROR(S20/$S$13,"-") -> - | X20: 0 | Y20: =IFERROR(S20/V20*1000,"-") -> - | Z20: =IFERROR(S20/X20*1000,"-") -> - | AB20: =IFERROR(X20/AA20,"-") -> - | AE20: =IFERROR(ROUNDDOWN(V20*AD20,0),"-") -> 0 | AF20: =IFERROR(S20/AE20,"-") -> - | AI20: =IF(G20="CPI",#REF!*AH20,IFERROR(ROUNDDOWN(AE20*AH20,0),"-")) -> 0 | AJ20: =IFERROR(S20/AI20,"-") -> -
F21: 01.02.2026 - 28.02.2026 | G21: CPC | I21: =IFERROR(V21*AD21,"-") -> 0 | N21: =IFERROR((H21*I21),"-") -> 0 | P21: =IFERROR(N21*(1-O21),"-") -> 0 | R21: =IFERROR(P21*(1+Q21),"-") -> 0 | S21: =IFERROR(R21*1.22,"-") -> 0 | T21: =IFERROR(S21/$S$13,"-") -> - | X21: 0 | Y21: =IFERROR(S21/V21*1000,"-") -> - | Z21: =IFERROR(S21/X21*1000,"-") -> - | AB21: =IFERROR(X21/AA21,"-") -> - | AE21: =IFERROR(ROUNDDOWN(V21*AD21,0),"-") -> 0 | AF21: =IFERROR(S21/AE21,"-") -> - | AI21: =IF(G21="CPI",#REF!*AH21,IFERROR(ROUNDDOWN(AE21*AH21,0),"-")) -> 0 | AJ21: =IFERROR(S21/AI21,"-") -> -
F22: 01.02.2026 - 28.02.2026 | G22: CPC | I22: =IFERROR(V22*AD22,"-") -> 0 | N22: =IFERROR((H22*I22),"-") -> 0 | P22: =IFERROR(N22*(1-O22),"-") -> 0 | R22: =IFERROR(P22*(1+Q22),"-") -> 0 | S22: =IFERROR(R22*1.22,"-") -> 0 | T22: =IFERROR(S22/$S$13,"-") -> - | X22: 0 | Y22: =IFERROR(S22/V22*1000,"-") -> - | Z22: =IFERROR(S22/X22*1000,"-") -> - | AB22: =IFERROR(X22/AA22,"-") -> - | AE22: =IFERROR(ROUNDDOWN(V22*AD22,0),"-") -> 0 | AF22: =IFERROR(S22/AE22,"-") -> - | AI22: =IF(G22="CPI",#REF!*AH22,IFERROR(ROUNDDOWN(AE22*AH22,0),"-")) -> 0 | AJ22: =IFERROR(S22/AI22,"-") -> -
F23: 01.02.2026 - 28.02.2026 | G23: CPC | I23: =IFERROR(V23*AD23,"-") -> 0 | N23: =IFERROR((H23*I23),"-") -> 0 | P23: =IFERROR(N23*(1-O23),"-") -> 0 | R23: =IFERROR(P23*(1+Q23),"-") -> 0 | S23: =IFERROR(R23*1.22,"-") -> 0 | T23: =IFERROR(S23/$S$13,"-") -> - | X23: - | Y23: =IFERROR(S23/V23*1000,"-") -> - | Z23: =IFERROR(S23/X23*1000,"-") -> - | AB23: =IFERROR(X23/AA23,"-") -> - | AE23: =IFERROR(ROUNDDOWN(V23*AD23,0),"-") -> 0 | AF23: =IFERROR(S23/AE23,"-") -> - | AI23: =IF(G23="CPI",#REF!*AH23,IFERROR(ROUNDDOWN(AE23*AH23,0),"-")) -> 0 | AJ23: =IFERROR(S23/AI23,"-") -> -
F24: 01.02.2026 - 28.02.2026 | G24: CPC | I24: =IFERROR(V24*AD24,"-") -> 0 | N24: =IFERROR((H24*I24),"-") -> 0 | P24: =IFERROR(N24*(1-O24),"-") -> 0 | R24: =IFERROR(P24*(1+Q24),"-") -> 0 | S24: =IFERROR(R24*1.22,"-") -> 0 | T24: =IFERROR(S24/$S$13,"-") -> - | X24: - | Y24: =IFERROR(S24/V24*1000,"-") -> - | Z24: =IFERROR(S24/X24*1000,"-") -> - | AB24: =IFERROR(X24/AA24,"-") -> - | AE24: =IFERROR(ROUNDDOWN(V24*AD24,0),"-") -> 0 | AF24: =IFERROR(S24/AE24,"-") -> - | AI24: =IF(G24="CPI",#REF!*AH24,IFERROR(ROUNDDOWN(AE24*AH24,0),"-")) -> 0 | AJ24: =IFERROR(S24/AI24,"-") -> -
F25: 01.02.2026 - 28.02.2026 | G25: CPC | I25: =IFERROR(V25*AD25,"-") -> 0 | N25: =IFERROR((H25*I25),"-") -> 0 | P25: =IFERROR(N25*(1-O25),"-") -> 0 | R25: =IFERROR(P25*(1+Q25),"-") -> 0 | S25: =IFERROR(R25*1.22,"-") -> 0 | T25: =IFERROR(S25/$S$13,"-") -> - | X25: - | Y25: =IFERROR(S25/V25*1000,"-") -> - | Z25: =IFERROR(S25/X25*1000,"-") -> - | AB25: =IFERROR(X25/AA25,"-") -> - | AE25: =IFERROR(ROUNDDOWN(V25*AD25,0),"-") -> 0 | AF25: =IFERROR(S25/AE25,"-") -> - | AI25: =IF(G25="CPI",#REF!*AH25,IFERROR(ROUNDDOWN(AE25*AH25,0),"-")) -> 0 | AJ25: =IFERROR(S25/AI25,"-") -> -
B26: Итого | C26: - | D26: - | F26: - | G26: - | H26: =IFERROR(N26/I26,"-") -> - | I26: =IFERROR(SUM(I16:I25),"-") -> 0 | N26: =IFERROR(SUM(N16:N25),"-") -> 0 | O26: - | P26: =IFERROR(SUM(P16:P25),"-") -> 0 | Q26: - | R26: =IFERROR(SUM(R16:R25),"-") -> 0 | S26: =IFERROR(R26*1.22,"-") -> 0 | T26: 0 | V26: =IFERROR(SUM(V16:V25),"-") -> 0 | W26: - | X26: - | Y26: =IFERROR(S26/V26*1000,"-") -> - | Z26: =IFERROR(S26/X26*1000,"-") -> - | AA26: - | AB26: - | AD26: =IFERROR(AE26/V26,"-") -> - | AE26: =IFERROR(SUM(AE16:AE25),"-") -> 0 | AF26: =IFERROR(S26/AE26,"-") -> - | AH26: =IFERROR(AI26/AE26,"-") -> - | AI26: =IFERROR(SUM(AI16:AI25),"-") -> 0 | AJ26: =IFERROR(S26/AI26,"-") -> -
B28: Рекламная система | C28: Рекламный формат, размер, вид размещения | D28: Таргетинги | F28: Период | G28: Единица измерения стоимости | H28: Цена за единицу (без НДС) | I28: Кол-во единиц | K28: ГЕО | L28: Сезонный коэф. | M28: Другое | N28: Стоимость (без НДС) | O28: СК, % | P28: Стоимость с учетом СК (без НДС) | Q28: АК, % | R28: Итоговая стоимость (без НДС) | S28: Итоговая стоимость (с НДС) | T28: Доля рекламного бюджета, % | V28: Показы | W28: Частота (весь срок) | X28: Охват | Y28: CPM (с НДС) | Z28: CPT (с НДС) | AA28: Доступная емкость аудитории | AB28: SOV, % | AD28: CTR, % | AE28: Клики | AF28: CPC (с НДС) | AH28: CR, % | AI28: Конверсии | AJ28: CPA (с НДС)
F29: 01.03.2026 - 31.03.2026 | G29: CPC | I29: =IFERROR(V29*AD29,"-") -> 0 | N29: =IFERROR((H29*I29),"-") -> 0 | P29: =IFERROR(N29*(1-O29),"-") -> 0 | R29: =IFERROR(P29*(1+Q29),"-") -> 0 | S29: =IFERROR(R29*1.22,"-") -> 0 | T29: =IFERROR(S29/$S$13,"-") -> - | X29: - | Y29: =IFERROR(S29/V29*1000,"-") -> - | Z29: =IFERROR(S29/X29*1000,"-") -> - | AB29: =IFERROR(X29/AA29,"-") -> - | AE29: =IFERROR(ROUNDDOWN(V29*AD29,0),"-") -> 0 | AF29: =IFERROR(S29/AE29,"-") -> - | AI29: =IF(G29="CPI",#REF!*AH29,IFERROR(ROUNDDOWN(AE29*AH29,0),"-")) -> 0 | AJ29: =IFERROR(S29/AI29,"-") -> -
F30: 01.03.2026 - 31.03.2026 | G30: CPC | I30: =IFERROR(V30*AD30,"-") -> 0 | N30: =IFERROR((H30*I30),"-") -> 0 | P30: =IFERROR(N30*(1-O30),"-") -> 0 | R30: =IFERROR(P30*(1+Q30),"-") -> 0 | S30: =IFERROR(R30*1.22,"-") -> 0 | T30: =IFERROR(S30/$S$13,"-") -> - | X30: - | Y30: =IFERROR(S30/V30*1000,"-") -> - | Z30: =IFERROR(S30/X30*1000,"-") -> - | AB30: =IFERROR(X30/AA30,"-") -> - | AE30: =IFERROR(ROUNDDOWN(V30*AD30,0),"-") -> 0 | AF30: =IFERROR(S30/AE30,"-") -> - | AI30: =IF(G30="CPI",#REF!*AH30,IFERROR(ROUNDDOWN(AE30*AH30,0),"-")) -> 0 | AJ30: =IFERROR(S30/AI30,"-") -> -
F31: 01.03.2026 - 31.03.2026 | G31: CPC | I31: =IFERROR(V31*AD31,"-") -> 0 | N31: =IFERROR((H31*I31),"-") -> 0 | P31: =IFERROR(N31*(1-O31),"-") -> 0 | R31: =IFERROR(P31*(1+Q31),"-") -> 0 | S31: =IFERROR(R31*1.22,"-") -> 0 | T31: =IFERROR(S31/$S$13,"-") -> - | X31: - | Y31: =IFERROR(S31/V31*1000,"-") -> - | Z31: =IFERROR(S31/X31*1000,"-") -> - | AB31: =IFERROR(X31/AA31,"-") -> - | AE31: =IFERROR(ROUNDDOWN(V31*AD31,0),"-") -> 0 | AF31: =IFERROR(S31/AE31,"-") -> - | AI31: =IF(G31="CPI",#REF!*AH31,IFERROR(ROUNDDOWN(AE31*AH31,0),"-")) -> 0 | AJ31: =IFERROR(S31/AI31,"-") -> -
F32: 01.03.2026 - 31.03.2026 | G32: CPC | I32: =IFERROR(V32*AD32,"-") -> 0 | N32: =IFERROR((H32*I32),"-") -> 0 | P32: =IFERROR(N32*(1-O32),"-") -> 0 | R32: =IFERROR(P32*(1+Q32),"-") -> 0 | S32: =IFERROR(R32*1.22,"-") -> 0 | T32: =IFERROR(S32/$S$13,"-") -> - | X32: - | Y32: =IFERROR(S32/V32*1000,"-") -> - | Z32: =IFERROR(S32/X32*1000,"-") -> - | AB32: =IFERROR(X32/AA32,"-") -> - | AE32: =IFERROR(ROUNDDOWN(V32*AD32,0),"-") -> 0 | AF32: =IFERROR(S32/AE32,"-") -> - | AI32: =IF(G32="CPI",#REF!*AH32,IFERROR(ROUNDDOWN(AE32*AH32,0),"-")) -> 0 | AJ32: =IFERROR(S32/AI32,"-") -> -
F33: 01.03.2026 - 31.03.2026 | G33: CPC | I33: =IFERROR(V33*AD33,"-") -> 0 | N33: =IFERROR((H33*I33),"-") -> 0 | P33: =IFERROR(N33*(1-O33),"-") -> 0 | R33: =IFERROR(P33*(1+Q33),"-") -> 0 | S33: =IFERROR(R33*1.22,"-") -> 0 | T33: =IFERROR(S33/$S$13,"-") -> - | X33: - | Y33: =IFERROR(S33/V33*1000,"-") -> - | Z33: =IFERROR(S33/X33*1000,"-") -> - | AB33: =IFERROR(X33/AA33,"-") -> - | AE33: =IFERROR(ROUNDDOWN(V33*AD33,0),"-") -> 0 | AF33: =IFERROR(S33/AE33,"-") -> - | AI33: =IF(G33="CPI",#REF!*AH33,IFERROR(ROUNDDOWN(AE33*AH33,0),"-")) -> 0 | AJ33: =IFERROR(S33/AI33,"-") -> -
F34: 01.03.2026 - 31.03.2026 | G34: CPC | I34: =IFERROR(V34*AD34,"-") -> 0 | N34: =IFERROR((H34*I34),"-") -> 0 | P34: =IFERROR(N34*(1-O34),"-") -> 0 | R34: =IFERROR(P34*(1+Q34),"-") -> 0 | S34: =IFERROR(R34*1.22,"-") -> 0 | T34: =IFERROR(S34/$S$13,"-") -> - | X34: - | Y34: =IFERROR(S34/V34*1000,"-") -> - | Z34: =IFERROR(S34/X34*1000,"-") -> - | AB34: =IFERROR(X34/AA34,"-") -> - | AE34: =IFERROR(ROUNDDOWN(V34*AD34,0),"-") -> 0 | AF34: =IFERROR(S34/AE34,"-") -> - | AI34: =IF(G34="CPI",#REF!*AH34,IFERROR(ROUNDDOWN(AE34*AH34,0),"-")) -> 0 | AJ34: =IFERROR(S34/AI34,"-") -> -
F35: 01.03.2026 - 31.03.2026 | G35: CPC | I35: =IFERROR(V35*AD35,"-") -> 0 | N35: =IFERROR((H35*I35),"-") -> 0 | P35: =IFERROR(N35*(1-O35),"-") -> 0 | R35: =IFERROR(P35*(1+Q35),"-") -> 0 | S35: =IFERROR(R35*1.22,"-") -> 0 | T35: =IFERROR(S35/$S$13,"-") -> - | X35: - | Y35: =IFERROR(S35/V35*1000,"-") -> - | Z35: =IFERROR(S35/X35*1000,"-") -> - | AB35: =IFERROR(X35/AA35,"-") -> - | AE35: =IFERROR(ROUNDDOWN(V35*AD35,0),"-") -> 0 | AF35: =IFERROR(S35/AE35,"-") -> - | AI35: =IF(G35="CPI",#REF!*AH35,IFERROR(ROUNDDOWN(AE35*AH35,0),"-")) -> 0 | AJ35: =IFERROR(S35/AI35,"-") -> -
F36: 01.03.2026 - 31.03.2026 | G36: CPC | I36: =IFERROR(V36*AD36,"-") -> 0 | N36: =IFERROR((H36*I36),"-") -> 0 | P36: =IFERROR(N36*(1-O36),"-") -> 0 | R36: =IFERROR(P36*(1+Q36),"-") -> 0 | S36: =IFERROR(R36*1.22,"-") -> 0 | T36: =IFERROR(S36/$S$13,"-") -> - | X36: - | Y36: =IFERROR(S36/V36*1000,"-") -> - | Z36: =IFERROR(S36/X36*1000,"-") -> - | AB36: =IFERROR(X36/AA36,"-") -> - | AE36: =IFERROR(ROUNDDOWN(V36*AD36,0),"-") -> 0 | AF36: =IFERROR(S36/AE36,"-") -> - | AI36: =IF(G36="CPI",#REF!*AH36,IFERROR(ROUNDDOWN(AE36*AH36,0),"-")) -> 0 | AJ36: =IFERROR(S36/AI36,"-") -> -
F37: 01.03.2026 - 31.03.2026 | G37: CPC | I37: =IFERROR(V37*AD37,"-") -> 0 | N37: =IFERROR((H37*I37),"-") -> 0 | P37: =IFERROR(N37*(1-O37),"-") -> 0 | R37: =IFERROR(P37*(1+Q37),"-") -> 0 | S37: =IFERROR(R37*1.22,"-") -> 0 | T37: =IFERROR(S37/$S$13,"-") -> - | X37: - | Y37: =IFERROR(S37/V37*1000,"-") -> - | Z37: =IFERROR(S37/X37*1000,"-") -> - | AB37: =IFERROR(X37/AA37,"-") -> - | AE37: =IFERROR(ROUNDDOWN(V37*AD37,0),"-") -> 0 | AF37: =IFERROR(S37/AE37,"-") -> - | AI37: =IF(G37="CPI",#REF!*AH37,IFERROR(ROUNDDOWN(AE37*AH37,0),"-")) -> 0 | AJ37: =IFERROR(S37/AI37,"-") -> -
F38: 01.03.2026 - 31.03.2026 | G38: CPC | I38: =IFERROR(V38*AD38,"-") -> 0 | N38: =IFERROR((H38*I38),"-") -> 0 | P38: =IFERROR(N38*(1-O38),"-") -> 0 | R38: =IFERROR(P38*(1+Q38),"-") -> 0 | S38: =IFERROR(R38*1.22,"-") -> 0 | T38: =IFERROR(S38/$S$13,"-") -> - | X38: - | Y38: =IFERROR(S38/V38*1000,"-") -> - | Z38: =IFERROR(S38/X38*1000,"-") -> - | AB38: =IFERROR(X38/AA38,"-") -> - | AE38: =IFERROR(ROUNDDOWN(V38*AD38,0),"-") -> 0 | AF38: =IFERROR(S38/AE38,"-") -> - | AI38: =IF(G38="CPI",#REF!*AH38,IFERROR(ROUNDDOWN(AE38*AH38,0),"-")) -> 0 | AJ38: =IFERROR(S38/AI38,"-") -> -
B39: Итого | C39: - | D39: - | F39: - | G39: - | H39: =IFERROR(N39/I39,"-") -> - | I39: =IFERROR(SUM(I29:I38),"-") -> 0 | N39: =IFERROR(SUM(N29:N38),"-") -> 0 | O39: - | P39: =IFERROR(SUM(P29:P38),"-") -> 0 | Q39: - | R39: =IFERROR(SUM(R29:R38),"-") -> 0 | S39: =IFERROR(R39*1.22,"-") -> 0 | T39: 0 | V39: =IFERROR(SUM(V29:V38),"-") -> 0 | W39: - | X39: - | Y39: =IFERROR(S39/V39*1000,"-") -> - | Z39: =IFERROR(S39/X39*1000,"-") -> - | AA39: - | AB39: - | AD39: =IFERROR(AE39/V39,"-") -> - | AE39: =IFERROR(SUM(AE29:AE38),"-") -> 0 | AF39: =IFERROR(S39/AE39,"-") -> - | AH39: =IFERROR(AI39/AE39,"-") -> - | AI39: =IFERROR(SUM(AI29:AI38),"-") -> 0 | AJ39: =IFERROR(S39/AI39,"-") -> -
B41: Рекламная система | C41: Рекламный формат, размер, вид размещения | D41: Таргетинги | F41: Период | G41: Единица измерения стоимости | H41: Цена за единицу (без НДС) | I41: Кол-во единиц | K41: ГЕО | L41: Сезонный коэф. | M41: Другое | N41: Стоимость (без НДС) | O41: СК, % | P41: Стоимость с учетом СК (без НДС) | Q41: АК, % | R41: Итоговая стоимость (без НДС) | S41: Итоговая стоимость (с НДС) | T41: Доля рекламного бюджета, % | V41: Показы | W41: Частота (весь срок) | X41: Охват | Y41: CPM (с НДС) | Z41: CPT (с НДС) | AA41: Доступная емкость аудитории | AB41: SOV, % | AD41: CTR, % | AE41: Клики | AF41: CPC (с НДС) | AH41: CR, % | AI41: Конверсии | AJ41: CPA (с НДС)
F42: 01.04.2026 - 30.04.2026 | G42: CPC | I42: =IFERROR(V42*AD42,"-") -> 0 | N42: =IFERROR((H42*I42),"-") -> 0 | P42: =IFERROR(N42*(1-O42),"-") -> 0 | R42: =IFERROR(P42*(1+Q42),"-") -> 0 | S42: =IFERROR(R42*1.22,"-") -> 0 | T42: =IFERROR(S42/$S$13,"-") -> - | X42: - | Y42: =IFERROR(S42/V42*1000,"-") -> - | Z42: =IFERROR(S42/X42*1000,"-") -> - | AB42: =IFERROR(X42/AA42,"-") -> - | AE42: =IFERROR(ROUNDDOWN(V42*AD42,0),"-") -> 0 | AF42: =IFERROR(S42/AE42,"-") -> - | AI42: =IF(G42="CPI",#REF!*AH42,IFERROR(ROUNDDOWN(AE42*AH42,0),"-")) -> 0 | AJ42: =IFERROR(S42/AI42,"-") -> -
F43: 01.04.2026 - 30.04.2026 | G43: CPC | I43: =IFERROR(V43*AD43,"-") -> 0 | N43: =IFERROR((H43*I43),"-") -> 0 | P43: =IFERROR(N43*(1-O43),"-") -> 0 | R43: =IFERROR(P43*(1+Q43),"-") -> 0 | S43: =IFERROR(R43*1.22,"-") -> 0 | T43: =IFERROR(S43/$S$13,"-") -> - | X43: - | Y43: =IFERROR(S43/V43*1000,"-") -> - | Z43: =IFERROR(S43/X43*1000,"-") -> - | AB43: =IFERROR(X43/AA43,"-") -> - | AE43: =IFERROR(ROUNDDOWN(V43*AD43,0),"-") -> 0 | AF43: =IFERROR(S43/AE43,"-") -> - | AI43: =IF(G43="CPI",#REF!*AH43,IFERROR(ROUNDDOWN(AE43*AH43,0),"-")) -> 0 | AJ43: =IFERROR(S43/AI43,"-") -> -
F44: 01.04.2026 - 30.04.2026 | G44: CPC | I44: =IFERROR(V44*AD44,"-") -> 0 | N44: =IFERROR((H44*I44),"-") -> 0 | P44: =IFERROR(N44*(1-O44),"-") -> 0 | R44: =IFERROR(P44*(1+Q44),"-") -> 0 | S44: =IFERROR(R44*1.22,"-") -> 0 | T44: =IFERROR(S44/$S$13,"-") -> - | X44: - | Y44: =IFERROR(S44/V44*1000,"-") -> - | Z44: =IFERROR(S44/X44*1000,"-") -> - | AB44: =IFERROR(X44/AA44,"-") -> - | AE44: =IFERROR(ROUNDDOWN(V44*AD44,0),"-") -> 0 | AF44: =IFERROR(S44/AE44,"-") -> - | AI44: =IF(G44="CPI",#REF!*AH44,IFERROR(ROUNDDOWN(AE44*AH44,0),"-")) -> 0 | AJ44: =IFERROR(S44/AI44,"-") -> -
...
