Workbook

Sheet МП_Total
B2: Рекламная система | C2: Рекламный формат, размер, вид размещения | D2: Таргетинги | F2: Январь | G2: Февраль | H2: Март | I2: Апрель | J2: Май | K2: Июнь | L2: Июль | M2: Август | N2: Сентябрь | O2: Октябрь | P2: Ноябрь | Q2: Декабрь | S2: Период | T2: Модель закупки | U2: Стоимость единицы закупки (без НДС) | V2: Кол-во единиц закупки | X2: Стоимость (без НДС) | Y2: СК, % | Z2: Стоимость с учетом СК (без НДС) | AA2: АК, % | AB2: Итоговая стоимость (без НДС) | AC2: Итоговая стоимость (с НДС) | AD2: Доля рекламного бюджета, % | AF2: Показы | AG2: Частота (весь срок) | AH2: Охват | AI2: CPM (с НДС) | AJ2: CPT (с НДС) | AK2: Доступная емкость аудитории | AL2: SOV, % | AN2: CTR, % | AO2: Клики | AP2: CPC (с НДС) | AR2: CR, % | AS2: Конверсии | AT2: CPA (с НДС) | AV2: ДРР, % | AW2: Средний чек | AX2: Доход | AZ2: RTR, % | BA2: Дочитывания | BB2: CPR (с НДС) | BC2: % открытий статьи | BD2: Открытия статьи | BF2: ER, % | BG2: Вовлечения | BH2: CPE (с НДС)
T3: CPC | U3: =IFERROR(X3/V3,"-") -> - | V3: =IFERROR(МП_Periods!I3+МП_Periods!I16+МП_Periods!I29+МП_Periods!I42+МП_Periods!I55+МП_Periods!I68+МП_Periods!I81+МП_Periods!I94+МП_Periods!I107+МП_Periods!I120+МП_Periods!I133+МП_Periods!I146,"-") -> 0 | X3: =SUM(МП_Periods!K3,МП_Periods!K16,МП_Periods!K29,МП_Periods!K42,МП_Periods!K55,МП_Periods!K68,МП_Periods!K81,МП_Periods!K94,МП_Periods!K107,МП_Periods!K120,МП_Periods!K133,МП_Periods!K146) -> 0 | Y3: =IFERROR(1-(Z3/X3),"-") -> - | Z3: =SUM(МП_Periods!M3,МП_Periods!M16,МП_Periods!M29,МП_Periods!M42,МП_Periods!M55,МП_Periods!M68,МП_Periods!M81,МП_Periods!M94,МП_Periods!M107,МП_Periods!M120,МП_Periods!M133,МП_Periods!M146) -> 0 | AA3: =IFERROR((AB3/Z3)-1,"-") -> - | AB3: =SUM(МП_Periods!O3,МП_Periods!O16,МП_Periods!O29,МП_Periods!O42,МП_Periods!O55,МП_Periods!O68,МП_Periods!O81,МП_Periods!O94,МП_Periods!O107,МП_Periods!O120,МП_Periods!O133,МП_Periods!O146) -> 0 | AC3: =SUM(МП_Periods!P3,МП_Periods!P16,МП_Periods!P29,МП_Periods!P42,МП_Periods!P55,МП_Periods!P68,МП_Periods!P81,МП_Periods!P94,МП_Periods!P107,МП_Periods!P120,МП_Periods!P133,МП_Periods!P146) -> 0 | AD3: =IFERROR(AC3/$AC$13,"-") -> - | AF3: =SUM(МП_Periods!S3,МП_Periods!S16,МП_Periods!S29,МП_Periods!S42,МП_Periods!S55,МП_Periods!S68,МП_Periods!S81,МП_Periods!S94,МП_Periods!S107,МП_Periods!S120,МП_Periods!S133,МП_Periods!S146) -> 0 | AG3: =IFERROR(AF3/AH3,"-") -> - | AH3: =IFERROR(МП_Periods!U3+МП_Periods!U16+МП_Periods!U29+МП_Periods!U42+МП_Periods!U55+МП_Periods!U68+МП_Periods!U81+МП_Periods!U94+МП_Periods!U107+МП_Periods!U120+МП_Periods!U133+МП_Periods!U146,"-") -> - | AI3: =IFERROR(AC3/AF3*1000,"-") -> - | AJ3: =IFERROR(AC3/AH3*1000,"-") -> - | AK3: =SUM(МП_Periods!X3,МП_Periods!X16,МП_Periods!X29,МП_Periods!X42,МП_Periods!X55,МП_Periods!X68,МП_Periods!X81,МП_Periods!X94,МП_Periods!X107,МП_Periods!X120,МП_Periods!X133,МП_Periods!X146) -> 0 | AL3: =IFERROR(#REF!/AK3,"-") -> - | AN3: =IFERROR(AO3/AF3,"-") -> - | AO3: =SUM(МП_Periods!AB3,МП_Periods!AB16,МП_Periods!AB29,МП_Periods!AB42,МП_Periods!AB55,МП_Periods!AB68,МП_Periods!AB81,МП_Periods!AB94,МП_Periods!AB107,МП_Periods!AB120,МП_Periods!AB133,МП_Periods!AB146) -> 0 | AP3: =IFERROR(AC3/AO3,"-") -> - | AR3: =IFERROR(AS3/AO3,"-") -> - | AS3: =SUM(МП_Periods!AF3,МП_Periods!AF16,МП_Periods!AF29,МП_Periods!AF42,МП_Periods!AF55,МП_Periods!AF68,МП_Periods!AF81,МП_Periods!AF94,МП_Periods!AF107,МП_Periods!AF120,МП_Periods!AF133,МП_Periods!AF146) -> 0 | AT3: =IFERROR(AC3/AS3,"-") -> - | AV3: =IFERROR(AC3/AX3,"-") -> - | AW3: =IFERROR(AX3/AS3,"-") -> - | AX3: =SUM(МП_Periods!AO3,МП_Periods!AO16,МП_Periods!AO29,МП_Periods!AO42,МП_Periods!AO55,МП_Periods!AO68,МП_Periods!AO81,МП_Periods!AO94,МП_Periods!AO107,МП_Periods!AO120,МП_Periods!AO133,МП_Periods!AO146) -> 0 | AZ3: =IFERROR(BA3/AF3,"-") -> - | BA3: =IFERROR(#REF!+#REF!+#REF!+#REF!+#REF!+#REF!+#REF!+#REF!+#REF!+#REF!+#REF!+#REF!,"-") -> - | BB3: =IFERROR(AC3/BA3,"-") -> - | BC3: =IFERROR(BD3/AF3,"-") -> - | BD3: =IFERROR(#REF!+#REF!+#REF!+#REF!+#REF!+#REF!+#REF!+#REF!+#REF!+#REF!+#REF!+#REF!,"-") -> - | BF3: =IFERROR(BG3/AF3,"-") -> - | BG3: =IFERROR(#REF!+#REF!+#REF!+#REF!+#REF!+#REF!+#REF!+#REF!+#REF!+#REF!+#REF!+#REF!,"-") -> - | BH3: =IFERROR(AC3/BG3,"-") -> -
T4: CPC | U4: =IFERROR(X4/V4,"-") -> - | V4: =IFERROR(МП_Periods!I4+МП_Periods!I17+МП_Periods!I30+МП_Periods!I48+МП_Periods!I56+МП_Periods!I69+МП_Periods!I82+МП_Periods!I95+МП_Periods!I108+МП_Periods!I121+МП_Periods!I134+МП_Periods!I147,"-") -> 0 | X4: =SUM(МП_Periods!K4,МП_Periods!K17,МП_Periods!K30,МП_Periods!K43,МП_Periods!K56,МП_Periods!K69,МП_Periods!K82,МП_Periods!K95,МП_Periods!K108,МП_Periods!K121,МП_Periods!K134,МП_Periods!K147) -> 0 | Y4: =IFERROR(1-(Z4/X4),"-") -> - | Z4: =SUM(МП_Periods!M4,МП_Periods!M17,МП_Periods!M30,МП_Periods!M43,МП_Periods!M56,МП_Periods!M69,МП_Periods!M82,МП_Periods!M95,МП_Periods!M108,МП_Periods!M121,МП_Periods!M134,МП_Periods!M147) -> 0 | AA4: =IFERROR((AB4/Z4)-1,"-") -> - | AB4: =SUM(МП_Periods!O4,МП_Periods!O17,МП_Periods!O30,МП_Periods!O43,МП_Periods!O56,МП_Periods!O69,МП_Periods!O82,МП_Periods!O95,МП_Periods!O108,МП_Periods!O121,МП_Periods!O134,МП_Periods!O147) -> 0 | AC4: =SUM(МП_Periods!P4,МП_Periods!P17,МП_Periods!P30,МП_Periods!P43,МП_Periods!P56,МП_Periods!P69,МП_Periods!P82,МП_Periods!P95,МП_Periods!P108,МП_Periods!P121,МП_Periods!P134,МП_Periods!P147) -> 0 | AD4: =IFERROR(AC4/$AC$13,"-") -> - | AF4: =SUM(МП_Periods!S4,МП_Periods!S17,МП_Periods!S30,МП_Periods!S43,МП_Periods!S56,МП_Periods!S69,МП_Periods!S82,МП_Periods!S95,МП_Periods!S108,МП_Periods!S121,МП_Periods!S134,МП_Periods!S147) -> 0 | AG4: =IFERROR(AF4/AH4,"-") -> - | AH4: =IFERROR(МП_Periods!U4+МП_Periods!U17+МП_Periods!U30+МП_Periods!U48+МП_Periods!U56+МП_Periods!U69+МП_Periods!U82+МП_Periods!U95+МП_Periods!U108+МП_Periods!U121+МП_Periods!U134+МП_Periods!U147,"-") -> - | AI4: =IFERROR(AC4/AF4*1000,"-") -> - | AJ4: =IFERROR(AC4/AH4*1000,"-") -> - | AK4: =IFERROR(MAX(МП_Periods!X4,МП_Periods!X17,МП_Periods!X30,МП_Periods!X48,МП_Periods!X56,МП_Periods!X69,МП_Periods!X82,МП_Periods!X95,МП_Periods!X108,МП_Periods!X121,МП_Periods!X134,МП_Periods!X147),"-") -> 0 | AL4: =IFERROR(#REF!/AK4,"-") -> - | AN4: =IFERROR(AO4/AF4,"-") -> - | AO4: =SUM(МП_Periods!AB4,МП_Periods!AB17,МП_Periods!AB30,МП_Periods!AB43,МП_Periods!AB56,МП_Periods!AB69,МП_Periods!AB82,МП_Periods!AB95,МП_Periods!AB108,МП_Periods!AB121,МП_Periods!AB134,МП_Periods!AB147) -> 0 | AP4: =IFERROR(AC4/AO4,"-") -> - | AR4: =IFERROR(AS4/AO4,"-") -> - | AS4: =SUM(МП_Periods!AF4,МП_Periods!AF17,МП_Periods!AF30,МП_Periods!AF43,МП_Periods!AF56,МП_Periods!AF69,МП_Periods!AF82,МП_Periods!AF95,МП_Periods!AF108,МП_Periods!AF121,МП_Periods!AF134,МП_Periods!AF147) -> 0 | AT4: =IFERROR(AC4/AS4,"-") -> - | AV4: =IFERROR(AC4/AX4,"-") -> - | AW4: =IFERROR(AX4/AS4,"-") -> - | AX4: =SUM(МП_Periods!AO4,МП_Periods!AO17,МП_Periods!AO30,МП_Periods!AO43,МП_Periods!AO56,МП_Periods!AO69,МП_Periods!AO82,МП_Periods!AO95,МП_Periods!AO108,МП_Periods!AO121,МП_Periods!AO134,МП_Periods!AO147) -> 0 | AZ4: =IFERROR(BA4/AF4,"-") -> - | BA4: =IFERROR(#REF!+#REF!+#REF!+#REF!+#REF!+#REF!+#REF!+#REF!+#REF!+#REF!+#REF!+#REF!,"-") -> - | BB4: =IFERROR(AC4/BA4,"-") -> - | BC4: =IFERROR(BD4/AF4,"-") -> - | BD4: =IFERROR(#REF!+#REF!+#REF!+#REF!+#REF!+#REF!+#REF!+#REF!+#REF!+#REF!+#REF!+#REF!,"-") -> - | BF4: =IFERROR(BG4/AF4,"-") -> - | BG4: =IFERROR(#REF!+#REF!+#REF!+#REF!+#REF!+#REF!+#REF!+#REF!+#REF!+#REF!+#REF!+#REF!,"-") -> - | BH4: =IFERROR(AC4/BG4,"-") -> -
T5: CPC | U5: =IFERROR(X5/V5,"-") -> - | V5: =IFERROR(МП_Periods!I5+МП_Periods!I18+МП_Periods!I31+МП_Periods!I44+МП_Periods!I57+МП_Periods!I70+МП_Periods!I83+МП_Periods!I96+МП_Periods!I109+МП_Periods!I122+МП_Periods!I135+МП_Periods!I148,"-") -> 0 | X5: =SUM(МП_Periods!K5,МП_Periods!K18,МП_Periods!K31,МП_Periods!K44,МП_Periods!K57,МП_Periods!K70,МП_Periods!K83,МП_Periods!K96,МП_Periods!K109,МП_Periods!K122,МП_Periods!K135,МП_Periods!K148) -> 0 | Y5: =IFERROR(1-(Z5/X5),"-") -> - | Z5: =SUM(МП_Periods!M5,МП_Periods!M18,МП_Periods!M31,МП_Periods!M44,МП_Periods!M57,МП_Periods!M70,МП_Periods!M83,МП_Periods!M96,МП_Periods!M109,МП_Periods!M122,МП_Periods!M135,МП_Periods!M148) -> 0 | AA5: =IFERROR((AB5/Z5)-1,"-") -> - | AB5: =SUM(МП_Periods!O5,МП_Periods!O18,МП_Periods!O31,МП_Periods!O44,МП_Periods!O57,МП_Periods!O70,МП_Periods!O83,МП_Periods!O96,МП_Periods!O109,МП_Periods!O122,МП_Periods!O135,МП_Periods!O148) -> 0 | AC5: =SUM(МП_Periods!P5,МП_Periods!P18,МП_Periods!P31,МП_Periods!P44,МП_Periods!P57,МП_Periods!P70,МП_Periods!P83,МП_Periods!P96,МП_Periods!P109,МП_Periods!P122,МП_Periods!P135,МП_Periods!P148) -> 0 | AD5: =IFERROR(AC5/$AC$13,"-") -> - | AF5: =SUM(МП_Periods!S5,МП_Periods!S18,МП_Periods!S31,МП_Periods!S44,МП_Periods!S57,МП_Periods!S70,МП_Periods!S83,МП_Periods!S96,МП_Periods!S109,МП_Periods!S122,МП_Periods!S135,МП_Periods!S148) -> 0 | AG5: =IFERROR(AF5/AH5,"-") -> - | AH5: =IFERROR(МП_Periods!U5+МП_Periods!U18+МП_Periods!U31+МП_Periods!U44+МП_Periods!U57+МП_Periods!U70+МП_Periods!U83+МП_Periods!U96+МП_Periods!U109+МП_Periods!U122+МП_Periods!U135+МП_Periods!U148,"-") -> - | AI5: =IFERROR(AC5/AF5*1000,"-") -> - | AJ5: =IFERROR(AC5/AH5*1000,"-") -> - | AK5: =IFERROR(MAX(МП_Periods!X5,МП_Periods!X18,МП_Periods!X31,МП_Periods!X44,МП_Periods!X57,МП_Periods!X70,МП_Periods!X83,МП_Periods!X96,МП_Periods!X109,МП_Periods!X122,МП_Periods!X135,МП_Periods!X148),"-") -> 0 | AL5: =IFERROR(#REF!/AK5,"-") -> - | AN5: =IFERROR(AO5/AF5,"-") -> - | AO5: =SUM(МП_Periods!AB5,МП_Periods!AB18,МП_Periods!AB31,МП_Periods!AB44,МП_Periods!AB57,МП_Periods!AB70,МП_Periods!AB83,МП_Periods!AB96,МП_Periods!AB109,МП_Periods!AB122,МП_Periods!AB135,МП_Periods!AB148) -> 0 | AP5: =IFERROR(AC5/AO5,"-") -> - | AR5: =IFERROR(AS5/AO5,"-") -> - | AS5: =SUM(МП_Periods!AF5,МП_Periods!AF18,МП_Periods!AF31,МП_Periods!AF44,МП_Periods!AF57,МП_Periods!AF70,МП_Periods!AF83,МП_Periods!AF96,МП_Periods!AF109,МП_Periods!AF122,МП_Periods!AF135,МП_Periods!AF148) -> 0 | AT5: =IFERROR(AC5/AS5,"-") -> - | AV5: =IFERROR(AC5/AX5,"-") -> - | AW5: =IFERROR(AX5/AS5,"-") -> - | AX5: =SUM(МП_Periods!AO5,МП_Periods!AO18,МП_Periods!AO31,МП_Periods!AO44,МП_Periods!AO57,МП_Periods!AO70,МП_Periods!AO83,МП_Periods!AO96,МП_Periods!AO109,МП_Periods!AO122,МП_Periods!AO135,МП_Periods!AO148) -> 0 | AZ5: =IFERROR(BA5/AF5,"-") -> - | BA5: =IFERROR(#REF!+#REF!+#REF!+#REF!+#REF!+#REF!+#REF!+#REF!+#REF!+#REF!+#REF!+#REF!,"-") -> - | BB5: =IFERROR(AC5/BA5,"-") -> - | BC5: =IFERROR(BD5/AF5,"-") -> - | BD5: =IFERROR(#REF!+#REF!+#REF!+#REF!+#REF!+#REF!+#REF!+#REF!+#REF!+#REF!+#REF!+#REF!,"-") -> - | BF5: =IFERROR(BG5/AF5,"-") -> - | BG5: =IFERROR(#REF!+#REF!+#REF!+#REF!+#REF!+#REF!+#REF!+#REF!+#REF!+#REF!+#REF!+#REF!,"-") -> - | BH5: =IFERROR(AC5/BG5,"-") -> -
T6: CPC | U6: =IFERROR(X6/V6,"-") -> - | V6: =IFERROR(МП_Periods!I6+МП_Periods!I19+МП_Periods!I32+МП_Periods!I45+МП_Periods!I58+МП_Periods!I71+МП_Periods!I84+МП_Periods!I97+МП_Periods!I110+МП_Periods!I123+МП_Periods!I136+МП_Periods!I149,"-") -> 0 | X6: =SUM(МП_Periods!K6,МП_Periods!K19,МП_Periods!K32,МП_Periods!K45,МП_Periods!K58,МП_Periods!K71,МП_Periods!K84,МП_Periods!K97,МП_Periods!K110,МП_Periods!K123,МП_Periods!K136,МП_Periods!K149) -> 0 | Y6: =IFERROR(1-(Z6/X6),"-") -> - | Z6: =SUM(МП_Periods!M6,МП_Periods!M19,МП_Periods!M32,МП_Periods!M45,МП_Periods!M58,МП_Periods!M71,МП_Periods!M84,МП_Periods!M97,МП_Periods!M110,МП_Periods!M123,МП_Periods!M136,МП_Periods!M149) -> 0 | AA6: =IFERROR((AB6/Z6)-1,"-") -> - | AB6: =SUM(МП_Periods!O6,МП_Periods!O19,МП_Periods!O32,МП_Periods!O45,МП_Periods!O58,МП_Periods!O71,МП_Periods!O84,МП_Periods!O97,МП_Periods!O110,МП_Periods!O123,МП_Periods!O136,МП_Periods!O149) -> 0 | AC6: =SUM(МП_Periods!P6,МП_Periods!P19,МП_Periods!P32,МП_Periods!P45,МП_Periods!P58,МП_Periods!P71,МП_Periods!P84,МП_Periods!P97,МП_Periods!P110,МП_Periods!P123,МП_Periods!P136,МП_Periods!P149) -> 0 | AD6: =IFERROR(AC6/$AC$13,"-") -> - | AF6: =SUM(МП_Periods!S6,МП_Periods!S19,МП_Periods!S32,МП_Periods!S45,МП_Periods!S58,МП_Periods!S71,МП_Periods!S84,МП_Periods!S97,МП_Periods!S110,МП_Periods!S123,МП_Periods!S136,МП_Periods!S149) -> 0 | AG6: =IFERROR(AF6/AH6,"-") -> - | AH6: =IFERROR(МП_Periods!U6+МП_Periods!U19+МП_Periods!U32+МП_Periods!U45+МП_Periods!U58+МП_Periods!U71+МП_Periods!U84+МП_Periods!U97+МП_Periods!U110+МП_Periods!U123+МП_Periods!U136+МП_Periods!U149,"-") -> - | AI6: =IFERROR(AC6/AF6*1000,"-") -> - | AJ6: =IFERROR(AC6/AH6*1000,"-") -> - | AK6: =IFERROR(MAX(МП_Periods!X6,МП_Periods!X19,МП_Periods!X32,МП_Periods!X45,МП_Periods!X58,МП_Periods!X71,МП_Periods!X84,МП_Periods!X97,МП_Periods!X110,МП_Periods!X123,МП_Periods!X136,МП_Periods!X149),"-") -> 0 | AL6: =IFERROR(#REF!/AK6,"-") -> - | AN6: =IFERROR(AO6/AF6,"-") -> - | AO6: =SUM(МП_Periods!AB6,МП_Periods!AB19,МП_Periods!AB32,МП_Periods!AB45,МП_Periods!AB58,МП_Periods!AB71,МП_Periods!AB84,МП_Periods!AB97,МП_Periods!AB110,МП_Periods!AB123,МП_Periods!AB136,МП_Periods!AB149) -> 0 | AP6: =IFERROR(AC6/AO6,"-") -> - | AR6: =IFERROR(AS6/AO6,"-") -> - | AS6: =SUM(МП_Periods!AF6,МП_Periods!AF19,МП_Periods!AF32,МП_Periods!AF45,МП_Periods!AF58,МП_Periods!AF71,МП_Periods!AF84,МП_Periods!AF97,МП_Periods!AF110,МП_Periods!AF123,МП_Periods!AF136,МП_Periods!AF149) -> 0 | AT6: =IFERROR(AC6/AS6,"-") -> - | AV6: =IFERROR(AC6/AX6,"-") -> - | AW6: =IFERROR(AX6/AS6,"-") -> - | AX6: =SUM(МП_Periods!AO6,МП_Periods!AO19,МП_Periods!AO32,МП_Periods!AO45,МП_Periods!AO58,МП_Periods!AO71,МП_Periods!AO84,МП_Periods!AO97,МП_Periods!AO110,МП_Periods!AO123,МП_Periods!AO136,МП_Periods!AO149) -> 0 | AZ6: =IFERROR(BA6/AF6,"-") -> - | BA6: =IFERROR(#REF!+#REF!+#REF!+#REF!+#REF!+#REF!+#REF!+#REF!+#REF!+#REF!+#REF!+#REF!,"-") -> - | BB6: =IFERROR(AC6/BA6,"-") -> - | BC6: =IFERROR(BD6/AF6,"-") -> - | BD6: =IFERROR(#REF!+#REF!+#REF!+#REF!+#REF!+#REF!+#REF!+#REF!+#REF!+#REF!+#REF!+#REF!,"-") -> - | BF6: =IFERROR(BG6/AF6,"-") -> - | BG6: =IFERROR(#REF!+#REF!+#REF!+#REF!+#REF!+#REF!+#REF!+#REF!+#REF!+#REF!+#REF!+#REF!,"-") -> - | BH6: =IFERROR(AC6/BG6,"-") -> -
T7: CPC | U7: =IFERROR(X7/V7,"-") -> - | V7: =IFERROR(МП_Periods!I7+МП_Periods!I20+МП_Periods!I33+МП_Periods!I46+МП_Periods!I59+МП_Periods!I72+МП_Periods!I85+МП_Periods!I98+МП_Periods!I111+МП_Periods!I124+МП_Periods!I137+МП_Periods!I150,"-") -> 0 | X7: =SUM(МП_Periods!K7,МП_Periods!K20,МП_Periods!K33,МП_Periods!K46,МП_Periods!K59,МП_Periods!K72,МП_Periods!K85,МП_Periods!K98,МП_Periods!K111,МП_Periods!K124,МП_Periods!K137,МП_Periods!K150) -> 0 | Y7: =IFERROR(1-(Z7/X7),"-") -> - | Z7: =SUM(МП_Periods!M7,МП_Periods!M20,МП_Periods!M33,МП_Periods!M46,МП_Periods!M59,МП_Periods!M72,МП_Periods!M85,МП_Periods!M98,МП_Periods!M111,МП_Periods!M124,МП_Periods!M137,МП_Periods!M150) -> 0 | AA7: =IFERROR((AB7/Z7)-1,"-") -> - | AB7: =SUM(МП_Periods!O7,МП_Periods!O20,МП_Periods!O33,МП_Periods!O46,МП_Periods!O59,МП_Periods!O72,МП_Periods!O85,МП_Periods!O98,МП_Periods!O111,МП_Periods!O124,МП_Periods!O137,МП_Periods!O150) -> 0 | AC7: =SUM(МП_Periods!P7,МП_Periods!P20,МП_Periods!P33,МП_Periods!P46,МП_Periods!P59,МП_Periods!P72,МП_Periods!P85,МП_Periods!P98,МП_Periods!P111,МП_Periods!P124,МП_Periods!P137,МП_Periods!P150) -> 0 | AD7: =IFERROR(AC7/$AC$13,"-") -> - | AF7: =SUM(МП_Periods!S7,МП_Periods!S20,МП_Periods!S33,МП_Periods!S46,МП_Periods!S59,МП_Periods!S72,МП_Periods!S85,МП_Periods!S98,МП_Periods!S111,МП_Periods!S124,МП_Periods!S137,МП_Periods!S150) -> 0 | AG7: =IFERROR(AF7/AH7,"-") -> - | AH7: =IFERROR(МП_Periods!U7+МП_Periods!U20+МП_Periods!U33+МП_Periods!U46+МП_Periods!U59+МП_Periods!U72+МП_Periods!U85+МП_Periods!U98+МП_Periods!U111+МП_Periods!U124+МП_Periods!U137+МП_Periods!U150,"-") -> - | AI7: =IFERROR(AC7/AF7*1000,"-") -> - | AJ7: =IFERROR(AC7/AH7*1000,"-") -> - | AK7: =IFERROR(MAX(МП_Periods!X7,МП_Periods!X20,МП_Periods!X33,МП_Periods!X46,МП_Periods!X59,МП_Periods!X72,МП_Periods!X85,МП_Periods!X98,МП_Periods!X111,МП_Periods!X124,МП_Periods!X137,МП_Periods!X150),"-") -> 0 | AL7: =IFERROR(#REF!/AK7,"-") -> - | AN7: =IFERROR(AO7/AF7,"-") -> - | AO7: =SUM(МП_Periods!AB7,МП_Periods!AB20,МП_Periods!AB33,МП_Periods!AB46,МП_Periods!AB59,МП_Periods!AB72,МП_Periods!AB85,МП_Periods!AB98,МП_Periods!AB111,МП_Periods!AB124,МП_Periods!AB137,МП_Periods!AB150) -> 0 | AP7: =IFERROR(AC7/AO7,"-") -> - | AR7: =IFERROR(AS7/AO7,"-") -> - | AS7: =SUM(МП_Periods!AF7,МП_Periods!AF20,МП_Periods!AF33,МП_Periods!AF46,МП_Periods!AF59,МП_Periods!AF72,МП_Periods!AF85,МП_Periods!AF98,МП_Periods!AF111,МП_Periods!AF124,МП_Periods!AF137,МП_Periods!AF150) -> 0 | AT7: =IFERROR(AC7/AS7,"-") -> - | AV7: =IFERROR(AC7/AX7,"-") -> - | AW7: =IFERROR(AX7/AS7,"-") -> - | AX7: =SUM(МП_Periods!AO7,МП_Periods!AO20,МП_Periods!AO33,МП_Periods!AO46,МП_Periods!AO59,МП_Periods!AO72,МП_Periods!AO85,МП_Periods!AO98,МП_Periods!AO111,МП_Periods!AO124,МП_Periods!AO137,МП_Periods!AO150) -> 0 | AZ7: =IFERROR(BA7/AF7,"-") -> - | BA7: =IFERROR(#REF!+#REF!+#REF!+#REF!+#REF!+#REF!+#REF!+#REF!+#REF!+#REF!+#REF!+#REF!,"-") -> - | BB7: =IFERROR(AC7/BA7,"-") -> - | BC7: =IFERROR(BD7/AF7,"-") -> - | BD7: =IFERROR(#REF!+#REF!+#REF!+#REF!+#REF!+#REF!+#REF!+#REF!+#REF!+#REF!+#REF!+#REF!,"-") -> - | BF7: =IFERROR(BG7/AF7,"-") -> - | BG7: =IFERROR(#REF!+#REF!+#REF!+#REF!+#REF!+#REF!+#REF!+#REF!+#REF!+#REF!+#REF!+#REF!,"-") -> - | BH7: =IFERROR(AC7/BG7,"-") -> -
T8: CPC | U8: =IFERROR(X8/V8,"-") -> - | V8: =IFERROR(МП_Periods!I8+МП_Periods!I21+МП_Periods!I34+МП_Periods!I47+МП_Periods!I60+МП_Periods!I73+МП_Periods!I86+МП_Periods!I99+МП_Periods!I112+МП_Periods!I125+МП_Periods!I138+МП_Periods!I151,"-") -> 0 | X8: =SUM(МП_Periods!K8,МП_Periods!K21,МП_Periods!K34,МП_Periods!K47,МП_Periods!K60,МП_Periods!K73,МП_Periods!K86,МП_Periods!K99,МП_Periods!K112,МП_Periods!K125,МП_Periods!K138,МП_Periods!K151) -> 0 | Y8: =IFERROR(1-(Z8/X8),"-") -> - | Z8: =SUM(МП_Periods!M8,МП_Periods!M21,МП_Periods!M34,МП_Periods!M47,МП_Periods!M60,МП_Periods!M73,МП_Periods!M86,МП_Periods!M99,МП_Periods!M112,МП_Periods!M125,МП_Periods!M138,МП_Periods!M151) -> 0 | AA8: =IFERROR((AB8/Z8)-1,"-") -> - | AB8: =SUM(МП_Periods!O8,МП_Periods!O21,МП_Periods!O34,МП_Periods!O47,МП_Periods!O60,МП_Periods!O73,МП_Periods!O86,МП_Periods!O99,МП_Periods!O112,МП_Periods!O125,МП_Periods!O138,МП_Periods!O151) -> 0 | AC8: =SUM(МП_Periods!P8,МП_Periods!P21,МП_Periods!P34,МП_Periods!P47,МП_Periods!P60,МП_Periods!P73,МП_Periods!P86,МП_Periods!P99,МП_Periods!P112,МП_Periods!P125,МП_Periods!P138,МП_Periods!P151) -> 0 | AD8: =IFERROR(AC8/$AC$13,"-") -> - | AF8: =SUM(МП_Periods!S8,МП_Periods!S21,МП_Periods!S34,МП_Periods!S47,МП_Periods!S60,МП_Periods!S73,МП_Periods!S86,МП_Periods!S99,МП_Periods!S112,МП_Periods!S125,МП_Periods!S138,МП_Periods!S151) -> 0 | AG8: =IFERROR(AF8/AH8,"-") -> - | AH8: =IFERROR(МП_Periods!U8+МП_Periods!U21+МП_Periods!U34+МП_Periods!U47+МП_Periods!U60+МП_Periods!U73+МП_Periods!U86+МП_Periods!U99+МП_Periods!U112+МП_Periods!U125+МП_Periods!U138+МП_Periods!U151,"-") -> - | AI8: =IFERROR(AC8/AF8*1000,"-") -> - | AJ8: =IFERROR(AC8/AH8*1000,"-") -> - | AK8: =IFERROR(MAX(МП_Periods!X8,МП_Periods!X21,МП_Periods!X34,МП_Periods!X47,МП_Periods!X60,МП_Periods!X73,МП_Periods!X86,МП_Periods!X99,МП_Periods!X112,МП_Periods!X125,МП_Periods!X138,МП_Periods!X151),"-") -> 0 | AL8: =IFERROR(#REF!/AK8,"-") -> - | AN8: =IFERROR(AO8/AF8,"-") -> - | AO8: =SUM(МП_Periods!AB8,МП_Periods!AB21,МП_Periods!AB34,МП_Periods!AB47,МП_Periods!AB60,МП_Periods!AB73,МП_Periods!AB86,МП_Periods!AB99,МП_Periods!AB112,МП_Periods!AB125,МП_Periods!AB138,МП_Periods!AB151) -> 0 | AP8: =IFERROR(AC8/AO8,"-") -> - | AR8: =IFERROR(AS8/AO8,"-") -> - | AS8: =SUM(МП_Periods!AF8,МП_Periods!AF21,МП_Periods!AF34,МП_Periods!AF47,МП_Periods!AF60,МП_Periods!AF73,МП_Periods!AF86,МП_Periods!AF99,МП_Periods!AF112,МП_Periods!AF125,МП_Periods!AF138,МП_Periods!AF151) -> 0 | AT8: =IFERROR(AC8/AS8,"-") -> - | AV8: =IFERROR(AC8/AX8,"-") -> - | AW8: =IFERROR(AX8/AS8,"-") -> - | AX8: =SUM(МП_Periods!AO8,МП_Periods!AO21,МП_Periods!AO34,МП_Periods!AO47,МП_Periods!AO60,МП_Periods!AO73,МП_Periods!AO86,МП_Periods!AO99,МП_Periods!AO112,МП_Periods!AO125,МП_Periods!AO138,МП_Periods!AO151) -> 0 | AZ8: =IFERROR(BA8/AF8,"-") -> - | BA8: =IFERROR(#REF!+#REF!+#REF!+#REF!+#REF!+#REF!+#REF!+#REF!+#REF!+#REF!+#REF!+#REF!,"-") -> - | BB8: =IFERROR(AC8/BA8,"-") -> - | BC8: =IFERROR(BD8/AF8,"-") -> - | BD8: =IFERROR(#REF!+#REF!+#REF!+#REF!+#REF!+#REF!+#REF!+#REF!+#REF!+#REF!+#REF!+#REF!,"-") -> - | BF8: =IFERROR(BG8/AF8,"-") -> - | BG8: =IFERROR(#REF!+#REF!+#REF!+#REF!+#REF!+#REF!+#REF!+#REF!+#REF!+#REF!+#REF!+#REF!,"-") -> - | BH8: =IFERROR(AC8/BG8,"-") -> -
T9: CPC | U9: =IFERROR(X9/V9,"-") -> - | V9: =IFERROR(МП_Periods!I9+МП_Periods!I22+МП_Periods!I35+МП_Periods!I48+МП_Periods!I61+МП_Periods!I74+МП_Periods!I87+МП_Periods!I100+МП_Periods!I113+МП_Periods!I126+МП_Periods!I139+МП_Periods!I152,"-") -> 0 | X9: =SUM(МП_Periods!K9,МП_Periods!K22,МП_Periods!K35,МП_Periods!K48,МП_Periods!K61,МП_Periods!K74,МП_Periods!K87,МП_Periods!K100,МП_Periods!K113,МП_Periods!K126,МП_Periods!K139,МП_Periods!K152) -> 0 | Y9: =IFERROR(1-(Z9/X9),"-") -> - | Z9: =SUM(МП_Periods!M9,МП_Periods!M22,МП_Periods!M35,МП_Periods!M48,МП_Periods!M61,МП_Periods!M74,МП_Periods!M87,МП_Periods!M100,МП_Periods!M113,МП_Periods!M126,МП_Periods!M139,МП_Periods!M152) -> 0 | AA9: =IFERROR((AB9/Z9)-1,"-") -> - | AB9: =SUM(МП_Periods!O9,МП_Periods!O22,МП_Periods!O35,МП_Periods!O48,МП_Periods!O61,МП_Periods!O74,МП_Periods!O87,МП_Periods!O100,МП_Periods!O113,МП_Periods!O126,МП_Periods!O139,МП_Periods!O152) -> 0 | AC9: =SUM(МП_Periods!P9,МП_Periods!P22,МП_Periods!P35,МП_Periods!P48,МП_Periods!P61,МП_Periods!P74,МП_Periods!P87,МП_Periods!P100,МП_Periods!P113,МП_Periods!P126,МП_Periods!P139,МП_Periods!P152) -> 0 | AD9: =IFERROR(AC9/$AC$13,"-") -> - | AF9: =SUM(МП_Periods!S9,МП_Periods!S22,МП_Periods!S35,МП_Periods!S48,МП_Periods!S61,МП_Periods!S74,МП_Periods!S87,МП_Periods!S100,МП_Periods!S113,МП_Periods!S126,МП_Periods!S139,МП_Periods!S152) -> 0 | AG9: =IFERROR(AF9/AH9,"-") -> - | AH9: =IFERROR(МП_Periods!U9+МП_Periods!U22+МП_Periods!U35+МП_Periods!U48+МП_Periods!U61+МП_Periods!U74+МП_Periods!U87+МП_Periods!U100+МП_Periods!U113+МП_Periods!U126+МП_Periods!U139+МП_Periods!U152,"-") -> - | AI9: =IFERROR(AC9/AF9*1000,"-") -> - | AJ9: =IFERROR(AC9/AH9*1000,"-") -> - | AK9: =IFERROR(MAX(МП_Periods!X9,МП_Periods!X22,МП_Periods!X35,МП_Periods!X48,МП_Periods!X61,МП_Periods!X74,МП_Periods!X87,МП_Periods!X100,МП_Periods!X113,МП_Periods!X126,МП_Periods!X139,МП_Periods!X152),"-") -> 0 | AL9: =IFERROR(#REF!/AK9,"-") -> - | AN9: =IFERROR(AO9/AF9,"-") -> - | AO9: =SUM(МП_Periods!AB9,МП_Periods!AB22,МП_Periods!AB35,МП_Periods!AB48,МП_Periods!AB61,МП_Periods!AB74,МП_Periods!AB87,МП_Periods!AB100,МП_Periods!AB113,МП_Periods!AB126,МП_Periods!AB139,МП_Periods!AB152) -> 0 | AP9: =IFERROR(AC9/AO9,"-") -> - | AR9: =IFERROR(AS9/AO9,"-") -> - | AS9: =SUM(МП_Periods!AF9,МП_Periods!AF22,МП_Periods!AF35,МП_Periods!AF48,МП_Periods!AF61,МП_Periods!AF74,МП_Periods!AF87,МП_Periods!AF100,МП_Periods!AF113,МП_Periods!AF126,МП_Periods!AF139,МП_Periods!AF152) -> 0 | AT9: =IFERROR(AC9/AS9,"-") -> - | AV9: =IFERROR(AC9/AX9,"-") -> - | AW9: =IFERROR(AX9/AS9,"-") -> - | AX9: =SUM(МП_Periods!AO9,МП_Periods!AO22,МП_Periods!AO35,МП_Periods!AO48,МП_Periods!AO61,МП_Periods!AO74,МП_Periods!AO87,МП_Periods!AO100,МП_Periods!AO113,МП_Periods!AO126,МП_Periods!AO139,МП_Periods!AO152) -> 0 | AZ9: =IFERROR(BA9/AF9,"-") -> - | BA9: =IFERROR(#REF!+#REF!+#REF!+#REF!+#REF!+#REF!+#REF!+#REF!+#REF!+#REF!+#REF!+#REF!,"-") -> - | BB9: =IFERROR(AC9/BA9,"-") -> - | BC9: =IFERROR(BD9/AF9,"-") -> - | BD9: =IFERROR(#REF!+#REF!+#REF!+#REF!+#REF!+#REF!+#REF!+#REF!+#REF!+#REF!+#REF!+#REF!,"-") -> - | BF9: =IFERROR(BG9/AF9,"-") -> - | BG9: =IFERROR(#REF!+#REF!+#REF!+#REF!+#REF!+#REF!+#REF!+#REF!+#REF!+#REF!+#REF!+#REF!,"-") -> - | BH9: =IFERROR(AC9/BG9,"-") -> -
T10: CPC | U10: =IFERROR(X10/V10,"-") -> - | V10: =IFERROR(МП_Periods!I10+МП_Periods!I23+МП_Periods!I36+МП_Periods!I49+МП_Periods!I62+МП_Periods!I75+МП_Periods!I88+МП_Periods!I101+МП_Periods!I114+МП_Periods!I127+МП_Periods!I140+МП_Periods!I153,"-") -> 0 | X10: =SUM(МП_Periods!K10,МП_Periods!K23,МП_Periods!K36,МП_Periods!K49,МП_Periods!K62,МП_Periods!K75,МП_Periods!K88,МП_Periods!K101,МП_Periods!K114,МП_Periods!K127,МП_Periods!K140,МП_Periods!K153) -> 0 | Y10: =IFERROR(1-(Z10/X10),"-") -> - | Z10: =SUM(МП_Periods!M10,МП_Periods!M23,МП_Periods!M36,МП_Periods!M49,МП_Periods!M62,МП_Periods!M75,МП_Periods!M88,МП_Periods!M101,МП_Periods!M114,МП_Periods!M127,МП_Periods!M140,МП_Periods!M153) -> 0 | AA10: =IFERROR((AB10/Z10)-1,"-") -> - | AB10: =SUM(МП_Periods!O10,МП_Periods!O23,МП_Periods!O36,МП_Periods!O49,МП_Periods!O62,МП_Periods!O75,МП_Periods!O88,МП_Periods!O101,МП_Periods!O114,МП_Periods!O127,МП_Periods!O140,МП_Periods!O153) -> 0 | AC10: =SUM(МП_Periods!P10,МП_Periods!P23,МП_Periods!P36,МП_Periods!P49,МП_Periods!P62,МП_Periods!P75,МП_Periods!P88,МП_Periods!P101,МП_Periods!P114,МП_Periods!P127,МП_Periods!P140,МП_Periods!P153) -> 0 | AD10: =IFERROR(AC10/$AC$13,"-") -> - | AF10: =SUM(МП_Periods!S10,МП_Periods!S23,МП_Periods!S36,МП_Periods!S49,МП_Periods!S62,МП_Periods!S75,МП_Periods!S88,МП_Periods!S101,МП_Periods!S114,МП_Periods!S127,МП_Periods!S140,МП_Periods!S153) -> 0 | AG10: =IFERROR(AF10/AH10,"-") -> - | AH10: =IFERROR(МП_Periods!U10+МП_Periods!U23+МП_Periods!U36+МП_Periods!U49+МП_Periods!U62+МП_Periods!U75+МП_Periods!U88+МП_Periods!U101+МП_Periods!U114+МП_Periods!U127+МП_Periods!U140+МП_Periods!U153,"-") -> - | AI10: =IFERROR(AC10/AF10*1000,"-") -> - | AJ10: =IFERROR(AC10/AH10*1000,"-") -> - | AK10: =IFERROR(MAX(МП_Periods!X10,МП_Periods!X23,МП_Periods!X36,МП_Periods!X49,МП_Periods!X62,МП_Periods!X75,МП_Periods!X88,МП_Periods!X101,МП_Periods!X114,МП_Periods!X127,МП_Periods!X140,МП_Periods!X153),"-") -> 0 | AL10: =IFERROR(#REF!/AK10,"-") -> - | AN10: =IFERROR(AO10/AF10,"-") -> - | AO10: =SUM(МП_Periods!AB10,МП_Periods!AB23,МП_Periods!AB36,МП_Periods!AB49,МП_Periods!AB62,МП_Periods!AB75,МП_Periods!AB88,МП_Periods!AB101,МП_Periods!AB114,МП_Periods!AB127,МП_Periods!AB140,МП_Periods!AB153) -> 0 | AP10: =IFERROR(AC10/AO10,"-") -> - | AR10: =IFERROR(AS10/AO10,"-") -> - | AS10: =SUM(МП_Periods!AF10,МП_Periods!AF23,МП_Periods!AF36,МП_Periods!AF49,МП_Periods!AF62,МП_Periods!AF75,МП_Periods!AF88,МП_Periods!AF101,МП_Periods!AF114,МП_Periods!AF127,МП_Periods!AF140,МП_Periods!AF153) -> 0 | AT10: =IFERROR(AC10/AS10,"-") -> - | AV10: =IFERROR(AC10/AX10,"-") -> - | AW10: =IFERROR(AX10/AS10,"-") -> - | AX10: =SUM(МП_Periods!AO10,МП_Periods!AO23,МП_Periods!AO36,МП_Periods!AO49,МП_Periods!AO62,МП_Periods!AO75,МП_Periods!AO88,МП_Periods!AO101,МП_Periods!AO114,МП_Periods!AO127,МП_Periods!AO140,МП_Periods!AO153) -> 0 | AZ10: =IFERROR(BA10/AF10,"-") -> - | BA10: =IFERROR(#REF!+#REF!+#REF!+#REF!+#REF!+#REF!+#REF!+#REF!+#REF!+#REF!+#REF!+#REF!,"-") -> - | BB10: =IFERROR(AC10/BA10,"-") -> - | BC10: =IFERROR(BD10/AF10,"-") -> - | BD10: =IFERROR(#REF!+#REF!+#REF!+#REF!+#REF!+#REF!+#REF!+#REF!+#REF!+#REF!+#REF!+#REF!,"-") -> - | BF10: =IFERROR(BG10/AF10,"-") -> - | BG10: =IFERROR(#REF!+#REF!+#REF!+#REF!+#REF!+#REF!+#REF!+#REF!+#REF!+#REF!+#REF!+#REF!,"-") -> - | BH10: =IFERROR(AC10/BG10,"-") -> -
T11: CPC | U11: =IFERROR(X11/V11,"-") -> - | V11: =IFERROR(МП_Periods!I11+МП_Periods!I24+МП_Periods!I37+МП_Periods!I50+МП_Periods!I63+МП_Periods!I76+МП_Periods!I89+МП_Periods!I102+МП_Periods!I115+МП_Periods!I128+МП_Periods!I141+МП_Periods!I154,"-") -> 0 | X11: =SUM(МП_Periods!K11,МП_Periods!K24,МП_Periods!K37,МП_Periods!K50,МП_Periods!K63,МП_Periods!K76,МП_Periods!K89,МП_Periods!K102,МП_Periods!K115,МП_Periods!K128,МП_Periods!K141,МП_Periods!K154) -> 0 | Y11: =IFERROR(1-(Z11/X11),"-") -> - | Z11: =SUM(МП_Periods!M11,МП_Periods!M24,МП_Periods!M37,МП_Periods!M50,МП_Periods!M63,МП_Periods!M76,МП_Periods!M89,МП_Periods!M102,МП_Periods!M115,МП_Periods!M128,МП_Periods!M141,МП_Periods!M154) -> 0 | AA11: =IFERROR((AB11/Z11)-1,"-") -> - | AB11: =SUM(МП_Periods!O11,МП_Periods!O24,МП_Periods!O37,МП_Periods!O50,МП_Periods!O63,МП_Periods!O76,МП_Periods!O89,МП_Periods!O102,МП_Periods!O115,МП_Periods!O128,МП_Periods!O141,МП_Periods!O154) -> 0 | AC11: =SUM(МП_Periods!P11,МП_Periods!P24,МП_Periods!P37,МП_Periods!P50,МП_Periods!P63,МП_Periods!P76,МП_Periods!P89,МП_Periods!P102,МП_Periods!P115,МП_Periods!P128,МП_Periods!P141,МП_Periods!P154) -> 0 | AD11: =IFERROR(AC11/$AC$13,"-") -> - | AF11: =SUM(МП_Periods!S11,МП_Periods!S24,МП_Periods!S37,МП_Periods!S50,МП_Periods!S63,МП_Periods!S76,МП_Periods!S89,МП_Periods!S102,МП_Periods!S115,МП_Periods!S128,МП_Periods!S141,МП_Periods!S154) -> 0 | AG11: =IFERROR(AF11/AH11,"-") -> - | AH11: =IFERROR(МП_Periods!U11+МП_Periods!U24+МП_Periods!U37+МП_Periods!U50+МП_Periods!U63+МП_Periods!U76+МП_Periods!U89+МП_Periods!U102+МП_Periods!U115+МП_Periods!U128+МП_Periods!U141+МП_Periods!U154,"-") -> - | AI11: =IFERROR(AC11/AF11*1000,"-") -> - | AJ11: =IFERROR(AC11/AH11*1000,"-") -> - | AK11: =IFERROR(MAX(МП_Periods!X11,МП_Periods!X24,МП_Periods!X37,МП_Periods!X50,МП_Periods!X63,МП_Periods!X76,МП_Periods!X89,МП_Periods!X102,МП_Periods!X115,МП_Periods!X128,МП_Periods!X141,МП_Periods!X154),"-") -> 0 | AL11: =IFERROR(#REF!/AK11,"-") -> - | AN11: =IFERROR(AO11/AF11,"-") -> - | AO11: =SUM(МП_Periods!AB11,МП_Periods!AB24,МП_Periods!AB37,МП_Periods!AB50,МП_Periods!AB63,МП_Periods!AB76,МП_Periods!AB89,МП_Periods!AB102,МП_Periods!AB115,МП_Periods!AB128,МП_Periods!AB141,МП_Periods!AB154) -> 0 | AP11: =IFERROR(AC11/AO11,"-") -> - | AR11: =IFERROR(AS11/AO11,"-") -> - | AS11: =SUM(МП_Periods!AF11,МП_Periods!AF24,МП_Periods!AF37,МП_Periods!AF50,МП_Periods!AF63,МП_Periods!AF76,МП_Periods!AF89,МП_Periods!AF102,МП_Periods!AF115,МП_Periods!AF128,МП_Periods!AF141,МП_Periods!AF154) -> 0 | AT11: =IFERROR(AC11/AS11,"-") -> - | AV11: =IFERROR(AC11/AX11,"-") -> - | AW11: =IFERROR(AX11/AS11,"-") -> - | AX11: =SUM(МП_Periods!AO11,МП_Periods!AO24,МП_Periods!AO37,МП_Periods!AO50,МП_Periods!AO63,МП_Periods!AO76,МП_Periods!AO89,МП_Periods!AO102,МП_Periods!AO115,МП_Periods!AO128,МП_Periods!AO141,МП_Periods!AO154) -> 0 | AZ11: =IFERROR(BA11/AF11,"-") -> - | BA11: =IFERROR(#REF!+#REF!+#REF!+#REF!+#REF!+#REF!+#REF!+#REF!+#REF!+#REF!+#REF!+#REF!,"-") -> - | BB11: =IFERROR(AC11/BA11,"-") -> - | BC11: =IFERROR(BD11/AF11,"-") -> - | BD11: =IFERROR(#REF!+#REF!+#REF!+#REF!+#REF!+#REF!+#REF!+#REF!+#REF!+#REF!+#REF!+#REF!,"-") -> - | BF11: =IFERROR(BG11/AF11,"-") -> - | BG11: =IFERROR(#REF!+#REF!+#REF!+#REF!+#REF!+#REF!+#REF!+#REF!+#REF!+#REF!+#REF!+#REF!,"-") -> - | BH11: =IFERROR(AC11/BG11,"-") -> -
T12: CPC | U12: =IFERROR(X12/V12,"-") -> - | V12: =IFERROR(МП_Periods!I12+МП_Periods!I25+МП_Periods!I38+МП_Periods!I51+МП_Periods!I64+МП_Periods!I77+МП_Periods!I90+МП_Periods!I103+МП_Periods!I116+МП_Periods!I129+МП_Periods!I142+МП_Periods!I155,"-") -> 0 | X12: =SUM(МП_Periods!K12,МП_Periods!K25,МП_Periods!K38,МП_Periods!K51,МП_Periods!K64,МП_Periods!K77,МП_Periods!K90,МП_Periods!K103,МП_Periods!K116,МП_Periods!K129,МП_Periods!K142,МП_Periods!K155) -> 0 | Y12: =IFERROR(1-(Z12/X12),"-") -> - | Z12: =SUM(МП_Periods!M12,МП_Periods!M25,МП_Periods!M38,МП_Periods!M51,МП_Periods!M64,МП_Periods!M77,МП_Periods!M90,МП_Periods!M103,МП_Periods!M116,МП_Periods!M129,МП_Periods!M142,МП_Periods!M155) -> 0 | AA12: =IFERROR((AB12/Z12)-1,"-") -> - | AB12: =SUM(МП_Periods!O12,МП_Periods!O25,МП_Periods!O38,МП_Periods!O51,МП_Periods!O64,МП_Periods!O77,МП_Periods!O90,МП_Periods!O103,МП_Periods!O116,МП_Periods!O129,МП_Periods!O142,МП_Periods!O155) -> 0 | AC12: =SUM(МП_Periods!P12,МП_Periods!P25,МП_Periods!P38,МП_Periods!P51,МП_Periods!P64,МП_Periods!P77,МП_Periods!P90,МП_Periods!P103,МП_Periods!P116,МП_Periods!P129,МП_Periods!P142,МП_Periods!P155) -> 0 | AD12: =IFERROR(AC12/$AC$13,"-") -> - | AF12: =SUM(МП_Periods!S12,МП_Periods!S25,МП_Periods!S38,МП_Periods!S51,МП_Periods!S64,МП_Periods!S77,МП_Periods!S90,МП_Periods!S103,МП_Periods!S116,МП_Periods!S129,МП_Periods!S142,МП_Periods!S155) -> 0 | AG12: =IFERROR(AF12/AH12,"-") -> - | AH12: =IFERROR(МП_Periods!U12+МП_Periods!U25+МП_Periods!U38+МП_Periods!U51+МП_Periods!U64+МП_Periods!U77+МП_Periods!U90+МП_Periods!U103+МП_Periods!U116+МП_Periods!U129+МП_Periods!U142+МП_Periods!U155,"-") -> - | AI12: =IFERROR(AC12/AF12*1000,"-") -> - | AJ12: =IFERROR(AC12/AH12*1000,"-") -> - | AK12: =IFERROR(MAX(МП_Periods!X12,МП_Periods!X25,МП_Periods!X38,МП_Periods!X51,МП_Periods!X64,МП_Periods!X77,МП_Periods!X90,МП_Periods!X103,МП_Periods!X116,МП_Periods!X129,МП_Periods!X142,МП_Periods!X155),"-") -> 0 | AL12: =IFERROR(#REF!/AK12,"-") -> - | AN12: =IFERROR(AO12/AF12,"-") -> - | AO12: =SUM(МП_Periods!AB12,МП_Periods!AB25,МП_Periods!AB38,МП_Periods!AB51,МП_Periods!AB64,МП_Periods!AB77,МП_Periods!AB90,МП_Periods!AB103,МП_Periods!AB116,МП_Periods!AB129,МП_Periods!AB142,МП_Periods!AB155) -> 0 | AP12: =IFERROR(AC12/AO12,"-") -> - | AR12: =IFERROR(AS12/AO12,"-") -> - | AS12: =SUM(МП_Periods!AF12,МП_Periods!AF25,МП_Periods!AF38,МП_Periods!AF51,МП_Periods!AF64,МП_Periods!AF77,МП_Periods!AF90,МП_Periods!AF103,МП_Periods!AF116,МП_Periods!AF129,МП_Periods!AF142,МП_Periods!AF155) -> 0 | AT12: =IFERROR(AC12/AS12,"-") -> - | AV12: =IFERROR(AC12/AX12,"-") -> - | AW12: =IFERROR(AX12/AS12,"-") -> - | AX12: =SUM(МП_Periods!AO12,МП_Periods!AO25,МП_Periods!AO38,МП_Periods!AO51,МП_Periods!AO64,МП_Periods!AO77,МП_Periods!AO90,МП_Periods!AO103,МП_Periods!AO116,МП_Periods!AO129,МП_Periods!AO142,МП_Periods!AO155) -> 0 | AZ12: =IFERROR(BA12/AF12,"-") -> - | BA12: =IFERROR(#REF!+#REF!+#REF!+#REF!+#REF!+#REF!+#REF!+#REF!+#REF!+#REF!+#REF!+#REF!,"-") -> - | BB12: =IFERROR(AC12/BA12,"-") -> - | BC12: =IFERROR(BD12/AF12,"-") -> - | BD12: =IFERROR(#REF!+#REF!+#REF!+#REF!+#REF!+#REF!+#REF!+#REF!+#REF!+#REF!+#REF!+#REF!,"-") -> - | BF12: =IFERROR(BG12/AF12,"-") -> - | BG12: =IFERROR(#REF!+#REF!+#REF!+#REF!+#REF!+#REF!+#REF!+#REF!+#REF!+#REF!+#REF!+#REF!,"-") -> - | BH12: =IFERROR(AC12/BG12,"-") -> -
B13: Итого | C13: - | D13: - | F13: - | G13: - | H13: - | I13: - | J13: - | K13: - | L13: - | M13: - | N13: - | O13: - | P13: - | Q13: - | S13: - | T13: - | U13: =IFERROR(X13/V13,"-") -> - | V13: =SUM(V3:V12) -> 0 | X13: =IFERROR(SUM(X3:X12),"-") -> 0 | Y13: - | Z13: =IFERROR(SUM(Z3:Z12),"-") -> 0 | AA13: - | AB13: =IFERROR(SUM(AB3:AB12),"-") -> 0 | AC13: =IFERROR(SUM(AC3:AC12),"-") -> 0 | AD13: 1 | AF13: =IFERROR(SUM(AF3:AF12),"-") -> 0 | AG13: - | AH13: - | AI13: =IFERROR(AC13/AF13*1000,"-") -> - | AJ13: =IFERROR(AC13/AH13*1000,"-") -> - | AK13: - | AL13: - | AN13: =IFERROR(AO13/AF13,"-") -> - | AO13: =IFERROR(SUM(AO3:AO12),"-") -> 0 | AP13: =IFERROR(AC13/AO13,"-") -> - | AR13: =IFERROR(AS13/AO13,"-") -> - | AS13: =IFERROR(SUM(AS3:AS12),"-") -> 0 | AT13: =IFERROR(AC13/AS13,"-") -> - | AV13: =IFERROR(AC13/AX13,"-") -> - | AW13: =IFERROR(AX13/#REF!,"-") -> - | AX13: =IFERROR(SUM(AX3:AX12),"-") -> 0 | AZ13: =IFERROR(BA13/AF13,"-") -> - | BA13: =IFERROR(SUM(BA3:BA12),"-") -> 0 | BB13: =IFERROR(AC13/BA13,"-") -> - | BC13: =IFERROR(BD13/AF13,"-") -> - | BD13: =IFERROR(SUM(BD3:BD12),"-") -> 0 | BF13: =IFERROR(BG13/AF13,"-") -> - | BG13: =IFERROR(SUM(BG3:BG12),"-") -> 0 | BH13: =IFERROR(AC13/BG13,"-") -> -
B15: Медиабюджет до НДС | C15: =IFERROR(Z13,"-") -> 0
B16: Агентская комиссия до НДС | C16: =IFERROR((AB13-Z13),"-") -> 0
B17: Медиабюджет с АК до НДС | C17: =IFERROR(SUM(C15:C16),"-") -> 0
B18: НДС | C18: =IFERROR((AC13-AB13),"-") -> 0
B19: Медиабюджет с АК и НДС | C19: =IFERROR(SUM(C17:C18),"-") -> 0
B20: Разработка креативов | C20: 0
B21: Настройка аналитики | C21: 0
B22: Итого с АК и НДС | C22: =IFERROR(SUM(C19:C21),"-") -> 0

Sheet МП_Periods
AH1: \
B2: Рекламная система | C2: Рекламный формат, размер, вид размещения | D2: Таргетинги | F2: Период | G2: Модель закупки | H2: Стоимость единицы закупки (без НДС) | I2: Кол-во единиц закупки | K2: Стоимость (без НДС) | L2: СК, % | M2: Стоимость с учетом СК (без НДС) | N2: АК, % | O2: Итоговая стоимость (без НДС) | P2: Итоговая стоимость (с НДС) | Q2: Доля рекламного бюджета, % | S2: Показы | T2: Частота (весь срок) | U2: Охват | V2: CPM (с НДС) | W2: CPT (с НДС) | X2: Доступная емкость аудитории | Y2: SOV, % | AA2: CTR, % | AB2: Клики | AC2: CPC (с НДС) | AE2: CR, % | AF2: Конверсии | AG2: CPA (с НДС) | AI2: CR(I), % | AJ2: Установки | AK2: CPI (с НДС) | AM2: ДРР, % | AN2: Средний чек | AO2: Доход
F3: 01.01.2026 - 31.01.2026 | G3: CPC | I3: =IFERROR(S3*AA3,"-") -> 0 | K3: =IFERROR((H3*I3),"-") -> 0 | M3: =IFERROR(K3*(1-L3),"-") -> 0 | O3: =IFERROR(M3*(1+N3),"-") -> 0 | P3: =IFERROR(O3*1.22,"-") -> 0 | Q3: =IFERROR(P3/$P$13,"-") -> - | U3: - | V3: =IFERROR(P3/S3*1000,"-") -> - | W3: =IFERROR(P3/U3*1000,"-") -> - | Y3: =IFERROR(U3/X3,"-") -> - | AB3: =IFERROR(ROUNDDOWN(S3*AA3,0),"-") -> 0 | AC3: =IFERROR(P3/AB3,"-") -> - | AF3: =IF(G3="CPI",AJ3*AE3,IFERROR(ROUNDDOWN(AB3*AE3,0),"-")) -> 0 | AG3: =IFERROR(P3/AF3,"-") -> - | AJ3: =IF(G3="CPI",I3,0) -> 0 | AK3: =IFERROR(P3/AJ3,"-") -> - | AM3: =IFERROR(P3/AO3,"-") -> - | AO3: =AN3*AF3 -> 0
F4: 01.01.2026 - 31.01.2026 | G4: CPC | I4: =IFERROR(S4*AA4,"-") -> 0 | K4: =IFERROR((H4*I4),"-") -> 0 | M4: =IFERROR(K4*(1-L4),"-") -> 0 | O4: =IFERROR(M4*(1+N4),"-") -> 0 | P4: =IFERROR(O4*1.22,"-") -> 0 | Q4: =IFERROR(P4/$P$13,"-") -> - | U4: - | V4: =IFERROR(P4/S4*1000,"-") -> - | W4: =IFERROR(P4/U4*1000,"-") -> - | Y4: =IFERROR(U4/X4,"-") -> - | AB4: =IFERROR(ROUNDDOWN(S4*AA4,0),"-") -> 0 | AC4: =IFERROR(P4/AB4,"-") -> - | AF4: =IF(G4="CPI",AJ4*AE4,IFERROR(ROUNDDOWN(AB4*AE4,0),"-")) -> 0 | AG4: =IFERROR(P4/AF4,"-") -> - | AJ4: =IF(G4="CPI",I4,0) -> 0 | AK4: =IFERROR(P4/AJ4,"-") -> - | AM4: =IFERROR(P4/AO4,"-") -> - | AO4: =AN4*AF4 -> 0
F5: 01.01.2026 - 31.01.2026 | G5: CPC | I5: =IFERROR(S5*AA5,"-") -> 0 | K5: =IFERROR((H5*I5),"-") -> 0 | M5: =IFERROR(K5*(1-L5),"-") -> 0 | O5: =IFERROR(M5*(1+N5),"-") -> 0 | P5: =IFERROR(O5*1.22,"-") -> 0 | Q5: =IFERROR(P5/$P$13,"-") -> - | U5: - | V5: =IFERROR(P5/S5*1000,"-") -> - | W5: =IFERROR(P5/U5*1000,"-") -> - | Y5: =IFERROR(U5/X5,"-") -> - | AB5: =IFERROR(ROUNDDOWN(S5*AA5,0),"-") -> 0 | AC5: =IFERROR(P5/AB5,"-") -> - | AF5: =IF(G5="CPI",AJ5*AE5,IFERROR(ROUNDDOWN(AB5*AE5,0),"-")) -> 0 | AG5: =IFERROR(P5/AF5,"-") -> - | AJ5: =IF(G5="CPI",I5,0) -> 0 | AK5: =IFERROR(P5/AJ5,"-") -> - | AM5: =IFERROR(P5/AO5,"-") -> - | AO5: =AN5*AF5 -> 0
F6: 01.01.2026 - 31.01.2026 | G6: CPC | I6: =IFERROR(S6*AA6,"-") -> 0 | K6: =IFERROR((H6*I6),"-") -> 0 | M6: =IFERROR(K6*(1-L6),"-") -> 0 | O6: =IFERROR(M6*(1+N6),"-") -> 0 | P6: =IFERROR(O6*1.22,"-") -> 0 | Q6: =IFERROR(P6/$P$13,"-") -> - | U6: - | V6: =IFERROR(P6/S6*1000,"-") -> - | W6: =IFERROR(P6/U6*1000,"-") -> - | Y6: =IFERROR(U6/X6,"-") -> - | AB6: =IFERROR(ROUNDDOWN(S6*AA6,0),"-") -> 0 | AC6: =IFERROR(P6/AB6,"-") -> - | AF6: =IF(G6="CPI",AJ6*AE6,IFERROR(ROUNDDOWN(AB6*AE6,0),"-")) -> 0 | AG6: =IFERROR(P6/AF6,"-") -> - | AJ6: =IF(G6="CPI",I6,0) -> 0 | AK6: =IFERROR(P6/AJ6,"-") -> - | AM6: =IFERROR(P6/AO6,"-") -> - | AO6: =AN6*AF6 -> 0
F7: 01.01.2026 - 31.01.2026 | G7: CPC | I7: =IFERROR(S7*AA7,"-") -> 0 | K7: =IFERROR((H7*I7),"-") -> 0 | M7: =IFERROR(K7*(1-L7),"-") -> 0 | O7: =IFERROR(M7*(1+N7),"-") -> 0 | P7: =IFERROR(O7*1.22,"-") -> 0 | Q7: =IFERROR(P7/$P$13,"-") -> - | U7: - | V7: =IFERROR(P7/S7*1000,"-") -> - | W7: =IFERROR(P7/U7*1000,"-") -> - | Y7: =IFERROR(U7/X7,"-") -> - | AB7: =IFERROR(ROUNDDOWN(S7*AA7,0),"-") -> 0 | AC7: =IFERROR(P7/AB7,"-") -> - | AF7: =IF(G7="CPI",AJ7*AE7,IFERROR(ROUNDDOWN(AB7*AE7,0),"-")) -> 0 | AG7: =IFERROR(P7/AF7,"-") -> - | AJ7: =IF(G7="CPI",I7,0) -> 0 | AK7: =IFERROR(P7/AJ7,"-") -> - | AM7: =IFERROR(P7/AO7,"-") -> - | AO7: =AN7*AF7 -> 0
F8: 01.01.2026 - 31.01.2026 | G8: CPC | I8: =IFERROR(S8*AA8,"-") -> 0 | K8: =IFERROR((H8*I8),"-") -> 0 | M8: =IFERROR(K8*(1-L8),"-") -> 0 | O8: =IFERROR(M8*(1+N8),"-") -> 0 | P8: =IFERROR(O8*1.22,"-") -> 0 | Q8: =IFERROR(P8/$P$13,"-") -> - | U8: - | V8: =IFERROR(P8/S8*1000,"-") -> - | W8: =IFERROR(P8/U8*1000,"-") -> - | Y8: =IFERROR(U8/X8,"-") -> - | AB8: =IFERROR(ROUNDDOWN(S8*AA8,0),"-") -> 0 | AC8: =IFERROR(P8/AB8,"-") -> - | AF8: =IF(G8="CPI",AJ8*AE8,IFERROR(ROUNDDOWN(AB8*AE8,0),"-")) -> 0 | AG8: =IFERROR(P8/AF8,"-") -> - | AJ8: =IF(G8="CPI",I8,0) -> 0 | AK8: =IFERROR(P8/AJ8,"-") -> - | AM8: =IFERROR(P8/AO8,"-") -> - | AO8: =AN8*AF8 -> 0
F9: 01.01.2026 - 31.01.2026 | G9: CPC | I9: =IFERROR(S9*AA9,"-") -> 0 | K9: =IFERROR((H9*I9),"-") -> 0 | M9: =IFERROR(K9*(1-L9),"-") -> 0 | O9: =IFERROR(M9*(1+N9),"-") -> 0 | P9: =IFERROR(O9*1.22,"-") -> 0 | Q9: =IFERROR(P9/$P$13,"-") -> - | U9: - | V9: =IFERROR(P9/S9*1000,"-") -> - | W9: =IFERROR(P9/U9*1000,"-") -> - | Y9: =IFERROR(U9/X9,"-") -> - | AB9: =IFERROR(ROUNDDOWN(S9*AA9,0),"-") -> 0 | AC9: =IFERROR(P9/AB9,"-") -> - | AF9: =IF(G9="CPI",AJ9*AE9,IFERROR(ROUNDDOWN(AB9*AE9,0),"-")) -> 0 | AG9: =IFERROR(P9/AF9,"-") -> - | AJ9: =IF(G9="CPI",I9,0) -> 0 | AK9: =IFERROR(P9/AJ9,"-") -> - | AM9: =IFERROR(P9/AO9,"-") -> - | AO9: =AN9*AF9 -> 0
F10: 01.01.2026 - 31.01.2026 | G10: CPC | I10: =IFERROR(S10*AA10,"-") -> 0 | K10: =IFERROR((H10*I10),"-") -> 0 | M10: =IFERROR(K10*(1-L10),"-") -> 0 | O10: =IFERROR(M10*(1+N10),"-") -> 0 | P10: =IFERROR(O10*1.22,"-") -> 0 | Q10: =IFERROR(P10/$P$13,"-") -> - | U10: - | V10: =IFERROR(P10/S10*1000,"-") -> - | W10: =IFERROR(P10/U10*1000,"-") -> - | Y10: =IFERROR(U10/X10,"-") -> - | AB10: =IFERROR(ROUNDDOWN(S10*AA10,0),"-") -> 0 | AC10: =IFERROR(P10/AB10,"-") -> - | AF10: =IF(G10="CPI",AJ10*AE10,IFERROR(ROUNDDOWN(AB10*AE10,0),"-")) -> 0 | AG10: =IFERROR(P10/AF10,"-") -> - | AJ10: =IF(G10="CPI",I10,0) -> 0 | AK10: =IFERROR(P10/AJ10,"-") -> - | AM10: =IFERROR(P10/AO10,"-") -> - | AO10: =AN10*AF10 -> 0
F11: 01.01.2026 - 31.01.2026 | G11: CPC | I11: =IFERROR(S11*AA11,"-") -> 0 | K11: =IFERROR((H11*I11),"-") -> 0 | M11: =IFERROR(K11*(1-L11),"-") -> 0 | O11: =IFERROR(M11*(1+N11),"-") -> 0 | P11: =IFERROR(O11*1.22,"-") -> 0 | Q11: =IFERROR(P11/$P$13,"-") -> - | U11: - | V11: =IFERROR(P11/S11*1000,"-") -> - | W11: =IFERROR(P11/U11*1000,"-") -> - | Y11: =IFERROR(U11/X11,"-") -> - | AB11: =IFERROR(ROUNDDOWN(S11*AA11,0),"-") -> 0 | AC11: =IFERROR(P11/AB11,"-") -> - | AF11: =IF(G11="CPI",AJ11*AE11,IFERROR(ROUNDDOWN(AB11*AE11,0),"-")) -> 0 | AG11: =IFERROR(P11/AF11,"-") -> - | AJ11: =IF(G11="CPI",I11,0) -> 0 | AK11: =IFERROR(P11/AJ11,"-") -> - | AM11: =IFERROR(P11/AO11,"-") -> - | AO11: =AN11*AF11 -> 0
F12: 01.01.2026 - 31.01.2026 | G12: CPC | I12: =IFERROR(S12*AA12,"-") -> 0 | K12: =IFERROR((H12*I12),"-") -> 0 | M12: =IFERROR(K12*(1-L12),"-") -> 0 | O12: =IFERROR(M12*(1+N12),"-") -> 0 | P12: =IFERROR(O12*1.22,"-") -> 0 | Q12: =IFERROR(P12/$P$13,"-") -> - | U12: - | V12: =IFERROR(P12/S12*1000,"-") -> - | W12: =IFERROR(P12/U12*1000,"-") -> - | Y12: =IFERROR(U12/X12,"-") -> - | AB12: =IFERROR(ROUNDDOWN(S12*AA12,0),"-") -> 0 | AC12: =IFERROR(P12/AB12,"-") -> - | AF12: =IF(G12="CPI",AJ12*AE12,IFERROR(ROUNDDOWN(AB12*AE12,0),"-")) -> 0 | AG12: =IFERROR(P12/AF12,"-") -> - | AJ12: =IF(G12="CPI",I12,0) -> 0 | AK12: =IFERROR(P12/AJ12,"-") -> - | AM12: =IFERROR(P12/AO12,"-") -> - | AO12: =AN12*AF12 -> 0
B13: Итого | C13: - | D13: - | F13: - | G13: - | H13: =IFERROR(K13/I13,"-") -> - | I13: =IFERROR(SUM(I3:I12),"-") -> 0 | K13: =IFERROR(SUM(K3:K12),"-") -> 0 | L13: - | M13: =IFERROR(SUM(M3:M12),"-") -> 0 | N13: - | O13: =IFERROR(SUM(O3:O12),"-") -> 0 | P13: =IFERROR(O13*1.22,"-") -> 0 | Q13: 0 | S13: =IFERROR(SUM(S3:S12),"-") -> 0 | T13: - | U13: - | V13: =IFERROR(P13/S13*1000,"-") -> - | W13: =IFERROR(P13/U13*1000,"-") -> - | X13: - | Y13: - | AA13: =IFERROR(AB13/S13,"-") -> - | AB13: =IFERROR(SUM(AB3:AB12),"-") -> 0 | AC13: =IFERROR(P13/AB13,"-") -> - | AE13: =IFERROR(AF13/AB13,"-") -> - | AF13: =IFERROR(SUM(AF3:AF12),"-") -> 0 | AG13: =IFERROR(P13/AF13,"-") -> - | AI13: =IFERROR(AJ13/AB13,"-") -> - | AJ13: 0 | AK13: =IFERROR(L13/AJ13,"-") -> - | AM13: =IFERROR(P13/AO13,"-") -> - | AN13: =IFERROR(AO13/AF13,"-") -> - | AO13: =IFERROR(SUM(AO3:AO12),"-") -> 0
B15: Рекламная система | C15: Рекламный формат, размер, вид размещения | D15: Таргетинги | F15: Период | G15: Единица измерения стоимости | H15: Цена за единицу (без НДС) | I15: Кол-во единиц | K15: Стоимость (без НДС) | L15: СК, % | M15: Стоимость с учетом СК (без НДС) | N15: АК, % | O15: Итоговая стоимость (без НДС) | P15: Итоговая стоимость (с НДС) | Q15: Доля рекламного бюджета, % | S15: Показы | T15: Частота (весь срок) | U15: Охват | V15: CPM (с НДС) | W15: CPT (с НДС) | X15: Доступная емкость аудитории | Y15: SOV, % | AA15: CTR, % | AB15: Клики | AC15: CPC (с НДС) | AE15: CR, % | AF15: Конверсии | AG15: CPA (с НДС) | AI15: CR(I), % | AJ15: Установки | AK15: CPI | AM15: ДРР, % | AN15: Средний чек | AO15: Доход
F16: 01.02.2026 - 28.02.2026 | G16: CPC | I16: =IFERROR(S16*AA16,"-") -> 0 | K16: =IFERROR((H16*I16),"-") -> 0 | M16: =IFERROR(K16*(1-L16),"-") -> 0 | O16: =IFERROR(M16*(1+N16),"-") -> 0 | P16: =IFERROR(O16*1.22,"-") -> 0 | Q16: =IFERROR(P16/$P$13,"-") -> - | U16: - | V16: =IFERROR(P16/S16*1000,"-") -> - | W16: =IFERROR(P16/U16*1000,"-") -> - | Y16: =IFERROR(U16/X16,"-") -> - | AB16: =IFERROR(ROUNDDOWN(S16*AA16,0),"-") -> 0 | AC16: =IFERROR(P16/AB16,"-") -> - | AF16: =IF(G16="CPI",AJ16*AE16,IFERROR(ROUNDDOWN(AB16*AE16,0),"-")) -> 0 | AG16: =IFERROR(P16/AF16,"-") -> - | AJ16: =IF(G16="CPI",I16,0) -> 0 | AK16: =IFERROR(P16/AJ16,"-") -> - | AM16: =IFERROR(P16/AO16,"-") -> - | AO16: =AN16*AF16 -> 0
F17: 01.02.2026 - 28.02.2026 | G17: CPC | I17: =IFERROR(S17*AA17,"-") -> 0 | K17: =IFERROR((H17*I17),"-") -> 0 | M17: =IFERROR(K17*(1-L17),"-") -> 0 | O17: =IFERROR(M17*(1+N17),"-") -> 0 | P17: =IFERROR(O17*1.22,"-") -> 0 | Q17: =IFERROR(P17/$P$13,"-") -> - | U17: 0 | V17: =IFERROR(P17/S17*1000,"-") -> - | W17: =IFERROR(P17/U17*1000,"-") -> - | Y17: =IFERROR(U17/X17,"-") -> - | AB17: =IFERROR(ROUNDDOWN(S17*AA17,0),"-") -> 0 | AC17: =IFERROR(P17/AB17,"-") -> - | AF17: =IF(G17="CPI",AJ17*AE17,IFERROR(ROUNDDOWN(AB17*AE17,0),"-")) -> 0 | AG17: =IFERROR(P17/AF17,"-") -> - | AJ17: =IF(G17="CPI",I17,0) -> 0 | AK17: =IFERROR(P17/AJ17,"-") -> - | AM17: =IFERROR(P17/AO17,"-") -> - | AO17: =AN17*AF17 -> 0
F18: 01.02.2026 - 28.02.2026 | G18: CPC | I18: =IFERROR(S18*AA18,"-") -> 0 | K18: =IFERROR((H18*I18),"-") -> 0 | M18: =IFERROR(K18*(1-L18),"-") -> 0 | O18: =IFERROR(M18*(1+N18),"-") -> 0 | P18: =IFERROR(O18*1.22,"-") -> 0 | Q18: =IFERROR(P18/$P$13,"-") -> - | U18: 0 | V18: =IFERROR(P18/S18*1000,"-") -> - | W18: =IFERROR(P18/U18*1000,"-") -> - | Y18: =IFERROR(U18/X18,"-") -> - | AB18: =IFERROR(ROUNDDOWN(S18*AA18,0),"-") -> 0 | AC18: =IFERROR(P18/AB18,"-") -> - | AF18: =IF(G18="CPI",AJ18*AE18,IFERROR(ROUNDDOWN(AB18*AE18,0),"-")) -> 0 | AG18: =IFERROR(P18/AF18,"-") -> - | AJ18: =IF(G18="CPI",I18,0) -> 0 | AK18: =IFERROR(P18/AJ18,"-") -> - | AM18: =IFERROR(P18/AO18,"-") -> - | AO18: =AN18*AF18 -> 0
F19: 01.02.2026 - 28.02.2026 | G19: CPC | I19: =IFERROR(S19*AA19,"-") -> 0 | K19: =IFERROR((H19*I19),"-") -> 0 | M19: =IFERROR(K19*(1-L19),"-") -> 0 | O19: =IFERROR(M19*(1+N19),"-") -> 0 | P19: =IFERROR(O19*1.22,"-") -> 0 | Q19: =IFERROR(P19/$P$13,"-") -> - | U19: 0 | V19: =IFERROR(P19/S19*1000,"-") -> - | W19: =IFERROR(P19/U19*1000,"-") -> - | Y19: =IFERROR(U19/X19,"-") -> - | AB19: =IFERROR(ROUNDDOWN(S19*AA19,0),"-") -> 0 | AC19: =IFERROR(P19/AB19,"-") -> - | AF19: =IF(G19="CPI",AJ19*AE19,IFERROR(ROUNDDOWN(AB19*AE19,0),"-")) -> 0 | AG19: =IFERROR(P19/AF19,"-") -> - | AJ19: =IF(G19="CPI",I19,0) -> 0 | AK19: =IFERROR(P19/AJ19,"-") -> - | AM19: =IFERROR(P19/AO19,"-") -> - | AO19: =AN19*AF19 -> 0
F20: 01.02.2026 - 28.02.2026 | G20: CPC | I20: =IFERROR(S20*AA20,"-") -> 0 | K20: =IFERROR((H20*I20),"-") -> 0 | M20: =IFERROR(K20*(1-L20),"-") -> 0 | O20: =IFERROR(M20*(1+N20),"-") -> 0 | P20: =IFERROR(O20*1.22,"-") -> 0 | Q20: =IFERROR(P20/$P$13,"-") -> - | U20: 0 | V20: =IFERROR(P20/S20*1000,"-") -> - | W20: =IFERROR(P20/U20*1000,"-") -> - | Y20: =IFERROR(U20/X20,"-") -> - | AB20: =IFERROR(ROUNDDOWN(S20*AA20,0),"-") -> 0 | AC20: =IFERROR(P20/AB20,"-") -> - | AF20: =IF(G20="CPI",AJ20*AE20,IFERROR(ROUNDDOWN(AB20*AE20,0),"-")) -> 0 | AG20: =IFERROR(P20/AF20,"-") -> - | AJ20: =IF(G20="CPI",I20,0) -> 0 | AK20: =IFERROR(P20/AJ20,"-") -> - | AM20: =IFERROR(P20/AO20,"-") -> - | AO20: =AN20*AF20 -> 0
F21: 01.02.2026 - 28.02.2026 | G21: CPC | I21: =IFERROR(S21*AA21,"-") -> 0 | K21: =IFERROR((H21*I21),"-") -> 0 | M21: =IFERROR(K21*(1-L21),"-") -> 0 | O21: =IFERROR(M21*(1+N21),"-") -> 0 | P21: =IFERROR(O21*1.22,"-") -> 0 | Q21: =IFERROR(P21/$P$13,"-") -> - | U21: 0 | V21: =IFERROR(P21/S21*1000,"-") -> - | W21: =IFERROR(P21/U21*1000,"-") -> - | Y21: =IFERROR(U21/X21,"-") -> - | AB21: =IFERROR(ROUNDDOWN(S21*AA21,0),"-") -> 0 | AC21: =IFERROR(P21/AB21,"-") -> - | AF21: =IF(G21="CPI",AJ21*AE21,IFERROR(ROUNDDOWN(AB21*AE21,0),"-")) -> 0 | AG21: =IFERROR(P21/AF21,"-") -> - | AJ21: =IF(G21="CPI",I21,0) -> 0 | AK21: =IFERROR(P21/AJ21,"-") -> - | AM21: =IFERROR(P21/AO21,"-") -> - | AO21: =AN21*AF21 -> 0
F22: 01.02.2026 - 28.02.2026 | G22: CPC | I22: =IFERROR(S22*AA22,"-") -> 0 | K22: =IFERROR((H22*I22),"-") -> 0 | M22: =IFERROR(K22*(1-L22),"-") -> 0 | O22: =IFERROR(M22*(1+N22),"-") -> 0 | P22: =IFERROR(O22*1.22,"-") -> 0 | Q22: =IFERROR(P22/$P$13,"-") -> - | U22: 0 | V22: =IFERROR(P22/S22*1000,"-") -> - | W22: =IFERROR(P22/U22*1000,"-") -> - | Y22: =IFERROR(U22/X22,"-") -> - | AB22: =IFERROR(ROUNDDOWN(S22*AA22,0),"-") -> 0 | AC22: =IFERROR(P22/AB22,"-") -> - | AF22: =IF(G22="CPI",AJ22*AE22,IFERROR(ROUNDDOWN(AB22*AE22,0),"-")) -> 0 | AG22: =IFERROR(P22/AF22,"-") -> - | AJ22: =IF(G22="CPI",I22,0) -> 0 | AK22: =IFERROR(P22/AJ22,"-") -> - | AM22: =IFERROR(P22/AO22,"-") -> - | AO22: =AN22*AF22 -> 0
F23: 01.02.2026 - 28.02.2026 | G23: CPC | I23: =IFERROR(S23*AA23,"-") -> 0 | K23: =IFERROR((H23*I23),"-") -> 0 | M23: =IFERROR(K23*(1-L23),"-") -> 0 | O23: =IFERROR(M23*(1+N23),"-") -> 0 | P23: =IFERROR(O23*1.22,"-") -> 0 | Q23: =IFERROR(P23/$P$13,"-") -> - | U23: - | V23: =IFERROR(P23/S23*1000,"-") -> - | W23: =IFERROR(P23/U23*1000,"-") -> - | Y23: =IFERROR(U23/X23,"-") -> - | AB23: =IFERROR(ROUNDDOWN(S23*AA23,0),"-") -> 0 | AC23: =IFERROR(P23/AB23,"-") -> - | AF23: =IF(G23="CPI",AJ23*AE23,IFERROR(ROUNDDOWN(AB23*AE23,0),"-")) -> 0 | AG23: =IFERROR(P23/AF23,"-") -> - | AJ23: =IF(G23="CPI",I23,0) -> 0 | AK23: =IFERROR(P23/AJ23,"-") -> - | AM23: =IFERROR(P23/AO23,"-") -> - | AO23: =AN23*AF23 -> 0
F24: 01.02.2026 - 28.02.2026 | G24: CPC | I24: =IFERROR(S24*AA24,"-") -> 0 | K24: =IFERROR((H24*I24),"-") -> 0 | M24: =IFERROR(K24*(1-L24),"-") -> 0 | O24: =IFERROR(M24*(1+N24),"-") -> 0 | P24: =IFERROR(O24*1.22,"-") -> 0 | Q24: =IFERROR(P24/$P$13,"-") -> - | U24: - | V24: =IFERROR(P24/S24*1000,"-") -> - | W24: =IFERROR(P24/U24*1000,"-") -> - | Y24: =IFERROR(U24/X24,"-") -> - | AB24: =IFERROR(ROUNDDOWN(S24*AA24,0),"-") -> 0 | AC24: =IFERROR(P24/AB24,"-") -> - | AF24: =IF(G24="CPI",AJ24*AE24,IFERROR(ROUNDDOWN(AB24*AE24,0),"-")) -> 0 | AG24: =IFERROR(P24/AF24,"-") -> - | AJ24: =IF(G24="CPI",I24,0) -> 0 | AK24: =IFERROR(P24/AJ24,"-") -> - | AM24: =IFERROR(P24/AO24,"-") -> - | AO24: =AN24*AF24 -> 0
F25: 01.02.2026 - 28.02.2026 | G25: CPC | I25: =IFERROR(S25*AA25,"-") -> 0 | K25: =IFERROR((H25*I25),"-") -> 0 | M25: =IFERROR(K25*(1-L25),"-") -> 0 | O25: =IFERROR(M25*(1+N25),"-") -> 0 | P25: =IFERROR(O25*1.22,"-") -> 0 | Q25: =IFERROR(P25/$P$13,"-") -> - | U25: - | V25: =IFERROR(P25/S25*1000,"-") -> - | W25: =IFERROR(P25/U25*1000,"-") -> - | Y25: =IFERROR(U25/X25,"-") -> - | AB25: =IFERROR(ROUNDDOWN(S25*AA25,0),"-") -> 0 | AC25: =IFERROR(P25/AB25,"-") -> - | AF25: =IF(G25="CPI",AJ25*AE25,IFERROR(ROUNDDOWN(AB25*AE25,0),"-")) -> 0 | AG25: =IFERROR(P25/AF25,"-") -> - | AJ25: =IF(G25="CPI",I25,0) -> 0 | AK25: =IFERROR(P25/AJ25,"-") -> - | AM25: =IFERROR(P25/AO25,"-") -> - | AO25: =AN25*AF25 -> 0
B26: Итого | C26: - | D26: - | F26: - | G26: - | H26: =IFERROR(K26/I26,"-") -> - | I26: =IFERROR(SUM(I16:I25),"-") -> 0 | K26: =IFERROR(SUM(K16:K25),"-") -> 0 | L26: - | M26: =IFERROR(SUM(M16:M25),"-") -> 0 | N26: - | O26: =IFERROR(SUM(O16:O25),"-") -> 0 | P26: =IFERROR(O26*1.22,"-") -> 0 | Q26: 0 | S26: =IFERROR(SUM(S16:S25),"-") -> 0 | T26: - | U26: - | V26: =IFERROR(P26/S26*1000,"-") -> - | W26: =IFERROR(P26/U26*1000,"-") -> - | X26: - | Y26: - | AA26: =IFERROR(AB26/S26,"-") -> - | AB26: =IFERROR(SUM(AB16:AB25),"-") -> 0 | AC26: =IFERROR(P26/AB26,"-") -> - | AE26: =IFERROR(AF26/AB26,"-") -> - | AF26: =IFERROR(SUM(AF16:AF25),"-") -> 0 | AG26: =IFERROR(P26/AF26,"-") -> - | AI26: =IFERROR(AJ26/AB26,"-") -> - | AJ26: 0 | AK26: =IFERROR(L26/AJ26,"-") -> - | AM26: =IFERROR(P26/AO26,"-") -> - | AN26: =IFERROR(AO26/AF26,"-") -> - | AO26: =IFERROR(SUM(AO16:AO25),"-") -> 0
B28: Рекламная система | C28: Рекламный формат, размер, вид размещения | D28: Таргетинги | F28: Период | G28: Единица измерения стоимости | H28: Цена за единицу (без НДС) | I28: Кол-во единиц | K28: Стоимость (без НДС) | L28: СК, % | M28: Стоимость с учетом СК (без НДС) | N28: АК, % | O28: Итоговая стоимость (без НДС) | P28: Итоговая стоимость (с НДС) | Q28: Доля рекламного бюджета, % | S28: Показы | T28: Частота (весь срок) | U28: Охват | V28: CPM (с НДС) | W28: CPT (с НДС) | X28: Доступная емкость аудитории | Y28: SOV, % | AA28: CTR, % | AB28: Клики | AC28: CPC (с НДС) | AE28: CR, % | AF28: Конверсии | AG28: CPA (с НДС) | AI28: CR(I), % | AJ28: Установки | AK28: CPI | AM28: ДРР, % | AN28: Средний чек | AO28: Доход
F29: 01.03.2026 - 31.03.2026 | G29: CPC | I29: =IFERROR(S29*AA29,"-") -> 0 | K29: =IFERROR((H29*I29),"-") -> 0 | M29: =IFERROR(K29*(1-L29),"-") -> 0 | O29: =IFERROR(M29*(1+N29),"-") -> 0 | P29: =IFERROR(O29*1.22,"-") -> 0 | Q29: =IFERROR(P29/$P$13,"-") -> - | U29: - | V29: =IFERROR(P29/S29*1000,"-") -> - | W29: =IFERROR(P29/U29*1000,"-") -> - | Y29: =IFERROR(U29/X29,"-") -> - | AB29: =IFERROR(ROUNDDOWN(S29*AA29,0),"-") -> 0 | AC29: =IFERROR(P29/AB29,"-") -> - | AF29: =IF(G29="CPI",AJ29*AE29,IFERROR(ROUNDDOWN(AB29*AE29,0),"-")) -> 0 | AG29: =IFERROR(P29/AF29,"-") -> - | AJ29: =IF(G29="CPI",I29,0) -> 0 | AK29: =IFERROR(P29/AJ29,"-") -> - | AM29: =IFERROR(P29/AO29,"-") -> - | AO29: =AN29*AF29 -> 0
F30: 01.03.2026 - 31.03.2026 | G30: CPC | I30: =IFERROR(S30*AA30,"-") -> 0 | K30: =IFERROR((H30*I30),"-") -> 0 | M30: =IFERROR(K30*(1-L30),"-") -> 0 | O30: =IFERROR(M30*(1+N30),"-") -> 0 | P30: =IFERROR(O30*1.22,"-") -> 0 | Q30: =IFERROR(P30/$P$13,"-") -> - | U30: - | V30: =IFERROR(P30/S30*1000,"-") -> - | W30: =IFERROR(P30/U30*1000,"-") -> - | Y30: =IFERROR(U30/X30,"-") -> - | AB30: =IFERROR(ROUNDDOWN(S30*AA30,0),"-") -> 0 | AC30: =IFERROR(P30/AB30,"-") -> - | AF30: =IF(G30="CPI",AJ30*AE30,IFERROR(ROUNDDOWN(AB30*AE30,0),"-")) -> 0 | AG30: =IFERROR(P30/AF30,"-") -> - | AJ30: =IF(G30="CPI",I30,0) -> 0 | AK30: =IFERROR(P30/AJ30,"-") -> - | AM30: =IFERROR(P30/AO30,"-") -> - | AO30: =AN30*AF30 -> 0
F31: 01.03.2026 - 31.03.2026 | G31: CPC | I31: =IFERROR(S31*AA31,"-") -> 0 | K31: =IFERROR((H31*I31),"-") -> 0 | M31: =IFERROR(K31*(1-L31),"-") -> 0 | O31: =IFERROR(M31*(1+N31),"-") -> 0 | P31: =IFERROR(O31*1.22,"-") -> 0 | Q31: =IFERROR(P31/$P$13,"-") -> - | U31: - | V31: =IFERROR(P31/S31*1000,"-") -> - | W31: =IFERROR(P31/U31*1000,"-") -> - | Y31: =IFERROR(U31/X31,"-") -> - | AB31: =IFERROR(ROUNDDOWN(S31*AA31,0),"-") -> 0 | AC31: =IFERROR(P31/AB31,"-") -> - | AF31: =IF(G31="CPI",AJ31*AE31,IFERROR(ROUNDDOWN(AB31*AE31,0),"-")) -> 0 | AG31: =IFERROR(P31/AF31,"-") -> - | AJ31: =IF(G31="CPI",I31,0) -> 0 | AK31: =IFERROR(P31/AJ31,"-") -> - | AM31: =IFERROR(P31/AO31,"-") -> - | AO31: =AN31*AF31 -> 0
F32: 01.03.2026 - 31.03.2026 | G32: CPC | I32: =IFERROR(S32*AA32,"-") -> 0 | K32: =IFERROR((H32*I32),"-") -> 0 | M32: =IFERROR(K32*(1-L32),"-") -> 0 | O32: =IFERROR(M32*(1+N32),"-") -> 0 | P32: =IFERROR(O32*1.22,"-") -> 0 | Q32: =IFERROR(P32/$P$13,"-") -> - | U32: - | V32: =IFERROR(P32/S32*1000,"-") -> - | W32: =IFERROR(P32/U32*1000,"-") -> - | Y32: =IFERROR(U32/X32,"-") -> - | AB32: =IFERROR(ROUNDDOWN(S32*AA32,0),"-") -> 0 | AC32: =IFERROR(P32/AB32,"-") -> - | AF32: =IF(G32="CPI",AJ32*AE32,IFERROR(ROUNDDOWN(AB32*AE32,0),"-")) -> 0 | AG32: =IFERROR(P32/AF32,"-") -> - | AJ32: =IF(G32="CPI",I32,0) -> 0 | AK32: =IFERROR(P32/AJ32,"-") -> - | AM32: =IFERROR(P32/AO32,"-") -> - | AO32: =AN32*AF32 -> 0
F33: 01.03.2026 - 31.03.2026 | G33: CPC | I33: =IFERROR(S33*AA33,"-") -> 0 | K33: =IFERROR((H33*I33),"-") -> 0 | M33: =IFERROR(K33*(1-L33),"-") -> 0 | O33: =IFERROR(M33*(1+N33),"-") -> 0 | P33: =IFERROR(O33*1.22,"-") -> 0 | Q33: =IFERROR(P33/$P$13,"-") -> - | U33: - | V33: =IFERROR(P33/S33*1000,"-") -> - | W33: =IFERROR(P33/U33*1000,"-") -> - | Y33: =IFERROR(U33/X33,"-") -> - | AB33: =IFERROR(ROUNDDOWN(S33*AA33,0),"-") -> 0 | AC33: =IFERROR(P33/AB33,"-") -> - | AF33: =IF(G33="CPI",AJ33*AE33,IFERROR(ROUNDDOWN(AB33*AE33,0),"-")) -> 0 | AG33: =IFERROR(P33/AF33,"-") -> - | AJ33: =IF(G33="CPI",I33,0) -> 0 | AK33: =IFERROR(P33/AJ33,"-") -> - | AM33: =IFERROR(P33/AO33,"-") -> - | AO33: =AN33*AF33 -> 0
F34: 01.03.2026 - 31.03.2026 | G34: CPC | I34: =IFERROR(S34*AA34,"-") -> 0 | K34: =IFERROR((H34*I34),"-") -> 0 | M34: =IFERROR(K34*(1-L34),"-") -> 0 | O34: =IFERROR(M34*(1+N34),"-") -> 0 | P34: =IFERROR(O34*1.22,"-") -> 0 | Q34: =IFERROR(P34/$P$13,"-") -> - | U34: - | V34: =IFERROR(P34/S34*1000,"-") -> - | W34: =IFERROR(P34/U34*1000,"-") -> - | Y34: =IFERROR(U34/X34,"-") -> - | AB34: =IFERROR(ROUNDDOWN(S34*AA34,0),"-") -> 0 | AC34: =IFERROR(P34/AB34,"-") -> - | AF34: =IF(G34="CPI",AJ34*AE34,IFERROR(ROUNDDOWN(AB34*AE34,0),"-")) -> 0 | AG34: =IFERROR(P34/AF34,"-") -> - | AJ34: =IF(G34="CPI",I34,0) -> 0 | AK34: =IFERROR(P34/AJ34,"-") -> - | AM34: =IFERROR(P34/AO34,"-") -> - | AO34: =AN34*AF34 -> 0
F35: 01.03.2026 - 31.03.2026 | G35: CPC | I35: =IFERROR(S35*AA35,"-") -> 0 | K35: =IFERROR((H35*I35),"-") -> 0 | M35: =IFERROR(K35*(1-L35),"-") -> 0 | O35: =IFERROR(M35*(1+N35),"-") -> 0 | P35: =IFERROR(O35*1.22,"-") -> 0 | Q35: =IFERROR(P35/$P$13,"-") -> - | U35: - | V35: =IFERROR(P35/S35*1000,"-") -> - | W35: =IFERROR(P35/U35*1000,"-") -> - | Y35: =IFERROR(U35/X35,"-") -> - | AB35: =IFERROR(ROUNDDOWN(S35*AA35,0),"-") -> 0 | AC35: =IFERROR(P35/AB35,"-") -> - | AF35: =IF(G35="CPI",AJ35*AE35,IFERROR(ROUNDDOWN(AB35*AE35,0),"-")) -> 0 | AG35: =IFERROR(P35/AF35,"-") -> - | AJ35: =IF(G35="CPI",I35,0) -> 0 | AK35: =IFERROR(P35/AJ35,"-") -> - | AM35: =IFERROR(P35/AO35,"-") -> - | AO35: =AN35*AF35 -> 0
F36: 01.03.2026 - 31.03.2026 | G36: CPC | I36: =IFERROR(S36*AA36,"-") -> 0 | K36: =IFERROR((H36*I36),"-") -> 0 | M36: =IFERROR(K36*(1-L36),"-") -> 0 | O36: =IFERROR(M36*(1+N36),"-") -> 0 | P36: =IFERROR(O36*1.22,"-") -> 0 | Q36: =IFERROR(P36/$P$13,"-") -> - | U36: - | V36: =IFERROR(P36/S36*1000,"-") -> - | W36: =IFERROR(P36/U36*1000,"-") -> - | Y36: =IFERROR(U36/X36,"-") -> - | AB36: =IFERROR(ROUNDDOWN(S36*AA36,0),"-") -> 0 | AC36: =IFERROR(P36/AB36,"-") -> - | AF36: =IF(G36="CPI",AJ36*AE36,IFERROR(ROUNDDOWN(AB36*AE36,0),"-")) -> 0 | AG36: =IFERROR(P36/AF36,"-") -> - | AJ36: =IF(G36="CPI",I36,0) -> 0 | AK36: =IFERROR(P36/AJ36,"-") -> - | AM36: =IFERROR(P36/AO36,"-") -> - | AO36: =AN36*AF36 -> 0
F37: 01.03.2026 - 31.03.2026 | G37: CPC | I37: =IFERROR(S37*AA37,"-") -> 0 | K37: =IFERROR((H37*I37),"-") -> 0 | M37: =IFERROR(K37*(1-L37),"-") -> 0 | O37: =IFERROR(M37*(1+N37),"-") -> 0 | P37: =IFERROR(O37*1.22,"-") -> 0 | Q37: =IFERROR(P37/$P$13,"-") -> - | U37: - | V37: =IFERROR(P37/S37*1000,"-") -> - | W37: =IFERROR(P37/U37*1000,"-") -> - | Y37: =IFERROR(U37/X37,"-") -> - | AB37: =IFERROR(ROUNDDOWN(S37*AA37,0),"-") -> 0 | AC37: =IFERROR(P37/AB37,"-") -> - | AF37: =IF(G37="CPI",AJ37*AE37,IFERROR(ROUNDDOWN(AB37*AE37,0),"-")) -> 0 | AG37: =IFERROR(P37/AF37,"-") -> - | AJ37: =IF(G37="CPI",I37,0) -> 0 | AK37: =IFERROR(P37/AJ37,"-") -> - | AM37: =IFERROR(P37/AO37,"-") -> - | AO37: =AN37*AF37 -> 0
F38: 01.03.2026 - 31.03.2026 | G38: CPC | I38: =IFERROR(S38*AA38,"-") -> 0 | K38: =IFERROR((H38*I38),"-") -> 0 | M38: =IFERROR(K38*(1-L38),"-") -> 0 | O38: =IFERROR(M38*(1+N38),"-") -> 0 | P38: =IFERROR(O38*1.22,"-") -> 0 | Q38: =IFERROR(P38/$P$13,"-") -> - | U38: - | V38: =IFERROR(P38/S38*1000,"-") -> - | W38: =IFERROR(P38/U38*1000,"-") -> - | Y38: =IFERROR(U38/X38,"-") -> - | AB38: =IFERROR(ROUNDDOWN(S38*AA38,0),"-") -> 0 | AC38: =IFERROR(P38/AB38,"-") -> - | AF38: =IF(G38="CPI",AJ38*AE38,IFERROR(ROUNDDOWN(AB38*AE38,0),"-")) -> 0 | AG38: =IFERROR(P38/AF38,"-") -> - | AJ38: =IF(G38="CPI",I38,0) -> 0 | AK38: =IFERROR(P38/AJ38,"-") -> - | AM38: =IFERROR(P38/AO38,"-") -> - | AO38: =AN38*AF38 -> 0
