Workbook

Sheet МП_Total
B2: Рекламная система | C2: Рекламный формат, размер, вид размещения | D2: Таргетинги | E2: ГЕО | F2: Январь | G2: Февраль | H2: Март | I2: Апрель | J2: Май | K2: Июнь | L2: Июль | M2: Август | N2: Сентябрь | O2: Октябрь | P2: Ноябрь | Q2: Декабрь | S2: Модель закупки | T2: Цена за единицу (без НДС) | U2: Кол-во единиц закупки | W2: Стоимость (без НДС) | X2: СК, % | Y2: Тотал бюджет, руб. без НДС и АК | Z2: АК, % | AA2: АК, руб. (без НДС) | AB2: Тотал бюджет, руб. без НДС и с учетом АК | AC2: Тотал бюджет руб. с учетом НДС и АК | AD2: НДС руб. | AE2: Доля рекламного бюджета, % | AG2: Кол-во показов | AH2: Частота (весь срок) | AI2: Доля новых клиентов, % | AJ2: Кол-во клиентов | AK2: Кол-во абсолютно новых клиентов (ранее не заказывали) | AL2: Кол-во вернувшихся клиентов (не заказывали более 12 мес) | AM2: Кол-во новых клиентов (абсолютно новые + вернувшиеся) | AN2: Частота заказа | AO2: САС, руб. | AP2: Доступная емкость аудитории | AQ2: SOV, % | AS2: CTR, % | AT2: Клики | AU2: CPC (с НДС) | AW2: CR, % | AX2: Кол-во оформленных заказов | AY2: Стоимость оформл. заказа, руб. с НДС | AZ2: Доля заказов, % | BB2: ROAS офомл. (Доход/Бюджет) | BC2: ДРР от оформл. дохода, % | BD2: Средний чек по оформл. доходу, с НДС | BE2: Оформленный доход, руб. с НДС | BF2: Доля выручки, % | BH2: CR2, % | BI2: Кол-во отгруженных заказов | BJ2: Стоимость отгр. заказа, руб. с НДС | BK2: Доля заказов, % | BM2: ROAS отгр. (Выручка/Бюджет) | BN2: ДРР от выручки, % | BO2: Средний чек по выручке, с НДС | BP2: Выручка (отгруженный доход), руб. с НДС | BQ2: Доля выручки, %
S3: CPC | T3: =IFERROR(W3/U3,"-") -> - | U3: =SUM(МП_Periods!J3,МП_Periods!J118,МП_Periods!J233,МП_Periods!J348,МП_Periods!J464,МП_Periods!J579,МП_Periods!J694,МП_Periods!J809,МП_Periods!J924,МП_Periods!J1039,МП_Periods!J1154,МП_Periods!J1269) -> 0 | W3: =SUM(МП_Periods!L3,МП_Periods!L118,МП_Periods!L233,МП_Periods!L348,МП_Periods!L464,МП_Periods!L579,МП_Periods!L694,МП_Periods!L809,МП_Periods!L924,МП_Periods!L1039,МП_Periods!L1154,МП_Periods!L1269) -> 0 | Y3: =SUM(МП_Periods!N3,МП_Periods!N118,МП_Periods!N233,МП_Periods!N348,МП_Periods!N464,МП_Periods!N579,МП_Periods!N694,МП_Periods!N809,МП_Periods!N924,МП_Periods!N1039,МП_Periods!N1154,МП_Periods!N1269) -> 0 | AA3: =SUM(МП_Periods!P3,МП_Periods!P118,МП_Periods!P233,МП_Periods!P348,МП_Periods!P464,МП_Periods!P579,МП_Periods!P694,МП_Periods!P809,МП_Periods!P924,МП_Periods!P1039,МП_Periods!P1154,МП_Periods!P1269) -> 0 | AB3: =SUM(МП_Periods!Q3,МП_Periods!Q118,МП_Periods!Q233,МП_Periods!Q348,МП_Periods!Q464,МП_Periods!Q579,МП_Periods!Q694,МП_Periods!Q809,МП_Periods!Q924,МП_Periods!Q1039,МП_Periods!Q1154,МП_Periods!Q1269) -> 0 | AC3: =SUM(МП_Periods!R3,МП_Periods!R118,МП_Periods!R233,МП_Periods!R348,МП_Periods!R464,МП_Periods!R579,МП_Periods!R694,МП_Periods!R809,МП_Periods!R924,МП_Periods!R1039,МП_Periods!R1154,МП_Periods!R1269) -> 0 | AD3: =SUM(МП_Periods!S3,МП_Periods!S118,МП_Periods!S233,МП_Periods!S348,МП_Periods!S464,МП_Periods!S579,МП_Periods!S694,МП_Periods!S809,МП_Periods!S924,МП_Periods!S1039,МП_Periods!S1154,МП_Periods!S1269) -> 0 | AE3: =IFERROR(AC3/$AC$115,"-") -> - | AG3: =SUM(МП_Periods!V3,МП_Periods!V118,МП_Periods!V233,МП_Periods!V348,МП_Periods!V464,МП_Periods!V579,МП_Periods!V694,МП_Periods!V809,МП_Periods!V924,МП_Periods!V1039,МП_Periods!V1154,МП_Periods!V1269) -> 0 | AJ3: =SUM(МП_Periods!Y3,МП_Periods!Y118,МП_Periods!Y233,МП_Periods!Y348,МП_Periods!Y464,МП_Periods!Y579,МП_Periods!Y694,МП_Periods!Y809,МП_Periods!Y924,МП_Periods!Y1039,МП_Periods!Y1154,МП_Periods!Y1269) -> 0 | AK3: =SUM(МП_Periods!Z3,МП_Periods!Z118,МП_Periods!Z233,МП_Periods!Z348,МП_Periods!Z464,МП_Periods!Z579,МП_Periods!Z694,МП_Periods!Z809,МП_Periods!Z924,МП_Periods!Z1039,МП_Periods!Z1154,МП_Periods!Z1269) -> 0 | AL3: =SUM(МП_Periods!AA3,МП_Periods!AA118,МП_Periods!AA233,МП_Periods!AA348,МП_Periods!AA464,МП_Periods!AA579,МП_Periods!AA694,МП_Periods!AA809,МП_Periods!AA924,МП_Periods!AA1039,МП_Periods!AA1154,МП_Periods!AA1269) -> 0 | AM3: =SUM(МП_Periods!AB3,МП_Periods!AB118,МП_Periods!AB233,МП_Periods!AB348,МП_Periods!AB464,МП_Periods!AB579,МП_Periods!AB694,МП_Periods!AB809,МП_Periods!AB924,МП_Periods!AB1039,МП_Periods!AB1154,МП_Periods!AB1269) -> 0 | AO3: =IFERROR(AC3/AM3,"-") -> - | AP3: =SUM(МП_Periods!AE3,МП_Periods!AE118,МП_Periods!AE233,МП_Periods!AE348,МП_Periods!AE464,МП_Periods!AE579,МП_Periods!AE694,МП_Periods!AE809,МП_Periods!AE924,МП_Periods!AE1039,МП_Periods!AE1154,МП_Periods!AE1269) -> 0 | AQ3: =IFERROR(#REF!/AP3,"-") -> - | AS3: =IFERROR(U3/AG3,"-") -> - | AT3: =SUM(МП_Periods!AI3,МП_Periods!AI118,МП_Periods!AI233,МП_Periods!AI348,МП_Periods!AI464,МП_Periods!AI579,МП_Periods!AI694,МП_Periods!AI809,МП_Periods!AI924,МП_Periods!AI1039,МП_Periods!AI1154,МП_Periods!AI1269) -> 0 | AU3: =IFERROR(AC3/AT3,"-") -> - | AW3: =IFERROR(AX3/AT3,"-") -> - | AX3: =SUM(МП_Periods!AM3,МП_Periods!AM118,МП_Periods!AM233,МП_Periods!AM348,МП_Periods!AM464,МП_Periods!AM579,МП_Periods!AM694,МП_Periods!AM809,МП_Periods!AM924,МП_Periods!AM1039,МП_Periods!AM1154,МП_Periods!AM1269,) -> 0 | AY3: =IFERROR(AC3/AX3,"-") -> - | AZ3: =IFERROR(AX3/$AX$115,"-") -> - | BB3: =IFERROR(BE3/AC3,"-") -> - | BC3: =IFERROR(AC3/BE3,"-") -> - | BD3: =IFERROR(BE3/AX3,"-") -> - | BE3: =SUM(МП_Periods!AT3,МП_Periods!AT118,МП_Periods!AT233,МП_Periods!AT348,МП_Periods!AT464,МП_Periods!AT579,МП_Periods!AT694,МП_Periods!AT809,МП_Periods!AT924,МП_Periods!AT1039,МП_Periods!AT1154,МП_Periods!AT1269) -> 0 | BF3: =IFERROR(BE3/$BE$115,"-") -> - | BH3: =IFERROR(BI3/AX3,"-") -> - | BI3: =SUM(МП_Periods!AX3,МП_Periods!AX118,МП_Periods!AX233,МП_Periods!AX348,МП_Periods!AX464,МП_Periods!AX579,МП_Periods!AX694,МП_Periods!AX809,МП_Periods!AX924,МП_Periods!AX1039,МП_Periods!AX1154,МП_Periods!AX1269) -> 0 | BJ3: =IFERROR(AC3/BI3,"-") -> - | BK3: =IFERROR(BI3/$AX$115,"-") -> - | BM3: =IFERROR(BP3/AC3,"-") -> - | BN3: =IFERROR(AC3/BP3,"-") -> - | BO3: =IFERROR(BP3/BI3,"-") -> - | BP3: =SUM(МП_Periods!BE3,МП_Periods!BE118,МП_Periods!BE233,МП_Periods!BE348,МП_Periods!BE464,МП_Periods!BE579,МП_Periods!BE694,МП_Periods!BE809,МП_Periods!BE924,МП_Periods!BE1039,МП_Periods!BE1154,МП_Periods!BE1269) -> 0 | BQ3: =IFERROR(BP3/$BP$115,"-") -> -
S4: CPC | T4: =IFERROR(W4/U4,"-") -> - | U4: =SUM(МП_Periods!J4,МП_Periods!J119,МП_Periods!J234,МП_Periods!J349,МП_Periods!J465,МП_Periods!J580,МП_Periods!J695,МП_Periods!J810,МП_Periods!J925,МП_Periods!J1040,МП_Periods!J1155,МП_Periods!J1270) -> 0 | W4: =SUM(МП_Periods!L4,МП_Periods!L119,МП_Periods!L234,МП_Periods!L349,МП_Periods!L465,МП_Periods!L580,МП_Periods!L695,МП_Periods!L810,МП_Periods!L925,МП_Periods!L1040,МП_Periods!L1155,МП_Periods!L1270) -> 0 | Y4: =SUM(МП_Periods!N4,МП_Periods!N119,МП_Periods!N234,МП_Periods!N349,МП_Periods!N465,МП_Periods!N580,МП_Periods!N695,МП_Periods!N810,МП_Periods!N925,МП_Periods!N1040,МП_Periods!N1155,МП_Periods!N1270) -> 0 | AA4: =SUM(МП_Periods!P4,МП_Periods!P119,МП_Periods!P234,МП_Periods!P349,МП_Periods!P465,МП_Periods!P580,МП_Periods!P695,МП_Periods!P810,МП_Periods!P925,МП_Periods!P1040,МП_Periods!P1155,МП_Periods!P1270) -> 0 | AB4: =SUM(МП_Periods!Q4,МП_Periods!Q119,МП_Periods!Q234,МП_Periods!Q349,МП_Periods!Q465,МП_Periods!Q580,МП_Periods!Q695,МП_Periods!Q810,МП_Periods!Q925,МП_Periods!Q1040,МП_Periods!Q1155,МП_Periods!Q1270) -> 0 | AC4: =SUM(МП_Periods!R4,МП_Periods!R119,МП_Periods!R234,МП_Periods!R349,МП_Periods!R465,МП_Periods!R580,МП_Periods!R695,МП_Periods!R810,МП_Periods!R925,МП_Periods!R1040,МП_Periods!R1155,МП_Periods!R1270) -> 0 | AD4: =SUM(МП_Periods!S4,МП_Periods!S119,МП_Periods!S234,МП_Periods!S349,МП_Periods!S465,МП_Periods!S580,МП_Periods!S695,МП_Periods!S810,МП_Periods!S925,МП_Periods!S1040,МП_Periods!S1155,МП_Periods!S1270) -> 0 | AE4: =IFERROR(AC4/$AC$115,"-") -> - | AG4: =SUM(МП_Periods!V4,МП_Periods!V119,МП_Periods!V234,МП_Periods!V349,МП_Periods!V465,МП_Periods!V580,МП_Periods!V695,МП_Periods!V810,МП_Periods!V925,МП_Periods!V1040,МП_Periods!V1155,МП_Periods!V1270) -> 0 | AJ4: =SUM(МП_Periods!Y4,МП_Periods!Y119,МП_Periods!Y234,МП_Periods!Y349,МП_Periods!Y465,МП_Periods!Y580,МП_Periods!Y695,МП_Periods!Y810,МП_Periods!Y925,МП_Periods!Y1040,МП_Periods!Y1155,МП_Periods!Y1270) -> 0 | AK4: =SUM(МП_Periods!Z4,МП_Periods!Z119,МП_Periods!Z234,МП_Periods!Z349,МП_Periods!Z465,МП_Periods!Z580,МП_Periods!Z695,МП_Periods!Z810,МП_Periods!Z925,МП_Periods!Z1040,МП_Periods!Z1155,МП_Periods!Z1270) -> 0 | AL4: =SUM(МП_Periods!AA4,МП_Periods!AA119,МП_Periods!AA234,МП_Periods!AA349,МП_Periods!AA465,МП_Periods!AA580,МП_Periods!AA695,МП_Periods!AA810,МП_Periods!AA925,МП_Periods!AA1040,МП_Periods!AA1155,МП_Periods!AA1270) -> 0 | AM4: =SUM(МП_Periods!AB4,МП_Periods!AB119,МП_Periods!AB234,МП_Periods!AB349,МП_Periods!AB465,МП_Periods!AB580,МП_Periods!AB695,МП_Periods!AB810,МП_Periods!AB925,МП_Periods!AB1040,МП_Periods!AB1155,МП_Periods!AB1270) -> 0 | AO4: =IFERROR(AC4/AM4,"-") -> - | AP4: =SUM(МП_Periods!AE4,МП_Periods!AE119,МП_Periods!AE234,МП_Periods!AE349,МП_Periods!AE465,МП_Periods!AE580,МП_Periods!AE695,МП_Periods!AE810,МП_Periods!AE925,МП_Periods!AE1040,МП_Periods!AE1155,МП_Periods!AE1270) -> 0 | AQ4: =IFERROR(#REF!/AP4,"-") -> - | AS4: =IFERROR(U4/AG4,"-") -> - | AT4: =SUM(МП_Periods!AI4,МП_Periods!AI119,МП_Periods!AI234,МП_Periods!AI349,МП_Periods!AI465,МП_Periods!AI580,МП_Periods!AI695,МП_Periods!AI810,МП_Periods!AI925,МП_Periods!AI1040,МП_Periods!AI1155,МП_Periods!AI1270) -> 0 | AU4: =IFERROR(AC4/AT4,"-") -> - | AW4: =IFERROR(AX4/AT4,"-") -> - | AX4: =SUM(МП_Periods!AM4,МП_Periods!AM119,МП_Periods!AM234,МП_Periods!AM349,МП_Periods!AM465,МП_Periods!AM580,МП_Periods!AM695,МП_Periods!AM810,МП_Periods!AM925,МП_Periods!AM1040,МП_Periods!AM1155,МП_Periods!AM1270,) -> 0 | AY4: =IFERROR(AC4/AX4,"-") -> - | AZ4: =IFERROR(AX4/$AX$115,"-") -> - | BB4: =IFERROR(BE4/AC4,"-") -> - | BC4: =IFERROR(AC4/BE4,"-") -> - | BD4: =IFERROR(BE4/AX4,"-") -> - | BE4: =SUM(МП_Periods!AT4,МП_Periods!AT119,МП_Periods!AT234,МП_Periods!AT349,МП_Periods!AT465,МП_Periods!AT580,МП_Periods!AT695,МП_Periods!AT810,МП_Periods!AT925,МП_Periods!AT1040,МП_Periods!AT1155,МП_Periods!AT1270) -> 0 | BF4: =IFERROR(BE4/$BE$115,"-") -> - | BH4: =IFERROR(BI4/AX4,"-") -> - | BI4: =SUM(МП_Periods!AX4,МП_Periods!AX119,МП_Periods!AX234,МП_Periods!AX349,МП_Periods!AX465,МП_Periods!AX580,МП_Periods!AX695,МП_Periods!AX810,МП_Periods!AX925,МП_Periods!AX1040,МП_Periods!AX1155,МП_Periods!AX1270) -> 0 | BJ4: =IFERROR(AC4/BI4,"-") -> - | BK4: =IFERROR(BI4/$AX$115,"-") -> - | BM4: =IFERROR(BP4/AC4,"-") -> - | BN4: =IFERROR(AC4/BP4,"-") -> - | BO4: =IFERROR(BP4/BI4,"-") -> - | BP4: =SUM(МП_Periods!BE4,МП_Periods!BE119,МП_Periods!BE234,МП_Periods!BE349,МП_Periods!BE465,МП_Periods!BE580,МП_Periods!BE695,МП_Periods!BE810,МП_Periods!BE925,МП_Periods!BE1040,МП_Periods!BE1155,МП_Periods!BE1270) -> 0 | BQ4: =IFERROR(BP4/$BP$115,"-") -> -
S5: CPC | T5: =IFERROR(W5/U5,"-") -> - | U5: =SUM(МП_Periods!J5,МП_Periods!J120,МП_Periods!J235,МП_Periods!J350,МП_Periods!J466,МП_Periods!J581,МП_Periods!J696,МП_Periods!J811,МП_Periods!J926,МП_Periods!J1041,МП_Periods!J1156,МП_Periods!J1271) -> 0 | W5: =SUM(МП_Periods!L5,МП_Periods!L120,МП_Periods!L235,МП_Periods!L350,МП_Periods!L466,МП_Periods!L581,МП_Periods!L696,МП_Periods!L811,МП_Periods!L926,МП_Periods!L1041,МП_Periods!L1156,МП_Periods!L1271) -> 0 | Y5: =SUM(МП_Periods!N5,МП_Periods!N120,МП_Periods!N235,МП_Periods!N350,МП_Periods!N466,МП_Periods!N581,МП_Periods!N696,МП_Periods!N811,МП_Periods!N926,МП_Periods!N1041,МП_Periods!N1156,МП_Periods!N1271) -> 0 | AA5: =SUM(МП_Periods!P5,МП_Periods!P120,МП_Periods!P235,МП_Periods!P350,МП_Periods!P466,МП_Periods!P581,МП_Periods!P696,МП_Periods!P811,МП_Periods!P926,МП_Periods!P1041,МП_Periods!P1156,МП_Periods!P1271) -> 0 | AB5: =SUM(МП_Periods!Q5,МП_Periods!Q120,МП_Periods!Q235,МП_Periods!Q350,МП_Periods!Q466,МП_Periods!Q581,МП_Periods!Q696,МП_Periods!Q811,МП_Periods!Q926,МП_Periods!Q1041,МП_Periods!Q1156,МП_Periods!Q1271) -> 0 | AC5: =SUM(МП_Periods!R5,МП_Periods!R120,МП_Periods!R235,МП_Periods!R350,МП_Periods!R466,МП_Periods!R581,МП_Periods!R696,МП_Periods!R811,МП_Periods!R926,МП_Periods!R1041,МП_Periods!R1156,МП_Periods!R1271) -> 0 | AD5: =SUM(МП_Periods!S5,МП_Periods!S120,МП_Periods!S235,МП_Periods!S350,МП_Periods!S466,МП_Periods!S581,МП_Periods!S696,МП_Periods!S811,МП_Periods!S926,МП_Periods!S1041,МП_Periods!S1156,МП_Periods!S1271) -> 0 | AE5: =IFERROR(AC5/$AC$115,"-") -> - | AG5: =SUM(МП_Periods!V5,МП_Periods!V120,МП_Periods!V235,МП_Periods!V350,МП_Periods!V466,МП_Periods!V581,МП_Periods!V696,МП_Periods!V811,МП_Periods!V926,МП_Periods!V1041,МП_Periods!V1156,МП_Periods!V1271) -> 0 | AJ5: =SUM(МП_Periods!Y5,МП_Periods!Y120,МП_Periods!Y235,МП_Periods!Y350,МП_Periods!Y466,МП_Periods!Y581,МП_Periods!Y696,МП_Periods!Y811,МП_Periods!Y926,МП_Periods!Y1041,МП_Periods!Y1156,МП_Periods!Y1271) -> 0 | AK5: =SUM(МП_Periods!Z5,МП_Periods!Z120,МП_Periods!Z235,МП_Periods!Z350,МП_Periods!Z466,МП_Periods!Z581,МП_Periods!Z696,МП_Periods!Z811,МП_Periods!Z926,МП_Periods!Z1041,МП_Periods!Z1156,МП_Periods!Z1271) -> 0 | AL5: =SUM(МП_Periods!AA5,МП_Periods!AA120,МП_Periods!AA235,МП_Periods!AA350,МП_Periods!AA466,МП_Periods!AA581,МП_Periods!AA696,МП_Periods!AA811,МП_Periods!AA926,МП_Periods!AA1041,МП_Periods!AA1156,МП_Periods!AA1271) -> 0 | AM5: =SUM(МП_Periods!AB5,МП_Periods!AB120,МП_Periods!AB235,МП_Periods!AB350,МП_Periods!AB466,МП_Periods!AB581,МП_Periods!AB696,МП_Periods!AB811,МП_Periods!AB926,МП_Periods!AB1041,МП_Periods!AB1156,МП_Periods!AB1271) -> 0 | AO5: =IFERROR(AC5/AM5,"-") -> - | AP5: =SUM(МП_Periods!AE5,МП_Periods!AE120,МП_Periods!AE235,МП_Periods!AE350,МП_Periods!AE466,МП_Periods!AE581,МП_Periods!AE696,МП_Periods!AE811,МП_Periods!AE926,МП_Periods!AE1041,МП_Periods!AE1156,МП_Periods!AE1271) -> 0 | AQ5: =IFERROR(#REF!/AP5,"-") -> - | AS5: =IFERROR(U5/AG5,"-") -> - | AT5: =SUM(МП_Periods!AI5,МП_Periods!AI120,МП_Periods!AI235,МП_Periods!AI350,МП_Periods!AI466,МП_Periods!AI581,МП_Periods!AI696,МП_Periods!AI811,МП_Periods!AI926,МП_Periods!AI1041,МП_Periods!AI1156,МП_Periods!AI1271) -> 0 | AU5: =IFERROR(AC5/AT5,"-") -> - | AW5: =IFERROR(AX5/AT5,"-") -> - | AX5: =SUM(МП_Periods!AM5,МП_Periods!AM120,МП_Periods!AM235,МП_Periods!AM350,МП_Periods!AM466,МП_Periods!AM581,МП_Periods!AM696,МП_Periods!AM811,МП_Periods!AM926,МП_Periods!AM1041,МП_Periods!AM1156,МП_Periods!AM1271,) -> 0 | AY5: =IFERROR(AC5/AX5,"-") -> - | AZ5: =IFERROR(AX5/$AX$115,"-") -> - | BB5: =IFERROR(BE5/AC5,"-") -> - | BC5: =IFERROR(AC5/BE5,"-") -> - | BD5: =IFERROR(BE5/AX5,"-") -> - | BE5: =SUM(МП_Periods!AT5,МП_Periods!AT120,МП_Periods!AT235,МП_Periods!AT350,МП_Periods!AT466,МП_Periods!AT581,МП_Periods!AT696,МП_Periods!AT811,МП_Periods!AT926,МП_Periods!AT1041,МП_Periods!AT1156,МП_Periods!AT1271) -> 0 | BF5: =IFERROR(BE5/$BE$115,"-") -> - | BH5: =IFERROR(BI5/AX5,"-") -> - | BI5: =SUM(МП_Periods!AX5,МП_Periods!AX120,МП_Periods!AX235,МП_Periods!AX350,МП_Periods!AX466,МП_Periods!AX581,МП_Periods!AX696,МП_Periods!AX811,МП_Periods!AX926,МП_Periods!AX1041,МП_Periods!AX1156,МП_Periods!AX1271) -> 0 | BJ5: =IFERROR(AC5/BI5,"-") -> - | BK5: =IFERROR(BI5/$AX$115,"-") -> - | BM5: =IFERROR(BP5/AC5,"-") -> - | BN5: =IFERROR(AC5/BP5,"-") -> - | BO5: =IFERROR(BP5/BI5,"-") -> - | BP5: =SUM(МП_Periods!BE5,МП_Periods!BE120,МП_Periods!BE235,МП_Periods!BE350,МП_Periods!BE466,МП_Periods!BE581,МП_Periods!BE696,МП_Periods!BE811,МП_Periods!BE926,МП_Periods!BE1041,МП_Periods!BE1156,МП_Periods!BE1271) -> 0 | BQ5: =IFERROR(BP5/$BP$115,"-") -> -
S6: CPC | T6: =IFERROR(W6/U6,"-") -> - | U6: =SUM(МП_Periods!J6,МП_Periods!J121,МП_Periods!J236,МП_Periods!J351,МП_Periods!J467,МП_Periods!J582,МП_Periods!J697,МП_Periods!J812,МП_Periods!J927,МП_Periods!J1042,МП_Periods!J1157,МП_Periods!J1272) -> 0 | W6: =SUM(МП_Periods!L6,МП_Periods!L121,МП_Periods!L236,МП_Periods!L351,МП_Periods!L467,МП_Periods!L582,МП_Periods!L697,МП_Periods!L812,МП_Periods!L927,МП_Periods!L1042,МП_Periods!L1157,МП_Periods!L1272) -> 0 | Y6: =SUM(МП_Periods!N6,МП_Periods!N121,МП_Periods!N236,МП_Periods!N351,МП_Periods!N467,МП_Periods!N582,МП_Periods!N697,МП_Periods!N812,МП_Periods!N927,МП_Periods!N1042,МП_Periods!N1157,МП_Periods!N1272) -> 0 | AA6: =SUM(МП_Periods!P6,МП_Periods!P121,МП_Periods!P236,МП_Periods!P351,МП_Periods!P467,МП_Periods!P582,МП_Periods!P697,МП_Periods!P812,МП_Periods!P927,МП_Periods!P1042,МП_Periods!P1157,МП_Periods!P1272) -> 0 | AB6: =SUM(МП_Periods!Q6,МП_Periods!Q121,МП_Periods!Q236,МП_Periods!Q351,МП_Periods!Q467,МП_Periods!Q582,МП_Periods!Q697,МП_Periods!Q812,МП_Periods!Q927,МП_Periods!Q1042,МП_Periods!Q1157,МП_Periods!Q1272) -> 0 | AC6: =SUM(МП_Periods!R6,МП_Periods!R121,МП_Periods!R236,МП_Periods!R351,МП_Periods!R467,МП_Periods!R582,МП_Periods!R697,МП_Periods!R812,МП_Periods!R927,МП_Periods!R1042,МП_Periods!R1157,МП_Periods!R1272) -> 0 | AD6: =SUM(МП_Periods!S6,МП_Periods!S121,МП_Periods!S236,МП_Periods!S351,МП_Periods!S467,МП_Periods!S582,МП_Periods!S697,МП_Periods!S812,МП_Periods!S927,МП_Periods!S1042,МП_Periods!S1157,МП_Periods!S1272) -> 0 | AE6: =IFERROR(AC6/$AC$115,"-") -> - | AG6: =SUM(МП_Periods!V6,МП_Periods!V121,МП_Periods!V236,МП_Periods!V351,МП_Periods!V467,МП_Periods!V582,МП_Periods!V697,МП_Periods!V812,МП_Periods!V927,МП_Periods!V1042,МП_Periods!V1157,МП_Periods!V1272) -> 0 | AJ6: =SUM(МП_Periods!Y6,МП_Periods!Y121,МП_Periods!Y236,МП_Periods!Y351,МП_Periods!Y467,МП_Periods!Y582,МП_Periods!Y697,МП_Periods!Y812,МП_Periods!Y927,МП_Periods!Y1042,МП_Periods!Y1157,МП_Periods!Y1272) -> 0 | AK6: =SUM(МП_Periods!Z6,МП_Periods!Z121,МП_Periods!Z236,МП_Periods!Z351,МП_Periods!Z467,МП_Periods!Z582,МП_Periods!Z697,МП_Periods!Z812,МП_Periods!Z927,МП_Periods!Z1042,МП_Periods!Z1157,МП_Periods!Z1272) -> 0 | AL6: =SUM(МП_Periods!AA6,МП_Periods!AA121,МП_Periods!AA236,МП_Periods!AA351,МП_Periods!AA467,МП_Periods!AA582,МП_Periods!AA697,МП_Periods!AA812,МП_Periods!AA927,МП_Periods!AA1042,МП_Periods!AA1157,МП_Periods!AA1272) -> 0 | AM6: =SUM(МП_Periods!AB6,МП_Periods!AB121,МП_Periods!AB236,МП_Periods!AB351,МП_Periods!AB467,МП_Periods!AB582,МП_Periods!AB697,МП_Periods!AB812,МП_Periods!AB927,МП_Periods!AB1042,МП_Periods!AB1157,МП_Periods!AB1272) -> 0 | AO6: =IFERROR(AC6/AM6,"-") -> - | AP6: =SUM(МП_Periods!AE6,МП_Periods!AE121,МП_Periods!AE236,МП_Periods!AE351,МП_Periods!AE467,МП_Periods!AE582,МП_Periods!AE697,МП_Periods!AE812,МП_Periods!AE927,МП_Periods!AE1042,МП_Periods!AE1157,МП_Periods!AE1272) -> 0 | AQ6: =IFERROR(#REF!/AP6,"-") -> - | AS6: =IFERROR(U6/AG6,"-") -> - | AT6: =SUM(МП_Periods!AI6,МП_Periods!AI121,МП_Periods!AI236,МП_Periods!AI351,МП_Periods!AI467,МП_Periods!AI582,МП_Periods!AI697,МП_Periods!AI812,МП_Periods!AI927,МП_Periods!AI1042,МП_Periods!AI1157,МП_Periods!AI1272) -> 0 | AU6: =IFERROR(AC6/AT6,"-") -> - | AW6: =IFERROR(AX6/AT6,"-") -> - | AX6: =SUM(МП_Periods!AM6,МП_Periods!AM121,МП_Periods!AM236,МП_Periods!AM351,МП_Periods!AM467,МП_Periods!AM582,МП_Periods!AM697,МП_Periods!AM812,МП_Periods!AM927,МП_Periods!AM1042,МП_Periods!AM1157,МП_Periods!AM1272,) -> 0 | AY6: =IFERROR(AC6/AX6,"-") -> - | AZ6: =IFERROR(AX6/$AX$115,"-") -> - | BB6: =IFERROR(BE6/AC6,"-") -> - | BC6: =IFERROR(AC6/BE6,"-") -> - | BD6: =IFERROR(BE6/AX6,"-") -> - | BE6: =SUM(МП_Periods!AT6,МП_Periods!AT121,МП_Periods!AT236,МП_Periods!AT351,МП_Periods!AT467,МП_Periods!AT582,МП_Periods!AT697,МП_Periods!AT812,МП_Periods!AT927,МП_Periods!AT1042,МП_Periods!AT1157,МП_Periods!AT1272) -> 0 | BF6: =IFERROR(BE6/$BE$115,"-") -> - | BH6: =IFERROR(BI6/AX6,"-") -> - | BI6: =SUM(МП_Periods!AX6,МП_Periods!AX121,МП_Periods!AX236,МП_Periods!AX351,МП_Periods!AX467,МП_Periods!AX582,МП_Periods!AX697,МП_Periods!AX812,МП_Periods!AX927,МП_Periods!AX1042,МП_Periods!AX1157,МП_Periods!AX1272) -> 0 | BJ6: =IFERROR(AC6/BI6,"-") -> - | BK6: =IFERROR(BI6/$AX$115,"-") -> - | BM6: =IFERROR(BP6/AC6,"-") -> - | BN6: =IFERROR(AC6/BP6,"-") -> - | BO6: =IFERROR(BP6/BI6,"-") -> - | BP6: =SUM(МП_Periods!BE6,МП_Periods!BE121,МП_Periods!BE236,МП_Periods!BE351,МП_Periods!BE467,МП_Periods!BE582,МП_Periods!BE697,МП_Periods!BE812,МП_Periods!BE927,МП_Periods!BE1042,МП_Periods!BE1157,МП_Periods!BE1272) -> 0 | BQ6: =IFERROR(BP6/$BP$115,"-") -> -
S7: CPC | T7: =IFERROR(W7/U7,"-") -> - | U7: =SUM(МП_Periods!J7,МП_Periods!J122,МП_Periods!J237,МП_Periods!J352,МП_Periods!J468,МП_Periods!J583,МП_Periods!J698,МП_Periods!J813,МП_Periods!J928,МП_Periods!J1043,МП_Periods!J1158,МП_Periods!J1273) -> 0 | W7: =SUM(МП_Periods!L7,МП_Periods!L122,МП_Periods!L237,МП_Periods!L352,МП_Periods!L468,МП_Periods!L583,МП_Periods!L698,МП_Periods!L813,МП_Periods!L928,МП_Periods!L1043,МП_Periods!L1158,МП_Periods!L1273) -> 0 | Y7: =SUM(МП_Periods!N7,МП_Periods!N122,МП_Periods!N237,МП_Periods!N352,МП_Periods!N468,МП_Periods!N583,МП_Periods!N698,МП_Periods!N813,МП_Periods!N928,МП_Periods!N1043,МП_Periods!N1158,МП_Periods!N1273) -> 0 | AA7: =SUM(МП_Periods!P7,МП_Periods!P122,МП_Periods!P237,МП_Periods!P352,МП_Periods!P468,МП_Periods!P583,МП_Periods!P698,МП_Periods!P813,МП_Periods!P928,МП_Periods!P1043,МП_Periods!P1158,МП_Periods!P1273) -> 0 | AB7: =SUM(МП_Periods!Q7,МП_Periods!Q122,МП_Periods!Q237,МП_Periods!Q352,МП_Periods!Q468,МП_Periods!Q583,МП_Periods!Q698,МП_Periods!Q813,МП_Periods!Q928,МП_Periods!Q1043,МП_Periods!Q1158,МП_Periods!Q1273) -> 0 | AC7: =SUM(МП_Periods!R7,МП_Periods!R122,МП_Periods!R237,МП_Periods!R352,МП_Periods!R468,МП_Periods!R583,МП_Periods!R698,МП_Periods!R813,МП_Periods!R928,МП_Periods!R1043,МП_Periods!R1158,МП_Periods!R1273) -> 0 | AD7: =SUM(МП_Periods!S7,МП_Periods!S122,МП_Periods!S237,МП_Periods!S352,МП_Periods!S468,МП_Periods!S583,МП_Periods!S698,МП_Periods!S813,МП_Periods!S928,МП_Periods!S1043,МП_Periods!S1158,МП_Periods!S1273) -> 0 | AE7: =IFERROR(AC7/$AC$115,"-") -> - | AG7: =SUM(МП_Periods!V7,МП_Periods!V122,МП_Periods!V237,МП_Periods!V352,МП_Periods!V468,МП_Periods!V583,МП_Periods!V698,МП_Periods!V813,МП_Periods!V928,МП_Periods!V1043,МП_Periods!V1158,МП_Periods!V1273) -> 0 | AJ7: =SUM(МП_Periods!Y7,МП_Periods!Y122,МП_Periods!Y237,МП_Periods!Y352,МП_Periods!Y468,МП_Periods!Y583,МП_Periods!Y698,МП_Periods!Y813,МП_Periods!Y928,МП_Periods!Y1043,МП_Periods!Y1158,МП_Periods!Y1273) -> 0 | AK7: =SUM(МП_Periods!Z7,МП_Periods!Z122,МП_Periods!Z237,МП_Periods!Z352,МП_Periods!Z468,МП_Periods!Z583,МП_Periods!Z698,МП_Periods!Z813,МП_Periods!Z928,МП_Periods!Z1043,МП_Periods!Z1158,МП_Periods!Z1273) -> 0 | AL7: =SUM(МП_Periods!AA7,МП_Periods!AA122,МП_Periods!AA237,МП_Periods!AA352,МП_Periods!AA468,МП_Periods!AA583,МП_Periods!AA698,МП_Periods!AA813,МП_Periods!AA928,МП_Periods!AA1043,МП_Periods!AA1158,МП_Periods!AA1273) -> 0 | AM7: =SUM(МП_Periods!AB7,МП_Periods!AB122,МП_Periods!AB237,МП_Periods!AB352,МП_Periods!AB468,МП_Periods!AB583,МП_Periods!AB698,МП_Periods!AB813,МП_Periods!AB928,МП_Periods!AB1043,МП_Periods!AB1158,МП_Periods!AB1273) -> 0 | AO7: =IFERROR(AC7/AM7,"-") -> - | AP7: =SUM(МП_Periods!AE7,МП_Periods!AE122,МП_Periods!AE237,МП_Periods!AE352,МП_Periods!AE468,МП_Periods!AE583,МП_Periods!AE698,МП_Periods!AE813,МП_Periods!AE928,МП_Periods!AE1043,МП_Periods!AE1158,МП_Periods!AE1273) -> 0 | AQ7: =IFERROR(#REF!/AP7,"-") -> - | AS7: =IFERROR(U7/AG7,"-") -> - | AT7: =SUM(МП_Periods!AI7,МП_Periods!AI122,МП_Periods!AI237,МП_Periods!AI352,МП_Periods!AI468,МП_Periods!AI583,МП_Periods!AI698,МП_Periods!AI813,МП_Periods!AI928,МП_Periods!AI1043,МП_Periods!AI1158,МП_Periods!AI1273) -> 0 | AU7: =IFERROR(AC7/AT7,"-") -> - | AW7: =IFERROR(AX7/AT7,"-") -> - | AX7: =SUM(МП_Periods!AM7,МП_Periods!AM122,МП_Periods!AM237,МП_Periods!AM352,МП_Periods!AM468,МП_Periods!AM583,МП_Periods!AM698,МП_Periods!AM813,МП_Periods!AM928,МП_Periods!AM1043,МП_Periods!AM1158,МП_Periods!AM1273,) -> 0 | AY7: =IFERROR(AC7/AX7,"-") -> - | AZ7: =IFERROR(AX7/$AX$115,"-") -> - | BB7: =IFERROR(BE7/AC7,"-") -> - | BC7: =IFERROR(AC7/BE7,"-") -> - | BD7: =IFERROR(BE7/AX7,"-") -> - | BE7: =SUM(МП_Periods!AT7,МП_Periods!AT122,МП_Periods!AT237,МП_Periods!AT352,МП_Periods!AT468,МП_Periods!AT583,МП_Periods!AT698,МП_Periods!AT813,МП_Periods!AT928,МП_Periods!AT1043,МП_Periods!AT1158,МП_Periods!AT1273) -> 0 | BF7: =IFERROR(BE7/$BE$115,"-") -> - | BH7: =IFERROR(BI7/AX7,"-") -> - | BI7: =SUM(МП_Periods!AX7,МП_Periods!AX122,МП_Periods!AX237,МП_Periods!AX352,МП_Periods!AX468,МП_Periods!AX583,МП_Periods!AX698,МП_Periods!AX813,МП_Periods!AX928,МП_Periods!AX1043,МП_Periods!AX1158,МП_Periods!AX1273) -> 0 | BJ7: =IFERROR(AC7/BI7,"-") -> - | BK7: =IFERROR(BI7/$AX$115,"-") -> - | BM7: =IFERROR(BP7/AC7,"-") -> - | BN7: =IFERROR(AC7/BP7,"-") -> - | BO7: =IFERROR(BP7/BI7,"-") -> - | BP7: =SUM(МП_Periods!BE7,МП_Periods!BE122,МП_Periods!BE237,МП_Periods!BE352,МП_Periods!BE468,МП_Periods!BE583,МП_Periods!BE698,МП_Periods!BE813,МП_Periods!BE928,МП_Periods!BE1043,МП_Periods!BE1158,МП_Periods!BE1273) -> 0 | BQ7: =IFERROR(BP7/$BP$115,"-") -> -
S8: CPC | T8: =IFERROR(W8/U8,"-") -> - | U8: =SUM(МП_Periods!J8,МП_Periods!J123,МП_Periods!J238,МП_Periods!J353,МП_Periods!J469,МП_Periods!J584,МП_Periods!J699,МП_Periods!J814,МП_Periods!J929,МП_Periods!J1044,МП_Periods!J1159,МП_Periods!J1274) -> 0 | W8: =SUM(МП_Periods!L8,МП_Periods!L123,МП_Periods!L238,МП_Periods!L353,МП_Periods!L469,МП_Periods!L584,МП_Periods!L699,МП_Periods!L814,МП_Periods!L929,МП_Periods!L1044,МП_Periods!L1159,МП_Periods!L1274) -> 0 | Y8: =SUM(МП_Periods!N8,МП_Periods!N123,МП_Periods!N238,МП_Periods!N353,МП_Periods!N469,МП_Periods!N584,МП_Periods!N699,МП_Periods!N814,МП_Periods!N929,МП_Periods!N1044,МП_Periods!N1159,МП_Periods!N1274) -> 0 | AA8: =SUM(МП_Periods!P8,МП_Periods!P123,МП_Periods!P238,МП_Periods!P353,МП_Periods!P469,МП_Periods!P584,МП_Periods!P699,МП_Periods!P814,МП_Periods!P929,МП_Periods!P1044,МП_Periods!P1159,МП_Periods!P1274) -> 0 | AB8: =SUM(МП_Periods!Q8,МП_Periods!Q123,МП_Periods!Q238,МП_Periods!Q353,МП_Periods!Q469,МП_Periods!Q584,МП_Periods!Q699,МП_Periods!Q814,МП_Periods!Q929,МП_Periods!Q1044,МП_Periods!Q1159,МП_Periods!Q1274) -> 0 | AC8: =SUM(МП_Periods!R8,МП_Periods!R123,МП_Periods!R238,МП_Periods!R353,МП_Periods!R469,МП_Periods!R584,МП_Periods!R699,МП_Periods!R814,МП_Periods!R929,МП_Periods!R1044,МП_Periods!R1159,МП_Periods!R1274) -> 0 | AD8: =SUM(МП_Periods!S8,МП_Periods!S123,МП_Periods!S238,МП_Periods!S353,МП_Periods!S469,МП_Periods!S584,МП_Periods!S699,МП_Periods!S814,МП_Periods!S929,МП_Periods!S1044,МП_Periods!S1159,МП_Periods!S1274) -> 0 | AE8: =IFERROR(AC8/$AC$115,"-") -> - | AG8: =SUM(МП_Periods!V8,МП_Periods!V123,МП_Periods!V238,МП_Periods!V353,МП_Periods!V469,МП_Periods!V584,МП_Periods!V699,МП_Periods!V814,МП_Periods!V929,МП_Periods!V1044,МП_Periods!V1159,МП_Periods!V1274) -> 0 | AJ8: =SUM(МП_Periods!Y8,МП_Periods!Y123,МП_Periods!Y238,МП_Periods!Y353,МП_Periods!Y469,МП_Periods!Y584,МП_Periods!Y699,МП_Periods!Y814,МП_Periods!Y929,МП_Periods!Y1044,МП_Periods!Y1159,МП_Periods!Y1274) -> 0 | AK8: =SUM(МП_Periods!Z8,МП_Periods!Z123,МП_Periods!Z238,МП_Periods!Z353,МП_Periods!Z469,МП_Periods!Z584,МП_Periods!Z699,МП_Periods!Z814,МП_Periods!Z929,МП_Periods!Z1044,МП_Periods!Z1159,МП_Periods!Z1274) -> 0 | AL8: =SUM(МП_Periods!AA8,МП_Periods!AA123,МП_Periods!AA238,МП_Periods!AA353,МП_Periods!AA469,МП_Periods!AA584,МП_Periods!AA699,МП_Periods!AA814,МП_Periods!AA929,МП_Periods!AA1044,МП_Periods!AA1159,МП_Periods!AA1274) -> 0 | AM8: =SUM(МП_Periods!AB8,МП_Periods!AB123,МП_Periods!AB238,МП_Periods!AB353,МП_Periods!AB469,МП_Periods!AB584,МП_Periods!AB699,МП_Periods!AB814,МП_Periods!AB929,МП_Periods!AB1044,МП_Periods!AB1159,МП_Periods!AB1274) -> 0 | AO8: =IFERROR(AC8/AM8,"-") -> - | AP8: =SUM(МП_Periods!AE8,МП_Periods!AE123,МП_Periods!AE238,МП_Periods!AE353,МП_Periods!AE469,МП_Periods!AE584,МП_Periods!AE699,МП_Periods!AE814,МП_Periods!AE929,МП_Periods!AE1044,МП_Periods!AE1159,МП_Periods!AE1274) -> 0 | AQ8: =IFERROR(#REF!/AP8,"-") -> - | AS8: =IFERROR(U8/AG8,"-") -> - | AT8: =SUM(МП_Periods!AI8,МП_Periods!AI123,МП_Periods!AI238,МП_Periods!AI353,МП_Periods!AI469,МП_Periods!AI584,МП_Periods!AI699,МП_Periods!AI814,МП_Periods!AI929,МП_Periods!AI1044,МП_Periods!AI1159,МП_Periods!AI1274) -> 0 | AU8: =IFERROR(AC8/AT8,"-") -> - | AW8: =IFERROR(AX8/AT8,"-") -> - | AX8: =SUM(МП_Periods!AM8,МП_Periods!AM123,МП_Periods!AM238,МП_Periods!AM353,МП_Periods!AM469,МП_Periods!AM584,МП_Periods!AM699,МП_Periods!AM814,МП_Periods!AM929,МП_Periods!AM1044,МП_Periods!AM1159,МП_Periods!AM1274,) -> 0 | AY8: =IFERROR(AC8/AX8,"-") -> - | AZ8: =IFERROR(AX8/$AX$115,"-") -> - | BB8: =IFERROR(BE8/AC8,"-") -> - | BC8: =IFERROR(AC8/BE8,"-") -> - | BD8: =IFERROR(BE8/AX8,"-") -> - | BE8: =SUM(МП_Periods!AT8,МП_Periods!AT123,МП_Periods!AT238,МП_Periods!AT353,МП_Periods!AT469,МП_Periods!AT584,МП_Periods!AT699,МП_Periods!AT814,МП_Periods!AT929,МП_Periods!AT1044,МП_Periods!AT1159,МП_Periods!AT1274) -> 0 | BF8: =IFERROR(BE8/$BE$115,"-") -> - | BH8: =IFERROR(BI8/AX8,"-") -> - | BI8: =SUM(МП_Periods!AX8,МП_Periods!AX123,МП_Periods!AX238,МП_Periods!AX353,МП_Periods!AX469,МП_Periods!AX584,МП_Periods!AX699,МП_Periods!AX814,МП_Periods!AX929,МП_Periods!AX1044,МП_Periods!AX1159,МП_Periods!AX1274) -> 0 | BJ8: =IFERROR(AC8/BI8,"-") -> - | BK8: =IFERROR(BI8/$AX$115,"-") -> - | BM8: =IFERROR(BP8/AC8,"-") -> - | BN8: =IFERROR(AC8/BP8,"-") -> - | BO8: =IFERROR(BP8/BI8,"-") -> - | BP8: =SUM(МП_Periods!BE8,МП_Periods!BE123,МП_Periods!BE238,МП_Periods!BE353,МП_Periods!BE469,МП_Periods!BE584,МП_Periods!BE699,МП_Periods!BE814,МП_Periods!BE929,МП_Periods!BE1044,МП_Periods!BE1159,МП_Periods!BE1274) -> 0 | BQ8: =IFERROR(BP8/$BP$115,"-") -> -
S9: CPC | T9: =IFERROR(W9/U9,"-") -> - | U9: =SUM(МП_Periods!J9,МП_Periods!J124,МП_Periods!J239,МП_Periods!J354,МП_Periods!J470,МП_Periods!J585,МП_Periods!J700,МП_Periods!J815,МП_Periods!J930,МП_Periods!J1045,МП_Periods!J1160,МП_Periods!J1275) -> 0 | W9: =SUM(МП_Periods!L9,МП_Periods!L124,МП_Periods!L239,МП_Periods!L354,МП_Periods!L470,МП_Periods!L585,МП_Periods!L700,МП_Periods!L815,МП_Periods!L930,МП_Periods!L1045,МП_Periods!L1160,МП_Periods!L1275) -> 0 | Y9: =SUM(МП_Periods!N9,МП_Periods!N124,МП_Periods!N239,МП_Periods!N354,МП_Periods!N470,МП_Periods!N585,МП_Periods!N700,МП_Periods!N815,МП_Periods!N930,МП_Periods!N1045,МП_Periods!N1160,МП_Periods!N1275) -> 0 | AA9: =SUM(МП_Periods!P9,МП_Periods!P124,МП_Periods!P239,МП_Periods!P354,МП_Periods!P470,МП_Periods!P585,МП_Periods!P700,МП_Periods!P815,МП_Periods!P930,МП_Periods!P1045,МП_Periods!P1160,МП_Periods!P1275) -> 0 | AB9: =SUM(МП_Periods!Q9,МП_Periods!Q124,МП_Periods!Q239,МП_Periods!Q354,МП_Periods!Q470,МП_Periods!Q585,МП_Periods!Q700,МП_Periods!Q815,МП_Periods!Q930,МП_Periods!Q1045,МП_Periods!Q1160,МП_Periods!Q1275) -> 0 | AC9: =SUM(МП_Periods!R9,МП_Periods!R124,МП_Periods!R239,МП_Periods!R354,МП_Periods!R470,МП_Periods!R585,МП_Periods!R700,МП_Periods!R815,МП_Periods!R930,МП_Periods!R1045,МП_Periods!R1160,МП_Periods!R1275) -> 0 | AD9: =SUM(МП_Periods!S9,МП_Periods!S124,МП_Periods!S239,МП_Periods!S354,МП_Periods!S470,МП_Periods!S585,МП_Periods!S700,МП_Periods!S815,МП_Periods!S930,МП_Periods!S1045,МП_Periods!S1160,МП_Periods!S1275) -> 0 | AE9: =IFERROR(AC9/$AC$115,"-") -> - | AG9: =SUM(МП_Periods!V9,МП_Periods!V124,МП_Periods!V239,МП_Periods!V354,МП_Periods!V470,МП_Periods!V585,МП_Periods!V700,МП_Periods!V815,МП_Periods!V930,МП_Periods!V1045,МП_Periods!V1160,МП_Periods!V1275) -> 0 | AJ9: =SUM(МП_Periods!Y9,МП_Periods!Y124,МП_Periods!Y239,МП_Periods!Y354,МП_Periods!Y470,МП_Periods!Y585,МП_Periods!Y700,МП_Periods!Y815,МП_Periods!Y930,МП_Periods!Y1045,МП_Periods!Y1160,МП_Periods!Y1275) -> 0 | AK9: =SUM(МП_Periods!Z9,МП_Periods!Z124,МП_Periods!Z239,МП_Periods!Z354,МП_Periods!Z470,МП_Periods!Z585,МП_Periods!Z700,МП_Periods!Z815,МП_Periods!Z930,МП_Periods!Z1045,МП_Periods!Z1160,МП_Periods!Z1275) -> 0 | AL9: =SUM(МП_Periods!AA9,МП_Periods!AA124,МП_Periods!AA239,МП_Periods!AA354,МП_Periods!AA470,МП_Periods!AA585,МП_Periods!AA700,МП_Periods!AA815,МП_Periods!AA930,МП_Periods!AA1045,МП_Periods!AA1160,МП_Periods!AA1275) -> 0 | AM9: =SUM(МП_Periods!AB9,МП_Periods!AB124,МП_Periods!AB239,МП_Periods!AB354,МП_Periods!AB470,МП_Periods!AB585,МП_Periods!AB700,МП_Periods!AB815,МП_Periods!AB930,МП_Periods!AB1045,МП_Periods!AB1160,МП_Periods!AB1275) -> 0 | AO9: =IFERROR(AC9/AM9,"-") -> - | AP9: =SUM(МП_Periods!AE9,МП_Periods!AE124,МП_Periods!AE239,МП_Periods!AE354,МП_Periods!AE470,МП_Periods!AE585,МП_Periods!AE700,МП_Periods!AE815,МП_Periods!AE930,МП_Periods!AE1045,МП_Periods!AE1160,МП_Periods!AE1275) -> 0 | AQ9: =IFERROR(#REF!/AP9,"-") -> - | AS9: =IFERROR(U9/AG9,"-") -> - | AT9: =SUM(МП_Periods!AI9,МП_Periods!AI124,МП_Periods!AI239,МП_Periods!AI354,МП_Periods!AI470,МП_Periods!AI585,МП_Periods!AI700,МП_Periods!AI815,МП_Periods!AI930,МП_Periods!AI1045,МП_Periods!AI1160,МП_Periods!AI1275) -> 0 | AU9: =IFERROR(AC9/AT9,"-") -> - | AW9: =IFERROR(AX9/AT9,"-") -> - | AX9: =SUM(МП_Periods!AM9,МП_Periods!AM124,МП_Periods!AM239,МП_Periods!AM354,МП_Periods!AM470,МП_Periods!AM585,МП_Periods!AM700,МП_Periods!AM815,МП_Periods!AM930,МП_Periods!AM1045,МП_Periods!AM1160,МП_Periods!AM1275,) -> 0 | AY9: =IFERROR(AC9/AX9,"-") -> - | AZ9: =IFERROR(AX9/$AX$115,"-") -> - | BB9: =IFERROR(BE9/AC9,"-") -> - | BC9: =IFERROR(AC9/BE9,"-") -> - | BD9: =IFERROR(BE9/AX9,"-") -> - | BE9: =SUM(МП_Periods!AT9,МП_Periods!AT124,МП_Periods!AT239,МП_Periods!AT354,МП_Periods!AT470,МП_Periods!AT585,МП_Periods!AT700,МП_Periods!AT815,МП_Periods!AT930,МП_Periods!AT1045,МП_Periods!AT1160,МП_Periods!AT1275) -> 0 | BF9: =IFERROR(BE9/$BE$115,"-") -> - | BH9: =IFERROR(BI9/AX9,"-") -> - | BI9: =SUM(МП_Periods!AX9,МП_Periods!AX124,МП_Periods!AX239,МП_Periods!AX354,МП_Periods!AX470,МП_Periods!AX585,МП_Periods!AX700,МП_Periods!AX815,МП_Periods!AX930,МП_Periods!AX1045,МП_Periods!AX1160,МП_Periods!AX1275) -> 0 | BJ9: =IFERROR(AC9/BI9,"-") -> - | BK9: =IFERROR(BI9/$AX$115,"-") -> - | BM9: =IFERROR(BP9/AC9,"-") -> - | BN9: =IFERROR(AC9/BP9,"-") -> - | BO9: =IFERROR(BP9/BI9,"-") -> - | BP9: =SUM(МП_Periods!BE9,МП_Periods!BE124,МП_Periods!BE239,МП_Periods!BE354,МП_Periods!BE470,МП_Periods!BE585,МП_Periods!BE700,МП_Periods!BE815,МП_Periods!BE930,МП_Periods!BE1045,МП_Periods!BE1160,МП_Periods!BE1275) -> 0 | BQ9: =IFERROR(BP9/$BP$115,"-") -> -
S10: CPC | T10: =IFERROR(W10/U10,"-") -> - | U10: =SUM(МП_Periods!J10,МП_Periods!J125,МП_Periods!J240,МП_Periods!J355,МП_Periods!J471,МП_Periods!J586,МП_Periods!J701,МП_Periods!J816,МП_Periods!J931,МП_Periods!J1046,МП_Periods!J1161,МП_Periods!J1276) -> 0 | W10: =SUM(МП_Periods!L10,МП_Periods!L125,МП_Periods!L240,МП_Periods!L355,МП_Periods!L471,МП_Periods!L586,МП_Periods!L701,МП_Periods!L816,МП_Periods!L931,МП_Periods!L1046,МП_Periods!L1161,МП_Periods!L1276) -> 0 | Y10: =SUM(МП_Periods!N10,МП_Periods!N125,МП_Periods!N240,МП_Periods!N355,МП_Periods!N471,МП_Periods!N586,МП_Periods!N701,МП_Periods!N816,МП_Periods!N931,МП_Periods!N1046,МП_Periods!N1161,МП_Periods!N1276) -> 0 | AA10: =SUM(МП_Periods!P10,МП_Periods!P125,МП_Periods!P240,МП_Periods!P355,МП_Periods!P471,МП_Periods!P586,МП_Periods!P701,МП_Periods!P816,МП_Periods!P931,МП_Periods!P1046,МП_Periods!P1161,МП_Periods!P1276) -> 0 | AB10: =SUM(МП_Periods!Q10,МП_Periods!Q125,МП_Periods!Q240,МП_Periods!Q355,МП_Periods!Q471,МП_Periods!Q586,МП_Periods!Q701,МП_Periods!Q816,МП_Periods!Q931,МП_Periods!Q1046,МП_Periods!Q1161,МП_Periods!Q1276) -> 0 | AC10: =SUM(МП_Periods!R10,МП_Periods!R125,МП_Periods!R240,МП_Periods!R355,МП_Periods!R471,МП_Periods!R586,МП_Periods!R701,МП_Periods!R816,МП_Periods!R931,МП_Periods!R1046,МП_Periods!R1161,МП_Periods!R1276) -> 0 | AD10: =SUM(МП_Periods!S10,МП_Periods!S125,МП_Periods!S240,МП_Periods!S355,МП_Periods!S471,МП_Periods!S586,МП_Periods!S701,МП_Periods!S816,МП_Periods!S931,МП_Periods!S1046,МП_Periods!S1161,МП_Periods!S1276) -> 0 | AE10: =IFERROR(AC10/$AC$115,"-") -> - | AG10: =SUM(МП_Periods!V10,МП_Periods!V125,МП_Periods!V240,МП_Periods!V355,МП_Periods!V471,МП_Periods!V586,МП_Periods!V701,МП_Periods!V816,МП_Periods!V931,МП_Periods!V1046,МП_Periods!V1161,МП_Periods!V1276) -> 0 | AJ10: =SUM(МП_Periods!Y10,МП_Periods!Y125,МП_Periods!Y240,МП_Periods!Y355,МП_Periods!Y471,МП_Periods!Y586,МП_Periods!Y701,МП_Periods!Y816,МП_Periods!Y931,МП_Periods!Y1046,МП_Periods!Y1161,МП_Periods!Y1276) -> 0 | AK10: =SUM(МП_Periods!Z10,МП_Periods!Z125,МП_Periods!Z240,МП_Periods!Z355,МП_Periods!Z471,МП_Periods!Z586,МП_Periods!Z701,МП_Periods!Z816,МП_Periods!Z931,МП_Periods!Z1046,МП_Periods!Z1161,МП_Periods!Z1276) -> 0 | AL10: =SUM(МП_Periods!AA10,МП_Periods!AA125,МП_Periods!AA240,МП_Periods!AA355,МП_Periods!AA471,МП_Periods!AA586,МП_Periods!AA701,МП_Periods!AA816,МП_Periods!AA931,МП_Periods!AA1046,МП_Periods!AA1161,МП_Periods!AA1276) -> 0 | AM10: =SUM(МП_Periods!AB10,МП_Periods!AB125,МП_Periods!AB240,МП_Periods!AB355,МП_Periods!AB471,МП_Periods!AB586,МП_Periods!AB701,МП_Periods!AB816,МП_Periods!AB931,МП_Periods!AB1046,МП_Periods!AB1161,МП_Periods!AB1276) -> 0 | AO10: =IFERROR(AC10/AM10,"-") -> - | AP10: =SUM(МП_Periods!AE10,МП_Periods!AE125,МП_Periods!AE240,МП_Periods!AE355,МП_Periods!AE471,МП_Periods!AE586,МП_Periods!AE701,МП_Periods!AE816,МП_Periods!AE931,МП_Periods!AE1046,МП_Periods!AE1161,МП_Periods!AE1276) -> 0 | AQ10: =IFERROR(#REF!/AP10,"-") -> - | AS10: =IFERROR(U10/AG10,"-") -> - | AT10: =SUM(МП_Periods!AI10,МП_Periods!AI125,МП_Periods!AI240,МП_Periods!AI355,МП_Periods!AI471,МП_Periods!AI586,МП_Periods!AI701,МП_Periods!AI816,МП_Periods!AI931,МП_Periods!AI1046,МП_Periods!AI1161,МП_Periods!AI1276) -> 0 | AU10: =IFERROR(AC10/AT10,"-") -> - | AW10: =IFERROR(AX10/AT10,"-") -> - | AX10: =SUM(МП_Periods!AM10,МП_Periods!AM125,МП_Periods!AM240,МП_Periods!AM355,МП_Periods!AM471,МП_Periods!AM586,МП_Periods!AM701,МП_Periods!AM816,МП_Periods!AM931,МП_Periods!AM1046,МП_Periods!AM1161,МП_Periods!AM1276,) -> 0 | AY10: =IFERROR(AC10/AX10,"-") -> - | AZ10: =IFERROR(AX10/$AX$115,"-") -> - | BB10: =IFERROR(BE10/AC10,"-") -> - | BC10: =IFERROR(AC10/BE10,"-") -> - | BD10: =IFERROR(BE10/AX10,"-") -> - | BE10: =SUM(МП_Periods!AT10,МП_Periods!AT125,МП_Periods!AT240,МП_Periods!AT355,МП_Periods!AT471,МП_Periods!AT586,МП_Periods!AT701,МП_Periods!AT816,МП_Periods!AT931,МП_Periods!AT1046,МП_Periods!AT1161,МП_Periods!AT1276) -> 0 | BF10: =IFERROR(BE10/$BE$115,"-") -> - | BH10: =IFERROR(BI10/AX10,"-") -> - | BI10: =SUM(МП_Periods!AX10,МП_Periods!AX125,МП_Periods!AX240,МП_Periods!AX355,МП_Periods!AX471,МП_Periods!AX586,МП_Periods!AX701,МП_Periods!AX816,МП_Periods!AX931,МП_Periods!AX1046,МП_Periods!AX1161,МП_Periods!AX1276) -> 0 | BJ10: =IFERROR(AC10/BI10,"-") -> - | BK10: =IFERROR(BI10/$AX$115,"-") -> - | BM10: =IFERROR(BP10/AC10,"-") -> - | BN10: =IFERROR(AC10/BP10,"-") -> - | BO10: =IFERROR(BP10/BI10,"-") -> - | BP10: =SUM(МП_Periods!BE10,МП_Periods!BE125,МП_Periods!BE240,МП_Periods!BE355,МП_Periods!BE471,МП_Periods!BE586,МП_Periods!BE701,МП_Periods!BE816,МП_Periods!BE931,МП_Periods!BE1046,МП_Periods!BE1161,МП_Periods!BE1276) -> 0 | BQ10: =IFERROR(BP10/$BP$115,"-") -> -
S11: CPC | T11: =IFERROR(W11/U11,"-") -> - | U11: =SUM(МП_Periods!J11,МП_Periods!J126,МП_Periods!J241,МП_Periods!J356,МП_Periods!J472,МП_Periods!J587,МП_Periods!J702,МП_Periods!J817,МП_Periods!J932,МП_Periods!J1047,МП_Periods!J1162,МП_Periods!J1277) -> 0 | W11: =SUM(МП_Periods!L11,МП_Periods!L126,МП_Periods!L241,МП_Periods!L356,МП_Periods!L472,МП_Periods!L587,МП_Periods!L702,МП_Periods!L817,МП_Periods!L932,МП_Periods!L1047,МП_Periods!L1162,МП_Periods!L1277) -> 0 | Y11: =SUM(МП_Periods!N11,МП_Periods!N126,МП_Periods!N241,МП_Periods!N356,МП_Periods!N472,МП_Periods!N587,МП_Periods!N702,МП_Periods!N817,МП_Periods!N932,МП_Periods!N1047,МП_Periods!N1162,МП_Periods!N1277) -> 0 | AA11: =SUM(МП_Periods!P11,МП_Periods!P126,МП_Periods!P241,МП_Periods!P356,МП_Periods!P472,МП_Periods!P587,МП_Periods!P702,МП_Periods!P817,МП_Periods!P932,МП_Periods!P1047,МП_Periods!P1162,МП_Periods!P1277) -> 0 | AB11: =SUM(МП_Periods!Q11,МП_Periods!Q126,МП_Periods!Q241,МП_Periods!Q356,МП_Periods!Q472,МП_Periods!Q587,МП_Periods!Q702,МП_Periods!Q817,МП_Periods!Q932,МП_Periods!Q1047,МП_Periods!Q1162,МП_Periods!Q1277) -> 0 | AC11: =SUM(МП_Periods!R11,МП_Periods!R126,МП_Periods!R241,МП_Periods!R356,МП_Periods!R472,МП_Periods!R587,МП_Periods!R702,МП_Periods!R817,МП_Periods!R932,МП_Periods!R1047,МП_Periods!R1162,МП_Periods!R1277) -> 0 | AD11: =SUM(МП_Periods!S11,МП_Periods!S126,МП_Periods!S241,МП_Periods!S356,МП_Periods!S472,МП_Periods!S587,МП_Periods!S702,МП_Periods!S817,МП_Periods!S932,МП_Periods!S1047,МП_Periods!S1162,МП_Periods!S1277) -> 0 | AE11: =IFERROR(AC11/$AC$115,"-") -> - | AG11: =SUM(МП_Periods!V11,МП_Periods!V126,МП_Periods!V241,МП_Periods!V356,МП_Periods!V472,МП_Periods!V587,МП_Periods!V702,МП_Periods!V817,МП_Periods!V932,МП_Periods!V1047,МП_Periods!V1162,МП_Periods!V1277) -> 0 | AJ11: =SUM(МП_Periods!Y11,МП_Periods!Y126,МП_Periods!Y241,МП_Periods!Y356,МП_Periods!Y472,МП_Periods!Y587,МП_Periods!Y702,МП_Periods!Y817,МП_Periods!Y932,МП_Periods!Y1047,МП_Periods!Y1162,МП_Periods!Y1277) -> 0 | AK11: =SUM(МП_Periods!Z11,МП_Periods!Z126,МП_Periods!Z241,МП_Periods!Z356,МП_Periods!Z472,МП_Periods!Z587,МП_Periods!Z702,МП_Periods!Z817,МП_Periods!Z932,МП_Periods!Z1047,МП_Periods!Z1162,МП_Periods!Z1277) -> 0 | AL11: =SUM(МП_Periods!AA11,МП_Periods!AA126,МП_Periods!AA241,МП_Periods!AA356,МП_Periods!AA472,МП_Periods!AA587,МП_Periods!AA702,МП_Periods!AA817,МП_Periods!AA932,МП_Periods!AA1047,МП_Periods!AA1162,МП_Periods!AA1277) -> 0 | AM11: =SUM(МП_Periods!AB11,МП_Periods!AB126,МП_Periods!AB241,МП_Periods!AB356,МП_Periods!AB472,МП_Periods!AB587,МП_Periods!AB702,МП_Periods!AB817,МП_Periods!AB932,МП_Periods!AB1047,МП_Periods!AB1162,МП_Periods!AB1277) -> 0 | AO11: =IFERROR(AC11/AM11,"-") -> - | AP11: =SUM(МП_Periods!AE11,МП_Periods!AE126,МП_Periods!AE241,МП_Periods!AE356,МП_Periods!AE472,МП_Periods!AE587,МП_Periods!AE702,МП_Periods!AE817,МП_Periods!AE932,МП_Periods!AE1047,МП_Periods!AE1162,МП_Periods!AE1277) -> 0 | AQ11: =IFERROR(#REF!/AP11,"-") -> - | AS11: =IFERROR(U11/AG11,"-") -> - | AT11: =SUM(МП_Periods!AI11,МП_Periods!AI126,МП_Periods!AI241,МП_Periods!AI356,МП_Periods!AI472,МП_Periods!AI587,МП_Periods!AI702,МП_Periods!AI817,МП_Periods!AI932,МП_Periods!AI1047,МП_Periods!AI1162,МП_Periods!AI1277) -> 0 | AU11: =IFERROR(AC11/AT11,"-") -> - | AW11: =IFERROR(AX11/AT11,"-") -> - | AX11: =SUM(МП_Periods!AM11,МП_Periods!AM126,МП_Periods!AM241,МП_Periods!AM356,МП_Periods!AM472,МП_Periods!AM587,МП_Periods!AM702,МП_Periods!AM817,МП_Periods!AM932,МП_Periods!AM1047,МП_Periods!AM1162,МП_Periods!AM1277,) -> 0 | AY11: =IFERROR(AC11/AX11,"-") -> - | AZ11: =IFERROR(AX11/$AX$115,"-") -> - | BB11: =IFERROR(BE11/AC11,"-") -> - | BC11: =IFERROR(AC11/BE11,"-") -> - | BD11: =IFERROR(BE11/AX11,"-") -> - | BE11: =SUM(МП_Periods!AT11,МП_Periods!AT126,МП_Periods!AT241,МП_Periods!AT356,МП_Periods!AT472,МП_Periods!AT587,МП_Periods!AT702,МП_Periods!AT817,МП_Periods!AT932,МП_Periods!AT1047,МП_Periods!AT1162,МП_Periods!AT1277) -> 0 | BF11: =IFERROR(BE11/$BE$115,"-") -> - | BH11: =IFERROR(BI11/AX11,"-") -> - | BI11: =SUM(МП_Periods!AX11,МП_Periods!AX126,МП_Periods!AX241,МП_Periods!AX356,МП_Periods!AX472,МП_Periods!AX587,МП_Periods!AX702,МП_Periods!AX817,МП_Periods!AX932,МП_Periods!AX1047,МП_Periods!AX1162,МП_Periods!AX1277) -> 0 | BJ11: =IFERROR(AC11/BI11,"-") -> - | BK11: =IFERROR(BI11/$AX$115,"-") -> - | BM11: =IFERROR(BP11/AC11,"-") -> - | BN11: =IFERROR(AC11/BP11,"-") -> - | BO11: =IFERROR(BP11/BI11,"-") -> - | BP11: =SUM(МП_Periods!BE11,МП_Periods!BE126,МП_Periods!BE241,МП_Periods!BE356,МП_Periods!BE472,МП_Periods!BE587,МП_Periods!BE702,МП_Periods!BE817,МП_Periods!BE932,МП_Periods!BE1047,МП_Periods!BE1162,МП_Periods!BE1277) -> 0 | BQ11: =IFERROR(BP11/$BP$115,"-") -> -
S12: CPC | T12: =IFERROR(W12/U12,"-") -> - | U12: =SUM(МП_Periods!J12,МП_Periods!J127,МП_Periods!J242,МП_Periods!J357,МП_Periods!J473,МП_Periods!J588,МП_Periods!J703,МП_Periods!J818,МП_Periods!J933,МП_Periods!J1048,МП_Periods!J1163,МП_Periods!J1278) -> 0 | W12: =SUM(МП_Periods!L12,МП_Periods!L127,МП_Periods!L242,МП_Periods!L357,МП_Periods!L473,МП_Periods!L588,МП_Periods!L703,МП_Periods!L818,МП_Periods!L933,МП_Periods!L1048,МП_Periods!L1163,МП_Periods!L1278) -> 0 | Y12: =SUM(МП_Periods!N12,МП_Periods!N127,МП_Periods!N242,МП_Periods!N357,МП_Periods!N473,МП_Periods!N588,МП_Periods!N703,МП_Periods!N818,МП_Periods!N933,МП_Periods!N1048,МП_Periods!N1163,МП_Periods!N1278) -> 0 | AA12: =SUM(МП_Periods!P12,МП_Periods!P127,МП_Periods!P242,МП_Periods!P357,МП_Periods!P473,МП_Periods!P588,МП_Periods!P703,МП_Periods!P818,МП_Periods!P933,МП_Periods!P1048,МП_Periods!P1163,МП_Periods!P1278) -> 0 | AB12: =SUM(МП_Periods!Q12,МП_Periods!Q127,МП_Periods!Q242,МП_Periods!Q357,МП_Periods!Q473,МП_Periods!Q588,МП_Periods!Q703,МП_Periods!Q818,МП_Periods!Q933,МП_Periods!Q1048,МП_Periods!Q1163,МП_Periods!Q1278) -> 0 | AC12: =SUM(МП_Periods!R12,МП_Periods!R127,МП_Periods!R242,МП_Periods!R357,МП_Periods!R473,МП_Periods!R588,МП_Periods!R703,МП_Periods!R818,МП_Periods!R933,МП_Periods!R1048,МП_Periods!R1163,МП_Periods!R1278) -> 0 | AD12: =SUM(МП_Periods!S12,МП_Periods!S127,МП_Periods!S242,МП_Periods!S357,МП_Periods!S473,МП_Periods!S588,МП_Periods!S703,МП_Periods!S818,МП_Periods!S933,МП_Periods!S1048,МП_Periods!S1163,МП_Periods!S1278) -> 0 | AE12: =IFERROR(AC12/$AC$115,"-") -> - | AG12: =SUM(МП_Periods!V12,МП_Periods!V127,МП_Periods!V242,МП_Periods!V357,МП_Periods!V473,МП_Periods!V588,МП_Periods!V703,МП_Periods!V818,МП_Periods!V933,МП_Periods!V1048,МП_Periods!V1163,МП_Periods!V1278) -> 0 | AJ12: =SUM(МП_Periods!Y12,МП_Periods!Y127,МП_Periods!Y242,МП_Periods!Y357,МП_Periods!Y473,МП_Periods!Y588,МП_Periods!Y703,МП_Periods!Y818,МП_Periods!Y933,МП_Periods!Y1048,МП_Periods!Y1163,МП_Periods!Y1278) -> 0 | AK12: =SUM(МП_Periods!Z12,МП_Periods!Z127,МП_Periods!Z242,МП_Periods!Z357,МП_Periods!Z473,МП_Periods!Z588,МП_Periods!Z703,МП_Periods!Z818,МП_Periods!Z933,МП_Periods!Z1048,МП_Periods!Z1163,МП_Periods!Z1278) -> 0 | AL12: =SUM(МП_Periods!AA12,МП_Periods!AA127,МП_Periods!AA242,МП_Periods!AA357,МП_Periods!AA473,МП_Periods!AA588,МП_Periods!AA703,МП_Periods!AA818,МП_Periods!AA933,МП_Periods!AA1048,МП_Periods!AA1163,МП_Periods!AA1278) -> 0 | AM12: =SUM(МП_Periods!AB12,МП_Periods!AB127,МП_Periods!AB242,МП_Periods!AB357,МП_Periods!AB473,МП_Periods!AB588,МП_Periods!AB703,МП_Periods!AB818,МП_Periods!AB933,МП_Periods!AB1048,МП_Periods!AB1163,МП_Periods!AB1278) -> 0 | AO12: =IFERROR(AC12/AM12,"-") -> - | AP12: =SUM(МП_Periods!AE12,МП_Periods!AE127,МП_Periods!AE242,МП_Periods!AE357,МП_Periods!AE473,МП_Periods!AE588,МП_Periods!AE703,МП_Periods!AE818,МП_Periods!AE933,МП_Periods!AE1048,МП_Periods!AE1163,МП_Periods!AE1278) -> 0 | AQ12: =IFERROR(#REF!/AP12,"-") -> - | AS12: =IFERROR(U12/AG12,"-") -> - | AT12: =SUM(МП_Periods!AI12,МП_Periods!AI127,МП_Periods!AI242,МП_Periods!AI357,МП_Periods!AI473,МП_Periods!AI588,МП_Periods!AI703,МП_Periods!AI818,МП_Periods!AI933,МП_Periods!AI1048,МП_Periods!AI1163,МП_Periods!AI1278) -> 0 | AU12: =IFERROR(AC12/AT12,"-") -> - | AW12: =IFERROR(AX12/AT12,"-") -> - | AX12: =SUM(МП_Periods!AM12,МП_Periods!AM127,МП_Periods!AM242,МП_Periods!AM357,МП_Periods!AM473,МП_Periods!AM588,МП_Periods!AM703,МП_Periods!AM818,МП_Periods!AM933,МП_Periods!AM1048,МП_Periods!AM1163,МП_Periods!AM1278,) -> 0 | AY12: =IFERROR(AC12/AX12,"-") -> - | AZ12: =IFERROR(AX12/$AX$115,"-") -> - | BB12: =IFERROR(BE12/AC12,"-") -> - | BC12: =IFERROR(AC12/BE12,"-") -> - | BD12: =IFERROR(BE12/AX12,"-") -> - | BE12: =SUM(МП_Periods!AT12,МП_Periods!AT127,МП_Periods!AT242,МП_Periods!AT357,МП_Periods!AT473,МП_Periods!AT588,МП_Periods!AT703,МП_Periods!AT818,МП_Periods!AT933,МП_Periods!AT1048,МП_Periods!AT1163,МП_Periods!AT1278) -> 0 | BF12: =IFERROR(BE12/$BE$115,"-") -> - | BH12: =IFERROR(BI12/AX12,"-") -> - | BI12: =SUM(МП_Periods!AX12,МП_Periods!AX127,МП_Periods!AX242,МП_Periods!AX357,МП_Periods!AX473,МП_Periods!AX588,МП_Periods!AX703,МП_Periods!AX818,МП_Periods!AX933,МП_Periods!AX1048,МП_Periods!AX1163,МП_Periods!AX1278) -> 0 | BJ12: =IFERROR(AC12/BI12,"-") -> - | BK12: =IFERROR(BI12/$AX$115,"-") -> - | BM12: =IFERROR(BP12/AC12,"-") -> - | BN12: =IFERROR(AC12/BP12,"-") -> - | BO12: =IFERROR(BP12/BI12,"-") -> - | BP12: =SUM(МП_Periods!BE12,МП_Periods!BE127,МП_Periods!BE242,МП_Periods!BE357,МП_Periods!BE473,МП_Periods!BE588,МП_Periods!BE703,МП_Periods!BE818,МП_Periods!BE933,МП_Periods!BE1048,МП_Periods!BE1163,МП_Periods!BE1278) -> 0 | BQ12: =IFERROR(BP12/$BP$115,"-") -> -
S13: CPC | T13: =IFERROR(W13/U13,"-") -> - | U13: =SUM(МП_Periods!J13,МП_Periods!J128,МП_Periods!J243,МП_Periods!J358,МП_Periods!J474,МП_Periods!J589,МП_Periods!J704,МП_Periods!J819,МП_Periods!J934,МП_Periods!J1049,МП_Periods!J1164,МП_Periods!J1279) -> 0 | W13: =SUM(МП_Periods!L13,МП_Periods!L128,МП_Periods!L243,МП_Periods!L358,МП_Periods!L474,МП_Periods!L589,МП_Periods!L704,МП_Periods!L819,МП_Periods!L934,МП_Periods!L1049,МП_Periods!L1164,МП_Periods!L1279) -> 0 | Y13: =SUM(МП_Periods!N13,МП_Periods!N128,МП_Periods!N243,МП_Periods!N358,МП_Periods!N474,МП_Periods!N589,МП_Periods!N704,МП_Periods!N819,МП_Periods!N934,МП_Periods!N1049,МП_Periods!N1164,МП_Periods!N1279) -> 0 | AA13: =SUM(МП_Periods!P13,МП_Periods!P128,МП_Periods!P243,МП_Periods!P358,МП_Periods!P474,МП_Periods!P589,МП_Periods!P704,МП_Periods!P819,МП_Periods!P934,МП_Periods!P1049,МП_Periods!P1164,МП_Periods!P1279) -> 0 | AB13: =SUM(МП_Periods!Q13,МП_Periods!Q128,МП_Periods!Q243,МП_Periods!Q358,МП_Periods!Q474,МП_Periods!Q589,МП_Periods!Q704,МП_Periods!Q819,МП_Periods!Q934,МП_Periods!Q1049,МП_Periods!Q1164,МП_Periods!Q1279) -> 0 | AC13: =SUM(МП_Periods!R13,МП_Periods!R128,МП_Periods!R243,МП_Periods!R358,МП_Periods!R474,МП_Periods!R589,МП_Periods!R704,МП_Periods!R819,МП_Periods!R934,МП_Periods!R1049,МП_Periods!R1164,МП_Periods!R1279) -> 0 | AD13: =SUM(МП_Periods!S13,МП_Periods!S128,МП_Periods!S243,МП_Periods!S358,МП_Periods!S474,МП_Periods!S589,МП_Periods!S704,МП_Periods!S819,МП_Periods!S934,МП_Periods!S1049,МП_Periods!S1164,МП_Periods!S1279) -> 0 | AE13: =IFERROR(AC13/$AC$115,"-") -> - | AG13: =SUM(МП_Periods!V13,МП_Periods!V128,МП_Periods!V243,МП_Periods!V358,МП_Periods!V474,МП_Periods!V589,МП_Periods!V704,МП_Periods!V819,МП_Periods!V934,МП_Periods!V1049,МП_Periods!V1164,МП_Periods!V1279) -> 0 | AJ13: =SUM(МП_Periods!Y13,МП_Periods!Y128,МП_Periods!Y243,МП_Periods!Y358,МП_Periods!Y474,МП_Periods!Y589,МП_Periods!Y704,МП_Periods!Y819,МП_Periods!Y934,МП_Periods!Y1049,МП_Periods!Y1164,МП_Periods!Y1279) -> 0 | AK13: =SUM(МП_Periods!Z13,МП_Periods!Z128,МП_Periods!Z243,МП_Periods!Z358,МП_Periods!Z474,МП_Periods!Z589,МП_Periods!Z704,МП_Periods!Z819,МП_Periods!Z934,МП_Periods!Z1049,МП_Periods!Z1164,МП_Periods!Z1279) -> 0 | AL13: =SUM(МП_Periods!AA13,МП_Periods!AA128,МП_Periods!AA243,МП_Periods!AA358,МП_Periods!AA474,МП_Periods!AA589,МП_Periods!AA704,МП_Periods!AA819,МП_Periods!AA934,МП_Periods!AA1049,МП_Periods!AA1164,МП_Periods!AA1279) -> 0 | AM13: =SUM(МП_Periods!AB13,МП_Periods!AB128,МП_Periods!AB243,МП_Periods!AB358,МП_Periods!AB474,МП_Periods!AB589,МП_Periods!AB704,МП_Periods!AB819,МП_Periods!AB934,МП_Periods!AB1049,МП_Periods!AB1164,МП_Periods!AB1279) -> 0 | AO13: =IFERROR(AC13/AM13,"-") -> - | AP13: =SUM(МП_Periods!AE13,МП_Periods!AE128,МП_Periods!AE243,МП_Periods!AE358,МП_Periods!AE474,МП_Periods!AE589,МП_Periods!AE704,МП_Periods!AE819,МП_Periods!AE934,МП_Periods!AE1049,МП_Periods!AE1164,МП_Periods!AE1279) -> 0 | AQ13: =IFERROR(#REF!/AP13,"-") -> - | AS13: =IFERROR(U13/AG13,"-") -> - | AT13: =SUM(МП_Periods!AI13,МП_Periods!AI128,МП_Periods!AI243,МП_Periods!AI358,МП_Periods!AI474,МП_Periods!AI589,МП_Periods!AI704,МП_Periods!AI819,МП_Periods!AI934,МП_Periods!AI1049,МП_Periods!AI1164,МП_Periods!AI1279) -> 0 | AU13: =IFERROR(AC13/AT13,"-") -> - | AW13: =IFERROR(AX13/AT13,"-") -> - | AX13: =SUM(МП_Periods!AM13,МП_Periods!AM128,МП_Periods!AM243,МП_Periods!AM358,МП_Periods!AM474,МП_Periods!AM589,МП_Periods!AM704,МП_Periods!AM819,МП_Periods!AM934,МП_Periods!AM1049,МП_Periods!AM1164,МП_Periods!AM1279,) -> 0 | AY13: =IFERROR(AC13/AX13,"-") -> - | AZ13: =IFERROR(AX13/$AX$115,"-") -> - | BB13: =IFERROR(BE13/AC13,"-") -> - | BC13: =IFERROR(AC13/BE13,"-") -> - | BD13: =IFERROR(BE13/AX13,"-") -> - | BE13: =SUM(МП_Periods!AT13,МП_Periods!AT128,МП_Periods!AT243,МП_Periods!AT358,МП_Periods!AT474,МП_Periods!AT589,МП_Periods!AT704,МП_Periods!AT819,МП_Periods!AT934,МП_Periods!AT1049,МП_Periods!AT1164,МП_Periods!AT1279) -> 0 | BF13: =IFERROR(BE13/$BE$115,"-") -> - | BH13: =IFERROR(BI13/AX13,"-") -> - | BI13: =SUM(МП_Periods!AX13,МП_Periods!AX128,МП_Periods!AX243,МП_Periods!AX358,МП_Periods!AX474,МП_Periods!AX589,МП_Periods!AX704,МП_Periods!AX819,МП_Periods!AX934,МП_Periods!AX1049,МП_Periods!AX1164,МП_Periods!AX1279) -> 0 | BJ13: =IFERROR(AC13/BI13,"-") -> - | BK13: =IFERROR(BI13/$AX$115,"-") -> - | BM13: =IFERROR(BP13/AC13,"-") -> - | BN13: =IFERROR(AC13/BP13,"-") -> - | BO13: =IFERROR(BP13/BI13,"-") -> - | BP13: =SUM(МП_Periods!BE13,МП_Periods!BE128,МП_Periods!BE243,МП_Periods!BE358,МП_Periods!BE474,МП_Periods!BE589,МП_Periods!BE704,МП_Periods!BE819,МП_Periods!BE934,МП_Periods!BE1049,МП_Periods!BE1164,МП_Periods!BE1279) -> 0 | BQ13: =IFERROR(BP13/$BP$115,"-") -> -
S14: CPC | T14: =IFERROR(W14/U14,"-") -> - | U14: =SUM(МП_Periods!J14,МП_Periods!J129,МП_Periods!J244,МП_Periods!J359,МП_Periods!J475,МП_Periods!J590,МП_Periods!J705,МП_Periods!J820,МП_Periods!J935,МП_Periods!J1050,МП_Periods!J1165,МП_Periods!J1280) -> 0 | W14: =SUM(МП_Periods!L14,МП_Periods!L129,МП_Periods!L244,МП_Periods!L359,МП_Periods!L475,МП_Periods!L590,МП_Periods!L705,МП_Periods!L820,МП_Periods!L935,МП_Periods!L1050,МП_Periods!L1165,МП_Periods!L1280) -> 0 | Y14: =SUM(МП_Periods!N14,МП_Periods!N129,МП_Periods!N244,МП_Periods!N359,МП_Periods!N475,МП_Periods!N590,МП_Periods!N705,МП_Periods!N820,МП_Periods!N935,МП_Periods!N1050,МП_Periods!N1165,МП_Periods!N1280) -> 0 | AA14: =SUM(МП_Periods!P14,МП_Periods!P129,МП_Periods!P244,МП_Periods!P359,МП_Periods!P475,МП_Periods!P590,МП_Periods!P705,МП_Periods!P820,МП_Periods!P935,МП_Periods!P1050,МП_Periods!P1165,МП_Periods!P1280) -> 0 | AB14: =SUM(МП_Periods!Q14,МП_Periods!Q129,МП_Periods!Q244,МП_Periods!Q359,МП_Periods!Q475,МП_Periods!Q590,МП_Periods!Q705,МП_Periods!Q820,МП_Periods!Q935,МП_Periods!Q1050,МП_Periods!Q1165,МП_Periods!Q1280) -> 0 | AC14: =SUM(МП_Periods!R14,МП_Periods!R129,МП_Periods!R244,МП_Periods!R359,МП_Periods!R475,МП_Periods!R590,МП_Periods!R705,МП_Periods!R820,МП_Periods!R935,МП_Periods!R1050,МП_Periods!R1165,МП_Periods!R1280) -> 0 | AD14: =SUM(МП_Periods!S14,МП_Periods!S129,МП_Periods!S244,МП_Periods!S359,МП_Periods!S475,МП_Periods!S590,МП_Periods!S705,МП_Periods!S820,МП_Periods!S935,МП_Periods!S1050,МП_Periods!S1165,МП_Periods!S1280) -> 0 | AE14: =IFERROR(AC14/$AC$115,"-") -> - | AG14: =SUM(МП_Periods!V14,МП_Periods!V129,МП_Periods!V244,МП_Periods!V359,МП_Periods!V475,МП_Periods!V590,МП_Periods!V705,МП_Periods!V820,МП_Periods!V935,МП_Periods!V1050,МП_Periods!V1165,МП_Periods!V1280) -> 0 | AJ14: =SUM(МП_Periods!Y14,МП_Periods!Y129,МП_Periods!Y244,МП_Periods!Y359,МП_Periods!Y475,МП_Periods!Y590,МП_Periods!Y705,МП_Periods!Y820,МП_Periods!Y935,МП_Periods!Y1050,МП_Periods!Y1165,МП_Periods!Y1280) -> 0 | AK14: =SUM(МП_Periods!Z14,МП_Periods!Z129,МП_Periods!Z244,МП_Periods!Z359,МП_Periods!Z475,МП_Periods!Z590,МП_Periods!Z705,МП_Periods!Z820,МП_Periods!Z935,МП_Periods!Z1050,МП_Periods!Z1165,МП_Periods!Z1280) -> 0 | AL14: =SUM(МП_Periods!AA14,МП_Periods!AA129,МП_Periods!AA244,МП_Periods!AA359,МП_Periods!AA475,МП_Periods!AA590,МП_Periods!AA705,МП_Periods!AA820,МП_Periods!AA935,МП_Periods!AA1050,МП_Periods!AA1165,МП_Periods!AA1280) -> 0 | AM14: =SUM(МП_Periods!AB14,МП_Periods!AB129,МП_Periods!AB244,МП_Periods!AB359,МП_Periods!AB475,МП_Periods!AB590,МП_Periods!AB705,МП_Periods!AB820,МП_Periods!AB935,МП_Periods!AB1050,МП_Periods!AB1165,МП_Periods!AB1280) -> 0 | AO14: =IFERROR(AC14/AM14,"-") -> - | AP14: =SUM(МП_Periods!AE14,МП_Periods!AE129,МП_Periods!AE244,МП_Periods!AE359,МП_Periods!AE475,МП_Periods!AE590,МП_Periods!AE705,МП_Periods!AE820,МП_Periods!AE935,МП_Periods!AE1050,МП_Periods!AE1165,МП_Periods!AE1280) -> 0 | AQ14: =IFERROR(#REF!/AP14,"-") -> - | AS14: =IFERROR(U14/AG14,"-") -> - | AT14: =SUM(МП_Periods!AI14,МП_Periods!AI129,МП_Periods!AI244,МП_Periods!AI359,МП_Periods!AI475,МП_Periods!AI590,МП_Periods!AI705,МП_Periods!AI820,МП_Periods!AI935,МП_Periods!AI1050,МП_Periods!AI1165,МП_Periods!AI1280) -> 0 | AU14: =IFERROR(AC14/AT14,"-") -> - | AW14: =IFERROR(AX14/AT14,"-") -> - | AX14: =SUM(МП_Periods!AM14,МП_Periods!AM129,МП_Periods!AM244,МП_Periods!AM359,МП_Periods!AM475,МП_Periods!AM590,МП_Periods!AM705,МП_Periods!AM820,МП_Periods!AM935,МП_Periods!AM1050,МП_Periods!AM1165,МП_Periods!AM1280,) -> 0 | AY14: =IFERROR(AC14/AX14,"-") -> - | AZ14: =IFERROR(AX14/$AX$115,"-") -> - | BB14: =IFERROR(BE14/AC14,"-") -> - | BC14: =IFERROR(AC14/BE14,"-") -> - | BD14: =IFERROR(BE14/AX14,"-") -> - | BE14: =SUM(МП_Periods!AT14,МП_Periods!AT129,МП_Periods!AT244,МП_Periods!AT359,МП_Periods!AT475,МП_Periods!AT590,МП_Periods!AT705,МП_Periods!AT820,МП_Periods!AT935,МП_Periods!AT1050,МП_Periods!AT1165,МП_Periods!AT1280) -> 0 | BF14: =IFERROR(BE14/$BE$115,"-") -> - | BH14: =IFERROR(BI14/AX14,"-") -> - | BI14: =SUM(МП_Periods!AX14,МП_Periods!AX129,МП_Periods!AX244,МП_Periods!AX359,МП_Periods!AX475,МП_Periods!AX590,МП_Periods!AX705,МП_Periods!AX820,МП_Periods!AX935,МП_Periods!AX1050,МП_Periods!AX1165,МП_Periods!AX1280) -> 0 | BJ14: =IFERROR(AC14/BI14,"-") -> - | BK14: =IFERROR(BI14/$AX$115,"-") -> - | BM14: =IFERROR(BP14/AC14,"-") -> - | BN14: =IFERROR(AC14/BP14,"-") -> - | BO14: =IFERROR(BP14/BI14,"-") -> - | BP14: =SUM(МП_Periods!BE14,МП_Periods!BE129,МП_Periods!BE244,МП_Periods!BE359,МП_Periods!BE475,МП_Periods!BE590,МП_Periods!BE705,МП_Periods!BE820,МП_Periods!BE935,МП_Periods!BE1050,МП_Periods!BE1165,МП_Periods!BE1280) -> 0 | BQ14: =IFERROR(BP14/$BP$115,"-") -> -
